Workbook

Sheet Bjälklag (C20-25)
A1: Slagg mängd | B1: Gjuttemperatur | C1: Temperatur motgjutningsyta | D1: Väderskydd, uppvärmning (ingen vind) | E1: Täckning [mm] | F1: Temperatur | G1: Vind | H1: <14 d och >70 % [Dagar] | I1: OK <14 Dagar | J1: <21 d och >70 % [Dagar] | K1: OK <21 Dagar | L1: Kommentar | M1: Åtgärdskåd
A2: 0.4 | B2: =Förutsättningar!M$18 -> 15 | C2: =Förutsättningar!N$18 -> 20 | D2: - | E2: - | F2: 20 | G2: 0 | H2: 7.7 | I2: OK14 | J2: 17.5 | M2: =Table141719202122[[#This Row],[Slagg mängd]]&Table141719202122[[#This Row],[Gjuttemperatur]]&Table141719202122[[#This Row],[Temperatur motgjutningsyta]]&Table141719202122[[#This Row],[Väderskydd, uppvärmning (ingen vind)]]&Table141719202122[[#This Row],[Täckning '[mm']]]&Table141719202122[[#This Row],[OK <14 Dagar]]&Table141719202122[[#This Row],[OK <21 Dagar]]&Table141719202122[[#This Row],[Kommentar]] -> 0,41520--OK14
A3: 0.4 | B3: =Förutsättningar!$M$18 -> 15 | C3: =Förutsättningar!N$18 -> 20 | D3: - | E3: - | F3: 20 | G3: 2 | H3: 8.1 | I3: OK14 | M3: =Table141719202122[[#This Row],[Slagg mängd]]&Table141719202122[[#This Row],[Gjuttemperatur]]&Table141719202122[[#This Row],[Temperatur motgjutningsyta]]&Table141719202122[[#This Row],[Väderskydd, uppvärmning (ingen vind)]]&Table141719202122[[#This Row],[Täckning '[mm']]]&Table141719202122[[#This Row],[OK <14 Dagar]]&Table141719202122[[#This Row],[OK <21 Dagar]]&Table141719202122[[#This Row],[Kommentar]] -> 0,41520--OK14
A4: 0.4 | B4: =Förutsättningar!$M$18 -> 15 | C4: =Förutsättningar!N$18 -> 20 | D4: - | E4: - | F4: 20 | G4: 7 | H4: 8.3 | I4: OK14 | M4: =Table141719202122[[#This Row],[Slagg mängd]]&Table141719202122[[#This Row],[Gjuttemperatur]]&Table141719202122[[#This Row],[Temperatur motgjutningsyta]]&Table141719202122[[#This Row],[Väderskydd, uppvärmning (ingen vind)]]&Table141719202122[[#This Row],[Täckning '[mm']]]&Table141719202122[[#This Row],[OK <14 Dagar]]&Table141719202122[[#This Row],[OK <21 Dagar]]&Table141719202122[[#This Row],[Kommentar]] -> 0,41520--OK14
A5: 0.4 | B5: =Förutsättningar!$M$18 -> 15 | C5: =Förutsättningar!N$18 -> 20 | D5: - | E5: - | F5: 20 | G5: 12 | H5: 8.4 | I5: OK14 | M5: =Table141719202122[[#This Row],[Slagg mängd]]&Table141719202122[[#This Row],[Gjuttemperatur]]&Table141719202122[[#This Row],[Temperatur motgjutningsyta]]&Table141719202122[[#This Row],[Väderskydd, uppvärmning (ingen vind)]]&Table141719202122[[#This Row],[Täckning '[mm']]]&Table141719202122[[#This Row],[OK <14 Dagar]]&Table141719202122[[#This Row],[OK <21 Dagar]]&Table141719202122[[#This Row],[Kommentar]] -> 0,41520--OK14
A6: 0.4 | B6: =Förutsättningar!$M$18 -> 15 | C6: =Förutsättningar!N$18 -> 20 | D6: - | E6: - | F6: 20 | G6: 20 | H6: 8.4 | I6: OK14 | M6: =Table141719202122[[#This Row],[Slagg mängd]]&Table141719202122[[#This Row],[Gjuttemperatur]]&Table141719202122[[#This Row],[Temperatur motgjutningsyta]]&Table141719202122[[#This Row],[Väderskydd, uppvärmning (ingen vind)]]&Table141719202122[[#This Row],[Täckning '[mm']]]&Table141719202122[[#This Row],[OK <14 Dagar]]&Table141719202122[[#This Row],[OK <21 Dagar]]&Table141719202122[[#This Row],[Kommentar]] -> 0,41520--OK14
A7: 0.4 | B7: =Förutsättningar!M$19 -> 15 | C7: =Förutsättningar!N$19 -> 15 | D7: - | E7: - | F7: 15 | G7: 0 | H7: 10.1 | I7: OK14 | M7: =Table141719202122[[#This Row],[Slagg mängd]]&Table141719202122[[#This Row],[Gjuttemperatur]]&Table141719202122[[#This Row],[Temperatur motgjutningsyta]]&Table141719202122[[#This Row],[Väderskydd, uppvärmning (ingen vind)]]&Table141719202122[[#This Row],[Täckning '[mm']]]&Table141719202122[[#This Row],[OK <14 Dagar]]&Table141719202122[[#This Row],[OK <21 Dagar]]&Table141719202122[[#This Row],[Kommentar]] -> 0,41515--OK14
A8: 0.4 | B8: =Förutsättningar!M$19 -> 15 | C8: =Förutsättningar!N$19 -> 15 | D8: - | E8: - | F8: 15 | G8: 2 | H8: 10.7 | I8: OK14 | M8: =Table141719202122[[#This Row],[Slagg mängd]]&Table141719202122[[#This Row],[Gjuttemperatur]]&Table141719202122[[#This Row],[Temperatur motgjutningsyta]]&Table141719202122[[#This Row],[Väderskydd, uppvärmning (ingen vind)]]&Table141719202122[[#This Row],[Täckning '[mm']]]&Table141719202122[[#This Row],[OK <14 Dagar]]&Table141719202122[[#This Row],[OK <21 Dagar]]&Table141719202122[[#This Row],[Kommentar]] -> 0,41515--OK14
A9: 0.4 | B9: =Förutsättningar!M$19 -> 15 | C9: =Förutsättningar!N$19 -> 15 | D9: - | E9: - | F9: 15 | G9: 7 | H9: 11 | I9: OK14 | M9: =Table141719202122[[#This Row],[Slagg mängd]]&Table141719202122[[#This Row],[Gjuttemperatur]]&Table141719202122[[#This Row],[Temperatur motgjutningsyta]]&Table141719202122[[#This Row],[Väderskydd, uppvärmning (ingen vind)]]&Table141719202122[[#This Row],[Täckning '[mm']]]&Table141719202122[[#This Row],[OK <14 Dagar]]&Table141719202122[[#This Row],[OK <21 Dagar]]&Table141719202122[[#This Row],[Kommentar]] -> 0,41515--OK14
A10: 0.4 | B10: =Förutsättningar!M$19 -> 15 | C10: =Förutsättningar!N$19 -> 15 | D10: - | E10: - | F10: 15 | G10: 12 | H10: 11 | I10: OK14 | M10: =Table141719202122[[#This Row],[Slagg mängd]]&Table141719202122[[#This Row],[Gjuttemperatur]]&Table141719202122[[#This Row],[Temperatur motgjutningsyta]]&Table141719202122[[#This Row],[Väderskydd, uppvärmning (ingen vind)]]&Table141719202122[[#This Row],[Täckning '[mm']]]&Table141719202122[[#This Row],[OK <14 Dagar]]&Table141719202122[[#This Row],[OK <21 Dagar]]&Table141719202122[[#This Row],[Kommentar]] -> 0,41515--OK14
A11: 0.4 | B11: =Förutsättningar!M$19 -> 15 | C11: =Förutsättningar!N$19 -> 15 | D11: - | E11: - | F11: 15 | G11: 20 | H11: 11.1 | I11: OK14 | M11: =Table141719202122[[#This Row],[Slagg mängd]]&Table141719202122[[#This Row],[Gjuttemperatur]]&Table141719202122[[#This Row],[Temperatur motgjutningsyta]]&Table141719202122[[#This Row],[Väderskydd, uppvärmning (ingen vind)]]&Table141719202122[[#This Row],[Täckning '[mm']]]&Table141719202122[[#This Row],[OK <14 Dagar]]&Table141719202122[[#This Row],[OK <21 Dagar]]&Table141719202122[[#This Row],[Kommentar]] -> 0,41515--OK14
A12: 0.4 | B12: =Förutsättningar!M$20 -> 15 | C12: =Förutsättningar!N$20 -> 10 | D12: - | E12: - | F12: 10 | G12: 0 | H12: 14 | I12: OK14 | M12: =Table141719202122[[#This Row],[Slagg mängd]]&Table141719202122[[#This Row],[Gjuttemperatur]]&Table141719202122[[#This Row],[Temperatur motgjutningsyta]]&Table141719202122[[#This Row],[Väderskydd, uppvärmning (ingen vind)]]&Table141719202122[[#This Row],[Täckning '[mm']]]&Table141719202122[[#This Row],[OK <14 Dagar]]&Table141719202122[[#This Row],[OK <21 Dagar]]&Table141719202122[[#This Row],[Kommentar]] -> 0,41510--OK14
A13: 0.4 | B13: =Förutsättningar!M$20 -> 15 | C13: =Förutsättningar!N$20 -> 10 | D13: 0 | E13: 10 | F13: 10 | G13: 2 | H13: 13.5 | I13: OK14 | M13: =Table141719202122[[#This Row],[Slagg mängd]]&Table141719202122[[#This Row],[Gjuttemperatur]]&Table141719202122[[#This Row],[Temperatur motgjutningsyta]]&Table141719202122[[#This Row],[Väderskydd, uppvärmning (ingen vind)]]&Table141719202122[[#This Row],[Täckning '[mm']]]&Table141719202122[[#This Row],[OK <14 Dagar]]&Table141719202122[[#This Row],[OK <21 Dagar]]&Table141719202122[[#This Row],[Kommentar]] -> 0,41510010OK14
A14: 0.4 | B14: =Förutsättningar!M$20 -> 15 | C14: =Förutsättningar!N$20 -> 10 | D14: 0 | E14: 10 | F14: 10 | G14: 7 | H14: 13.6 | I14: OK14 | M14: =Table141719202122[[#This Row],[Slagg mängd]]&Table141719202122[[#This Row],[Gjuttemperatur]]&Table141719202122[[#This Row],[Temperatur motgjutningsyta]]&Table141719202122[[#This Row],[Väderskydd, uppvärmning (ingen vind)]]&Table141719202122[[#This Row],[Täckning '[mm']]]&Table141719202122[[#This Row],[OK <14 Dagar]]&Table141719202122[[#This Row],[OK <21 Dagar]]&Table141719202122[[#This Row],[Kommentar]] -> 0,41510010OK14
A15: 0.4 | B15: =Förutsättningar!M$20 -> 15 | C15: =Förutsättningar!N$20 -> 10 | D15: 0 | E15: 10 | F15: 10 | G15: 12 | H15: 13.7 | I15: OK14 | M15: =Table141719202122[[#This Row],[Slagg mängd]]&Table141719202122[[#This Row],[Gjuttemperatur]]&Table141719202122[[#This Row],[Temperatur motgjutningsyta]]&Table141719202122[[#This Row],[Väderskydd, uppvärmning (ingen vind)]]&Table141719202122[[#This Row],[Täckning '[mm']]]&Table141719202122[[#This Row],[OK <14 Dagar]]&Table141719202122[[#This Row],[OK <21 Dagar]]&Table141719202122[[#This Row],[Kommentar]] -> 0,41510010OK14
A16: 0.4 | B16: =Förutsättningar!M$20 -> 15 | C16: =Förutsättningar!N$20 -> 10 | D16: 0 | E16: 10 | F16: 10 | G16: 20 | H16: 13.7 | I16: OK14 | M16: =Table141719202122[[#This Row],[Slagg mängd]]&Table141719202122[[#This Row],[Gjuttemperatur]]&Table141719202122[[#This Row],[Temperatur motgjutningsyta]]&Table141719202122[[#This Row],[Väderskydd, uppvärmning (ingen vind)]]&Table141719202122[[#This Row],[Täckning '[mm']]]&Table141719202122[[#This Row],[OK <14 Dagar]]&Table141719202122[[#This Row],[OK <21 Dagar]]&Table141719202122[[#This Row],[Kommentar]] -> 0,41510010OK14
A17: 0.4 | B17: =Förutsättningar!M$21 -> 20 | C17: =Förutsättningar!N$21 -> 5 | D17: 20 | E17: - | F17: 5 | G17: 0 | H17: 10.5 | I17: OK14 | M17: =Table141719202122[[#This Row],[Slagg mängd]]&Table141719202122[[#This Row],[Gjuttemperatur]]&Table141719202122[[#This Row],[Temperatur motgjutningsyta]]&Table141719202122[[#This Row],[Väderskydd, uppvärmning (ingen vind)]]&Table141719202122[[#This Row],[Täckning '[mm']]]&Table141719202122[[#This Row],[OK <14 Dagar]]&Table141719202122[[#This Row],[OK <21 Dagar]]&Table141719202122[[#This Row],[Kommentar]] -> 0,420520-OK14
A18: 0.4 | B18: =Förutsättningar!M$21 -> 20 | C18: =Förutsättningar!N$21 -> 5 | D18: 20 | E18: - | F18: 5 | G18: 2 | H18: 13.1 | I18: OK14 | M18: =Table141719202122[[#This Row],[Slagg mängd]]&Table141719202122[[#This Row],[Gjuttemperatur]]&Table141719202122[[#This Row],[Temperatur motgjutningsyta]]&Table141719202122[[#This Row],[Väderskydd, uppvärmning (ingen vind)]]&Table141719202122[[#This Row],[Täckning '[mm']]]&Table141719202122[[#This Row],[OK <14 Dagar]]&Table141719202122[[#This Row],[OK <21 Dagar]]&Table141719202122[[#This Row],[Kommentar]] -> 0,420520-OK14
A19: 0.4 | B19: =Förutsättningar!M$21 -> 20 | C19: =Förutsättningar!N$21 -> 5 | D19: 20 | E19: Presenning | F19: 5 | G19: 7 | H19: 9.3 | I19: OK14 | M19: =Table141719202122[[#This Row],[Slagg mängd]]&Table141719202122[[#This Row],[Gjuttemperatur]]&Table141719202122[[#This Row],[Temperatur motgjutningsyta]]&Table141719202122[[#This Row],[Väderskydd, uppvärmning (ingen vind)]]&Table141719202122[[#This Row],[Täckning '[mm']]]&Table141719202122[[#This Row],[OK <14 Dagar]]&Table141719202122[[#This Row],[OK <21 Dagar]]&Table141719202122[[#This Row],[Kommentar]] -> 0,420520PresenningOK14
A20: 0.4 | B20: =Förutsättningar!M$21 -> 20 | C20: =Förutsättningar!N$21 -> 5 | D20: 20 | E20: Presenning | F20: 5 | G20: 12 | H20: 9.5 | I20: OK14 | M20: =Table141719202122[[#This Row],[Slagg mängd]]&Table141719202122[[#This Row],[Gjuttemperatur]]&Table141719202122[[#This Row],[Temperatur motgjutningsyta]]&Table141719202122[[#This Row],[Väderskydd, uppvärmning (ingen vind)]]&Table141719202122[[#This Row],[Täckning '[mm']]]&Table141719202122[[#This Row],[OK <14 Dagar]]&Table141719202122[[#This Row],[OK <21 Dagar]]&Table141719202122[[#This Row],[Kommentar]] -> 0,420520PresenningOK14
A21: 0.4 | B21: =Förutsättningar!M$21 -> 20 | C21: =Förutsättningar!N$21 -> 5 | D21: 20 | E21: Presenning | F21: 5 | G21: 20 | H21: 9.5 | I21: OK14 | M21: =Table141719202122[[#This Row],[Slagg mängd]]&Table141719202122[[#This Row],[Gjuttemperatur]]&Table141719202122[[#This Row],[Temperatur motgjutningsyta]]&Table141719202122[[#This Row],[Väderskydd, uppvärmning (ingen vind)]]&Table141719202122[[#This Row],[Täckning '[mm']]]&Table141719202122[[#This Row],[OK <14 Dagar]]&Table141719202122[[#This Row],[OK <21 Dagar]]&Table141719202122[[#This Row],[Kommentar]] -> 0,420520PresenningOK14
A22: 0.4 | B22: =Förutsättningar!M$22 -> 20 | C22: =Förutsättningar!N$22 -> 5 | D22: 20 | E22: Presenning | F22: 0 | G22: 0 | H22: 13.6 | I22: OK14 | M22: =Table141719202122[[#This Row],[Slagg mängd]]&Table141719202122[[#This Row],[Gjuttemperatur]]&Table141719202122[[#This Row],[Temperatur motgjutningsyta]]&Table141719202122[[#This Row],[Väderskydd, uppvärmning (ingen vind)]]&Table141719202122[[#This Row],[Täckning '[mm']]]&Table141719202122[[#This Row],[OK <14 Dagar]]&Table141719202122[[#This Row],[OK <21 Dagar]]&Table141719202122[[#This Row],[Kommentar]] -> 0,420520PresenningOK14
A23: 0.4 | B23: =Förutsättningar!M$22 -> 20 | C23: =Förutsättningar!N$22 -> 5 | D23: 20 | E23: 10 | F23: 0 | G23: 2 | H23: 11.9 | I23: OK14 | M23: =Table141719202122[[#This Row],[Slagg mängd]]&Table141719202122[[#This Row],[Gjuttemperatur]]&Table141719202122[[#This Row],[Temperatur motgjutningsyta]]&Table141719202122[[#This Row],[Väderskydd, uppvärmning (ingen vind)]]&Table141719202122[[#This Row],[Täckning '[mm']]]&Table141719202122[[#This Row],[OK <14 Dagar]]&Table141719202122[[#This Row],[OK <21 Dagar]]&Table141719202122[[#This Row],[Kommentar]] -> 0,42052010OK14
A24: 0.4 | B24: =Förutsättningar!M$22 -> 20 | C24: =Förutsättningar!N$22 -> 5 | D24: 20 | E24: 10 | F24: 0 | G24: 7 | H24: 12.7 | I24: OK14 | M24: =Table141719202122[[#This Row],[Slagg mängd]]&Table141719202122[[#This Row],[Gjuttemperatur]]&Table141719202122[[#This Row],[Temperatur motgjutningsyta]]&Table141719202122[[#This Row],[Väderskydd, uppvärmning (ingen vind)]]&Table141719202122[[#This Row],[Täckning '[mm']]]&Table141719202122[[#This Row],[OK <14 Dagar]]&Table141719202122[[#This Row],[OK <21 Dagar]]&Table141719202122[[#This Row],[Kommentar]] -> 0,42052010OK14
A25: 0.4 | B25: =Förutsättningar!M$22 -> 20 | C25: =Förutsättningar!N$22 -> 5 | D25: 20 | E25: 10 | F25: 0 | G25: 12 | H25: 12.9 | I25: OK14 | M25: =Table141719202122[[#This Row],[Slagg mängd]]&Table141719202122[[#This Row],[Gjuttemperatur]]&Table141719202122[[#This Row],[Temperatur motgjutningsyta]]&Table141719202122[[#This Row],[Väderskydd, uppvärmning (ingen vind)]]&Table141719202122[[#This Row],[Täckning '[mm']]]&Table141719202122[[#This Row],[OK <14 Dagar]]&Table141719202122[[#This Row],[OK <21 Dagar]]&Table141719202122[[#This Row],[Kommentar]] -> 0,42052010OK14
A26: 0.4 | B26: =Förutsättningar!M$22 -> 20 | C26: =Förutsättningar!N$22 -> 5 | D26: 20 | E26: 10 | F26: 0 | G26: 20 | H26: 13 | I26: OK14 | M26: =Table141719202122[[#This Row],[Slagg mängd]]&Table141719202122[[#This Row],[Gjuttemperatur]]&Table141719202122[[#This Row],[Temperatur motgjutningsyta]]&Table141719202122[[#This Row],[Väderskydd, uppvärmning (ingen vind)]]&Table141719202122[[#This Row],[Täckning '[mm']]]&Table141719202122[[#This Row],[OK <14 Dagar]]&Table141719202122[[#This Row],[OK <21 Dagar]]&Table141719202122[[#This Row],[Kommentar]] -> 0,42052010OK14
A27: 0.4 | B27: =Förutsättningar!M$23 -> 20 | C27: =Förutsättningar!N$23 -> 5 | D27: 20 | E27: 20 | F27: -5 | G27: 0 | H27: 12.9 | I27: OK14 | M27: =Table141719202122[[#This Row],[Slagg mängd]]&Table141719202122[[#This Row],[Gjuttemperatur]]&Table141719202122[[#This Row],[Temperatur motgjutningsyta]]&Table141719202122[[#This Row],[Väderskydd, uppvärmning (ingen vind)]]&Table141719202122[[#This Row],[Täckning '[mm']]]&Table141719202122[[#This Row],[OK <14 Dagar]]&Table141719202122[[#This Row],[OK <21 Dagar]]&Table141719202122[[#This Row],[Kommentar]] -> 0,42052020OK14
A28: 0.4 | B28: =Förutsättningar!M$23 -> 20 | C28: =Förutsättningar!N$23 -> 5 | D28: 20 | E28: 20 | F28: -5 | G28: 2 | H28: 13.8 | I28: OK14 | M28: =Table141719202122[[#This Row],[Slagg mängd]]&Table141719202122[[#This Row],[Gjuttemperatur]]&Table141719202122[[#This Row],[Temperatur motgjutningsyta]]&Table141719202122[[#This Row],[Väderskydd, uppvärmning (ingen vind)]]&Table141719202122[[#This Row],[Täckning '[mm']]]&Table141719202122[[#This Row],[OK <14 Dagar]]&Table141719202122[[#This Row],[OK <21 Dagar]]&Table141719202122[[#This Row],[Kommentar]] -> 0,42052020OK14
A29: 0.4 | B29: =Förutsättningar!M$23 -> 20 | C29: =Förutsättningar!N$23 -> 5 | D29: 20 | E29: 30 | F29: -5 | G29: 7 | H29: 12.7 | I29: OK14 | M29: =Table141719202122[[#This Row],[Slagg mängd]]&Table141719202122[[#This Row],[Gjuttemperatur]]&Table141719202122[[#This Row],[Temperatur motgjutningsyta]]&Table141719202122[[#This Row],[Väderskydd, uppvärmning (ingen vind)]]&Table141719202122[[#This Row],[Täckning '[mm']]]&Table141719202122[[#This Row],[OK <14 Dagar]]&Table141719202122[[#This Row],[OK <21 Dagar]]&Table141719202122[[#This Row],[Kommentar]] -> 0,42052030OK14
A30: 0.4 | B30: =Förutsättningar!M$23 -> 20 | C30: =Förutsättningar!N$23 -> 5 | D30: 20 | E30: 30 | F30: -5 | G30: 12 | H30: 12.8 | I30: OK14 | M30: =Table141719202122[[#This Row],[Slagg mängd]]&Table141719202122[[#This Row],[Gjuttemperatur]]&Table141719202122[[#This Row],[Temperatur motgjutningsyta]]&Table141719202122[[#This Row],[Väderskydd, uppvärmning (ingen vind)]]&Table141719202122[[#This Row],[Täckning '[mm']]]&Table141719202122[[#This Row],[OK <14 Dagar]]&Table141719202122[[#This Row],[OK <21 Dagar]]&Table141719202122[[#This Row],[Kommentar]] -> 0,42052030OK14
A31: 0.4 | B31: =Förutsättningar!M$23 -> 20 | C31: =Förutsättningar!N$23 -> 5 | D31: 20 | E31: 30 | F31: -5 | G31: 20 | H31: 12.9 | I31: OK14 | M31: =Table141719202122[[#This Row],[Slagg mängd]]&Table141719202122[[#This Row],[Gjuttemperatur]]&Table141719202122[[#This Row],[Temperatur motgjutningsyta]]&Table141719202122[[#This Row],[Väderskydd, uppvärmning (ingen vind)]]&Table141719202122[[#This Row],[Täckning '[mm']]]&Table141719202122[[#This Row],[OK <14 Dagar]]&Table141719202122[[#This Row],[OK <21 Dagar]]&Table141719202122[[#This Row],[Kommentar]] -> 0,42052030OK14
A32: 0.3 | B32: =Förutsättningar!M$24 -> 20 | C32: =Förutsättningar!N$24 -> 5 | D32: 20 | E32: 50 | F32: -10 | G32: 0 | H32: 12.9 | I32: OK14 | M32: =Table141719202122[[#This Row],[Slagg mängd]]&Table141719202122[[#This Row],[Gjuttemperatur]]&Table141719202122[[#This Row],[Temperatur motgjutningsyta]]&Table141719202122[[#This Row],[Väderskydd, uppvärmning (ingen vind)]]&Table141719202122[[#This Row],[Täckning '[mm']]]&Table141719202122[[#This Row],[OK <14 Dagar]]&Table141719202122[[#This Row],[OK <21 Dagar]]&Table141719202122[[#This Row],[Kommentar]] -> 0,32052050OK14
A33: 0.3 | B33: =Förutsättningar!M$24 -> 20 | C33: =Förutsättningar!N$24 -> 5 | D33: 20 | E33: 50 | F33: -10 | G33: 2 | H33: 13.3 | I33: OK14 | M33: =Table141719202122[[#This Row],[Slagg mängd]]&Table141719202122[[#This Row],[Gjuttemperatur]]&Table141719202122[[#This Row],[Temperatur motgjutningsyta]]&Table141719202122[[#This Row],[Väderskydd, uppvärmning (ingen vind)]]&Table141719202122[[#This Row],[Täckning '[mm']]]&Table141719202122[[#This Row],[OK <14 Dagar]]&Table141719202122[[#This Row],[OK <21 Dagar]]&Table141719202122[[#This Row],[Kommentar]] -> 0,32052050OK14
A34: 0.3 | B34: =Förutsättningar!M$24 -> 20 | C34: =Förutsättningar!N$24 -> 5 | D34: 20 | E34: 50 | F34: -10 | G34: 7 | H34: 13.7 | I34: OK14 | M34: =Table141719202122[[#This Row],[Slagg mängd]]&Table141719202122[[#This Row],[Gjuttemperatur]]&Table141719202122[[#This Row],[Temperatur motgjutningsyta]]&Table141719202122[[#This Row],[Väderskydd, uppvärmning (ingen vind)]]&Table141719202122[[#This Row],[Täckning '[mm']]]&Table141719202122[[#This Row],[OK <14 Dagar]]&Table141719202122[[#This Row],[OK <21 Dagar]]&Table141719202122[[#This Row],[Kommentar]] -> 0,32052050OK14
A35: - | B35: - | C35: - | D35: - | E35: - | F35: -10 | G35: 12 | L35: Frys innan täck | M35: =Table141719202122[[#This Row],[Slagg mängd]]&Table141719202122[[#This Row],[Gjuttemperatur]]&Table141719202122[[#This Row],[Temperatur motgjutningsyta]]&Table141719202122[[#This Row],[Väderskydd, uppvärmning (ingen vind)]]&Table141719202122[[#This Row],[Täckning '[mm']]]&Table141719202122[[#This Row],[OK <14 Dagar]]&Table141719202122[[#This Row],[OK <21 Dagar]]&Table141719202122[[#This Row],[Kommentar]] -> -----Frys innan täck
A36: - | B36: - | C36: - | D36: - | E36: - | F36: -10 | G36: 20 | L36: Frys innan täck | M36: =Table141719202122[[#This Row],[Slagg mängd]]&Table141719202122[[#This Row],[Gjuttemperatur]]&Table141719202122[[#This Row],[Temperatur motgjutningsyta]]&Table141719202122[[#This Row],[Väderskydd, uppvärmning (ingen vind)]]&Table141719202122[[#This Row],[Täckning '[mm']]]&Table141719202122[[#This Row],[OK <14 Dagar]]&Table141719202122[[#This Row],[OK <21 Dagar]]&Table141719202122[[#This Row],[Kommentar]] -> -----Frys innan täck
A37: 0.1 | B37: =Förutsättningar!M$25 -> 15 | C37: =Förutsättningar!N$25 -> 5 | D37: 20 | E37: 50 | F37: -15 | G37: 0 | H37: 13 | I37: OK14 | M37: =Table141719202122[[#This Row],[Slagg mängd]]&Table141719202122[[#This Row],[Gjuttemperatur]]&Table141719202122[[#This Row],[Temperatur motgjutningsyta]]&Table141719202122[[#This Row],[Väderskydd, uppvärmning (ingen vind)]]&Table141719202122[[#This Row],[Täckning '[mm']]]&Table141719202122[[#This Row],[OK <14 Dagar]]&Table141719202122[[#This Row],[OK <21 Dagar]]&Table141719202122[[#This Row],[Kommentar]] -> 0,11552050OK14
A38: 0.1 | B38: =Förutsättningar!M$25 -> 15 | C38: =Förutsättningar!N$25 -> 5 | D38: 20 | E38: 50 | F38: -15 | G38: 2 | H38: 13.5 | I38: OK14 | M38: =Table141719202122[[#This Row],[Slagg mängd]]&Table141719202122[[#This Row],[Gjuttemperatur]]&Table141719202122[[#This Row],[Temperatur motgjutningsyta]]&Table141719202122[[#This Row],[Väderskydd, uppvärmning (ingen vind)]]&Table141719202122[[#This Row],[Täckning '[mm']]]&Table141719202122[[#This Row],[OK <14 Dagar]]&Table141719202122[[#This Row],[OK <21 Dagar]]&Table141719202122[[#This Row],[Kommentar]] -> 0,11552050OK14
A39: - | B39: - | C39: - | D39: - | E39: - | F39: -15 | G39: 7 | L39: Frys innan täck | M39: =Table141719202122[[#This Row],[Slagg mängd]]&Table141719202122[[#This Row],[Gjuttemperatur]]&Table141719202122[[#This Row],[Temperatur motgjutningsyta]]&Table141719202122[[#This Row],[Väderskydd, uppvärmning (ingen vind)]]&Table141719202122[[#This Row],[Täckning '[mm']]]&Table141719202122[[#This Row],[OK <14 Dagar]]&Table141719202122[[#This Row],[OK <21 Dagar]]&Table141719202122[[#This Row],[Kommentar]] -> -----Frys innan täck
A40: - | B40: - | C40: - | D40: - | E40: - | F40: -15 | G40: 12 | L40: Frys innan täck | M40: =Table141719202122[[#This Row],[Slagg mängd]]&Table141719202122[[#This Row],[Gjuttemperatur]]&Table141719202122[[#This Row],[Temperatur motgjutningsyta]]&Table141719202122[[#This Row],[Väderskydd, uppvärmning (ingen vind)]]&Table141719202122[[#This Row],[Täckning '[mm']]]&Table141719202122[[#This Row],[OK <14 Dagar]]&Table141719202122[[#This Row],[OK <21 Dagar]]&Table141719202122[[#This Row],[Kommentar]] -> -----Frys innan täck
...

Sheet Bjälklag (C25-30)
A1: Slagg mängd | B1: Gjuttemperatur | C1: Temperatur motgjutningsyta | D1: Väderskydd, uppvärmning (ingen vind) | E1: Täckning [mm] | F1: Temperatur | G1: Vind | H1: <14 d och >70 % [Dagar] | I1: OK <14 Dagar | J1: <21 d och >70 % [Dagar] | K1: OK <21 Dagar | L1: Kommentar | M1: Åtgärdskåd
A2: 0.4 | B2: =Förutsättningar!M$18 -> 15 | C2: =Förutsättningar!N$18 -> 20 | D2: - | E2: - | F2: 20 | G2: 0 | H2: 7.1 | I2: OK14 | J2: 21 | M2: =Table1417192021[[#This Row],[Slagg mängd]]&Table1417192021[[#This Row],[Gjuttemperatur]]&Table1417192021[[#This Row],[Temperatur motgjutningsyta]]&Table1417192021[[#This Row],[Väderskydd, uppvärmning (ingen vind)]]&Table1417192021[[#This Row],[Täckning '[mm']]]&Table1417192021[[#This Row],[OK <14 Dagar]]&Table1417192021[[#This Row],[OK <21 Dagar]]&Table1417192021[[#This Row],[Kommentar]] -> 0,41520--OK14
A3: 0.4 | B3: =Förutsättningar!$M$18 -> 15 | C3: =Förutsättningar!N$18 -> 20 | D3: - | E3: - | F3: 20 | G3: 2 | H3: 7.5 | I3: OK14 | M3: =Table1417192021[[#This Row],[Slagg mängd]]&Table1417192021[[#This Row],[Gjuttemperatur]]&Table1417192021[[#This Row],[Temperatur motgjutningsyta]]&Table1417192021[[#This Row],[Väderskydd, uppvärmning (ingen vind)]]&Table1417192021[[#This Row],[Täckning '[mm']]]&Table1417192021[[#This Row],[OK <14 Dagar]]&Table1417192021[[#This Row],[OK <21 Dagar]]&Table1417192021[[#This Row],[Kommentar]] -> 0,41520--OK14
A4: 0.4 | B4: =Förutsättningar!$M$18 -> 15 | C4: =Förutsättningar!N$18 -> 20 | D4: - | E4: - | F4: 20 | G4: 7 | H4: 7.8 | I4: OK14 | M4: =Table1417192021[[#This Row],[Slagg mängd]]&Table1417192021[[#This Row],[Gjuttemperatur]]&Table1417192021[[#This Row],[Temperatur motgjutningsyta]]&Table1417192021[[#This Row],[Väderskydd, uppvärmning (ingen vind)]]&Table1417192021[[#This Row],[Täckning '[mm']]]&Table1417192021[[#This Row],[OK <14 Dagar]]&Table1417192021[[#This Row],[OK <21 Dagar]]&Table1417192021[[#This Row],[Kommentar]] -> 0,41520--OK14
A5: 0.4 | B5: =Förutsättningar!$M$18 -> 15 | C5: =Förutsättningar!N$18 -> 20 | D5: - | E5: - | F5: 20 | G5: 12 | H5: 7.8 | I5: OK14 | M5: =Table1417192021[[#This Row],[Slagg mängd]]&Table1417192021[[#This Row],[Gjuttemperatur]]&Table1417192021[[#This Row],[Temperatur motgjutningsyta]]&Table1417192021[[#This Row],[Väderskydd, uppvärmning (ingen vind)]]&Table1417192021[[#This Row],[Täckning '[mm']]]&Table1417192021[[#This Row],[OK <14 Dagar]]&Table1417192021[[#This Row],[OK <21 Dagar]]&Table1417192021[[#This Row],[Kommentar]] -> 0,41520--OK14
A6: 0.4 | B6: =Förutsättningar!$M$18 -> 15 | C6: =Förutsättningar!N$18 -> 20 | D6: - | E6: - | F6: 20 | G6: 20 | H6: 7.8 | I6: OK14 | M6: =Table1417192021[[#This Row],[Slagg mängd]]&Table1417192021[[#This Row],[Gjuttemperatur]]&Table1417192021[[#This Row],[Temperatur motgjutningsyta]]&Table1417192021[[#This Row],[Väderskydd, uppvärmning (ingen vind)]]&Table1417192021[[#This Row],[Täckning '[mm']]]&Table1417192021[[#This Row],[OK <14 Dagar]]&Table1417192021[[#This Row],[OK <21 Dagar]]&Table1417192021[[#This Row],[Kommentar]] -> 0,41520--OK14
A7: 0.4 | B7: =Förutsättningar!M$19 -> 15 | C7: =Förutsättningar!N$19 -> 15 | D7: - | E7: - | F7: 15 | G7: 0 | H7: 9.3 | I7: OK14 | M7: =Table1417192021[[#This Row],[Slagg mängd]]&Table1417192021[[#This Row],[Gjuttemperatur]]&Table1417192021[[#This Row],[Temperatur motgjutningsyta]]&Table1417192021[[#This Row],[Väderskydd, uppvärmning (ingen vind)]]&Table1417192021[[#This Row],[Täckning '[mm']]]&Table1417192021[[#This Row],[OK <14 Dagar]]&Table1417192021[[#This Row],[OK <21 Dagar]]&Table1417192021[[#This Row],[Kommentar]] -> 0,41515--OK14
A8: 0.4 | B8: =Förutsättningar!M$19 -> 15 | C8: =Förutsättningar!N$19 -> 15 | D8: - | E8: - | F8: 15 | G8: 2 | H8: 10 | I8: OK14 | M8: =Table1417192021[[#This Row],[Slagg mängd]]&Table1417192021[[#This Row],[Gjuttemperatur]]&Table1417192021[[#This Row],[Temperatur motgjutningsyta]]&Table1417192021[[#This Row],[Väderskydd, uppvärmning (ingen vind)]]&Table1417192021[[#This Row],[Täckning '[mm']]]&Table1417192021[[#This Row],[OK <14 Dagar]]&Table1417192021[[#This Row],[OK <21 Dagar]]&Table1417192021[[#This Row],[Kommentar]] -> 0,41515--OK14
A9: 0.4 | B9: =Förutsättningar!M$19 -> 15 | C9: =Förutsättningar!N$19 -> 15 | D9: - | E9: - | F9: 15 | G9: 7 | H9: 10.2 | I9: OK14 | M9: =Table1417192021[[#This Row],[Slagg mängd]]&Table1417192021[[#This Row],[Gjuttemperatur]]&Table1417192021[[#This Row],[Temperatur motgjutningsyta]]&Table1417192021[[#This Row],[Väderskydd, uppvärmning (ingen vind)]]&Table1417192021[[#This Row],[Täckning '[mm']]]&Table1417192021[[#This Row],[OK <14 Dagar]]&Table1417192021[[#This Row],[OK <21 Dagar]]&Table1417192021[[#This Row],[Kommentar]] -> 0,41515--OK14
A10: 0.4 | B10: =Förutsättningar!M$19 -> 15 | C10: =Förutsättningar!N$19 -> 15 | D10: - | E10: - | F10: 15 | G10: 12 | H10: 10.3 | I10: OK14 | M10: =Table1417192021[[#This Row],[Slagg mängd]]&Table1417192021[[#This Row],[Gjuttemperatur]]&Table1417192021[[#This Row],[Temperatur motgjutningsyta]]&Table1417192021[[#This Row],[Väderskydd, uppvärmning (ingen vind)]]&Table1417192021[[#This Row],[Täckning '[mm']]]&Table1417192021[[#This Row],[OK <14 Dagar]]&Table1417192021[[#This Row],[OK <21 Dagar]]&Table1417192021[[#This Row],[Kommentar]] -> 0,41515--OK14
A11: 0.4 | B11: =Förutsättningar!M$19 -> 15 | C11: =Förutsättningar!N$19 -> 15 | D11: - | E11: - | F11: 15 | G11: 20 | H11: 10.3 | I11: OK14 | M11: =Table1417192021[[#This Row],[Slagg mängd]]&Table1417192021[[#This Row],[Gjuttemperatur]]&Table1417192021[[#This Row],[Temperatur motgjutningsyta]]&Table1417192021[[#This Row],[Väderskydd, uppvärmning (ingen vind)]]&Table1417192021[[#This Row],[Täckning '[mm']]]&Table1417192021[[#This Row],[OK <14 Dagar]]&Table1417192021[[#This Row],[OK <21 Dagar]]&Table1417192021[[#This Row],[Kommentar]] -> 0,41515--OK14
A12: 0.4 | B12: =Förutsättningar!M$20 -> 15 | C12: =Förutsättningar!N$20 -> 10 | D12: - | E12: - | F12: 10 | G12: 0 | H12: 12.8 | I12: OK14 | M12: =Table1417192021[[#This Row],[Slagg mängd]]&Table1417192021[[#This Row],[Gjuttemperatur]]&Table1417192021[[#This Row],[Temperatur motgjutningsyta]]&Table1417192021[[#This Row],[Väderskydd, uppvärmning (ingen vind)]]&Table1417192021[[#This Row],[Täckning '[mm']]]&Table1417192021[[#This Row],[OK <14 Dagar]]&Table1417192021[[#This Row],[OK <21 Dagar]]&Table1417192021[[#This Row],[Kommentar]] -> 0,41510--OK14
A13: 0.4 | B13: =Förutsättningar!M$20 -> 15 | C13: =Förutsättningar!N$20 -> 10 | D13: - | E13: - | F13: 10 | G13: 2 | H13: 13.7 | I13: OK14 | M13: =Table1417192021[[#This Row],[Slagg mängd]]&Table1417192021[[#This Row],[Gjuttemperatur]]&Table1417192021[[#This Row],[Temperatur motgjutningsyta]]&Table1417192021[[#This Row],[Väderskydd, uppvärmning (ingen vind)]]&Table1417192021[[#This Row],[Täckning '[mm']]]&Table1417192021[[#This Row],[OK <14 Dagar]]&Table1417192021[[#This Row],[OK <21 Dagar]]&Table1417192021[[#This Row],[Kommentar]] -> 0,41510--OK14
A14: 0.4 | B14: =Förutsättningar!M$20 -> 15 | C14: =Förutsättningar!N$20 -> 10 | D14: - | E14: - | F14: 10 | G14: 7 | H14: 14 | I14: OK14 | M14: =Table1417192021[[#This Row],[Slagg mängd]]&Table1417192021[[#This Row],[Gjuttemperatur]]&Table1417192021[[#This Row],[Temperatur motgjutningsyta]]&Table1417192021[[#This Row],[Väderskydd, uppvärmning (ingen vind)]]&Table1417192021[[#This Row],[Täckning '[mm']]]&Table1417192021[[#This Row],[OK <14 Dagar]]&Table1417192021[[#This Row],[OK <21 Dagar]]&Table1417192021[[#This Row],[Kommentar]] -> 0,41510--OK14
A15: 0.4 | B15: =Förutsättningar!M$20 -> 15 | C15: =Förutsättningar!N$20 -> 10 | D15: - | E15: - | F15: 10 | G15: 12 | H15: 14 | I15: OK14 | M15: =Table1417192021[[#This Row],[Slagg mängd]]&Table1417192021[[#This Row],[Gjuttemperatur]]&Table1417192021[[#This Row],[Temperatur motgjutningsyta]]&Table1417192021[[#This Row],[Väderskydd, uppvärmning (ingen vind)]]&Table1417192021[[#This Row],[Täckning '[mm']]]&Table1417192021[[#This Row],[OK <14 Dagar]]&Table1417192021[[#This Row],[OK <21 Dagar]]&Table1417192021[[#This Row],[Kommentar]] -> 0,41510--OK14
A16: 0.4 | B16: =Förutsättningar!M$20 -> 15 | C16: =Förutsättningar!N$20 -> 10 | D16: 0 | E16: - | F16: 10 | G16: 20 | H16: 13.9 | I16: OK14 | M16: =Table1417192021[[#This Row],[Slagg mängd]]&Table1417192021[[#This Row],[Gjuttemperatur]]&Table1417192021[[#This Row],[Temperatur motgjutningsyta]]&Table1417192021[[#This Row],[Väderskydd, uppvärmning (ingen vind)]]&Table1417192021[[#This Row],[Täckning '[mm']]]&Table1417192021[[#This Row],[OK <14 Dagar]]&Table1417192021[[#This Row],[OK <21 Dagar]]&Table1417192021[[#This Row],[Kommentar]] -> 0,415100-OK14
A17: 0.4 | B17: =Förutsättningar!M$21 -> 20 | C17: =Förutsättningar!N$21 -> 5 | D17: 20 | E17: - | F17: 5 | G17: 0 | H17: 9.6 | I17: OK14 | M17: =Table1417192021[[#This Row],[Slagg mängd]]&Table1417192021[[#This Row],[Gjuttemperatur]]&Table1417192021[[#This Row],[Temperatur motgjutningsyta]]&Table1417192021[[#This Row],[Väderskydd, uppvärmning (ingen vind)]]&Table1417192021[[#This Row],[Täckning '[mm']]]&Table1417192021[[#This Row],[OK <14 Dagar]]&Table1417192021[[#This Row],[OK <21 Dagar]]&Table1417192021[[#This Row],[Kommentar]] -> 0,420520-OK14
A18: 0.4 | B18: =Förutsättningar!M$21 -> 20 | C18: =Förutsättningar!N$21 -> 5 | D18: 20 | E18: - | F18: 5 | G18: 2 | H18: 12.1 | I18: OK14 | M18: =Table1417192021[[#This Row],[Slagg mängd]]&Table1417192021[[#This Row],[Gjuttemperatur]]&Table1417192021[[#This Row],[Temperatur motgjutningsyta]]&Table1417192021[[#This Row],[Väderskydd, uppvärmning (ingen vind)]]&Table1417192021[[#This Row],[Täckning '[mm']]]&Table1417192021[[#This Row],[OK <14 Dagar]]&Table1417192021[[#This Row],[OK <21 Dagar]]&Table1417192021[[#This Row],[Kommentar]] -> 0,420520-OK14
A19: 0.4 | B19: =Förutsättningar!M$21 -> 20 | C19: =Förutsättningar!N$21 -> 5 | D19: 20 | E19: Presenning | F19: 5 | G19: 7 | H19: 12.6 | I19: OK14 | M19: =Table1417192021[[#This Row],[Slagg mängd]]&Table1417192021[[#This Row],[Gjuttemperatur]]&Table1417192021[[#This Row],[Temperatur motgjutningsyta]]&Table1417192021[[#This Row],[Väderskydd, uppvärmning (ingen vind)]]&Table1417192021[[#This Row],[Täckning '[mm']]]&Table1417192021[[#This Row],[OK <14 Dagar]]&Table1417192021[[#This Row],[OK <21 Dagar]]&Table1417192021[[#This Row],[Kommentar]] -> 0,420520PresenningOK14
A20: 0.4 | B20: =Förutsättningar!M$21 -> 20 | C20: =Förutsättningar!N$21 -> 5 | D20: 20 | E20: Presenning | F20: 5 | G20: 12 | H20: 13 | I20: OK14 | M20: =Table1417192021[[#This Row],[Slagg mängd]]&Table1417192021[[#This Row],[Gjuttemperatur]]&Table1417192021[[#This Row],[Temperatur motgjutningsyta]]&Table1417192021[[#This Row],[Väderskydd, uppvärmning (ingen vind)]]&Table1417192021[[#This Row],[Täckning '[mm']]]&Table1417192021[[#This Row],[OK <14 Dagar]]&Table1417192021[[#This Row],[OK <21 Dagar]]&Table1417192021[[#This Row],[Kommentar]] -> 0,420520PresenningOK14
A21: 0.4 | B21: =Förutsättningar!M$21 -> 20 | C21: =Förutsättningar!N$21 -> 5 | D21: 20 | E21: Presenning | F21: 5 | G21: 20 | H21: 13.3 | I21: OK14 | M21: =Table1417192021[[#This Row],[Slagg mängd]]&Table1417192021[[#This Row],[Gjuttemperatur]]&Table1417192021[[#This Row],[Temperatur motgjutningsyta]]&Table1417192021[[#This Row],[Väderskydd, uppvärmning (ingen vind)]]&Table1417192021[[#This Row],[Täckning '[mm']]]&Table1417192021[[#This Row],[OK <14 Dagar]]&Table1417192021[[#This Row],[OK <21 Dagar]]&Table1417192021[[#This Row],[Kommentar]] -> 0,420520PresenningOK14
A22: 0.4 | B22: =Förutsättningar!M$22 -> 20 | C22: =Förutsättningar!N$22 -> 5 | D22: 20 | E22: - | F22: 0 | G22: 0 | H22: 13.3 | I22: OK14 | M22: =Table1417192021[[#This Row],[Slagg mängd]]&Table1417192021[[#This Row],[Gjuttemperatur]]&Table1417192021[[#This Row],[Temperatur motgjutningsyta]]&Table1417192021[[#This Row],[Väderskydd, uppvärmning (ingen vind)]]&Table1417192021[[#This Row],[Täckning '[mm']]]&Table1417192021[[#This Row],[OK <14 Dagar]]&Table1417192021[[#This Row],[OK <21 Dagar]]&Table1417192021[[#This Row],[Kommentar]] -> 0,420520-OK14
A23: 0.4 | B23: =Förutsättningar!M$22 -> 20 | C23: =Förutsättningar!N$22 -> 5 | D23: 20 | E23: 10 | F23: 0 | G23: 2 | H23: 10.9 | I23: OK14 | M23: =Table1417192021[[#This Row],[Slagg mängd]]&Table1417192021[[#This Row],[Gjuttemperatur]]&Table1417192021[[#This Row],[Temperatur motgjutningsyta]]&Table1417192021[[#This Row],[Väderskydd, uppvärmning (ingen vind)]]&Table1417192021[[#This Row],[Täckning '[mm']]]&Table1417192021[[#This Row],[OK <14 Dagar]]&Table1417192021[[#This Row],[OK <21 Dagar]]&Table1417192021[[#This Row],[Kommentar]] -> 0,42052010OK14
A24: 0.4 | B24: =Förutsättningar!M$22 -> 20 | C24: =Förutsättningar!N$22 -> 5 | D24: 20 | E24: 10 | F24: 0 | G24: 7 | H24: 11.6 | I24: OK14 | M24: =Table1417192021[[#This Row],[Slagg mängd]]&Table1417192021[[#This Row],[Gjuttemperatur]]&Table1417192021[[#This Row],[Temperatur motgjutningsyta]]&Table1417192021[[#This Row],[Väderskydd, uppvärmning (ingen vind)]]&Table1417192021[[#This Row],[Täckning '[mm']]]&Table1417192021[[#This Row],[OK <14 Dagar]]&Table1417192021[[#This Row],[OK <21 Dagar]]&Table1417192021[[#This Row],[Kommentar]] -> 0,42052010OK14
A25: 0.4 | B25: =Förutsättningar!M$22 -> 20 | C25: =Förutsättningar!N$22 -> 5 | D25: 20 | E25: 10 | F25: 0 | G25: 12 | H25: 11.8 | I25: OK14 | M25: =Table1417192021[[#This Row],[Slagg mängd]]&Table1417192021[[#This Row],[Gjuttemperatur]]&Table1417192021[[#This Row],[Temperatur motgjutningsyta]]&Table1417192021[[#This Row],[Väderskydd, uppvärmning (ingen vind)]]&Table1417192021[[#This Row],[Täckning '[mm']]]&Table1417192021[[#This Row],[OK <14 Dagar]]&Table1417192021[[#This Row],[OK <21 Dagar]]&Table1417192021[[#This Row],[Kommentar]] -> 0,42052010OK14
A26: 0.4 | B26: =Förutsättningar!M$22 -> 20 | C26: =Förutsättningar!N$22 -> 5 | D26: 20 | E26: 10 | F26: 0 | G26: 20 | H26: 12 | I26: OK14 | M26: =Table1417192021[[#This Row],[Slagg mängd]]&Table1417192021[[#This Row],[Gjuttemperatur]]&Table1417192021[[#This Row],[Temperatur motgjutningsyta]]&Table1417192021[[#This Row],[Väderskydd, uppvärmning (ingen vind)]]&Table1417192021[[#This Row],[Täckning '[mm']]]&Table1417192021[[#This Row],[OK <14 Dagar]]&Table1417192021[[#This Row],[OK <21 Dagar]]&Table1417192021[[#This Row],[Kommentar]] -> 0,42052010OK14
A27: 0.4 | B27: =Förutsättningar!M$23 -> 20 | C27: =Förutsättningar!N$23 -> 5 | D27: 20 | E27: 10 | F27: -5 | G27: 0 | H27: 13.8 | I27: OK14 | M27: =Table1417192021[[#This Row],[Slagg mängd]]&Table1417192021[[#This Row],[Gjuttemperatur]]&Table1417192021[[#This Row],[Temperatur motgjutningsyta]]&Table1417192021[[#This Row],[Väderskydd, uppvärmning (ingen vind)]]&Table1417192021[[#This Row],[Täckning '[mm']]]&Table1417192021[[#This Row],[OK <14 Dagar]]&Table1417192021[[#This Row],[OK <21 Dagar]]&Table1417192021[[#This Row],[Kommentar]] -> 0,42052010OK14
A28: 0.4 | B28: =Förutsättningar!M$23 -> 20 | C28: =Förutsättningar!N$23 -> 5 | D28: 20 | E28: 20 | F28: -5 | G28: 2 | H28: 12.6 | I28: OK14 | M28: =Table1417192021[[#This Row],[Slagg mängd]]&Table1417192021[[#This Row],[Gjuttemperatur]]&Table1417192021[[#This Row],[Temperatur motgjutningsyta]]&Table1417192021[[#This Row],[Väderskydd, uppvärmning (ingen vind)]]&Table1417192021[[#This Row],[Täckning '[mm']]]&Table1417192021[[#This Row],[OK <14 Dagar]]&Table1417192021[[#This Row],[OK <21 Dagar]]&Table1417192021[[#This Row],[Kommentar]] -> 0,42052020OK14
A29: 0.4 | B29: =Förutsättningar!M$23 -> 20 | C29: =Förutsättningar!N$23 -> 5 | D29: 20 | E29: 20 | F29: -5 | G29: 7 | H29: 13.1 | I29: OK14 | M29: =Table1417192021[[#This Row],[Slagg mängd]]&Table1417192021[[#This Row],[Gjuttemperatur]]&Table1417192021[[#This Row],[Temperatur motgjutningsyta]]&Table1417192021[[#This Row],[Väderskydd, uppvärmning (ingen vind)]]&Table1417192021[[#This Row],[Täckning '[mm']]]&Table1417192021[[#This Row],[OK <14 Dagar]]&Table1417192021[[#This Row],[OK <21 Dagar]]&Table1417192021[[#This Row],[Kommentar]] -> 0,42052020OK14
A30: 0.4 | B30: =Förutsättningar!M$23 -> 20 | C30: =Förutsättningar!N$23 -> 5 | D30: 20 | E30: 20 | F30: -5 | G30: 12 | H30: 13.3 | I30: OK14 | M30: =Table1417192021[[#This Row],[Slagg mängd]]&Table1417192021[[#This Row],[Gjuttemperatur]]&Table1417192021[[#This Row],[Temperatur motgjutningsyta]]&Table1417192021[[#This Row],[Väderskydd, uppvärmning (ingen vind)]]&Table1417192021[[#This Row],[Täckning '[mm']]]&Table1417192021[[#This Row],[OK <14 Dagar]]&Table1417192021[[#This Row],[OK <21 Dagar]]&Table1417192021[[#This Row],[Kommentar]] -> 0,42052020OK14
A31: 0.4 | B31: =Förutsättningar!M$23 -> 20 | C31: =Förutsättningar!N$23 -> 5 | D31: 20 | E31: 20 | F31: -5 | G31: 20 | H31: 13.5 | I31: OK14 | M31: =Table1417192021[[#This Row],[Slagg mängd]]&Table1417192021[[#This Row],[Gjuttemperatur]]&Table1417192021[[#This Row],[Temperatur motgjutningsyta]]&Table1417192021[[#This Row],[Väderskydd, uppvärmning (ingen vind)]]&Table1417192021[[#This Row],[Täckning '[mm']]]&Table1417192021[[#This Row],[OK <14 Dagar]]&Table1417192021[[#This Row],[OK <21 Dagar]]&Table1417192021[[#This Row],[Kommentar]] -> 0,42052020OK14
A32: 0.4 | B32: =Förutsättningar!M$24 -> 20 | C32: =Förutsättningar!N$24 -> 5 | D32: 20 | E32: 50 | F32: -10 | G32: 0 | H32: 13.1 | I32: OK14 | M32: =Table1417192021[[#This Row],[Slagg mängd]]&Table1417192021[[#This Row],[Gjuttemperatur]]&Table1417192021[[#This Row],[Temperatur motgjutningsyta]]&Table1417192021[[#This Row],[Väderskydd, uppvärmning (ingen vind)]]&Table1417192021[[#This Row],[Täckning '[mm']]]&Table1417192021[[#This Row],[OK <14 Dagar]]&Table1417192021[[#This Row],[OK <21 Dagar]]&Table1417192021[[#This Row],[Kommentar]] -> 0,42052050OK14
A33: 0.4 | B33: =Förutsättningar!M$24 -> 20 | C33: =Förutsättningar!N$24 -> 5 | D33: 20 | E33: 50 | F33: -10 | G33: 2 | H33: 13.5 | I33: OK14 | M33: =Table1417192021[[#This Row],[Slagg mängd]]&Table1417192021[[#This Row],[Gjuttemperatur]]&Table1417192021[[#This Row],[Temperatur motgjutningsyta]]&Table1417192021[[#This Row],[Väderskydd, uppvärmning (ingen vind)]]&Table1417192021[[#This Row],[Täckning '[mm']]]&Table1417192021[[#This Row],[OK <14 Dagar]]&Table1417192021[[#This Row],[OK <21 Dagar]]&Table1417192021[[#This Row],[Kommentar]] -> 0,42052050OK14
A34: 0.4 | B34: =Förutsättningar!M$24 -> 20 | C34: =Förutsättningar!N$24 -> 5 | D34: 20 | E34: 50 | F34: -10 | G34: 7 | H34: 13.9 | I34: OK14 | M34: =Table1417192021[[#This Row],[Slagg mängd]]&Table1417192021[[#This Row],[Gjuttemperatur]]&Table1417192021[[#This Row],[Temperatur motgjutningsyta]]&Table1417192021[[#This Row],[Väderskydd, uppvärmning (ingen vind)]]&Table1417192021[[#This Row],[Täckning '[mm']]]&Table1417192021[[#This Row],[OK <14 Dagar]]&Table1417192021[[#This Row],[OK <21 Dagar]]&Table1417192021[[#This Row],[Kommentar]] -> 0,42052050OK14
A35: - | B35: - | C35: - | D35: - | E35: - | F35: -10 | G35: 12 | L35: Frys innan täck | M35: =Table1417192021[[#This Row],[Slagg mängd]]&Table1417192021[[#This Row],[Gjuttemperatur]]&Table1417192021[[#This Row],[Temperatur motgjutningsyta]]&Table1417192021[[#This Row],[Väderskydd, uppvärmning (ingen vind)]]&Table1417192021[[#This Row],[Täckning '[mm']]]&Table1417192021[[#This Row],[OK <14 Dagar]]&Table1417192021[[#This Row],[OK <21 Dagar]]&Table1417192021[[#This Row],[Kommentar]] -> -----Frys innan täck
A36: - | B36: - | C36: - | D36: - | E36: - | F36: -10 | G36: 20 | L36: Frys innan täck | M36: =Table1417192021[[#This Row],[Slagg mängd]]&Table1417192021[[#This Row],[Gjuttemperatur]]&Table1417192021[[#This Row],[Temperatur motgjutningsyta]]&Table1417192021[[#This Row],[Väderskydd, uppvärmning (ingen vind)]]&Table1417192021[[#This Row],[Täckning '[mm']]]&Table1417192021[[#This Row],[OK <14 Dagar]]&Table1417192021[[#This Row],[OK <21 Dagar]]&Table1417192021[[#This Row],[Kommentar]] -> -----Frys innan täck
A37: 0.1 | B37: =Förutsättningar!M$25 -> 15 | C37: =Förutsättningar!N$25 -> 5 | D37: 20 | E37: 50 | F37: -15 | G37: 0 | H37: 11.3 | I37: OK14 | M37: =Table1417192021[[#This Row],[Slagg mängd]]&Table1417192021[[#This Row],[Gjuttemperatur]]&Table1417192021[[#This Row],[Temperatur motgjutningsyta]]&Table1417192021[[#This Row],[Väderskydd, uppvärmning (ingen vind)]]&Table1417192021[[#This Row],[Täckning '[mm']]]&Table1417192021[[#This Row],[OK <14 Dagar]]&Table1417192021[[#This Row],[OK <21 Dagar]]&Table1417192021[[#This Row],[Kommentar]] -> 0,11552050OK14
A38: 0.1 | B38: =Förutsättningar!M$25 -> 15 | C38: =Förutsättningar!N$25 -> 5 | D38: 20 | E38: 50 | F38: -15 | G38: 2 | H38: 11.8 | I38: OK14 | M38: =Table1417192021[[#This Row],[Slagg mängd]]&Table1417192021[[#This Row],[Gjuttemperatur]]&Table1417192021[[#This Row],[Temperatur motgjutningsyta]]&Table1417192021[[#This Row],[Väderskydd, uppvärmning (ingen vind)]]&Table1417192021[[#This Row],[Täckning '[mm']]]&Table1417192021[[#This Row],[OK <14 Dagar]]&Table1417192021[[#This Row],[OK <21 Dagar]]&Table1417192021[[#This Row],[Kommentar]] -> 0,11552050OK14
A39: - | B39: - | C39: - | D39: - | E39: - | F39: -15 | G39: 7 | L39: Frys innan täck | M39: =Table1417192021[[#This Row],[Slagg mängd]]&Table1417192021[[#This Row],[Gjuttemperatur]]&Table1417192021[[#This Row],[Temperatur motgjutningsyta]]&Table1417192021[[#This Row],[Väderskydd, uppvärmning (ingen vind)]]&Table1417192021[[#This Row],[Täckning '[mm']]]&Table1417192021[[#This Row],[OK <14 Dagar]]&Table1417192021[[#This Row],[OK <21 Dagar]]&Table1417192021[[#This Row],[Kommentar]] -> -----Frys innan täck
A40: - | B40: - | C40: - | D40: - | E40: - | F40: -15 | G40: 12 | L40: Frys innan täck | M40: =Table1417192021[[#This Row],[Slagg mängd]]&Table1417192021[[#This Row],[Gjuttemperatur]]&Table1417192021[[#This Row],[Temperatur motgjutningsyta]]&Table1417192021[[#This Row],[Väderskydd, uppvärmning (ingen vind)]]&Table1417192021[[#This Row],[Täckning '[mm']]]&Table1417192021[[#This Row],[OK <14 Dagar]]&Table1417192021[[#This Row],[OK <21 Dagar]]&Table1417192021[[#This Row],[Kommentar]] -> -----Frys innan täck
...

Sheet Bjälklag (C28-35)
A1: Slagg mängd | B1: Gjuttemperatur | C1: Temperatur motgjutningsyta | D1: Väderskydd, uppvärmning (ingen vind) | E1: Täckning [mm] | F1: Temperatur | G1: Vind | H1: <14 d och >70 % [Dagar] | I1: OK <14 Dagar | J1: <21 d och >70 % [Dagar] | K1: OK <21 Dagar | L1: Kommentar | M1: Åtgärdskåd
A2: 0.4 | B2: =Förutsättningar!M$18 -> 15 | C2: =Förutsättningar!N$18 -> 20 | D2: - | E2: - | F2: 20 | G2: 0 | H2: 6.5 | I2: OK14 | J2: 24.5 | M2: =Table14171920[[#This Row],[Slagg mängd]]&Table14171920[[#This Row],[Gjuttemperatur]]&Table14171920[[#This Row],[Temperatur motgjutningsyta]]&Table14171920[[#This Row],[Väderskydd, uppvärmning (ingen vind)]]&Table14171920[[#This Row],[Täckning '[mm']]]&Table14171920[[#This Row],[OK <14 Dagar]]&Table14171920[[#This Row],[OK <21 Dagar]]&Table14171920[[#This Row],[Kommentar]] -> 0,41520--OK14
A3: 0.4 | B3: =Förutsättningar!$M$18 -> 15 | C3: =Förutsättningar!N$18 -> 20 | D3: - | E3: - | F3: 20 | G3: 2 | H3: 7 | I3: OK14 | M3: =Table14171920[[#This Row],[Slagg mängd]]&Table14171920[[#This Row],[Gjuttemperatur]]&Table14171920[[#This Row],[Temperatur motgjutningsyta]]&Table14171920[[#This Row],[Väderskydd, uppvärmning (ingen vind)]]&Table14171920[[#This Row],[Täckning '[mm']]]&Table14171920[[#This Row],[OK <14 Dagar]]&Table14171920[[#This Row],[OK <21 Dagar]]&Table14171920[[#This Row],[Kommentar]] -> 0,41520--OK14
A4: 0.4 | B4: =Förutsättningar!$M$18 -> 15 | C4: =Förutsättningar!N$18 -> 20 | D4: - | E4: - | F4: 20 | G4: 7 | H4: 7.2 | I4: OK14 | M4: =Table14171920[[#This Row],[Slagg mängd]]&Table14171920[[#This Row],[Gjuttemperatur]]&Table14171920[[#This Row],[Temperatur motgjutningsyta]]&Table14171920[[#This Row],[Väderskydd, uppvärmning (ingen vind)]]&Table14171920[[#This Row],[Täckning '[mm']]]&Table14171920[[#This Row],[OK <14 Dagar]]&Table14171920[[#This Row],[OK <21 Dagar]]&Table14171920[[#This Row],[Kommentar]] -> 0,41520--OK14
A5: 0.4 | B5: =Förutsättningar!$M$18 -> 15 | C5: =Förutsättningar!N$18 -> 20 | D5: - | E5: - | F5: 20 | G5: 12 | H5: 7.3 | I5: OK14 | M5: =Table14171920[[#This Row],[Slagg mängd]]&Table14171920[[#This Row],[Gjuttemperatur]]&Table14171920[[#This Row],[Temperatur motgjutningsyta]]&Table14171920[[#This Row],[Väderskydd, uppvärmning (ingen vind)]]&Table14171920[[#This Row],[Täckning '[mm']]]&Table14171920[[#This Row],[OK <14 Dagar]]&Table14171920[[#This Row],[OK <21 Dagar]]&Table14171920[[#This Row],[Kommentar]] -> 0,41520--OK14
A6: 0.4 | B6: =Förutsättningar!$M$18 -> 15 | C6: =Förutsättningar!N$18 -> 20 | D6: - | E6: - | F6: 20 | G6: 20 | H6: 7.3 | I6: OK14 | M6: =Table14171920[[#This Row],[Slagg mängd]]&Table14171920[[#This Row],[Gjuttemperatur]]&Table14171920[[#This Row],[Temperatur motgjutningsyta]]&Table14171920[[#This Row],[Väderskydd, uppvärmning (ingen vind)]]&Table14171920[[#This Row],[Täckning '[mm']]]&Table14171920[[#This Row],[OK <14 Dagar]]&Table14171920[[#This Row],[OK <21 Dagar]]&Table14171920[[#This Row],[Kommentar]] -> 0,41520--OK14
A7: 0.4 | B7: =Förutsättningar!M$19 -> 15 | C7: =Förutsättningar!N$19 -> 15 | D7: - | E7: - | F7: 15 | G7: 0 | H7: 8.5 | I7: OK14 | M7: =Table14171920[[#This Row],[Slagg mängd]]&Table14171920[[#This Row],[Gjuttemperatur]]&Table14171920[[#This Row],[Temperatur motgjutningsyta]]&Table14171920[[#This Row],[Väderskydd, uppvärmning (ingen vind)]]&Table14171920[[#This Row],[Täckning '[mm']]]&Table14171920[[#This Row],[OK <14 Dagar]]&Table14171920[[#This Row],[OK <21 Dagar]]&Table14171920[[#This Row],[Kommentar]] -> 0,41515--OK14
A8: 0.4 | B8: =Förutsättningar!M$19 -> 15 | C8: =Förutsättningar!N$19 -> 15 | D8: - | E8: - | F8: 15 | G8: 2 | H8: 9.2 | I8: OK14 | M8: =Table14171920[[#This Row],[Slagg mängd]]&Table14171920[[#This Row],[Gjuttemperatur]]&Table14171920[[#This Row],[Temperatur motgjutningsyta]]&Table14171920[[#This Row],[Väderskydd, uppvärmning (ingen vind)]]&Table14171920[[#This Row],[Täckning '[mm']]]&Table14171920[[#This Row],[OK <14 Dagar]]&Table14171920[[#This Row],[OK <21 Dagar]]&Table14171920[[#This Row],[Kommentar]] -> 0,41515--OK14
A9: 0.4 | B9: =Förutsättningar!M$19 -> 15 | C9: =Förutsättningar!N$19 -> 15 | D9: - | E9: - | F9: 15 | G9: 7 | H9: 9.5 | I9: OK14 | M9: =Table14171920[[#This Row],[Slagg mängd]]&Table14171920[[#This Row],[Gjuttemperatur]]&Table14171920[[#This Row],[Temperatur motgjutningsyta]]&Table14171920[[#This Row],[Väderskydd, uppvärmning (ingen vind)]]&Table14171920[[#This Row],[Täckning '[mm']]]&Table14171920[[#This Row],[OK <14 Dagar]]&Table14171920[[#This Row],[OK <21 Dagar]]&Table14171920[[#This Row],[Kommentar]] -> 0,41515--OK14
A10: 0.4 | B10: =Förutsättningar!M$19 -> 15 | C10: =Förutsättningar!N$19 -> 15 | D10: - | E10: - | F10: 15 | G10: 12 | H10: 9.5 | I10: OK14 | M10: =Table14171920[[#This Row],[Slagg mängd]]&Table14171920[[#This Row],[Gjuttemperatur]]&Table14171920[[#This Row],[Temperatur motgjutningsyta]]&Table14171920[[#This Row],[Väderskydd, uppvärmning (ingen vind)]]&Table14171920[[#This Row],[Täckning '[mm']]]&Table14171920[[#This Row],[OK <14 Dagar]]&Table14171920[[#This Row],[OK <21 Dagar]]&Table14171920[[#This Row],[Kommentar]] -> 0,41515--OK14
A11: 0.4 | B11: =Förutsättningar!M$19 -> 15 | C11: =Förutsättningar!N$19 -> 15 | D11: - | E11: - | F11: 15 | G11: 20 | H11: 9.6 | I11: OK14 | M11: =Table14171920[[#This Row],[Slagg mängd]]&Table14171920[[#This Row],[Gjuttemperatur]]&Table14171920[[#This Row],[Temperatur motgjutningsyta]]&Table14171920[[#This Row],[Väderskydd, uppvärmning (ingen vind)]]&Table14171920[[#This Row],[Täckning '[mm']]]&Table14171920[[#This Row],[OK <14 Dagar]]&Table14171920[[#This Row],[OK <21 Dagar]]&Table14171920[[#This Row],[Kommentar]] -> 0,41515--OK14
A12: 0.4 | B12: =Förutsättningar!M$20 -> 15 | C12: =Förutsättningar!N$20 -> 10 | D12: - | E12: - | F12: 10 | G12: 0 | H12: 11.8 | I12: OK14 | M12: =Table14171920[[#This Row],[Slagg mängd]]&Table14171920[[#This Row],[Gjuttemperatur]]&Table14171920[[#This Row],[Temperatur motgjutningsyta]]&Table14171920[[#This Row],[Väderskydd, uppvärmning (ingen vind)]]&Table14171920[[#This Row],[Täckning '[mm']]]&Table14171920[[#This Row],[OK <14 Dagar]]&Table14171920[[#This Row],[OK <21 Dagar]]&Table14171920[[#This Row],[Kommentar]] -> 0,41510--OK14
A13: 0.4 | B13: =Förutsättningar!M$20 -> 15 | C13: =Förutsättningar!N$20 -> 10 | D13: - | E13: - | F13: 10 | G13: 2 | H13: 12.7 | I13: OK14 | M13: =Table14171920[[#This Row],[Slagg mängd]]&Table14171920[[#This Row],[Gjuttemperatur]]&Table14171920[[#This Row],[Temperatur motgjutningsyta]]&Table14171920[[#This Row],[Väderskydd, uppvärmning (ingen vind)]]&Table14171920[[#This Row],[Täckning '[mm']]]&Table14171920[[#This Row],[OK <14 Dagar]]&Table14171920[[#This Row],[OK <21 Dagar]]&Table14171920[[#This Row],[Kommentar]] -> 0,41510--OK14
A14: 0.4 | B14: =Förutsättningar!M$20 -> 15 | C14: =Förutsättningar!N$20 -> 10 | D14: - | E14: - | F14: 10 | G14: 7 | H14: 13 | I14: OK14 | M14: =Table14171920[[#This Row],[Slagg mängd]]&Table14171920[[#This Row],[Gjuttemperatur]]&Table14171920[[#This Row],[Temperatur motgjutningsyta]]&Table14171920[[#This Row],[Väderskydd, uppvärmning (ingen vind)]]&Table14171920[[#This Row],[Täckning '[mm']]]&Table14171920[[#This Row],[OK <14 Dagar]]&Table14171920[[#This Row],[OK <21 Dagar]]&Table14171920[[#This Row],[Kommentar]] -> 0,41510--OK14
A15: 0.4 | B15: =Förutsättningar!M$20 -> 15 | C15: =Förutsättningar!N$20 -> 10 | D15: - | E15: - | F15: 10 | G15: 12 | H15: 13.1 | I15: OK14 | M15: =Table14171920[[#This Row],[Slagg mängd]]&Table14171920[[#This Row],[Gjuttemperatur]]&Table14171920[[#This Row],[Temperatur motgjutningsyta]]&Table14171920[[#This Row],[Väderskydd, uppvärmning (ingen vind)]]&Table14171920[[#This Row],[Täckning '[mm']]]&Table14171920[[#This Row],[OK <14 Dagar]]&Table14171920[[#This Row],[OK <21 Dagar]]&Table14171920[[#This Row],[Kommentar]] -> 0,41510--OK14
A16: 0.4 | B16: =Förutsättningar!M$20 -> 15 | C16: =Förutsättningar!N$20 -> 10 | D16: - | E16: - | F16: 10 | G16: 20 | H16: 13.2 | I16: OK14 | M16: =Table14171920[[#This Row],[Slagg mängd]]&Table14171920[[#This Row],[Gjuttemperatur]]&Table14171920[[#This Row],[Temperatur motgjutningsyta]]&Table14171920[[#This Row],[Väderskydd, uppvärmning (ingen vind)]]&Table14171920[[#This Row],[Täckning '[mm']]]&Table14171920[[#This Row],[OK <14 Dagar]]&Table14171920[[#This Row],[OK <21 Dagar]]&Table14171920[[#This Row],[Kommentar]] -> 0,41510--OK14
A17: 0.4 | B17: =Förutsättningar!M$21 -> 20 | C17: =Förutsättningar!N$21 -> 5 | D17: 0 | E17: 50 | F17: 5 | G17: 0 | H17: 14 | I17: OK14 | M17: =Table14171920[[#This Row],[Slagg mängd]]&Table14171920[[#This Row],[Gjuttemperatur]]&Table14171920[[#This Row],[Temperatur motgjutningsyta]]&Table14171920[[#This Row],[Väderskydd, uppvärmning (ingen vind)]]&Table14171920[[#This Row],[Täckning '[mm']]]&Table14171920[[#This Row],[OK <14 Dagar]]&Table14171920[[#This Row],[OK <21 Dagar]]&Table14171920[[#This Row],[Kommentar]] -> 0,4205050OK14
A18: 0.4 | B18: =Förutsättningar!M$21 -> 20 | C18: =Förutsättningar!N$21 -> 5 | D18: 20 | E18: - | F18: 5 | G18: 2 | H18: 11.2 | I18: OK14 | M18: =Table14171920[[#This Row],[Slagg mängd]]&Table14171920[[#This Row],[Gjuttemperatur]]&Table14171920[[#This Row],[Temperatur motgjutningsyta]]&Table14171920[[#This Row],[Väderskydd, uppvärmning (ingen vind)]]&Table14171920[[#This Row],[Täckning '[mm']]]&Table14171920[[#This Row],[OK <14 Dagar]]&Table14171920[[#This Row],[OK <21 Dagar]]&Table14171920[[#This Row],[Kommentar]] -> 0,420520-OK14
A19: 0.4 | B19: =Förutsättningar!M$21 -> 20 | C19: =Förutsättningar!N$21 -> 5 | D19: 20 | E19: - | F19: 5 | G19: 7 | H19: 13.2 | I19: OK14 | M19: =Table14171920[[#This Row],[Slagg mängd]]&Table14171920[[#This Row],[Gjuttemperatur]]&Table14171920[[#This Row],[Temperatur motgjutningsyta]]&Table14171920[[#This Row],[Väderskydd, uppvärmning (ingen vind)]]&Table14171920[[#This Row],[Täckning '[mm']]]&Table14171920[[#This Row],[OK <14 Dagar]]&Table14171920[[#This Row],[OK <21 Dagar]]&Table14171920[[#This Row],[Kommentar]] -> 0,420520-OK14
A20: 0.4 | B20: =Förutsättningar!M$21 -> 20 | C20: =Förutsättningar!N$21 -> 5 | D20: 20 | E20: - | F20: 5 | G20: 12 | H20: 13.8 | I20: OK14 | M20: =Table14171920[[#This Row],[Slagg mängd]]&Table14171920[[#This Row],[Gjuttemperatur]]&Table14171920[[#This Row],[Temperatur motgjutningsyta]]&Table14171920[[#This Row],[Väderskydd, uppvärmning (ingen vind)]]&Table14171920[[#This Row],[Täckning '[mm']]]&Table14171920[[#This Row],[OK <14 Dagar]]&Table14171920[[#This Row],[OK <21 Dagar]]&Table14171920[[#This Row],[Kommentar]] -> 0,420520-OK14
A21: 0.4 | B21: =Förutsättningar!M$21 -> 20 | C21: =Förutsättningar!N$21 -> 5 | D21: 20 | E21: Presenning | F21: 5 | G21: 20 | H21: 12.4 | I21: OK14 | M21: =Table14171920[[#This Row],[Slagg mängd]]&Table14171920[[#This Row],[Gjuttemperatur]]&Table14171920[[#This Row],[Temperatur motgjutningsyta]]&Table14171920[[#This Row],[Väderskydd, uppvärmning (ingen vind)]]&Table14171920[[#This Row],[Täckning '[mm']]]&Table14171920[[#This Row],[OK <14 Dagar]]&Table14171920[[#This Row],[OK <21 Dagar]]&Table14171920[[#This Row],[Kommentar]] -> 0,420520PresenningOK14
A22: 0.4 | B22: =Förutsättningar!M$22 -> 20 | C22: =Förutsättningar!N$22 -> 5 | D22: 20 | E22: - | F22: 0 | G22: 0 | H22: 13.5 | I22: OK14 | M22: =Table14171920[[#This Row],[Slagg mängd]]&Table14171920[[#This Row],[Gjuttemperatur]]&Table14171920[[#This Row],[Temperatur motgjutningsyta]]&Table14171920[[#This Row],[Väderskydd, uppvärmning (ingen vind)]]&Table14171920[[#This Row],[Täckning '[mm']]]&Table14171920[[#This Row],[OK <14 Dagar]]&Table14171920[[#This Row],[OK <21 Dagar]]&Table14171920[[#This Row],[Kommentar]] -> 0,420520-OK14
A23: 0.4 | B23: =Förutsättningar!M$22 -> 20 | C23: =Förutsättningar!N$22 -> 5 | D23: 20 | E23: 10 | F23: 0 | G23: 2 | H23: 9.9 | I23: OK14 | M23: =Table14171920[[#This Row],[Slagg mängd]]&Table14171920[[#This Row],[Gjuttemperatur]]&Table14171920[[#This Row],[Temperatur motgjutningsyta]]&Table14171920[[#This Row],[Väderskydd, uppvärmning (ingen vind)]]&Table14171920[[#This Row],[Täckning '[mm']]]&Table14171920[[#This Row],[OK <14 Dagar]]&Table14171920[[#This Row],[OK <21 Dagar]]&Table14171920[[#This Row],[Kommentar]] -> 0,42052010OK14
A24: 0.4 | B24: =Förutsättningar!M$22 -> 20 | C24: =Förutsättningar!N$22 -> 5 | D24: 20 | E24: 10 | F24: 0 | G24: 7 | H24: 10.6 | I24: OK14 | M24: =Table14171920[[#This Row],[Slagg mängd]]&Table14171920[[#This Row],[Gjuttemperatur]]&Table14171920[[#This Row],[Temperatur motgjutningsyta]]&Table14171920[[#This Row],[Väderskydd, uppvärmning (ingen vind)]]&Table14171920[[#This Row],[Täckning '[mm']]]&Table14171920[[#This Row],[OK <14 Dagar]]&Table14171920[[#This Row],[OK <21 Dagar]]&Table14171920[[#This Row],[Kommentar]] -> 0,42052010OK14
A25: 0.4 | B25: =Förutsättningar!M$22 -> 20 | C25: =Förutsättningar!N$22 -> 5 | D25: 20 | E25: 10 | F25: 0 | G25: 12 | H25: 10.8 | I25: OK14 | M25: =Table14171920[[#This Row],[Slagg mängd]]&Table14171920[[#This Row],[Gjuttemperatur]]&Table14171920[[#This Row],[Temperatur motgjutningsyta]]&Table14171920[[#This Row],[Väderskydd, uppvärmning (ingen vind)]]&Table14171920[[#This Row],[Täckning '[mm']]]&Table14171920[[#This Row],[OK <14 Dagar]]&Table14171920[[#This Row],[OK <21 Dagar]]&Table14171920[[#This Row],[Kommentar]] -> 0,42052010OK14
A26: 0.4 | B26: =Förutsättningar!M$22 -> 20 | C26: =Förutsättningar!N$22 -> 5 | D26: 20 | E26: 10 | F26: 0 | G26: 20 | H26: 10.9 | I26: OK14 | M26: =Table14171920[[#This Row],[Slagg mängd]]&Table14171920[[#This Row],[Gjuttemperatur]]&Table14171920[[#This Row],[Temperatur motgjutningsyta]]&Table14171920[[#This Row],[Väderskydd, uppvärmning (ingen vind)]]&Table14171920[[#This Row],[Täckning '[mm']]]&Table14171920[[#This Row],[OK <14 Dagar]]&Table14171920[[#This Row],[OK <21 Dagar]]&Table14171920[[#This Row],[Kommentar]] -> 0,42052010OK14
A27: 0.4 | B27: =Förutsättningar!M$23 -> 20 | C27: =Förutsättningar!N$23 -> 5 | D27: 20 | E27: 10 | F27: -5 | G27: 0 | H27: 12.5 | I27: OK14 | M27: =Table14171920[[#This Row],[Slagg mängd]]&Table14171920[[#This Row],[Gjuttemperatur]]&Table14171920[[#This Row],[Temperatur motgjutningsyta]]&Table14171920[[#This Row],[Väderskydd, uppvärmning (ingen vind)]]&Table14171920[[#This Row],[Täckning '[mm']]]&Table14171920[[#This Row],[OK <14 Dagar]]&Table14171920[[#This Row],[OK <21 Dagar]]&Table14171920[[#This Row],[Kommentar]] -> 0,42052010OK14
A28: 0.4 | B28: =Förutsättningar!M$23 -> 20 | C28: =Förutsättningar!N$23 -> 5 | D28: 20 | E28: 20 | F28: -5 | G28: 2 | H28: 11.3 | I28: OK14 | M28: =Table14171920[[#This Row],[Slagg mängd]]&Table14171920[[#This Row],[Gjuttemperatur]]&Table14171920[[#This Row],[Temperatur motgjutningsyta]]&Table14171920[[#This Row],[Väderskydd, uppvärmning (ingen vind)]]&Table14171920[[#This Row],[Täckning '[mm']]]&Table14171920[[#This Row],[OK <14 Dagar]]&Table14171920[[#This Row],[OK <21 Dagar]]&Table14171920[[#This Row],[Kommentar]] -> 0,42052020OK14
A29: 0.4 | B29: =Förutsättningar!M$23 -> 20 | C29: =Förutsättningar!N$23 -> 5 | D29: 20 | E29: 20 | F29: -5 | G29: 7 | H29: 11.9 | I29: OK14 | M29: =Table14171920[[#This Row],[Slagg mängd]]&Table14171920[[#This Row],[Gjuttemperatur]]&Table14171920[[#This Row],[Temperatur motgjutningsyta]]&Table14171920[[#This Row],[Väderskydd, uppvärmning (ingen vind)]]&Table14171920[[#This Row],[Täckning '[mm']]]&Table14171920[[#This Row],[OK <14 Dagar]]&Table14171920[[#This Row],[OK <21 Dagar]]&Table14171920[[#This Row],[Kommentar]] -> 0,42052020OK14
