Workbook

Sheet Bjälklag (10% slagg)
A1: Kvalitet | B1: Gjuttemperatur | C1: Temperatur motgjutningsyta | D1: Väderskydd, uppvärmning (ingen vind) | E1: Täckning [mm] | F1: Temperatur | G1: Vind | H1: <14 d och >70 % [Dagar] | I1: OK <14 Dagar | J1: <21 d och >70 % [Dagar] | K1: OK <21 Dagar | L1: Kommentar | M1: Åtgärdskåd
A2: C20/25 | B2: 15 | C2: 20 | D2: - | E2: 0 | F2: 20 | G2: 0 | H2: 4.8 | I2: OK14 | M2: =Table1[[#This Row],[Kvalitet]]&Table1[[#This Row],[Gjuttemperatur]]&Table1[[#This Row],[Temperatur motgjutningsyta]]&Table1[[#This Row],[Väderskydd, uppvärmning (ingen vind)]]&Table1[[#This Row],[Täckning '[mm']]]&Table1[[#This Row],[OK <14 Dagar]]&Table1[[#This Row],[OK <21 Dagar]] -> C20/251520-0OK14
A3: C20/25 | B3: 15 | C3: 20 | D3: - | E3: 0 | F3: 20 | G3: 2 | H3: 5.3 | I3: OK14 | M3: =Table1[[#This Row],[Kvalitet]]&Table1[[#This Row],[Gjuttemperatur]]&Table1[[#This Row],[Temperatur motgjutningsyta]]&Table1[[#This Row],[Väderskydd, uppvärmning (ingen vind)]]&Table1[[#This Row],[Täckning '[mm']]]&Table1[[#This Row],[OK <14 Dagar]]&Table1[[#This Row],[OK <21 Dagar]] -> C20/251520-0OK14
A4: C20/25 | B4: 15 | C4: 20 | D4: - | E4: 0 | F4: 20 | G4: 7 | H4: 5.5 | I4: OK14 | M4: =Table1[[#This Row],[Kvalitet]]&Table1[[#This Row],[Gjuttemperatur]]&Table1[[#This Row],[Temperatur motgjutningsyta]]&Table1[[#This Row],[Väderskydd, uppvärmning (ingen vind)]]&Table1[[#This Row],[Täckning '[mm']]]&Table1[[#This Row],[OK <14 Dagar]]&Table1[[#This Row],[OK <21 Dagar]] -> C20/251520-0OK14
A5: C20/25 | B5: 15 | C5: 20 | D5: - | E5: 0 | F5: 20 | G5: 12 | H5: 5.6 | I5: OK14 | M5: =Table1[[#This Row],[Kvalitet]]&Table1[[#This Row],[Gjuttemperatur]]&Table1[[#This Row],[Temperatur motgjutningsyta]]&Table1[[#This Row],[Väderskydd, uppvärmning (ingen vind)]]&Table1[[#This Row],[Täckning '[mm']]]&Table1[[#This Row],[OK <14 Dagar]]&Table1[[#This Row],[OK <21 Dagar]] -> C20/251520-0OK14
A6: C20/25 | B6: 15 | C6: 20 | D6: - | E6: 0 | F6: 20 | G6: 20 | H6: 5.6 | I6: OK14 | M6: =Table1[[#This Row],[Kvalitet]]&Table1[[#This Row],[Gjuttemperatur]]&Table1[[#This Row],[Temperatur motgjutningsyta]]&Table1[[#This Row],[Väderskydd, uppvärmning (ingen vind)]]&Table1[[#This Row],[Täckning '[mm']]]&Table1[[#This Row],[OK <14 Dagar]]&Table1[[#This Row],[OK <21 Dagar]] -> C20/251520-0OK14
A7: C20/25 | B7: 15 | C7: 15 | D7: - | E7: 0 | F7: 15 | G7: 0 | H7: 6.2 | I7: OK14 | M7: =Table1[[#This Row],[Kvalitet]]&Table1[[#This Row],[Gjuttemperatur]]&Table1[[#This Row],[Temperatur motgjutningsyta]]&Table1[[#This Row],[Väderskydd, uppvärmning (ingen vind)]]&Table1[[#This Row],[Täckning '[mm']]]&Table1[[#This Row],[OK <14 Dagar]]&Table1[[#This Row],[OK <21 Dagar]] -> C20/251515-0OK14
A8: C20/25 | B8: 15 | C8: 15 | D8: - | E8: 0 | F8: 15 | G8: 2 | H8: 6.9 | I8: OK14 | M8: =Table1[[#This Row],[Kvalitet]]&Table1[[#This Row],[Gjuttemperatur]]&Table1[[#This Row],[Temperatur motgjutningsyta]]&Table1[[#This Row],[Väderskydd, uppvärmning (ingen vind)]]&Table1[[#This Row],[Täckning '[mm']]]&Table1[[#This Row],[OK <14 Dagar]]&Table1[[#This Row],[OK <21 Dagar]] -> C20/251515-0OK14
A9: C20/25 | B9: 15 | C9: 15 | D9: - | E9: 0 | F9: 15 | G9: 7 | H9: 7.2 | I9: OK14 | M9: =Table1[[#This Row],[Kvalitet]]&Table1[[#This Row],[Gjuttemperatur]]&Table1[[#This Row],[Temperatur motgjutningsyta]]&Table1[[#This Row],[Väderskydd, uppvärmning (ingen vind)]]&Table1[[#This Row],[Täckning '[mm']]]&Table1[[#This Row],[OK <14 Dagar]]&Table1[[#This Row],[OK <21 Dagar]] -> C20/251515-0OK14
A10: C20/25 | B10: 15 | C10: 15 | D10: - | E10: 0 | F10: 15 | G10: 12 | H10: 7.3 | I10: OK14 | M10: =Table1[[#This Row],[Kvalitet]]&Table1[[#This Row],[Gjuttemperatur]]&Table1[[#This Row],[Temperatur motgjutningsyta]]&Table1[[#This Row],[Väderskydd, uppvärmning (ingen vind)]]&Table1[[#This Row],[Täckning '[mm']]]&Table1[[#This Row],[OK <14 Dagar]]&Table1[[#This Row],[OK <21 Dagar]] -> C20/251515-0OK14
A11: C20/25 | B11: 15 | C11: 15 | D11: - | E11: 0 | F11: 15 | G11: 20 | H11: 7.3 | I11: OK14 | M11: =Table1[[#This Row],[Kvalitet]]&Table1[[#This Row],[Gjuttemperatur]]&Table1[[#This Row],[Temperatur motgjutningsyta]]&Table1[[#This Row],[Väderskydd, uppvärmning (ingen vind)]]&Table1[[#This Row],[Täckning '[mm']]]&Table1[[#This Row],[OK <14 Dagar]]&Table1[[#This Row],[OK <21 Dagar]] -> C20/251515-0OK14
A12: C20/25 | B12: 15 | C12: 10 | D12: - | E12: 0 | F12: 10 | G12: 0 | H12: 8.6 | I12: OK14 | M12: =Table1[[#This Row],[Kvalitet]]&Table1[[#This Row],[Gjuttemperatur]]&Table1[[#This Row],[Temperatur motgjutningsyta]]&Table1[[#This Row],[Väderskydd, uppvärmning (ingen vind)]]&Table1[[#This Row],[Täckning '[mm']]]&Table1[[#This Row],[OK <14 Dagar]]&Table1[[#This Row],[OK <21 Dagar]] -> C20/251510-0OK14
A13: C20/25 | B13: 15 | C13: 10 | D13: - | E13: 0 | F13: 10 | G13: 2 | H13: 9.5 | I13: OK14 | M13: =Table1[[#This Row],[Kvalitet]]&Table1[[#This Row],[Gjuttemperatur]]&Table1[[#This Row],[Temperatur motgjutningsyta]]&Table1[[#This Row],[Väderskydd, uppvärmning (ingen vind)]]&Table1[[#This Row],[Täckning '[mm']]]&Table1[[#This Row],[OK <14 Dagar]]&Table1[[#This Row],[OK <21 Dagar]] -> C20/251510-0OK14
A14: C20/25 | B14: 15 | C14: 10 | D14: - | E14: 0 | F14: 10 | G14: 7 | H14: 9.9 | I14: OK14 | M14: =Table1[[#This Row],[Kvalitet]]&Table1[[#This Row],[Gjuttemperatur]]&Table1[[#This Row],[Temperatur motgjutningsyta]]&Table1[[#This Row],[Väderskydd, uppvärmning (ingen vind)]]&Table1[[#This Row],[Täckning '[mm']]]&Table1[[#This Row],[OK <14 Dagar]]&Table1[[#This Row],[OK <21 Dagar]] -> C20/251510-0OK14
A15: C20/25 | B15: 15 | C15: 10 | D15: - | E15: 0 | F15: 10 | G15: 12 | H15: 10 | I15: OK14 | M15: =Table1[[#This Row],[Kvalitet]]&Table1[[#This Row],[Gjuttemperatur]]&Table1[[#This Row],[Temperatur motgjutningsyta]]&Table1[[#This Row],[Väderskydd, uppvärmning (ingen vind)]]&Table1[[#This Row],[Täckning '[mm']]]&Table1[[#This Row],[OK <14 Dagar]]&Table1[[#This Row],[OK <21 Dagar]] -> C20/251510-0OK14
A16: C20/25 | B16: 15 | C16: 10 | D16: - | E16: 0 | F16: 10 | G16: 20 | H16: 10.1 | I16: OK14 | M16: =Table1[[#This Row],[Kvalitet]]&Table1[[#This Row],[Gjuttemperatur]]&Table1[[#This Row],[Temperatur motgjutningsyta]]&Table1[[#This Row],[Väderskydd, uppvärmning (ingen vind)]]&Table1[[#This Row],[Täckning '[mm']]]&Table1[[#This Row],[OK <14 Dagar]]&Table1[[#This Row],[OK <21 Dagar]] -> C20/251510-0OK14
A17: C20/25 | B17: 20 | C17: 5 | D17: - | E17: 0 | F17: 5 | G17: 0 | H17: 12.5 | I17: OK14 | M17: =Table1[[#This Row],[Kvalitet]]&Table1[[#This Row],[Gjuttemperatur]]&Table1[[#This Row],[Temperatur motgjutningsyta]]&Table1[[#This Row],[Väderskydd, uppvärmning (ingen vind)]]&Table1[[#This Row],[Täckning '[mm']]]&Table1[[#This Row],[OK <14 Dagar]]&Table1[[#This Row],[OK <21 Dagar]] -> C20/25205-0OK14
A18: C20/25 | B18: 20 | C18: 5 | D18: 5 | E18: 0 | F18: 5 | G18: 2 | H18: 11.9 | I18: OK14 | M18: =Table1[[#This Row],[Kvalitet]]&Table1[[#This Row],[Gjuttemperatur]]&Table1[[#This Row],[Temperatur motgjutningsyta]]&Table1[[#This Row],[Väderskydd, uppvärmning (ingen vind)]]&Table1[[#This Row],[Täckning '[mm']]]&Table1[[#This Row],[OK <14 Dagar]]&Table1[[#This Row],[OK <21 Dagar]] -> C20/2520550OK14
A19: C20/25 | B19: 20 | C19: 5 | D19: 5 | E19: 0 | F19: 5 | G19: 7 | H19: 13 | I19: OK14 | M19: =Table1[[#This Row],[Kvalitet]]&Table1[[#This Row],[Gjuttemperatur]]&Table1[[#This Row],[Temperatur motgjutningsyta]]&Table1[[#This Row],[Väderskydd, uppvärmning (ingen vind)]]&Table1[[#This Row],[Täckning '[mm']]]&Table1[[#This Row],[OK <14 Dagar]]&Table1[[#This Row],[OK <21 Dagar]] -> C20/2520550OK14
A20: C20/25 | B20: 20 | C20: 5 | D20: 5 | E20: 0 | F20: 5 | G20: 12 | H20: 13.3 | I20: OK14 | M20: =Table1[[#This Row],[Kvalitet]]&Table1[[#This Row],[Gjuttemperatur]]&Table1[[#This Row],[Temperatur motgjutningsyta]]&Table1[[#This Row],[Väderskydd, uppvärmning (ingen vind)]]&Table1[[#This Row],[Täckning '[mm']]]&Table1[[#This Row],[OK <14 Dagar]]&Table1[[#This Row],[OK <21 Dagar]] -> C20/2520550OK14
A21: C20/25 | B21: 20 | C21: 5 | D21: 5 | E21: 0 | F21: 5 | G21: 20 | H21: 13.5 | I21: OK14 | M21: =Table1[[#This Row],[Kvalitet]]&Table1[[#This Row],[Gjuttemperatur]]&Table1[[#This Row],[Temperatur motgjutningsyta]]&Table1[[#This Row],[Väderskydd, uppvärmning (ingen vind)]]&Table1[[#This Row],[Täckning '[mm']]]&Table1[[#This Row],[OK <14 Dagar]]&Table1[[#This Row],[OK <21 Dagar]] -> C20/2520550OK14
A22: C20/25 | B22: 20 | C22: 5 | D22: 10 | E22: 0 | F22: 0 | G22: 0 | H22: 12.9 | I22: OK14 | M22: =Table1[[#This Row],[Kvalitet]]&Table1[[#This Row],[Gjuttemperatur]]&Table1[[#This Row],[Temperatur motgjutningsyta]]&Table1[[#This Row],[Väderskydd, uppvärmning (ingen vind)]]&Table1[[#This Row],[Täckning '[mm']]]&Table1[[#This Row],[OK <14 Dagar]]&Table1[[#This Row],[OK <21 Dagar]] -> C20/25205100OK14
A23: C20/25 | B23: 20 | C23: 5 | D23: 15 | E23: 0 | F23: 0 | G23: 2 | H23: 14 | I23: OK14 | M23: =Table1[[#This Row],[Kvalitet]]&Table1[[#This Row],[Gjuttemperatur]]&Table1[[#This Row],[Temperatur motgjutningsyta]]&Table1[[#This Row],[Väderskydd, uppvärmning (ingen vind)]]&Table1[[#This Row],[Täckning '[mm']]]&Table1[[#This Row],[OK <14 Dagar]]&Table1[[#This Row],[OK <21 Dagar]] -> C20/25205150OK14
A24: C20/25 | B24: 20 | C24: 5 | D24: 20 | E24: Presenning | F24: 0 | G24: 7 | H24: 12.9 | I24: OK14 | M24: =Table1[[#This Row],[Kvalitet]]&Table1[[#This Row],[Gjuttemperatur]]&Table1[[#This Row],[Temperatur motgjutningsyta]]&Table1[[#This Row],[Väderskydd, uppvärmning (ingen vind)]]&Table1[[#This Row],[Täckning '[mm']]]&Table1[[#This Row],[OK <14 Dagar]]&Table1[[#This Row],[OK <21 Dagar]] -> C20/2520520PresenningOK14
A25: C20/25 | B25: 20 | C25: 5 | D25: 20 | E25: Presenning | F25: 0 | G25: 12 | H25: 13.5 | I25: OK14 | M25: =Table1[[#This Row],[Kvalitet]]&Table1[[#This Row],[Gjuttemperatur]]&Table1[[#This Row],[Temperatur motgjutningsyta]]&Table1[[#This Row],[Väderskydd, uppvärmning (ingen vind)]]&Table1[[#This Row],[Täckning '[mm']]]&Table1[[#This Row],[OK <14 Dagar]]&Table1[[#This Row],[OK <21 Dagar]] -> C20/2520520PresenningOK14
A26: C20/25 | B26: 20 | C26: 5 | D26: 20 | E26: Presenning | F26: 0 | G26: 20 | H26: 13.9 | I26: OK14 | M26: =Table1[[#This Row],[Kvalitet]]&Table1[[#This Row],[Gjuttemperatur]]&Table1[[#This Row],[Temperatur motgjutningsyta]]&Table1[[#This Row],[Väderskydd, uppvärmning (ingen vind)]]&Table1[[#This Row],[Täckning '[mm']]]&Table1[[#This Row],[OK <14 Dagar]]&Table1[[#This Row],[OK <21 Dagar]] -> C20/2520520PresenningOK14
A27: C20/25 | B27: 20 | C27: 5 | D27: 20 | E27: 0 | F27: -5 | G27: 0 | H27: 13.3 | I27: OK14 | M27: =Table1[[#This Row],[Kvalitet]]&Table1[[#This Row],[Gjuttemperatur]]&Table1[[#This Row],[Temperatur motgjutningsyta]]&Table1[[#This Row],[Väderskydd, uppvärmning (ingen vind)]]&Table1[[#This Row],[Täckning '[mm']]]&Table1[[#This Row],[OK <14 Dagar]]&Table1[[#This Row],[OK <21 Dagar]] -> C20/25205200OK14
A28: C20/25 | B28: 20 | C28: 5 | D28: 20 | E28: 10 | F28: -5 | G28: 2 | H28: 10 | I28: OK14 | M28: =Table1[[#This Row],[Kvalitet]]&Table1[[#This Row],[Gjuttemperatur]]&Table1[[#This Row],[Temperatur motgjutningsyta]]&Table1[[#This Row],[Väderskydd, uppvärmning (ingen vind)]]&Table1[[#This Row],[Täckning '[mm']]]&Table1[[#This Row],[OK <14 Dagar]]&Table1[[#This Row],[OK <21 Dagar]] -> C20/252052010OK14
A29: C20/25 | B29: 20 | C29: 5 | D29: 20 | E29: 10 | F29: -5 | G29: 7 | H29: 11 | I29: OK14 | M29: =Table1[[#This Row],[Kvalitet]]&Table1[[#This Row],[Gjuttemperatur]]&Table1[[#This Row],[Temperatur motgjutningsyta]]&Table1[[#This Row],[Väderskydd, uppvärmning (ingen vind)]]&Table1[[#This Row],[Täckning '[mm']]]&Table1[[#This Row],[OK <14 Dagar]]&Table1[[#This Row],[OK <21 Dagar]] -> C20/252052010OK14
A30: C20/25 | B30: 20 | C30: 5 | D30: 20 | E30: 10 | F30: -5 | G30: 12 | H30: 11.4 | I30: OK14 | M30: =Table1[[#This Row],[Kvalitet]]&Table1[[#This Row],[Gjuttemperatur]]&Table1[[#This Row],[Temperatur motgjutningsyta]]&Table1[[#This Row],[Väderskydd, uppvärmning (ingen vind)]]&Table1[[#This Row],[Täckning '[mm']]]&Table1[[#This Row],[OK <14 Dagar]]&Table1[[#This Row],[OK <21 Dagar]] -> C20/252052010OK14
A31: C20/25 | B31: 20 | C31: 5 | D31: 20 | E31: 10 | F31: -5 | G31: 20 | H31: 11.6 | I31: OK14 | M31: =Table1[[#This Row],[Kvalitet]]&Table1[[#This Row],[Gjuttemperatur]]&Table1[[#This Row],[Temperatur motgjutningsyta]]&Table1[[#This Row],[Väderskydd, uppvärmning (ingen vind)]]&Table1[[#This Row],[Täckning '[mm']]]&Table1[[#This Row],[OK <14 Dagar]]&Table1[[#This Row],[OK <21 Dagar]] -> C20/252052010OK14
A32: C20/25 | B32: 20 | C32: 5 | D32: 20 | E32: 10 | F32: -10 | G32: 0 | H32: 13.6 | I32: OK14 | M32: =Table1[[#This Row],[Kvalitet]]&Table1[[#This Row],[Gjuttemperatur]]&Table1[[#This Row],[Temperatur motgjutningsyta]]&Table1[[#This Row],[Väderskydd, uppvärmning (ingen vind)]]&Table1[[#This Row],[Täckning '[mm']]]&Table1[[#This Row],[OK <14 Dagar]]&Table1[[#This Row],[OK <21 Dagar]] -> C20/252052010OK14
A33: C20/25 | B33: 20 | C33: 5 | D33: 20 | E33: 20 | F33: -10 | G33: 2 | H33: 11.9 | I33: OK14 | M33: =Table1[[#This Row],[Kvalitet]]&Table1[[#This Row],[Gjuttemperatur]]&Table1[[#This Row],[Temperatur motgjutningsyta]]&Table1[[#This Row],[Väderskydd, uppvärmning (ingen vind)]]&Table1[[#This Row],[Täckning '[mm']]]&Table1[[#This Row],[OK <14 Dagar]]&Table1[[#This Row],[OK <21 Dagar]] -> C20/252052020OK14
A34: C20/25 | B34: 20 | C34: 5 | D34: 20 | E34: 20 | F34: -10 | G34: 7 | H34: 12.7 | I34: OK14 | M34: =Table1[[#This Row],[Kvalitet]]&Table1[[#This Row],[Gjuttemperatur]]&Table1[[#This Row],[Temperatur motgjutningsyta]]&Table1[[#This Row],[Väderskydd, uppvärmning (ingen vind)]]&Table1[[#This Row],[Täckning '[mm']]]&Table1[[#This Row],[OK <14 Dagar]]&Table1[[#This Row],[OK <21 Dagar]] -> C20/252052020OK14
A35: - | B35: - | C35: - | D35: - | E35: - | F35: -10 | G35: 12 | H35: - | L35: Frys innan täck | M35: =Table1[[#This Row],[Kvalitet]]&Table1[[#This Row],[Gjuttemperatur]]&Table1[[#This Row],[Temperatur motgjutningsyta]]&Table1[[#This Row],[Väderskydd, uppvärmning (ingen vind)]]&Table1[[#This Row],[Täckning '[mm']]]&Table1[[#This Row],[OK <14 Dagar]]&Table1[[#This Row],[OK <21 Dagar]] -> -----
A36: - | B36: - | C36: - | D36: - | E36: - | F36: -10 | G36: 20 | H36: - | L36: Frys innan täck | M36: =Table1[[#This Row],[Kvalitet]]&Table1[[#This Row],[Gjuttemperatur]]&Table1[[#This Row],[Temperatur motgjutningsyta]]&Table1[[#This Row],[Väderskydd, uppvärmning (ingen vind)]]&Table1[[#This Row],[Täckning '[mm']]]&Table1[[#This Row],[OK <14 Dagar]]&Table1[[#This Row],[OK <21 Dagar]] -> -----
A37: C28/35 | B37: 15 | C37: 5 | D37: 20 | E37: 30 | F37: -15 | G37: 0 | H37: 12 | I37: OK14 | M37: =Table1[[#This Row],[Kvalitet]]&Table1[[#This Row],[Gjuttemperatur]]&Table1[[#This Row],[Temperatur motgjutningsyta]]&Table1[[#This Row],[Väderskydd, uppvärmning (ingen vind)]]&Table1[[#This Row],[Täckning '[mm']]]&Table1[[#This Row],[OK <14 Dagar]]&Table1[[#This Row],[OK <21 Dagar]] -> C28/351552030OK14
A38: C28/35 | B38: 15 | C38: 5 | D38: 20 | E38: 30 | F38: -15 | G38: 2 | H38: 13.2 | I38: OK14 | M38: =Table1[[#This Row],[Kvalitet]]&Table1[[#This Row],[Gjuttemperatur]]&Table1[[#This Row],[Temperatur motgjutningsyta]]&Table1[[#This Row],[Väderskydd, uppvärmning (ingen vind)]]&Table1[[#This Row],[Täckning '[mm']]]&Table1[[#This Row],[OK <14 Dagar]]&Table1[[#This Row],[OK <21 Dagar]] -> C28/351552030OK14
A39: - | B39: - | C39: - | D39: - | E39: - | F39: -15 | G39: 7 | H39: - | L39: Frys innan täck | M39: =Table1[[#This Row],[Kvalitet]]&Table1[[#This Row],[Gjuttemperatur]]&Table1[[#This Row],[Temperatur motgjutningsyta]]&Table1[[#This Row],[Väderskydd, uppvärmning (ingen vind)]]&Table1[[#This Row],[Täckning '[mm']]]&Table1[[#This Row],[OK <14 Dagar]]&Table1[[#This Row],[OK <21 Dagar]] -> -----
A40: - | B40: - | C40: - | D40: - | E40: - | F40: -15 | G40: 12 | H40: - | L40: Frys innan täck | M40: =Table1[[#This Row],[Kvalitet]]&Table1[[#This Row],[Gjuttemperatur]]&Table1[[#This Row],[Temperatur motgjutningsyta]]&Table1[[#This Row],[Väderskydd, uppvärmning (ingen vind)]]&Table1[[#This Row],[Täckning '[mm']]]&Table1[[#This Row],[OK <14 Dagar]]&Table1[[#This Row],[OK <21 Dagar]] -> -----
...

Sheet Bjälklag (20% slagg)
A1: Kvalitet | B1: Gjuttemperatur | C1: Temperatur motgjutningsyta | D1: Väderskydd, uppvärmning (ingen vind) | E1: Täckning [mm] | F1: Temperatur | G1: Vind | H1: <14 d och >70 % [Dagar] | I1: OK under 14 D | J1: <21 d och >70 % [Dagar] | K1: OK <21 Dagar | L1: Kommentar | M1: Åtgärdskåd
A2: C20/25 | B2: 15 | C2: 20 | D2: - | E2: 0 | F2: 20 | G2: 0 | H2: 6.2 | I2: OK14 | M2: =Table14[[#This Row],[Kvalitet]]&Table14[[#This Row],[Gjuttemperatur]]&Table14[[#This Row],[Temperatur motgjutningsyta]]&Table14[[#This Row],[Väderskydd, uppvärmning (ingen vind)]]&Table14[[#This Row],[Täckning '[mm']]]&Table14[[#This Row],[OK under 14 D]]&Table14[[#This Row],[OK <21 Dagar]] -> C20/251520-0OK14
A3: C20/25 | B3: 15 | C3: 20 | D3: - | E3: 0 | F3: 20 | G3: 2 | H3: 6.8 | I3: OK14 | M3: =Table14[[#This Row],[Kvalitet]]&Table14[[#This Row],[Gjuttemperatur]]&Table14[[#This Row],[Temperatur motgjutningsyta]]&Table14[[#This Row],[Väderskydd, uppvärmning (ingen vind)]]&Table14[[#This Row],[Täckning '[mm']]]&Table14[[#This Row],[OK under 14 D]]&Table14[[#This Row],[OK <21 Dagar]] -> C20/251520-0OK14
A4: C20/25 | B4: 15 | C4: 20 | D4: - | E4: 0 | F4: 20 | G4: 7 | H4: 7 | I4: OK14 | M4: =Table14[[#This Row],[Kvalitet]]&Table14[[#This Row],[Gjuttemperatur]]&Table14[[#This Row],[Temperatur motgjutningsyta]]&Table14[[#This Row],[Väderskydd, uppvärmning (ingen vind)]]&Table14[[#This Row],[Täckning '[mm']]]&Table14[[#This Row],[OK under 14 D]]&Table14[[#This Row],[OK <21 Dagar]] -> C20/251520-0OK14
A5: C20/25 | B5: 15 | C5: 20 | D5: - | E5: 0 | F5: 20 | G5: 12 | H5: 7.1 | I5: OK14 | M5: =Table14[[#This Row],[Kvalitet]]&Table14[[#This Row],[Gjuttemperatur]]&Table14[[#This Row],[Temperatur motgjutningsyta]]&Table14[[#This Row],[Väderskydd, uppvärmning (ingen vind)]]&Table14[[#This Row],[Täckning '[mm']]]&Table14[[#This Row],[OK under 14 D]]&Table14[[#This Row],[OK <21 Dagar]] -> C20/251520-0OK14
A6: C20/25 | B6: 15 | C6: 20 | D6: - | E6: 0 | F6: 20 | G6: 20 | H6: 7.1 | I6: OK14 | M6: =Table14[[#This Row],[Kvalitet]]&Table14[[#This Row],[Gjuttemperatur]]&Table14[[#This Row],[Temperatur motgjutningsyta]]&Table14[[#This Row],[Väderskydd, uppvärmning (ingen vind)]]&Table14[[#This Row],[Täckning '[mm']]]&Table14[[#This Row],[OK under 14 D]]&Table14[[#This Row],[OK <21 Dagar]] -> C20/251520-0OK14
A7: C20/25 | B7: 15 | C7: 15 | D7: - | E7: 0 | F7: 15 | G7: 0 | H7: 8.2 | I7: OK14 | M7: =Table14[[#This Row],[Kvalitet]]&Table14[[#This Row],[Gjuttemperatur]]&Table14[[#This Row],[Temperatur motgjutningsyta]]&Table14[[#This Row],[Väderskydd, uppvärmning (ingen vind)]]&Table14[[#This Row],[Täckning '[mm']]]&Table14[[#This Row],[OK under 14 D]]&Table14[[#This Row],[OK <21 Dagar]] -> C20/251515-0OK14
A8: C20/25 | B8: 15 | C8: 15 | D8: - | E8: 0 | F8: 15 | G8: 2 | H8: 8.9 | I8: OK14 | M8: =Table14[[#This Row],[Kvalitet]]&Table14[[#This Row],[Gjuttemperatur]]&Table14[[#This Row],[Temperatur motgjutningsyta]]&Table14[[#This Row],[Väderskydd, uppvärmning (ingen vind)]]&Table14[[#This Row],[Täckning '[mm']]]&Table14[[#This Row],[OK under 14 D]]&Table14[[#This Row],[OK <21 Dagar]] -> C20/251515-0OK14
A9: C20/25 | B9: 15 | C9: 15 | D9: - | E9: 0 | F9: 15 | G9: 7 | H9: 9.2 | I9: OK14 | M9: =Table14[[#This Row],[Kvalitet]]&Table14[[#This Row],[Gjuttemperatur]]&Table14[[#This Row],[Temperatur motgjutningsyta]]&Table14[[#This Row],[Väderskydd, uppvärmning (ingen vind)]]&Table14[[#This Row],[Täckning '[mm']]]&Table14[[#This Row],[OK under 14 D]]&Table14[[#This Row],[OK <21 Dagar]] -> C20/251515-0OK14
A10: C20/25 | B10: 15 | C10: 15 | D10: - | E10: 0 | F10: 15 | G10: 12 | H10: 9.3 | I10: OK14 | M10: =Table14[[#This Row],[Kvalitet]]&Table14[[#This Row],[Gjuttemperatur]]&Table14[[#This Row],[Temperatur motgjutningsyta]]&Table14[[#This Row],[Väderskydd, uppvärmning (ingen vind)]]&Table14[[#This Row],[Täckning '[mm']]]&Table14[[#This Row],[OK under 14 D]]&Table14[[#This Row],[OK <21 Dagar]] -> C20/251515-0OK14
A11: C20/25 | B11: 15 | C11: 15 | D11: - | E11: 0 | F11: 15 | G11: 20 | H11: 9.3 | I11: OK14 | M11: =Table14[[#This Row],[Kvalitet]]&Table14[[#This Row],[Gjuttemperatur]]&Table14[[#This Row],[Temperatur motgjutningsyta]]&Table14[[#This Row],[Väderskydd, uppvärmning (ingen vind)]]&Table14[[#This Row],[Täckning '[mm']]]&Table14[[#This Row],[OK under 14 D]]&Table14[[#This Row],[OK <21 Dagar]] -> C20/251515-0OK14
A12: C20/25 | B12: 15 | C12: 10 | D12: - | E12: 0 | F12: 10 | G12: 0 | H12: 11.3 | I12: OK14 | M12: =Table14[[#This Row],[Kvalitet]]&Table14[[#This Row],[Gjuttemperatur]]&Table14[[#This Row],[Temperatur motgjutningsyta]]&Table14[[#This Row],[Väderskydd, uppvärmning (ingen vind)]]&Table14[[#This Row],[Täckning '[mm']]]&Table14[[#This Row],[OK under 14 D]]&Table14[[#This Row],[OK <21 Dagar]] -> C20/251510-0OK14
A13: C20/25 | B13: 15 | C13: 10 | D13: - | E13: 0 | F13: 10 | G13: 2 | H13: 12.2 | I13: OK14 | M13: =Table14[[#This Row],[Kvalitet]]&Table14[[#This Row],[Gjuttemperatur]]&Table14[[#This Row],[Temperatur motgjutningsyta]]&Table14[[#This Row],[Väderskydd, uppvärmning (ingen vind)]]&Table14[[#This Row],[Täckning '[mm']]]&Table14[[#This Row],[OK under 14 D]]&Table14[[#This Row],[OK <21 Dagar]] -> C20/251510-0OK14
A14: C20/25 | B14: 15 | C14: 10 | D14: - | E14: 0 | F14: 10 | G14: 7 | H14: 12.6 | I14: OK14 | M14: =Table14[[#This Row],[Kvalitet]]&Table14[[#This Row],[Gjuttemperatur]]&Table14[[#This Row],[Temperatur motgjutningsyta]]&Table14[[#This Row],[Väderskydd, uppvärmning (ingen vind)]]&Table14[[#This Row],[Täckning '[mm']]]&Table14[[#This Row],[OK under 14 D]]&Table14[[#This Row],[OK <21 Dagar]] -> C20/251510-0OK14
A15: C20/25 | B15: 15 | C15: 10 | D15: - | E15: 0 | F15: 10 | G15: 12 | H15: 12.7 | I15: OK14 | M15: =Table14[[#This Row],[Kvalitet]]&Table14[[#This Row],[Gjuttemperatur]]&Table14[[#This Row],[Temperatur motgjutningsyta]]&Table14[[#This Row],[Väderskydd, uppvärmning (ingen vind)]]&Table14[[#This Row],[Täckning '[mm']]]&Table14[[#This Row],[OK under 14 D]]&Table14[[#This Row],[OK <21 Dagar]] -> C20/251510-0OK14
A16: C20/25 | B16: 15 | C16: 10 | D16: - | E16: 0 | F16: 10 | G16: 20 | H16: 12.8 | I16: OK14 | M16: =Table14[[#This Row],[Kvalitet]]&Table14[[#This Row],[Gjuttemperatur]]&Table14[[#This Row],[Temperatur motgjutningsyta]]&Table14[[#This Row],[Väderskydd, uppvärmning (ingen vind)]]&Table14[[#This Row],[Täckning '[mm']]]&Table14[[#This Row],[OK under 14 D]]&Table14[[#This Row],[OK <21 Dagar]] -> C20/251510-0OK14
A17: C20/25 | B17: 20 | C17: 5 | D17: 5 | E17: 0 | F17: 5 | G17: 0 | H17: 13.5 | I17: OK14 | M17: =Table14[[#This Row],[Kvalitet]]&Table14[[#This Row],[Gjuttemperatur]]&Table14[[#This Row],[Temperatur motgjutningsyta]]&Table14[[#This Row],[Väderskydd, uppvärmning (ingen vind)]]&Table14[[#This Row],[Täckning '[mm']]]&Table14[[#This Row],[OK under 14 D]]&Table14[[#This Row],[OK <21 Dagar]] -> C20/2520550OK14
A18: C20/25 | B18: 20 | C18: 5 | D18: 10 | E18: 0 | F18: 5 | G18: 2 | H18: 13.5 | I18: OK14 | M18: =Table14[[#This Row],[Kvalitet]]&Table14[[#This Row],[Gjuttemperatur]]&Table14[[#This Row],[Temperatur motgjutningsyta]]&Table14[[#This Row],[Väderskydd, uppvärmning (ingen vind)]]&Table14[[#This Row],[Täckning '[mm']]]&Table14[[#This Row],[OK under 14 D]]&Table14[[#This Row],[OK <21 Dagar]] -> C20/25205100OK14
A19: C20/25 | B19: 20 | C19: 5 | D19: 15 | E19: 0 | F19: 5 | G19: 7 | H19: 13.8 | I19: OK14 | M19: =Table14[[#This Row],[Kvalitet]]&Table14[[#This Row],[Gjuttemperatur]]&Table14[[#This Row],[Temperatur motgjutningsyta]]&Table14[[#This Row],[Väderskydd, uppvärmning (ingen vind)]]&Table14[[#This Row],[Täckning '[mm']]]&Table14[[#This Row],[OK under 14 D]]&Table14[[#This Row],[OK <21 Dagar]] -> C20/25205150OK14
A20: C20/25 | B20: 20 | C20: 5 | D20: 20 | E20: 0 | F20: 5 | G20: 12 | H20: 13.3 | I20: OK14 | M20: =Table14[[#This Row],[Kvalitet]]&Table14[[#This Row],[Gjuttemperatur]]&Table14[[#This Row],[Temperatur motgjutningsyta]]&Table14[[#This Row],[Väderskydd, uppvärmning (ingen vind)]]&Table14[[#This Row],[Täckning '[mm']]]&Table14[[#This Row],[OK under 14 D]]&Table14[[#This Row],[OK <21 Dagar]] -> C20/25205200OK14
A21: C20/25 | B21: 20 | C21: 5 | D21: 20 | E21: 0 | F21: 5 | G21: 20 | H21: 13.7 | I21: OK14 | M21: =Table14[[#This Row],[Kvalitet]]&Table14[[#This Row],[Gjuttemperatur]]&Table14[[#This Row],[Temperatur motgjutningsyta]]&Table14[[#This Row],[Väderskydd, uppvärmning (ingen vind)]]&Table14[[#This Row],[Täckning '[mm']]]&Table14[[#This Row],[OK under 14 D]]&Table14[[#This Row],[OK <21 Dagar]] -> C20/25205200OK14
A22: C20/25 | B22: 20 | C22: 5 | D22: 15 | E22: 0 | F22: 0 | G22: 0 | H22: 13.9 | I22: OK14 | M22: =Table14[[#This Row],[Kvalitet]]&Table14[[#This Row],[Gjuttemperatur]]&Table14[[#This Row],[Temperatur motgjutningsyta]]&Table14[[#This Row],[Väderskydd, uppvärmning (ingen vind)]]&Table14[[#This Row],[Täckning '[mm']]]&Table14[[#This Row],[OK under 14 D]]&Table14[[#This Row],[OK <21 Dagar]] -> C20/25205150OK14
A23: C20/25 | B23: 20 | C23: 5 | D23: 20 | E23: Presenning | F23: 0 | G23: 2 | H23: 14 | I23: OK14 | M23: =Table14[[#This Row],[Kvalitet]]&Table14[[#This Row],[Gjuttemperatur]]&Table14[[#This Row],[Temperatur motgjutningsyta]]&Table14[[#This Row],[Väderskydd, uppvärmning (ingen vind)]]&Table14[[#This Row],[Täckning '[mm']]]&Table14[[#This Row],[OK under 14 D]]&Table14[[#This Row],[OK <21 Dagar]] -> C20/2520520PresenningOK14
A24: C20/25 | B24: 20 | C24: 5 | D24: 20 | E24: 10 | F24: 0 | G24: 7 | H24: 10.2 | I24: OK14 | M24: =Table14[[#This Row],[Kvalitet]]&Table14[[#This Row],[Gjuttemperatur]]&Table14[[#This Row],[Temperatur motgjutningsyta]]&Table14[[#This Row],[Väderskydd, uppvärmning (ingen vind)]]&Table14[[#This Row],[Täckning '[mm']]]&Table14[[#This Row],[OK under 14 D]]&Table14[[#This Row],[OK <21 Dagar]] -> C20/252052010OK14
A25: C20/25 | B25: 20 | C25: 5 | D25: 20 | E25: 10 | F25: 0 | G25: 12 | H25: 10.3 | I25: OK14 | M25: =Table14[[#This Row],[Kvalitet]]&Table14[[#This Row],[Gjuttemperatur]]&Table14[[#This Row],[Temperatur motgjutningsyta]]&Table14[[#This Row],[Väderskydd, uppvärmning (ingen vind)]]&Table14[[#This Row],[Täckning '[mm']]]&Table14[[#This Row],[OK under 14 D]]&Table14[[#This Row],[OK <21 Dagar]] -> C20/252052010OK14
A26: C20/25 | B26: 20 | C26: 5 | D26: 20 | E26: 10 | F26: 0 | G26: 20 | H26: 10.5 | I26: OK14 | M26: =Table14[[#This Row],[Kvalitet]]&Table14[[#This Row],[Gjuttemperatur]]&Table14[[#This Row],[Temperatur motgjutningsyta]]&Table14[[#This Row],[Väderskydd, uppvärmning (ingen vind)]]&Table14[[#This Row],[Täckning '[mm']]]&Table14[[#This Row],[OK under 14 D]]&Table14[[#This Row],[OK <21 Dagar]] -> C20/252052010OK14
A27: C20/25 | B27: 20 | C27: 5 | D27: 20 | E27: 10 | F27: -5 | G27: 0 | H27: 12 | I27: OK14 | M27: =Table14[[#This Row],[Kvalitet]]&Table14[[#This Row],[Gjuttemperatur]]&Table14[[#This Row],[Temperatur motgjutningsyta]]&Table14[[#This Row],[Väderskydd, uppvärmning (ingen vind)]]&Table14[[#This Row],[Täckning '[mm']]]&Table14[[#This Row],[OK under 14 D]]&Table14[[#This Row],[OK <21 Dagar]] -> C20/252052010OK14
A28: C20/25 | B28: 20 | C28: 5 | D28: 20 | E28: 10 | F28: -5 | G28: 2 | H28: 13.6 | I28: OK14 | M28: =Table14[[#This Row],[Kvalitet]]&Table14[[#This Row],[Gjuttemperatur]]&Table14[[#This Row],[Temperatur motgjutningsyta]]&Table14[[#This Row],[Väderskydd, uppvärmning (ingen vind)]]&Table14[[#This Row],[Täckning '[mm']]]&Table14[[#This Row],[OK under 14 D]]&Table14[[#This Row],[OK <21 Dagar]] -> C20/252052010OK14
A29: C20/25 | B29: 20 | C29: 5 | D29: 20 | E29: 20 | F29: -5 | G29: 7 | H29: 11.3 | I29: OK14 | M29: =Table14[[#This Row],[Kvalitet]]&Table14[[#This Row],[Gjuttemperatur]]&Table14[[#This Row],[Temperatur motgjutningsyta]]&Table14[[#This Row],[Väderskydd, uppvärmning (ingen vind)]]&Table14[[#This Row],[Täckning '[mm']]]&Table14[[#This Row],[OK under 14 D]]&Table14[[#This Row],[OK <21 Dagar]] -> C20/252052020OK14
A30: C20/25 | B30: 20 | C30: 5 | D30: 20 | E30: 20 | F30: -5 | G30: 12 | H30: 11.5 | I30: OK14 | M30: =Table14[[#This Row],[Kvalitet]]&Table14[[#This Row],[Gjuttemperatur]]&Table14[[#This Row],[Temperatur motgjutningsyta]]&Table14[[#This Row],[Väderskydd, uppvärmning (ingen vind)]]&Table14[[#This Row],[Täckning '[mm']]]&Table14[[#This Row],[OK under 14 D]]&Table14[[#This Row],[OK <21 Dagar]] -> C20/252052020OK14
A31: C20/25 | B31: 20 | C31: 5 | D31: 20 | E31: 20 | F31: -5 | G31: 20 | H31: 11.6 | I31: OK14 | M31: =Table14[[#This Row],[Kvalitet]]&Table14[[#This Row],[Gjuttemperatur]]&Table14[[#This Row],[Temperatur motgjutningsyta]]&Table14[[#This Row],[Väderskydd, uppvärmning (ingen vind)]]&Table14[[#This Row],[Täckning '[mm']]]&Table14[[#This Row],[OK under 14 D]]&Table14[[#This Row],[OK <21 Dagar]] -> C20/252052020OK14
A32: C20/25 | B32: 20 | C32: 5 | D32: 20 | E32: 30 | F32: -10 | G32: 0 | H32: 13 | I32: OK14 | M32: =Table14[[#This Row],[Kvalitet]]&Table14[[#This Row],[Gjuttemperatur]]&Table14[[#This Row],[Temperatur motgjutningsyta]]&Table14[[#This Row],[Väderskydd, uppvärmning (ingen vind)]]&Table14[[#This Row],[Täckning '[mm']]]&Table14[[#This Row],[OK under 14 D]]&Table14[[#This Row],[OK <21 Dagar]] -> C20/252052030OK14
A33: C20/25 | B33: 20 | C33: 5 | D33: 20 | E33: 30 | F33: -10 | G33: 2 | H33: 13.8 | I33: OK14 | M33: =Table14[[#This Row],[Kvalitet]]&Table14[[#This Row],[Gjuttemperatur]]&Table14[[#This Row],[Temperatur motgjutningsyta]]&Table14[[#This Row],[Väderskydd, uppvärmning (ingen vind)]]&Table14[[#This Row],[Täckning '[mm']]]&Table14[[#This Row],[OK under 14 D]]&Table14[[#This Row],[OK <21 Dagar]] -> C20/252052030OK14
A34: C20/25 | B34: 20 | C34: 5 | D34: 20 | E34: 50 | F34: -10 | G34: 7 | H34: 11.6 | I34: OK14 | M34: =Table14[[#This Row],[Kvalitet]]&Table14[[#This Row],[Gjuttemperatur]]&Table14[[#This Row],[Temperatur motgjutningsyta]]&Table14[[#This Row],[Väderskydd, uppvärmning (ingen vind)]]&Table14[[#This Row],[Täckning '[mm']]]&Table14[[#This Row],[OK under 14 D]]&Table14[[#This Row],[OK <21 Dagar]] -> C20/252052050OK14
A35: - | B35: - | C35: - | D35: - | E35: - | F35: -10 | G35: 12 | H35: - | L35: Tidig frysning | M35: =Table14[[#This Row],[Kvalitet]]&Table14[[#This Row],[Gjuttemperatur]]&Table14[[#This Row],[Temperatur motgjutningsyta]]&Table14[[#This Row],[Väderskydd, uppvärmning (ingen vind)]]&Table14[[#This Row],[Täckning '[mm']]]&Table14[[#This Row],[OK under 14 D]]&Table14[[#This Row],[OK <21 Dagar]] -> -----
A36: - | B36: - | C36: - | D36: - | E36: - | F36: -10 | G36: 20 | H36: - | L36: Tidig frysning | M36: =Table14[[#This Row],[Kvalitet]]&Table14[[#This Row],[Gjuttemperatur]]&Table14[[#This Row],[Temperatur motgjutningsyta]]&Table14[[#This Row],[Väderskydd, uppvärmning (ingen vind)]]&Table14[[#This Row],[Täckning '[mm']]]&Table14[[#This Row],[OK under 14 D]]&Table14[[#This Row],[OK <21 Dagar]] -> -----
A37: C28/35 | B37: 15 | C37: 5 | D37: 20 | E37: 50 | F37: -15 | G37: 0 | H37: 13 | I37: OK14 | M37: =Table14[[#This Row],[Kvalitet]]&Table14[[#This Row],[Gjuttemperatur]]&Table14[[#This Row],[Temperatur motgjutningsyta]]&Table14[[#This Row],[Väderskydd, uppvärmning (ingen vind)]]&Table14[[#This Row],[Täckning '[mm']]]&Table14[[#This Row],[OK under 14 D]]&Table14[[#This Row],[OK <21 Dagar]] -> C28/351552050OK14
A38: C28/35 | B38: 15 | C38: 5 | D38: 20 | E38: 50 | F38: -15 | G38: 2 | H38: 13.6 | I38: OK14 | M38: =Table14[[#This Row],[Kvalitet]]&Table14[[#This Row],[Gjuttemperatur]]&Table14[[#This Row],[Temperatur motgjutningsyta]]&Table14[[#This Row],[Väderskydd, uppvärmning (ingen vind)]]&Table14[[#This Row],[Täckning '[mm']]]&Table14[[#This Row],[OK under 14 D]]&Table14[[#This Row],[OK <21 Dagar]] -> C28/351552050OK14
A39: - | B39: - | C39: - | D39: - | E39: - | F39: -15 | G39: 7 | L39: Tidig frysning | M39: =Table14[[#This Row],[Kvalitet]]&Table14[[#This Row],[Gjuttemperatur]]&Table14[[#This Row],[Temperatur motgjutningsyta]]&Table14[[#This Row],[Väderskydd, uppvärmning (ingen vind)]]&Table14[[#This Row],[Täckning '[mm']]]&Table14[[#This Row],[OK under 14 D]]&Table14[[#This Row],[OK <21 Dagar]] -> -----
A40: - | B40: - | C40: - | D40: - | E40: - | F40: -15 | G40: 12 | L40: Tidig frysning | M40: =Table14[[#This Row],[Kvalitet]]&Table14[[#This Row],[Gjuttemperatur]]&Table14[[#This Row],[Temperatur motgjutningsyta]]&Table14[[#This Row],[Väderskydd, uppvärmning (ingen vind)]]&Table14[[#This Row],[Täckning '[mm']]]&Table14[[#This Row],[OK under 14 D]]&Table14[[#This Row],[OK <21 Dagar]] -> -----
...

Sheet Bjälklag (30% slagg)
A1: Kvalitet | B1: Gjuttemperatur | C1: Temperatur motgjutningsyta | D1: Väderskydd, uppvärmning (ingen vind) | E1: Täckning [mm] | F1: Temperatur | G1: Vind | H1: <14 d och >70 % [Dagar] | I1: OK under 14 D | J1: <21 d och >70 % [Dagar] | K1: OK <21 Dagar | L1: Kommentar | M1: Åtgärdskåd
A2: C20/25 | B2: 15 | C2: 20 | D2: - | E2: 0 | F2: 20 | G2: 0 | H2: 7 | I2: OK14 | M2: =Table145[[#This Row],[Kvalitet]]&Table145[[#This Row],[Gjuttemperatur]]&Table145[[#This Row],[Temperatur motgjutningsyta]]&Table145[[#This Row],[Väderskydd, uppvärmning (ingen vind)]]&Table145[[#This Row],[Täckning '[mm']]]&Table145[[#This Row],[OK under 14 D]]&Table145[[#This Row],[OK <21 Dagar]] -> C20/251520-0OK14
A3: C20/25 | B3: 15 | C3: 20 | D3: - | E3: 0 | F3: 20 | G3: 2 | H3: 7.5 | I3: OK14 | M3: =Table145[[#This Row],[Kvalitet]]&Table145[[#This Row],[Gjuttemperatur]]&Table145[[#This Row],[Temperatur motgjutningsyta]]&Table145[[#This Row],[Väderskydd, uppvärmning (ingen vind)]]&Table145[[#This Row],[Täckning '[mm']]]&Table145[[#This Row],[OK under 14 D]]&Table145[[#This Row],[OK <21 Dagar]] -> C20/251520-0OK14
A4: C20/25 | B4: 15 | C4: 20 | D4: - | E4: 0 | F4: 20 | G4: 7 | H4: 7.7 | I4: OK14 | M4: =Table145[[#This Row],[Kvalitet]]&Table145[[#This Row],[Gjuttemperatur]]&Table145[[#This Row],[Temperatur motgjutningsyta]]&Table145[[#This Row],[Väderskydd, uppvärmning (ingen vind)]]&Table145[[#This Row],[Täckning '[mm']]]&Table145[[#This Row],[OK under 14 D]]&Table145[[#This Row],[OK <21 Dagar]] -> C20/251520-0OK14
A5: C20/25 | B5: 15 | C5: 20 | D5: - | E5: 0 | F5: 20 | G5: 12 | H5: 7.8 | I5: OK14 | M5: =Table145[[#This Row],[Kvalitet]]&Table145[[#This Row],[Gjuttemperatur]]&Table145[[#This Row],[Temperatur motgjutningsyta]]&Table145[[#This Row],[Väderskydd, uppvärmning (ingen vind)]]&Table145[[#This Row],[Täckning '[mm']]]&Table145[[#This Row],[OK under 14 D]]&Table145[[#This Row],[OK <21 Dagar]] -> C20/251520-0OK14
A6: C20/25 | B6: 15 | C6: 20 | D6: - | E6: 0 | F6: 20 | G6: 20 | H6: 7.8 | I6: OK14 | M6: =Table145[[#This Row],[Kvalitet]]&Table145[[#This Row],[Gjuttemperatur]]&Table145[[#This Row],[Temperatur motgjutningsyta]]&Table145[[#This Row],[Väderskydd, uppvärmning (ingen vind)]]&Table145[[#This Row],[Täckning '[mm']]]&Table145[[#This Row],[OK under 14 D]]&Table145[[#This Row],[OK <21 Dagar]] -> C20/251520-0OK14
A7: C20/25 | B7: 15 | C7: 15 | D7: - | E7: 0 | F7: 15 | G7: 0 | H7: 9.3 | I7: OK14 | M7: =Table145[[#This Row],[Kvalitet]]&Table145[[#This Row],[Gjuttemperatur]]&Table145[[#This Row],[Temperatur motgjutningsyta]]&Table145[[#This Row],[Väderskydd, uppvärmning (ingen vind)]]&Table145[[#This Row],[Täckning '[mm']]]&Table145[[#This Row],[OK under 14 D]]&Table145[[#This Row],[OK <21 Dagar]] -> C20/251515-0OK14
A8: C20/25 | B8: 15 | C8: 15 | D8: - | E8: 0 | F8: 15 | G8: 2 | H8: 9.9 | I8: OK14 | M8: =Table145[[#This Row],[Kvalitet]]&Table145[[#This Row],[Gjuttemperatur]]&Table145[[#This Row],[Temperatur motgjutningsyta]]&Table145[[#This Row],[Väderskydd, uppvärmning (ingen vind)]]&Table145[[#This Row],[Täckning '[mm']]]&Table145[[#This Row],[OK under 14 D]]&Table145[[#This Row],[OK <21 Dagar]] -> C20/251515-0OK14
A9: C20/25 | B9: 15 | C9: 15 | D9: - | E9: 0 | F9: 15 | G9: 7 | H9: 10.2 | I9: OK14 | M9: =Table145[[#This Row],[Kvalitet]]&Table145[[#This Row],[Gjuttemperatur]]&Table145[[#This Row],[Temperatur motgjutningsyta]]&Table145[[#This Row],[Väderskydd, uppvärmning (ingen vind)]]&Table145[[#This Row],[Täckning '[mm']]]&Table145[[#This Row],[OK under 14 D]]&Table145[[#This Row],[OK <21 Dagar]] -> C20/251515-0OK14
A10: C20/25 | B10: 15 | C10: 15 | D10: - | E10: 0 | F10: 15 | G10: 12 | H10: 10.3 | I10: OK14 | M10: =Table145[[#This Row],[Kvalitet]]&Table145[[#This Row],[Gjuttemperatur]]&Table145[[#This Row],[Temperatur motgjutningsyta]]&Table145[[#This Row],[Väderskydd, uppvärmning (ingen vind)]]&Table145[[#This Row],[Täckning '[mm']]]&Table145[[#This Row],[OK under 14 D]]&Table145[[#This Row],[OK <21 Dagar]] -> C20/251515-0OK14
A11: C20/25 | B11: 15 | C11: 15 | D11: - | E11: 0 | F11: 15 | G11: 20 | H11: 10.3 | I11: OK14 | M11: =Table145[[#This Row],[Kvalitet]]&Table145[[#This Row],[Gjuttemperatur]]&Table145[[#This Row],[Temperatur motgjutningsyta]]&Table145[[#This Row],[Väderskydd, uppvärmning (ingen vind)]]&Table145[[#This Row],[Täckning '[mm']]]&Table145[[#This Row],[OK under 14 D]]&Table145[[#This Row],[OK <21 Dagar]] -> C20/251515-0OK14
A12: C20/25 | B12: 15 | C12: 10 | D12: - | E12: 0 | F12: 10 | G12: 0 | H12: 12.8 | I12: OK14 | M12: =Table145[[#This Row],[Kvalitet]]&Table145[[#This Row],[Gjuttemperatur]]&Table145[[#This Row],[Temperatur motgjutningsyta]]&Table145[[#This Row],[Väderskydd, uppvärmning (ingen vind)]]&Table145[[#This Row],[Täckning '[mm']]]&Table145[[#This Row],[OK under 14 D]]&Table145[[#This Row],[OK <21 Dagar]] -> C20/251510-0OK14
A13: C20/25 | B13: 15 | C13: 10 | D13: - | E13: 0 | F13: 10 | G13: 2 | H13: 13.6 | I13: OK14 | M13: =Table145[[#This Row],[Kvalitet]]&Table145[[#This Row],[Gjuttemperatur]]&Table145[[#This Row],[Temperatur motgjutningsyta]]&Table145[[#This Row],[Väderskydd, uppvärmning (ingen vind)]]&Table145[[#This Row],[Täckning '[mm']]]&Table145[[#This Row],[OK under 14 D]]&Table145[[#This Row],[OK <21 Dagar]] -> C20/251510-0OK14
A14: C20/25 | B14: 15 | C14: 10 | D14: - | E14: 0 | F14: 10 | G14: 7 | H14: 14 | I14: OK14 | M14: =Table145[[#This Row],[Kvalitet]]&Table145[[#This Row],[Gjuttemperatur]]&Table145[[#This Row],[Temperatur motgjutningsyta]]&Table145[[#This Row],[Väderskydd, uppvärmning (ingen vind)]]&Table145[[#This Row],[Täckning '[mm']]]&Table145[[#This Row],[OK under 14 D]]&Table145[[#This Row],[OK <21 Dagar]] -> C20/251510-0OK14
A15: C20/25 | B15: 15 | C15: 10 | D15: 0 | E15: 0 | F15: 10 | G15: 12 | H15: 13.8 | I15: OK14 | M15: =Table145[[#This Row],[Kvalitet]]&Table145[[#This Row],[Gjuttemperatur]]&Table145[[#This Row],[Temperatur motgjutningsyta]]&Table145[[#This Row],[Väderskydd, uppvärmning (ingen vind)]]&Table145[[#This Row],[Täckning '[mm']]]&Table145[[#This Row],[OK under 14 D]]&Table145[[#This Row],[OK <21 Dagar]] -> C20/25151000OK14
A16: C20/25 | B16: 15 | C16: 10 | D16: 0 | E16: 0 | F16: 10 | G16: 20 | H16: 14 | I16: OK14 | M16: =Table145[[#This Row],[Kvalitet]]&Table145[[#This Row],[Gjuttemperatur]]&Table145[[#This Row],[Temperatur motgjutningsyta]]&Table145[[#This Row],[Väderskydd, uppvärmning (ingen vind)]]&Table145[[#This Row],[Täckning '[mm']]]&Table145[[#This Row],[OK under 14 D]]&Table145[[#This Row],[OK <21 Dagar]] -> C20/25151000OK14
A17: C20/25 | B17: 20 | C17: 5 | D17: 10 | E17: 0 | F17: 5 | G17: 0 | H17: 12.8 | I17: OK14 | M17: =Table145[[#This Row],[Kvalitet]]&Table145[[#This Row],[Gjuttemperatur]]&Table145[[#This Row],[Temperatur motgjutningsyta]]&Table145[[#This Row],[Väderskydd, uppvärmning (ingen vind)]]&Table145[[#This Row],[Täckning '[mm']]]&Table145[[#This Row],[OK under 14 D]]&Table145[[#This Row],[OK <21 Dagar]] -> C20/25205100OK14
A18: C20/25 | B18: 20 | C18: 5 | D18: 10 | E18: 0 | F18: 5 | G18: 2 | H18: 13.5 | I18: OK14 | M18: =Table145[[#This Row],[Kvalitet]]&Table145[[#This Row],[Gjuttemperatur]]&Table145[[#This Row],[Temperatur motgjutningsyta]]&Table145[[#This Row],[Väderskydd, uppvärmning (ingen vind)]]&Table145[[#This Row],[Täckning '[mm']]]&Table145[[#This Row],[OK under 14 D]]&Table145[[#This Row],[OK <21 Dagar]] -> C20/25205100OK14
A19: C20/25 | B19: 20 | C19: 5 | D19: 20 | E19: Presenning | F19: 5 | G19: 7 | H19: 12.6 | I19: OK14 | M19: =Table145[[#This Row],[Kvalitet]]&Table145[[#This Row],[Gjuttemperatur]]&Table145[[#This Row],[Temperatur motgjutningsyta]]&Table145[[#This Row],[Väderskydd, uppvärmning (ingen vind)]]&Table145[[#This Row],[Täckning '[mm']]]&Table145[[#This Row],[OK under 14 D]]&Table145[[#This Row],[OK <21 Dagar]] -> C20/2520520PresenningOK14
A20: C20/25 | B20: 20 | C20: 5 | D20: 20 | E20: Presenning | F20: 5 | G20: 12 | H20: 13 | I20: OK14 | M20: =Table145[[#This Row],[Kvalitet]]&Table145[[#This Row],[Gjuttemperatur]]&Table145[[#This Row],[Temperatur motgjutningsyta]]&Table145[[#This Row],[Väderskydd, uppvärmning (ingen vind)]]&Table145[[#This Row],[Täckning '[mm']]]&Table145[[#This Row],[OK under 14 D]]&Table145[[#This Row],[OK <21 Dagar]] -> C20/2520520PresenningOK14
A21: C20/25 | B21: 20 | C21: 5 | D21: 20 | E21: Presenning | F21: 5 | G21: 20 | H21: 13.3 | I21: OK14 | M21: =Table145[[#This Row],[Kvalitet]]&Table145[[#This Row],[Gjuttemperatur]]&Table145[[#This Row],[Temperatur motgjutningsyta]]&Table145[[#This Row],[Väderskydd, uppvärmning (ingen vind)]]&Table145[[#This Row],[Täckning '[mm']]]&Table145[[#This Row],[OK under 14 D]]&Table145[[#This Row],[OK <21 Dagar]] -> C20/2520520PresenningOK14
A22: C20/25 | B22: 20 | C22: 5 | D22: 20 | E22: 0 | F22: 0 | G22: 0 | H22: 13.2 | I22: OK14 | M22: =Table145[[#This Row],[Kvalitet]]&Table145[[#This Row],[Gjuttemperatur]]&Table145[[#This Row],[Temperatur motgjutningsyta]]&Table145[[#This Row],[Väderskydd, uppvärmning (ingen vind)]]&Table145[[#This Row],[Täckning '[mm']]]&Table145[[#This Row],[OK under 14 D]]&Table145[[#This Row],[OK <21 Dagar]] -> C20/25205200OK14
A23: C20/25 | B23: 20 | C23: 5 | D23: 20 | E23: 10 | F23: 0 | G23: 2 | H23: 10.8 | I23: OK14 | M23: =Table145[[#This Row],[Kvalitet]]&Table145[[#This Row],[Gjuttemperatur]]&Table145[[#This Row],[Temperatur motgjutningsyta]]&Table145[[#This Row],[Väderskydd, uppvärmning (ingen vind)]]&Table145[[#This Row],[Täckning '[mm']]]&Table145[[#This Row],[OK under 14 D]]&Table145[[#This Row],[OK <21 Dagar]] -> C20/252052010OK14
A24: C20/25 | B24: 20 | C24: 5 | D24: 20 | E24: 10 | F24: 0 | G24: 7 | H24: 11.5 | I24: OK14 | M24: =Table145[[#This Row],[Kvalitet]]&Table145[[#This Row],[Gjuttemperatur]]&Table145[[#This Row],[Temperatur motgjutningsyta]]&Table145[[#This Row],[Väderskydd, uppvärmning (ingen vind)]]&Table145[[#This Row],[Täckning '[mm']]]&Table145[[#This Row],[OK under 14 D]]&Table145[[#This Row],[OK <21 Dagar]] -> C20/252052010OK14
A25: C20/25 | B25: 20 | C25: 5 | D25: 20 | E25: 10 | F25: 0 | G25: 12 | H25: 11.8 | I25: OK14 | M25: =Table145[[#This Row],[Kvalitet]]&Table145[[#This Row],[Gjuttemperatur]]&Table145[[#This Row],[Temperatur motgjutningsyta]]&Table145[[#This Row],[Väderskydd, uppvärmning (ingen vind)]]&Table145[[#This Row],[Täckning '[mm']]]&Table145[[#This Row],[OK under 14 D]]&Table145[[#This Row],[OK <21 Dagar]] -> C20/252052010OK14
A26: C20/25 | B26: 20 | C26: 5 | D26: 20 | E26: 10 | F26: 0 | G26: 20 | H26: 11.9 | I26: OK14 | M26: =Table145[[#This Row],[Kvalitet]]&Table145[[#This Row],[Gjuttemperatur]]&Table145[[#This Row],[Temperatur motgjutningsyta]]&Table145[[#This Row],[Väderskydd, uppvärmning (ingen vind)]]&Table145[[#This Row],[Täckning '[mm']]]&Table145[[#This Row],[OK under 14 D]]&Table145[[#This Row],[OK <21 Dagar]] -> C20/252052010OK14
A27: C20/25 | B27: 20 | C27: 5 | D27: 20 | E27: 10 | F27: -5 | G27: 0 | H27: 13.7 | I27: OK14 | M27: =Table145[[#This Row],[Kvalitet]]&Table145[[#This Row],[Gjuttemperatur]]&Table145[[#This Row],[Temperatur motgjutningsyta]]&Table145[[#This Row],[Väderskydd, uppvärmning (ingen vind)]]&Table145[[#This Row],[Täckning '[mm']]]&Table145[[#This Row],[OK under 14 D]]&Table145[[#This Row],[OK <21 Dagar]] -> C20/252052010OK14
A28: C20/25 | B28: 20 | C28: 5 | D28: 20 | E28: 20 | F28: -5 | G28: 2 | H28: 12.4 | I28: OK14 | M28: =Table145[[#This Row],[Kvalitet]]&Table145[[#This Row],[Gjuttemperatur]]&Table145[[#This Row],[Temperatur motgjutningsyta]]&Table145[[#This Row],[Väderskydd, uppvärmning (ingen vind)]]&Table145[[#This Row],[Täckning '[mm']]]&Table145[[#This Row],[OK under 14 D]]&Table145[[#This Row],[OK <21 Dagar]] -> C20/252052020OK14
A29: C20/25 | B29: 20 | C29: 5 | D29: 20 | E29: 20 | F29: -5 | G29: 7 | H29: 13 | I29: OK14 | M29: =Table145[[#This Row],[Kvalitet]]&Table145[[#This Row],[Gjuttemperatur]]&Table145[[#This Row],[Temperatur motgjutningsyta]]&Table145[[#This Row],[Väderskydd, uppvärmning (ingen vind)]]&Table145[[#This Row],[Täckning '[mm']]]&Table145[[#This Row],[OK under 14 D]]&Table145[[#This Row],[OK <21 Dagar]] -> C20/252052020OK14
A30: C20/25 | B30: 20 | C30: 5 | D30: 20 | E30: 20 | F30: -5 | G30: 12 | H30: 13.2 | I30: OK14 | M30: =Table145[[#This Row],[Kvalitet]]&Table145[[#This Row],[Gjuttemperatur]]&Table145[[#This Row],[Temperatur motgjutningsyta]]&Table145[[#This Row],[Väderskydd, uppvärmning (ingen vind)]]&Table145[[#This Row],[Täckning '[mm']]]&Table145[[#This Row],[OK under 14 D]]&Table145[[#This Row],[OK <21 Dagar]] -> C20/252052020OK14
A31: C20/25 | B31: 20 | C31: 5 | D31: 20 | E31: 20 | F31: -5 | G31: 20 | H31: 13.3 | I31: OK14 | M31: =Table145[[#This Row],[Kvalitet]]&Table145[[#This Row],[Gjuttemperatur]]&Table145[[#This Row],[Temperatur motgjutningsyta]]&Table145[[#This Row],[Väderskydd, uppvärmning (ingen vind)]]&Table145[[#This Row],[Täckning '[mm']]]&Table145[[#This Row],[OK under 14 D]]&Table145[[#This Row],[OK <21 Dagar]] -> C20/252052020OK14
A32: C20/25 | B32: 20 | C32: 5 | D32: 20 | E32: 50 | F32: -10 | G32: 0 | H32: 12.8 | I32: OK14 | M32: =Table145[[#This Row],[Kvalitet]]&Table145[[#This Row],[Gjuttemperatur]]&Table145[[#This Row],[Temperatur motgjutningsyta]]&Table145[[#This Row],[Väderskydd, uppvärmning (ingen vind)]]&Table145[[#This Row],[Täckning '[mm']]]&Table145[[#This Row],[OK under 14 D]]&Table145[[#This Row],[OK <21 Dagar]] -> C20/252052050OK14
A33: C20/25 | B33: 20 | C33: 5 | D33: 20 | E33: 50 | F33: -10 | G33: 2 | H33: 13.2 | I33: OK14 | M33: =Table145[[#This Row],[Kvalitet]]&Table145[[#This Row],[Gjuttemperatur]]&Table145[[#This Row],[Temperatur motgjutningsyta]]&Table145[[#This Row],[Väderskydd, uppvärmning (ingen vind)]]&Table145[[#This Row],[Täckning '[mm']]]&Table145[[#This Row],[OK under 14 D]]&Table145[[#This Row],[OK <21 Dagar]] -> C20/252052050OK14
A34: C20/25 | B34: 20 | C34: 5 | D34: 20 | E34: 50 | F34: -10 | G34: 7 | H34: 13.6 | I34: OK14 | M34: =Table145[[#This Row],[Kvalitet]]&Table145[[#This Row],[Gjuttemperatur]]&Table145[[#This Row],[Temperatur motgjutningsyta]]&Table145[[#This Row],[Väderskydd, uppvärmning (ingen vind)]]&Table145[[#This Row],[Täckning '[mm']]]&Table145[[#This Row],[OK under 14 D]]&Table145[[#This Row],[OK <21 Dagar]] -> C20/252052050OK14
A35: - | B35: - | C35: - | D35: - | E35: - | F35: -10 | G35: 12 | L35: Fryser innan täck | M35: =Table145[[#This Row],[Kvalitet]]&Table145[[#This Row],[Gjuttemperatur]]&Table145[[#This Row],[Temperatur motgjutningsyta]]&Table145[[#This Row],[Väderskydd, uppvärmning (ingen vind)]]&Table145[[#This Row],[Täckning '[mm']]]&Table145[[#This Row],[OK under 14 D]]&Table145[[#This Row],[OK <21 Dagar]] -> -----
A36: - | B36: - | C36: - | D36: - | E36: - | F36: -10 | G36: 20 | L36: Fryser innan täck | M36: =Table145[[#This Row],[Kvalitet]]&Table145[[#This Row],[Gjuttemperatur]]&Table145[[#This Row],[Temperatur motgjutningsyta]]&Table145[[#This Row],[Väderskydd, uppvärmning (ingen vind)]]&Table145[[#This Row],[Täckning '[mm']]]&Table145[[#This Row],[OK under 14 D]]&Table145[[#This Row],[OK <21 Dagar]] -> -----
A37: C25/30 | B37: 15 | C37: 5 | D37: 20 | E37: 30 | F37: -15 | G37: 0 | H37: 12.8 | I37: OK14 | M37: =Table145[[#This Row],[Kvalitet]]&Table145[[#This Row],[Gjuttemperatur]]&Table145[[#This Row],[Temperatur motgjutningsyta]]&Table145[[#This Row],[Väderskydd, uppvärmning (ingen vind)]]&Table145[[#This Row],[Täckning '[mm']]]&Table145[[#This Row],[OK under 14 D]]&Table145[[#This Row],[OK <21 Dagar]] -> C25/301552030OK14
A38: C25/30 | B38: 15 | C38: 5 | D38: 20 | E38: 30 | F38: -15 | G38: 2 | H38: 13.9 | I38: OK14 | M38: =Table145[[#This Row],[Kvalitet]]&Table145[[#This Row],[Gjuttemperatur]]&Table145[[#This Row],[Temperatur motgjutningsyta]]&Table145[[#This Row],[Väderskydd, uppvärmning (ingen vind)]]&Table145[[#This Row],[Täckning '[mm']]]&Table145[[#This Row],[OK under 14 D]]&Table145[[#This Row],[OK <21 Dagar]] -> C25/301552030OK14
A39: - | B39: - | C39: - | D39: - | E39: - | F39: -15 | G39: 7 | L39: Fryser innan täck | M39: =Table145[[#This Row],[Kvalitet]]&Table145[[#This Row],[Gjuttemperatur]]&Table145[[#This Row],[Temperatur motgjutningsyta]]&Table145[[#This Row],[Väderskydd, uppvärmning (ingen vind)]]&Table145[[#This Row],[Täckning '[mm']]]&Table145[[#This Row],[OK under 14 D]]&Table145[[#This Row],[OK <21 Dagar]] -> -----
A40: - | B40: - | C40: - | D40: - | E40: - | F40: -15 | G40: 12 | L40: Fryser innan täck | M40: =Table145[[#This Row],[Kvalitet]]&Table145[[#This Row],[Gjuttemperatur]]&Table145[[#This Row],[Temperatur motgjutningsyta]]&Table145[[#This Row],[Väderskydd, uppvärmning (ingen vind)]]&Table145[[#This Row],[Täckning '[mm']]]&Table145[[#This Row],[OK under 14 D]]&Table145[[#This Row],[OK <21 Dagar]] -> -----
...

Sheet Bjälklag (40% slagg)
A1: Kvalitet | B1: Gjuttemperatur | C1: Temperatur motgjutningsyta | D1: Väderskydd, uppvärmning (ingen vind) | E1: Täckning [mm] | F1: Temperatur | G1: Vind | H1: <14 d och >70 % [Dagar] | I1: OK14 under 14 D | J1: <21 d och >70 % [Dagar] | K1: OK <21 Dagar | L1: Kommentar | M1: Åtgärdskåd
A2: C20/25 | B2: 15 | C2: 20 | D2: - | E2: 0 | F2: 20 | G2: 0 | H2: 7.7 | I2: OK14 | M2: =Table1456[[#This Row],[Kvalitet]]&Table1456[[#This Row],[Gjuttemperatur]]&Table1456[[#This Row],[Temperatur motgjutningsyta]]&Table1456[[#This Row],[Väderskydd, uppvärmning (ingen vind)]]&Table1456[[#This Row],[Täckning '[mm']]]&Table1456[[#This Row],[OK14 under 14 D]]&Table1456[[#This Row],[OK <21 Dagar]] -> C20/251520-0OK14
A3: C20/25 | B3: 15 | C3: 20 | D3: - | E3: 0 | F3: 20 | G3: 2 | H3: 8.1 | I3: OK14 | M3: =Table1456[[#This Row],[Kvalitet]]&Table1456[[#This Row],[Gjuttemperatur]]&Table1456[[#This Row],[Temperatur motgjutningsyta]]&Table1456[[#This Row],[Väderskydd, uppvärmning (ingen vind)]]&Table1456[[#This Row],[Täckning '[mm']]]&Table1456[[#This Row],[OK14 under 14 D]]&Table1456[[#This Row],[OK <21 Dagar]] -> C20/251520-0OK14
A4: C20/25 | B4: 15 | C4: 20 | D4: - | E4: 0 | F4: 20 | G4: 7 | H4: 8.3 | I4: OK14 | M4: =Table1456[[#This Row],[Kvalitet]]&Table1456[[#This Row],[Gjuttemperatur]]&Table1456[[#This Row],[Temperatur motgjutningsyta]]&Table1456[[#This Row],[Väderskydd, uppvärmning (ingen vind)]]&Table1456[[#This Row],[Täckning '[mm']]]&Table1456[[#This Row],[OK14 under 14 D]]&Table1456[[#This Row],[OK <21 Dagar]] -> C20/251520-0OK14
A5: C20/25 | B5: 15 | C5: 20 | D5: - | E5: 0 | F5: 20 | G5: 12 | H5: 8.4 | I5: OK14 | M5: =Table1456[[#This Row],[Kvalitet]]&Table1456[[#This Row],[Gjuttemperatur]]&Table1456[[#This Row],[Temperatur motgjutningsyta]]&Table1456[[#This Row],[Väderskydd, uppvärmning (ingen vind)]]&Table1456[[#This Row],[Täckning '[mm']]]&Table1456[[#This Row],[OK14 under 14 D]]&Table1456[[#This Row],[OK <21 Dagar]] -> C20/251520-0OK14
A6: C20/25 | B6: 15 | C6: 20 | D6: - | E6: 0 | F6: 20 | G6: 20 | H6: 8.4 | I6: OK14 | M6: =Table1456[[#This Row],[Kvalitet]]&Table1456[[#This Row],[Gjuttemperatur]]&Table1456[[#This Row],[Temperatur motgjutningsyta]]&Table1456[[#This Row],[Väderskydd, uppvärmning (ingen vind)]]&Table1456[[#This Row],[Täckning '[mm']]]&Table1456[[#This Row],[OK14 under 14 D]]&Table1456[[#This Row],[OK <21 Dagar]] -> C20/251520-0OK14
A7: C20/25 | B7: 15 | C7: 15 | D7: - | E7: 0 | F7: 15 | G7: 0 | H7: 10.1 | I7: OK14 | M7: =Table1456[[#This Row],[Kvalitet]]&Table1456[[#This Row],[Gjuttemperatur]]&Table1456[[#This Row],[Temperatur motgjutningsyta]]&Table1456[[#This Row],[Väderskydd, uppvärmning (ingen vind)]]&Table1456[[#This Row],[Täckning '[mm']]]&Table1456[[#This Row],[OK14 under 14 D]]&Table1456[[#This Row],[OK <21 Dagar]] -> C20/251515-0OK14
A8: C20/25 | B8: 15 | C8: 15 | D8: - | E8: 0 | F8: 15 | G8: 2 | H8: 10.7 | I8: OK14 | M8: =Table1456[[#This Row],[Kvalitet]]&Table1456[[#This Row],[Gjuttemperatur]]&Table1456[[#This Row],[Temperatur motgjutningsyta]]&Table1456[[#This Row],[Väderskydd, uppvärmning (ingen vind)]]&Table1456[[#This Row],[Täckning '[mm']]]&Table1456[[#This Row],[OK14 under 14 D]]&Table1456[[#This Row],[OK <21 Dagar]] -> C20/251515-0OK14
A9: C20/25 | B9: 15 | C9: 15 | D9: - | E9: 0 | F9: 15 | G9: 7 | H9: 11 | I9: OK14 | M9: =Table1456[[#This Row],[Kvalitet]]&Table1456[[#This Row],[Gjuttemperatur]]&Table1456[[#This Row],[Temperatur motgjutningsyta]]&Table1456[[#This Row],[Väderskydd, uppvärmning (ingen vind)]]&Table1456[[#This Row],[Täckning '[mm']]]&Table1456[[#This Row],[OK14 under 14 D]]&Table1456[[#This Row],[OK <21 Dagar]] -> C20/251515-0OK14
A10: C20/25 | B10: 15 | C10: 15 | D10: - | E10: 0 | F10: 15 | G10: 12 | H10: 11 | I10: OK14 | M10: =Table1456[[#This Row],[Kvalitet]]&Table1456[[#This Row],[Gjuttemperatur]]&Table1456[[#This Row],[Temperatur motgjutningsyta]]&Table1456[[#This Row],[Väderskydd, uppvärmning (ingen vind)]]&Table1456[[#This Row],[Täckning '[mm']]]&Table1456[[#This Row],[OK14 under 14 D]]&Table1456[[#This Row],[OK <21 Dagar]] -> C20/251515-0OK14
A11: C20/25 | B11: 15 | C11: 15 | D11: - | E11: 0 | F11: 15 | G11: 20 | H11: 11.1 | I11: OK14 | M11: =Table1456[[#This Row],[Kvalitet]]&Table1456[[#This Row],[Gjuttemperatur]]&Table1456[[#This Row],[Temperatur motgjutningsyta]]&Table1456[[#This Row],[Väderskydd, uppvärmning (ingen vind)]]&Table1456[[#This Row],[Täckning '[mm']]]&Table1456[[#This Row],[OK14 under 14 D]]&Table1456[[#This Row],[OK <21 Dagar]] -> C20/251515-0OK14
A12: C20/25 | B12: 15 | C12: 10 | D12: - | E12: 0 | F12: 10 | G12: 0 | H12: 13.9 | I12: OK14 | M12: =Table1456[[#This Row],[Kvalitet]]&Table1456[[#This Row],[Gjuttemperatur]]&Table1456[[#This Row],[Temperatur motgjutningsyta]]&Table1456[[#This Row],[Väderskydd, uppvärmning (ingen vind)]]&Table1456[[#This Row],[Täckning '[mm']]]&Table1456[[#This Row],[OK14 under 14 D]]&Table1456[[#This Row],[OK <21 Dagar]] -> C20/251510-0OK14
A13: C20/25 | B13: 15 | C13: 10 | D13: 5 | E13: 0 | F13: 10 | G13: 2 | H13: 13 | I13: OK14 | M13: =Table1456[[#This Row],[Kvalitet]]&Table1456[[#This Row],[Gjuttemperatur]]&Table1456[[#This Row],[Temperatur motgjutningsyta]]&Table1456[[#This Row],[Väderskydd, uppvärmning (ingen vind)]]&Table1456[[#This Row],[Täckning '[mm']]]&Table1456[[#This Row],[OK14 under 14 D]]&Table1456[[#This Row],[OK <21 Dagar]] -> C20/25151050OK14
A14: C20/25 | B14: 15 | C14: 10 | D14: 5 | E14: 0 | F14: 10 | G14: 7 | H14: 13.7 | I14: OK14 | M14: =Table1456[[#This Row],[Kvalitet]]&Table1456[[#This Row],[Gjuttemperatur]]&Table1456[[#This Row],[Temperatur motgjutningsyta]]&Table1456[[#This Row],[Väderskydd, uppvärmning (ingen vind)]]&Table1456[[#This Row],[Täckning '[mm']]]&Table1456[[#This Row],[OK14 under 14 D]]&Table1456[[#This Row],[OK <21 Dagar]] -> C20/25151050OK14
A15: C20/25 | B15: 15 | C15: 10 | D15: 5 | E15: 0 | F15: 10 | G15: 12 | H15: 13.9 | I15: OK14 | M15: =Table1456[[#This Row],[Kvalitet]]&Table1456[[#This Row],[Gjuttemperatur]]&Table1456[[#This Row],[Temperatur motgjutningsyta]]&Table1456[[#This Row],[Väderskydd, uppvärmning (ingen vind)]]&Table1456[[#This Row],[Täckning '[mm']]]&Table1456[[#This Row],[OK14 under 14 D]]&Table1456[[#This Row],[OK <21 Dagar]] -> C20/25151050OK14
A16: C20/25 | B16: 15 | C16: 10 | D16: 5 | E16: 0 | F16: 10 | G16: 20 | H16: 14 | I16: OK14 | M16: =Table1456[[#This Row],[Kvalitet]]&Table1456[[#This Row],[Gjuttemperatur]]&Table1456[[#This Row],[Temperatur motgjutningsyta]]&Table1456[[#This Row],[Väderskydd, uppvärmning (ingen vind)]]&Table1456[[#This Row],[Täckning '[mm']]]&Table1456[[#This Row],[OK14 under 14 D]]&Table1456[[#This Row],[OK <21 Dagar]] -> C20/25151050OK14
A17: C20/25 | B17: 20 | C17: 5 | D17: 15 | E17: 0 | F17: 5 | G17: 0 | H17: 12 | I17: OK14 | M17: =Table1456[[#This Row],[Kvalitet]]&Table1456[[#This Row],[Gjuttemperatur]]&Table1456[[#This Row],[Temperatur motgjutningsyta]]&Table1456[[#This Row],[Väderskydd, uppvärmning (ingen vind)]]&Table1456[[#This Row],[Täckning '[mm']]]&Table1456[[#This Row],[OK14 under 14 D]]&Table1456[[#This Row],[OK <21 Dagar]] -> C20/25205150OK14
A18: C20/25 | B18: 20 | C18: 5 | D18: 20 | E18: 0 | F18: 5 | G18: 2 | H18: 13.1 | I18: OK14 | M18: =Table1456[[#This Row],[Kvalitet]]&Table1456[[#This Row],[Gjuttemperatur]]&Table1456[[#This Row],[Temperatur motgjutningsyta]]&Table1456[[#This Row],[Väderskydd, uppvärmning (ingen vind)]]&Table1456[[#This Row],[Täckning '[mm']]]&Table1456[[#This Row],[OK14 under 14 D]]&Table1456[[#This Row],[OK <21 Dagar]] -> C20/25205200OK14
A19: C20/25 | B19: 20 | C19: 5 | D19: 20 | E19: 10 | F19: 5 | G19: 7 | H19: 9.3 | I19: OK14 | M19: =Table1456[[#This Row],[Kvalitet]]&Table1456[[#This Row],[Gjuttemperatur]]&Table1456[[#This Row],[Temperatur motgjutningsyta]]&Table1456[[#This Row],[Väderskydd, uppvärmning (ingen vind)]]&Table1456[[#This Row],[Täckning '[mm']]]&Table1456[[#This Row],[OK14 under 14 D]]&Table1456[[#This Row],[OK <21 Dagar]] -> C20/252052010OK14
A20: C20/25 | B20: 20 | C20: 5 | D20: 20 | E20: 10 | F20: 5 | G20: 12 | H20: 9.5 | I20: OK14 | M20: =Table1456[[#This Row],[Kvalitet]]&Table1456[[#This Row],[Gjuttemperatur]]&Table1456[[#This Row],[Temperatur motgjutningsyta]]&Table1456[[#This Row],[Väderskydd, uppvärmning (ingen vind)]]&Table1456[[#This Row],[Täckning '[mm']]]&Table1456[[#This Row],[OK14 under 14 D]]&Table1456[[#This Row],[OK <21 Dagar]] -> C20/252052010OK14
A21: C20/25 | B21: 20 | C21: 5 | D21: 20 | E21: 10 | F21: 5 | G21: 20 | H21: 9.5 | I21: OK14 | M21: =Table1456[[#This Row],[Kvalitet]]&Table1456[[#This Row],[Gjuttemperatur]]&Table1456[[#This Row],[Temperatur motgjutningsyta]]&Table1456[[#This Row],[Väderskydd, uppvärmning (ingen vind)]]&Table1456[[#This Row],[Täckning '[mm']]]&Table1456[[#This Row],[OK14 under 14 D]]&Table1456[[#This Row],[OK <21 Dagar]] -> C20/252052010OK14
A22: C20/25 | B22: 20 | C22: 5 | D22: 20 | E22: Presenning | F22: 0 | G22: 0 | H22: 13.6 | I22: OK14 | M22: =Table1456[[#This Row],[Kvalitet]]&Table1456[[#This Row],[Gjuttemperatur]]&Table1456[[#This Row],[Temperatur motgjutningsyta]]&Table1456[[#This Row],[Väderskydd, uppvärmning (ingen vind)]]&Table1456[[#This Row],[Täckning '[mm']]]&Table1456[[#This Row],[OK14 under 14 D]]&Table1456[[#This Row],[OK <21 Dagar]] -> C20/2520520PresenningOK14
A23: C20/25 | B23: 20 | C23: 5 | D23: 20 | E23: 10 | F23: 0 | G23: 2 | H23: 11.9 | I23: OK14 | M23: =Table1456[[#This Row],[Kvalitet]]&Table1456[[#This Row],[Gjuttemperatur]]&Table1456[[#This Row],[Temperatur motgjutningsyta]]&Table1456[[#This Row],[Väderskydd, uppvärmning (ingen vind)]]&Table1456[[#This Row],[Täckning '[mm']]]&Table1456[[#This Row],[OK14 under 14 D]]&Table1456[[#This Row],[OK <21 Dagar]] -> C20/252052010OK14
A24: C20/25 | B24: 20 | C24: 5 | D24: 20 | E24: 10 | F24: 0 | G24: 7 | H24: 12.6 | I24: OK14 | M24: =Table1456[[#This Row],[Kvalitet]]&Table1456[[#This Row],[Gjuttemperatur]]&Table1456[[#This Row],[Temperatur motgjutningsyta]]&Table1456[[#This Row],[Väderskydd, uppvärmning (ingen vind)]]&Table1456[[#This Row],[Täckning '[mm']]]&Table1456[[#This Row],[OK14 under 14 D]]&Table1456[[#This Row],[OK <21 Dagar]] -> C20/252052010OK14
A25: C20/25 | B25: 20 | C25: 5 | D25: 20 | E25: 10 | F25: 0 | G25: 12 | H25: 12.8 | I25: OK14 | M25: =Table1456[[#This Row],[Kvalitet]]&Table1456[[#This Row],[Gjuttemperatur]]&Table1456[[#This Row],[Temperatur motgjutningsyta]]&Table1456[[#This Row],[Väderskydd, uppvärmning (ingen vind)]]&Table1456[[#This Row],[Täckning '[mm']]]&Table1456[[#This Row],[OK14 under 14 D]]&Table1456[[#This Row],[OK <21 Dagar]] -> C20/252052010OK14
A26: C20/25 | B26: 20 | C26: 5 | D26: 20 | E26: 10 | F26: 0 | G26: 20 | H26: 13 | I26: OK14 | M26: =Table1456[[#This Row],[Kvalitet]]&Table1456[[#This Row],[Gjuttemperatur]]&Table1456[[#This Row],[Temperatur motgjutningsyta]]&Table1456[[#This Row],[Väderskydd, uppvärmning (ingen vind)]]&Table1456[[#This Row],[Täckning '[mm']]]&Table1456[[#This Row],[OK14 under 14 D]]&Table1456[[#This Row],[OK <21 Dagar]] -> C20/252052010OK14
