Workbook

Sheet Bjälklag (C20-25)
A1: Slagg mängd | B1: Gjuttemperatur | C1: Temperatur motgjutningsyta | D1: Väderskydd, uppvärmning (ingen vind) | E1: Täckning [mm] | F1: Temperatur | G1: Vind | H1: <7 d och >70% [Dagar] | I1: OK<7 dagar | J1: Kommentar | K1: Åtgärdskåd
A2: 0.3 | B2: 15 °C | C2: 20 °C | D2: Vindskydd | E2: Presenning | F2: 20 | G2: 0 | H2: 7 | I2: OK7 | K2: =Table141719202122[[#This Row],[Slagg mängd]]&Table141719202122[[#This Row],[Gjuttemperatur]]&Table141719202122[[#This Row],[Temperatur motgjutningsyta]]&Table141719202122[[#This Row],[Väderskydd, uppvärmning (ingen vind)]]&Table141719202122[[#This Row],[Täckning '[mm']]]&Table141719202122[[#This Row],[OK<7 dagar]]&Table141719202122[[#This Row],[Kommentar]] -> 0,315 °C20 °CVindskyddPresenningOK7 | O2: funkar utan väderskydd
A3: 0.2 | B3: 15 °C | C3: 20 °C | D3: - | E3: - | F3: 20 | G3: 2 | H3: 6.8 | I3: OK7 | K3: =Table141719202122[[#This Row],[Slagg mängd]]&Table141719202122[[#This Row],[Gjuttemperatur]]&Table141719202122[[#This Row],[Temperatur motgjutningsyta]]&Table141719202122[[#This Row],[Väderskydd, uppvärmning (ingen vind)]]&Table141719202122[[#This Row],[Täckning '[mm']]]&Table141719202122[[#This Row],[OK<7 dagar]]&Table141719202122[[#This Row],[Kommentar]] -> 0,215 °C20 °C--OK7 | O3: funkar utan väderskydd
A4: 0.2 | B4: 15 °C | C4: 20 °C | D4: - | E4: - | F4: 20 | G4: 7 | H4: 7 | I4: OK7 | K4: =Table141719202122[[#This Row],[Slagg mängd]]&Table141719202122[[#This Row],[Gjuttemperatur]]&Table141719202122[[#This Row],[Temperatur motgjutningsyta]]&Table141719202122[[#This Row],[Väderskydd, uppvärmning (ingen vind)]]&Table141719202122[[#This Row],[Täckning '[mm']]]&Table141719202122[[#This Row],[OK<7 dagar]]&Table141719202122[[#This Row],[Kommentar]] -> 0,215 °C20 °C--OK7 | O4: funkar utan väderskydd
A5: 0.2 | B5: 15 °C | C5: 20 °C | D5: - | E5: - | F5: 20 | G5: 12 | H5: 7 | I5: OK7 | K5: =Table141719202122[[#This Row],[Slagg mängd]]&Table141719202122[[#This Row],[Gjuttemperatur]]&Table141719202122[[#This Row],[Temperatur motgjutningsyta]]&Table141719202122[[#This Row],[Väderskydd, uppvärmning (ingen vind)]]&Table141719202122[[#This Row],[Täckning '[mm']]]&Table141719202122[[#This Row],[OK<7 dagar]]&Table141719202122[[#This Row],[Kommentar]] -> 0,215 °C20 °C--OK7 | O5: funkar utan väderskydd
A6: 0.2 | B6: 15 °C | C6: 20 °C | D6: - | E6: - | F6: 20 | G6: 20 | H6: 7 | I6: OK7 | K6: =Table141719202122[[#This Row],[Slagg mängd]]&Table141719202122[[#This Row],[Gjuttemperatur]]&Table141719202122[[#This Row],[Temperatur motgjutningsyta]]&Table141719202122[[#This Row],[Väderskydd, uppvärmning (ingen vind)]]&Table141719202122[[#This Row],[Täckning '[mm']]]&Table141719202122[[#This Row],[OK<7 dagar]]&Table141719202122[[#This Row],[Kommentar]] -> 0,215 °C20 °C--OK7 | O6: funkar utan väderskydd
A7: 0.1 | B7: 15 °C | C7: 20 °C | D7: - | E7: - | F7: 15 | G7: 0 | H7: 6.2 | I7: OK7 | K7: =Table141719202122[[#This Row],[Slagg mängd]]&Table141719202122[[#This Row],[Gjuttemperatur]]&Table141719202122[[#This Row],[Temperatur motgjutningsyta]]&Table141719202122[[#This Row],[Väderskydd, uppvärmning (ingen vind)]]&Table141719202122[[#This Row],[Täckning '[mm']]]&Table141719202122[[#This Row],[OK<7 dagar]]&Table141719202122[[#This Row],[Kommentar]] -> 0,115 °C20 °C--OK7
A8: 0.1 | B8: 15 °C | C8: 20 °C | D8: Vindskydd | E8: - | F8: 15 | G8: 2 | H8: 6.9 | I8: OK7 | K8: =Table141719202122[[#This Row],[Slagg mängd]]&Table141719202122[[#This Row],[Gjuttemperatur]]&Table141719202122[[#This Row],[Temperatur motgjutningsyta]]&Table141719202122[[#This Row],[Väderskydd, uppvärmning (ingen vind)]]&Table141719202122[[#This Row],[Täckning '[mm']]]&Table141719202122[[#This Row],[OK<7 dagar]]&Table141719202122[[#This Row],[Kommentar]] -> 0,115 °C20 °CVindskydd-OK7
A9: 0.1 | B9: 15 °C | C9: 20 °C | D9: Vindskydd | E9: - | F9: 15 | G9: 7 | H9: 7 | I9: OK7 | K9: =Table141719202122[[#This Row],[Slagg mängd]]&Table141719202122[[#This Row],[Gjuttemperatur]]&Table141719202122[[#This Row],[Temperatur motgjutningsyta]]&Table141719202122[[#This Row],[Väderskydd, uppvärmning (ingen vind)]]&Table141719202122[[#This Row],[Täckning '[mm']]]&Table141719202122[[#This Row],[OK<7 dagar]]&Table141719202122[[#This Row],[Kommentar]] -> 0,115 °C20 °CVindskydd-OK7
A10: 0.1 | B10: 15 °C | C10: 20 °C | D10: Vindskydd | E10: Presenning | F10: 15 | G10: 12 | H10: 6.9 | I10: OK7 | K10: =Table141719202122[[#This Row],[Slagg mängd]]&Table141719202122[[#This Row],[Gjuttemperatur]]&Table141719202122[[#This Row],[Temperatur motgjutningsyta]]&Table141719202122[[#This Row],[Väderskydd, uppvärmning (ingen vind)]]&Table141719202122[[#This Row],[Täckning '[mm']]]&Table141719202122[[#This Row],[OK<7 dagar]]&Table141719202122[[#This Row],[Kommentar]] -> 0,115 °C20 °CVindskyddPresenningOK7
A11: 0.1 | B11: 15 °C | C11: 20 °C | D11: Vindskydd | E11: Presenning | F11: 15 | G11: 20 | H11: 6.9 | I11: OK7 | K11: =Table141719202122[[#This Row],[Slagg mängd]]&Table141719202122[[#This Row],[Gjuttemperatur]]&Table141719202122[[#This Row],[Temperatur motgjutningsyta]]&Table141719202122[[#This Row],[Väderskydd, uppvärmning (ingen vind)]]&Table141719202122[[#This Row],[Täckning '[mm']]]&Table141719202122[[#This Row],[OK<7 dagar]]&Table141719202122[[#This Row],[Kommentar]] -> 0,115 °C20 °CVindskyddPresenningOK7
A12: Bas+0% | B12: 15 °C | C12: 20 °C | D12: - | E12: - | F12: 10 | G12: 0 | H12: 6.3 | I12: OK7 | K12: =Table141719202122[[#This Row],[Slagg mängd]]&Table141719202122[[#This Row],[Gjuttemperatur]]&Table141719202122[[#This Row],[Temperatur motgjutningsyta]]&Table141719202122[[#This Row],[Väderskydd, uppvärmning (ingen vind)]]&Table141719202122[[#This Row],[Täckning '[mm']]]&Table141719202122[[#This Row],[OK<7 dagar]]&Table141719202122[[#This Row],[Kommentar]] -> Bas+0%15 °C20 °C--OK7
A13: Bas+0% | B13: 15 °C | C13: 20 °C | D13: Vindskydd | E13: - | F13: 10 | G13: 2 | H13: 7 | I13: OK7 | K13: =Table141719202122[[#This Row],[Slagg mängd]]&Table141719202122[[#This Row],[Gjuttemperatur]]&Table141719202122[[#This Row],[Temperatur motgjutningsyta]]&Table141719202122[[#This Row],[Väderskydd, uppvärmning (ingen vind)]]&Table141719202122[[#This Row],[Täckning '[mm']]]&Table141719202122[[#This Row],[OK<7 dagar]]&Table141719202122[[#This Row],[Kommentar]] -> Bas+0%15 °C20 °CVindskydd-OK7
A14: - | B14: - | C14: - | D14: - | E14: - | F14: 10 | G14: 7 | J14: Når ej 70% | K14: =Table141719202122[[#This Row],[Slagg mängd]]&Table141719202122[[#This Row],[Gjuttemperatur]]&Table141719202122[[#This Row],[Temperatur motgjutningsyta]]&Table141719202122[[#This Row],[Väderskydd, uppvärmning (ingen vind)]]&Table141719202122[[#This Row],[Täckning '[mm']]]&Table141719202122[[#This Row],[OK<7 dagar]]&Table141719202122[[#This Row],[Kommentar]] -> -----Når ej 70%
A15: - | B15: - | C15: - | D15: - | E15: - | F15: 10 | G15: 12 | J15: Når ej 70% | K15: =Table141719202122[[#This Row],[Slagg mängd]]&Table141719202122[[#This Row],[Gjuttemperatur]]&Table141719202122[[#This Row],[Temperatur motgjutningsyta]]&Table141719202122[[#This Row],[Väderskydd, uppvärmning (ingen vind)]]&Table141719202122[[#This Row],[Täckning '[mm']]]&Table141719202122[[#This Row],[OK<7 dagar]]&Table141719202122[[#This Row],[Kommentar]] -> -----Når ej 70%
A16: - | B16: - | C16: - | D16: - | E16: - | F16: 10 | G16: 20 | J16: Når ej 70% | K16: =Table141719202122[[#This Row],[Slagg mängd]]&Table141719202122[[#This Row],[Gjuttemperatur]]&Table141719202122[[#This Row],[Temperatur motgjutningsyta]]&Table141719202122[[#This Row],[Väderskydd, uppvärmning (ingen vind)]]&Table141719202122[[#This Row],[Täckning '[mm']]]&Table141719202122[[#This Row],[OK<7 dagar]]&Table141719202122[[#This Row],[Kommentar]] -> -----Når ej 70%
A17: 0.4 | B17: =Förutsättningar!M$21 -> 20 | C17: =Förutsättningar!N$21 -> 5 | D17: Vindskydd och 20 °C uppvärmning | E17: 30 mm | F17: 5 | G17: 0 | H17: 6.8 | I17: OK7 | K17: =Table141719202122[[#This Row],[Slagg mängd]]&Table141719202122[[#This Row],[Gjuttemperatur]]&Table141719202122[[#This Row],[Temperatur motgjutningsyta]]&Table141719202122[[#This Row],[Väderskydd, uppvärmning (ingen vind)]]&Table141719202122[[#This Row],[Täckning '[mm']]]&Table141719202122[[#This Row],[OK<7 dagar]]&Table141719202122[[#This Row],[Kommentar]] -> 0,4205Vindskydd och 20 °C uppvärmning30 mmOK7
A18: 0.4 | B18: =Förutsättningar!M$21 -> 20 | C18: =Förutsättningar!N$21 -> 5 | D18: Vindskydd och 20 °C uppvärmning | E18: 30 mm | F18: 5 | G18: 2 | H18: 6.9 | I18: OK7 | K18: =Table141719202122[[#This Row],[Slagg mängd]]&Table141719202122[[#This Row],[Gjuttemperatur]]&Table141719202122[[#This Row],[Temperatur motgjutningsyta]]&Table141719202122[[#This Row],[Väderskydd, uppvärmning (ingen vind)]]&Table141719202122[[#This Row],[Täckning '[mm']]]&Table141719202122[[#This Row],[OK<7 dagar]]&Table141719202122[[#This Row],[Kommentar]] -> 0,4205Vindskydd och 20 °C uppvärmning30 mmOK7
A19: 0.4 | B19: =Förutsättningar!M$21 -> 20 | C19: =Förutsättningar!N$21 -> 5 | D19: Vindskydd och 20 °C uppvärmning | E19: 50 mm | F19: 5 | G19: 7 | H19: 6.3 | I19: OK7 | K19: =Table141719202122[[#This Row],[Slagg mängd]]&Table141719202122[[#This Row],[Gjuttemperatur]]&Table141719202122[[#This Row],[Temperatur motgjutningsyta]]&Table141719202122[[#This Row],[Väderskydd, uppvärmning (ingen vind)]]&Table141719202122[[#This Row],[Täckning '[mm']]]&Table141719202122[[#This Row],[OK<7 dagar]]&Table141719202122[[#This Row],[Kommentar]] -> 0,4205Vindskydd och 20 °C uppvärmning50 mmOK7
A20: 0.4 | B20: =Förutsättningar!M$21 -> 20 | C20: =Förutsättningar!N$21 -> 5 | D20: Vindskydd och 20 °C uppvärmning | E20: 50 mm | F20: 5 | G20: 12 | H20: 6.3 | I20: OK7 | K20: =Table141719202122[[#This Row],[Slagg mängd]]&Table141719202122[[#This Row],[Gjuttemperatur]]&Table141719202122[[#This Row],[Temperatur motgjutningsyta]]&Table141719202122[[#This Row],[Väderskydd, uppvärmning (ingen vind)]]&Table141719202122[[#This Row],[Täckning '[mm']]]&Table141719202122[[#This Row],[OK<7 dagar]]&Table141719202122[[#This Row],[Kommentar]] -> 0,4205Vindskydd och 20 °C uppvärmning50 mmOK7
A21: 0.4 | B21: =Förutsättningar!M$21 -> 20 | C21: =Förutsättningar!N$21 -> 5 | D21: Vindskydd och 20 °C uppvärmning | E21: 50 mm | F21: 5 | G21: 20 | H21: 6.3 | I21: OK7 | K21: =Table141719202122[[#This Row],[Slagg mängd]]&Table141719202122[[#This Row],[Gjuttemperatur]]&Table141719202122[[#This Row],[Temperatur motgjutningsyta]]&Table141719202122[[#This Row],[Väderskydd, uppvärmning (ingen vind)]]&Table141719202122[[#This Row],[Täckning '[mm']]]&Table141719202122[[#This Row],[OK<7 dagar]]&Table141719202122[[#This Row],[Kommentar]] -> 0,4205Vindskydd och 20 °C uppvärmning50 mmOK7
A22: 0.3 | B22: =Förutsättningar!M$22 -> 20 | C22: =Förutsättningar!N$22 -> 5 | D22: Vindskydd och 20 °C uppvärmning | E22: 50 mm | F22: 0 | G22: 0 | H22: 6.9 | I22: OK7 | K22: =Table141719202122[[#This Row],[Slagg mängd]]&Table141719202122[[#This Row],[Gjuttemperatur]]&Table141719202122[[#This Row],[Temperatur motgjutningsyta]]&Table141719202122[[#This Row],[Väderskydd, uppvärmning (ingen vind)]]&Table141719202122[[#This Row],[Täckning '[mm']]]&Table141719202122[[#This Row],[OK<7 dagar]]&Table141719202122[[#This Row],[Kommentar]] -> 0,3205Vindskydd och 20 °C uppvärmning50 mmOK7
A23: 0.3 | B23: =Förutsättningar!M$22 -> 20 | C23: =Förutsättningar!N$22 -> 5 | D23: Vindskydd och 20 °C uppvärmning | E23: 50 mm | F23: 0 | G23: 2 | H23: 7 | I23: OK7 | K23: =Table141719202122[[#This Row],[Slagg mängd]]&Table141719202122[[#This Row],[Gjuttemperatur]]&Table141719202122[[#This Row],[Temperatur motgjutningsyta]]&Table141719202122[[#This Row],[Väderskydd, uppvärmning (ingen vind)]]&Table141719202122[[#This Row],[Täckning '[mm']]]&Table141719202122[[#This Row],[OK<7 dagar]]&Table141719202122[[#This Row],[Kommentar]] -> 0,3205Vindskydd och 20 °C uppvärmning50 mmOK7
A24: 0.2 | B24: =Förutsättningar!M$22 -> 20 | C24: =Förutsättningar!N$22 -> 5 | D24: Vindskydd och 20 °C uppvärmning | E24: 50 mm | F24: 0 | G24: 7 | H24: 6.1 | I24: OK7 | K24: =Table141719202122[[#This Row],[Slagg mängd]]&Table141719202122[[#This Row],[Gjuttemperatur]]&Table141719202122[[#This Row],[Temperatur motgjutningsyta]]&Table141719202122[[#This Row],[Väderskydd, uppvärmning (ingen vind)]]&Table141719202122[[#This Row],[Täckning '[mm']]]&Table141719202122[[#This Row],[OK<7 dagar]]&Table141719202122[[#This Row],[Kommentar]] -> 0,2205Vindskydd och 20 °C uppvärmning50 mmOK7
A25: 0.2 | B25: =Förutsättningar!M$22 -> 20 | C25: =Förutsättningar!N$22 -> 5 | D25: Vindskydd och 20 °C uppvärmning | E25: 50 mm | F25: 0 | G25: 12 | H25: 6.2 | I25: OK7 | K25: =Table141719202122[[#This Row],[Slagg mängd]]&Table141719202122[[#This Row],[Gjuttemperatur]]&Table141719202122[[#This Row],[Temperatur motgjutningsyta]]&Table141719202122[[#This Row],[Väderskydd, uppvärmning (ingen vind)]]&Table141719202122[[#This Row],[Täckning '[mm']]]&Table141719202122[[#This Row],[OK<7 dagar]]&Table141719202122[[#This Row],[Kommentar]] -> 0,2205Vindskydd och 20 °C uppvärmning50 mmOK7
A26: 0.2 | B26: =Förutsättningar!M$22 -> 20 | C26: =Förutsättningar!N$22 -> 5 | D26: Vindskydd och 20 °C uppvärmning | E26: 50 mm | F26: 0 | G26: 20 | H26: 6.2 | I26: OK7 | K26: =Table141719202122[[#This Row],[Slagg mängd]]&Table141719202122[[#This Row],[Gjuttemperatur]]&Table141719202122[[#This Row],[Temperatur motgjutningsyta]]&Table141719202122[[#This Row],[Väderskydd, uppvärmning (ingen vind)]]&Table141719202122[[#This Row],[Täckning '[mm']]]&Table141719202122[[#This Row],[OK<7 dagar]]&Table141719202122[[#This Row],[Kommentar]] -> 0,2205Vindskydd och 20 °C uppvärmning50 mmOK7
A27: 0.1 | B27: =Förutsättningar!M$23 -> 20 | C27: =Förutsättningar!N$23 -> 5 | D27: Vindskydd och 20 °C uppvärmning | E27: 30 mm | F27: -5 | G27: 0 | H27: 6.4 | I27: OK7 | K27: =Table141719202122[[#This Row],[Slagg mängd]]&Table141719202122[[#This Row],[Gjuttemperatur]]&Table141719202122[[#This Row],[Temperatur motgjutningsyta]]&Table141719202122[[#This Row],[Väderskydd, uppvärmning (ingen vind)]]&Table141719202122[[#This Row],[Täckning '[mm']]]&Table141719202122[[#This Row],[OK<7 dagar]]&Table141719202122[[#This Row],[Kommentar]] -> 0,1205Vindskydd och 20 °C uppvärmning30 mmOK7
A28: 0.1 | B28: =Förutsättningar!M$23 -> 20 | C28: =Förutsättningar!N$23 -> 5 | D28: Vindskydd och 20 °C uppvärmning | E28: 30 mm | F28: -5 | G28: 2 | H28: 6.8 | I28: OK7 | K28: =Table141719202122[[#This Row],[Slagg mängd]]&Table141719202122[[#This Row],[Gjuttemperatur]]&Table141719202122[[#This Row],[Temperatur motgjutningsyta]]&Table141719202122[[#This Row],[Väderskydd, uppvärmning (ingen vind)]]&Table141719202122[[#This Row],[Täckning '[mm']]]&Table141719202122[[#This Row],[OK<7 dagar]]&Table141719202122[[#This Row],[Kommentar]] -> 0,1205Vindskydd och 20 °C uppvärmning30 mmOK7
A29: 0.1 | B29: =Förutsättningar!M$23 -> 20 | C29: =Förutsättningar!N$23 -> 5 | D29: Vindskydd och 20 °C uppvärmning | E29: 50 mm | F29: -5 | G29: 7 | H29: 5.8 | I29: OK7 | K29: =Table141719202122[[#This Row],[Slagg mängd]]&Table141719202122[[#This Row],[Gjuttemperatur]]&Table141719202122[[#This Row],[Temperatur motgjutningsyta]]&Table141719202122[[#This Row],[Väderskydd, uppvärmning (ingen vind)]]&Table141719202122[[#This Row],[Täckning '[mm']]]&Table141719202122[[#This Row],[OK<7 dagar]]&Table141719202122[[#This Row],[Kommentar]] -> 0,1205Vindskydd och 20 °C uppvärmning50 mmOK7
A30: 0.1 | B30: =Förutsättningar!M$23 -> 20 | C30: =Förutsättningar!N$23 -> 5 | D30: Vindskydd och 20 °C uppvärmning | E30: 50 mm | F30: -5 | G30: 12 | H30: 6 | I30: OK7 | K30: =Table141719202122[[#This Row],[Slagg mängd]]&Table141719202122[[#This Row],[Gjuttemperatur]]&Table141719202122[[#This Row],[Temperatur motgjutningsyta]]&Table141719202122[[#This Row],[Väderskydd, uppvärmning (ingen vind)]]&Table141719202122[[#This Row],[Täckning '[mm']]]&Table141719202122[[#This Row],[OK<7 dagar]]&Table141719202122[[#This Row],[Kommentar]] -> 0,1205Vindskydd och 20 °C uppvärmning50 mmOK7
A31: 0.1 | B31: =Förutsättningar!M$23 -> 20 | C31: =Förutsättningar!N$23 -> 5 | D31: Vindskydd och 20 °C uppvärmning | E31: 50 mm | F31: -5 | G31: 20 | H31: 6 | I31: OK7 | K31: =Table141719202122[[#This Row],[Slagg mängd]]&Table141719202122[[#This Row],[Gjuttemperatur]]&Table141719202122[[#This Row],[Temperatur motgjutningsyta]]&Table141719202122[[#This Row],[Väderskydd, uppvärmning (ingen vind)]]&Table141719202122[[#This Row],[Täckning '[mm']]]&Table141719202122[[#This Row],[OK<7 dagar]]&Table141719202122[[#This Row],[Kommentar]] -> 0,1205Vindskydd och 20 °C uppvärmning50 mmOK7
A32: Bas+0% | B32: =Förutsättningar!M$24 -> 20 | C32: =Förutsättningar!N$24 -> 5 | D32: Vindskydd och 20 °C uppvärmning | E32: 30 mm | F32: -10 | G32: 0 | H32: 6.2 | I32: OK7 | K32: =Table141719202122[[#This Row],[Slagg mängd]]&Table141719202122[[#This Row],[Gjuttemperatur]]&Table141719202122[[#This Row],[Temperatur motgjutningsyta]]&Table141719202122[[#This Row],[Väderskydd, uppvärmning (ingen vind)]]&Table141719202122[[#This Row],[Täckning '[mm']]]&Table141719202122[[#This Row],[OK<7 dagar]]&Table141719202122[[#This Row],[Kommentar]] -> Bas+0%205Vindskydd och 20 °C uppvärmning30 mmOK7
A33: Bas+0% | B33: =Förutsättningar!M$24 -> 20 | C33: =Förutsättningar!N$24 -> 5 | D33: Vindskydd och 20 °C uppvärmning | E33: 30 mm | F33: -10 | G33: 2 | H33: 6.8 | I33: OK7 | K33: =Table141719202122[[#This Row],[Slagg mängd]]&Table141719202122[[#This Row],[Gjuttemperatur]]&Table141719202122[[#This Row],[Temperatur motgjutningsyta]]&Table141719202122[[#This Row],[Väderskydd, uppvärmning (ingen vind)]]&Table141719202122[[#This Row],[Täckning '[mm']]]&Table141719202122[[#This Row],[OK<7 dagar]]&Table141719202122[[#This Row],[Kommentar]] -> Bas+0%205Vindskydd och 20 °C uppvärmning30 mmOK7
A34: Bas+0% | B34: =Förutsättningar!M$24 -> 20 | C34: =Förutsättningar!N$24 -> 5 | D34: Vindskydd och 20 °C uppvärmning | E34: 50 mm | F34: -10 | G34: 7 | H34: 5.5 | I34: OK7 | K34: =Table141719202122[[#This Row],[Slagg mängd]]&Table141719202122[[#This Row],[Gjuttemperatur]]&Table141719202122[[#This Row],[Temperatur motgjutningsyta]]&Table141719202122[[#This Row],[Väderskydd, uppvärmning (ingen vind)]]&Table141719202122[[#This Row],[Täckning '[mm']]]&Table141719202122[[#This Row],[OK<7 dagar]]&Table141719202122[[#This Row],[Kommentar]] -> Bas+0%205Vindskydd och 20 °C uppvärmning50 mmOK7
A35: - | B35: - | C35: - | D35: - | E35: - | F35: -10 | G35: 12 | J35: Frys innan täck | K35: =Table141719202122[[#This Row],[Slagg mängd]]&Table141719202122[[#This Row],[Gjuttemperatur]]&Table141719202122[[#This Row],[Temperatur motgjutningsyta]]&Table141719202122[[#This Row],[Väderskydd, uppvärmning (ingen vind)]]&Table141719202122[[#This Row],[Täckning '[mm']]]&Table141719202122[[#This Row],[OK<7 dagar]]&Table141719202122[[#This Row],[Kommentar]] -> -----Frys innan täck
A36: - | B36: - | C36: - | D36: - | E36: - | F36: -10 | G36: 20 | J36: Frys innan täck | K36: =Table141719202122[[#This Row],[Slagg mängd]]&Table141719202122[[#This Row],[Gjuttemperatur]]&Table141719202122[[#This Row],[Temperatur motgjutningsyta]]&Table141719202122[[#This Row],[Väderskydd, uppvärmning (ingen vind)]]&Table141719202122[[#This Row],[Täckning '[mm']]]&Table141719202122[[#This Row],[OK<7 dagar]]&Table141719202122[[#This Row],[Kommentar]] -> -----Frys innan täck
A37: - | B37: - | C37: - | D37: - | E37: - | F37: -15 | G37: 0 | J37: Når ej 70% | K37: =Table141719202122[[#This Row],[Slagg mängd]]&Table141719202122[[#This Row],[Gjuttemperatur]]&Table141719202122[[#This Row],[Temperatur motgjutningsyta]]&Table141719202122[[#This Row],[Väderskydd, uppvärmning (ingen vind)]]&Table141719202122[[#This Row],[Täckning '[mm']]]&Table141719202122[[#This Row],[OK<7 dagar]]&Table141719202122[[#This Row],[Kommentar]] -> -----Når ej 70%
A38: - | B38: - | C38: - | D38: - | E38: - | F38: -15 | G38: 2 | J38: Når ej 70% | K38: =Table141719202122[[#This Row],[Slagg mängd]]&Table141719202122[[#This Row],[Gjuttemperatur]]&Table141719202122[[#This Row],[Temperatur motgjutningsyta]]&Table141719202122[[#This Row],[Väderskydd, uppvärmning (ingen vind)]]&Table141719202122[[#This Row],[Täckning '[mm']]]&Table141719202122[[#This Row],[OK<7 dagar]]&Table141719202122[[#This Row],[Kommentar]] -> -----Når ej 70%
A39: - | B39: - | C39: - | D39: - | E39: - | F39: -15 | G39: 7 | J39: Frys innan täck | K39: =Table141719202122[[#This Row],[Slagg mängd]]&Table141719202122[[#This Row],[Gjuttemperatur]]&Table141719202122[[#This Row],[Temperatur motgjutningsyta]]&Table141719202122[[#This Row],[Väderskydd, uppvärmning (ingen vind)]]&Table141719202122[[#This Row],[Täckning '[mm']]]&Table141719202122[[#This Row],[OK<7 dagar]]&Table141719202122[[#This Row],[Kommentar]] -> -----Frys innan täck
A40: - | B40: - | C40: - | D40: - | E40: - | F40: -15 | G40: 12 | J40: Frys innan täck | K40: =Table141719202122[[#This Row],[Slagg mängd]]&Table141719202122[[#This Row],[Gjuttemperatur]]&Table141719202122[[#This Row],[Temperatur motgjutningsyta]]&Table141719202122[[#This Row],[Väderskydd, uppvärmning (ingen vind)]]&Table141719202122[[#This Row],[Täckning '[mm']]]&Table141719202122[[#This Row],[OK<7 dagar]]&Table141719202122[[#This Row],[Kommentar]] -> -----Frys innan täck
...

Sheet Bjälklag (C25-30)
A1: Slagg mängd | B1: Gjuttemperatur | C1: Temperatur motgjutningsyta | D1: Väderskydd, uppvärmning (ingen vind) | E1: Täckning [mm] | F1: Temperatur | G1: Vind | H1: <7 d och >70% [Dagar] | I1: OK<7 dagar | J1: Kommentar | K1: Åtgärdskåd
A2: 0.4 | B2: =Förutsättningar!M$18 -> 15 | C2: =Förutsättningar!N$18 -> 20 | D2: 0 | E2: Presenning | F2: 20 | G2: 0 | H2: 7 | I2: OK7 | K2: =Table1417192021[[#This Row],[Slagg mängd]]&Table1417192021[[#This Row],[Gjuttemperatur]]&Table1417192021[[#This Row],[Temperatur motgjutningsyta]]&Table1417192021[[#This Row],[Väderskydd, uppvärmning (ingen vind)]]&Table1417192021[[#This Row],[Täckning '[mm']]]&Table1417192021[[#This Row],[OK<7 dagar]]&Table1417192021[[#This Row],[Kommentar]] -> 0,415200PresenningOK7
A3: 0.3 | B3: =Förutsättningar!$M$18 -> 15 | C3: =Förutsättningar!N$18 -> 20 | D3: - | E3: - | F3: 20 | G3: 2 | H3: 6.8 | I3: OK7 | K3: =Table1417192021[[#This Row],[Slagg mängd]]&Table1417192021[[#This Row],[Gjuttemperatur]]&Table1417192021[[#This Row],[Temperatur motgjutningsyta]]&Table1417192021[[#This Row],[Väderskydd, uppvärmning (ingen vind)]]&Table1417192021[[#This Row],[Täckning '[mm']]]&Table1417192021[[#This Row],[OK<7 dagar]]&Table1417192021[[#This Row],[Kommentar]] -> 0,31520--OK7
A4: 0.3 | B4: =Förutsättningar!$M$18 -> 15 | C4: =Förutsättningar!N$18 -> 20 | D4: - | E4: - | F4: 20 | G4: 7 | H4: 7 | I4: OK7 | K4: =Table1417192021[[#This Row],[Slagg mängd]]&Table1417192021[[#This Row],[Gjuttemperatur]]&Table1417192021[[#This Row],[Temperatur motgjutningsyta]]&Table1417192021[[#This Row],[Väderskydd, uppvärmning (ingen vind)]]&Table1417192021[[#This Row],[Täckning '[mm']]]&Table1417192021[[#This Row],[OK<7 dagar]]&Table1417192021[[#This Row],[Kommentar]] -> 0,31520--OK7
A5: 0.3 | B5: =Förutsättningar!$M$18 -> 15 | C5: =Förutsättningar!N$18 -> 20 | D5: - | E5: - | F5: 20 | G5: 12 | H5: 7 | I5: OK7 | K5: =Table1417192021[[#This Row],[Slagg mängd]]&Table1417192021[[#This Row],[Gjuttemperatur]]&Table1417192021[[#This Row],[Temperatur motgjutningsyta]]&Table1417192021[[#This Row],[Väderskydd, uppvärmning (ingen vind)]]&Table1417192021[[#This Row],[Täckning '[mm']]]&Table1417192021[[#This Row],[OK<7 dagar]]&Table1417192021[[#This Row],[Kommentar]] -> 0,31520--OK7
A6: 0.3 | B6: =Förutsättningar!$M$18 -> 15 | C6: =Förutsättningar!N$18 -> 20 | D6: - | E6: - | F6: 20 | G6: 20 | H6: 7 | I6: OK7 | K6: =Table1417192021[[#This Row],[Slagg mängd]]&Table1417192021[[#This Row],[Gjuttemperatur]]&Table1417192021[[#This Row],[Temperatur motgjutningsyta]]&Table1417192021[[#This Row],[Väderskydd, uppvärmning (ingen vind)]]&Table1417192021[[#This Row],[Täckning '[mm']]]&Table1417192021[[#This Row],[OK<7 dagar]]&Table1417192021[[#This Row],[Kommentar]] -> 0,31520--OK7
A7: 0.1 | B7: =Förutsättningar!M$19 -> 15 | C7: =Förutsättningar!N$19 -> 15 | D7: - | E7: - | F7: 15 | G7: 0 | H7: 5.6 | I7: OK7 | K7: =Table1417192021[[#This Row],[Slagg mängd]]&Table1417192021[[#This Row],[Gjuttemperatur]]&Table1417192021[[#This Row],[Temperatur motgjutningsyta]]&Table1417192021[[#This Row],[Väderskydd, uppvärmning (ingen vind)]]&Table1417192021[[#This Row],[Täckning '[mm']]]&Table1417192021[[#This Row],[OK<7 dagar]]&Table1417192021[[#This Row],[Kommentar]] -> 0,11515--OK7
A8: 0.1 | B8: =Förutsättningar!M$19 -> 15 | C8: =Förutsättningar!N$19 -> 15 | D8: - | E8: - | F8: 15 | G8: 2 | H8: 6.3 | I8: OK7 | K8: =Table1417192021[[#This Row],[Slagg mängd]]&Table1417192021[[#This Row],[Gjuttemperatur]]&Table1417192021[[#This Row],[Temperatur motgjutningsyta]]&Table1417192021[[#This Row],[Väderskydd, uppvärmning (ingen vind)]]&Table1417192021[[#This Row],[Täckning '[mm']]]&Table1417192021[[#This Row],[OK<7 dagar]]&Table1417192021[[#This Row],[Kommentar]] -> 0,11515--OK7
A9: 0.1 | B9: 15 | C9: 15 | D9: - | E9: - | F9: 15 | G9: 7 | H9: 6.6 | I9: OK7 | K9: =Table1417192021[[#This Row],[Slagg mängd]]&Table1417192021[[#This Row],[Gjuttemperatur]]&Table1417192021[[#This Row],[Temperatur motgjutningsyta]]&Table1417192021[[#This Row],[Väderskydd, uppvärmning (ingen vind)]]&Table1417192021[[#This Row],[Täckning '[mm']]]&Table1417192021[[#This Row],[OK<7 dagar]]&Table1417192021[[#This Row],[Kommentar]] -> 0,11515--OK7
A10: 0.1 | B10: 15 | C10: 15 | D10: - | E10: - | F10: 15 | G10: 12 | H10: 6.7 | I10: OK7 | K10: =Table1417192021[[#This Row],[Slagg mängd]]&Table1417192021[[#This Row],[Gjuttemperatur]]&Table1417192021[[#This Row],[Temperatur motgjutningsyta]]&Table1417192021[[#This Row],[Väderskydd, uppvärmning (ingen vind)]]&Table1417192021[[#This Row],[Täckning '[mm']]]&Table1417192021[[#This Row],[OK<7 dagar]]&Table1417192021[[#This Row],[Kommentar]] -> 0,11515--OK7
A11: 0.1 | B11: 15 | C11: 15 | D11: - | E11: - | F11: 15 | G11: 20 | H11: 6.8 | I11: OK7 | K11: =Table1417192021[[#This Row],[Slagg mängd]]&Table1417192021[[#This Row],[Gjuttemperatur]]&Table1417192021[[#This Row],[Temperatur motgjutningsyta]]&Table1417192021[[#This Row],[Väderskydd, uppvärmning (ingen vind)]]&Table1417192021[[#This Row],[Täckning '[mm']]]&Table1417192021[[#This Row],[OK<7 dagar]]&Table1417192021[[#This Row],[Kommentar]] -> 0,11515--OK7
A12: Bas+0% | B12: =Förutsättningar!M$20 -> 15 | C12: =Förutsättningar!N$20 -> 10 | D12: - | E12: - | F12: 10 | G12: 0 | H12: 5.5 | I12: OK7 | K12: =Table1417192021[[#This Row],[Slagg mängd]]&Table1417192021[[#This Row],[Gjuttemperatur]]&Table1417192021[[#This Row],[Temperatur motgjutningsyta]]&Table1417192021[[#This Row],[Väderskydd, uppvärmning (ingen vind)]]&Table1417192021[[#This Row],[Täckning '[mm']]]&Table1417192021[[#This Row],[OK<7 dagar]]&Table1417192021[[#This Row],[Kommentar]] -> Bas+0%1510--OK7
A13: Bas+0% | B13: =Förutsättningar!M$20 -> 15 | C13: =Förutsättningar!N$20 -> 10 | D13: - | E13: - | F13: 10 | G13: 2 | H13: 6.5 | I13: OK7 | K13: =Table1417192021[[#This Row],[Slagg mängd]]&Table1417192021[[#This Row],[Gjuttemperatur]]&Table1417192021[[#This Row],[Temperatur motgjutningsyta]]&Table1417192021[[#This Row],[Väderskydd, uppvärmning (ingen vind)]]&Table1417192021[[#This Row],[Täckning '[mm']]]&Table1417192021[[#This Row],[OK<7 dagar]]&Table1417192021[[#This Row],[Kommentar]] -> Bas+0%1510--OK7
A14: Bas+0% | B14: =Förutsättningar!M$20 -> 15 | C14: =Förutsättningar!N$20 -> 10 | D14: - | E14: - | F14: 10 | G14: 7 | H14: 7 | I14: OK7 | K14: =Table1417192021[[#This Row],[Slagg mängd]]&Table1417192021[[#This Row],[Gjuttemperatur]]&Table1417192021[[#This Row],[Temperatur motgjutningsyta]]&Table1417192021[[#This Row],[Väderskydd, uppvärmning (ingen vind)]]&Table1417192021[[#This Row],[Täckning '[mm']]]&Table1417192021[[#This Row],[OK<7 dagar]]&Table1417192021[[#This Row],[Kommentar]] -> Bas+0%1510--OK7
A15: Bas+0% | B15: =Förutsättningar!M$20 -> 15 | C15: =Förutsättningar!N$20 -> 10 | D15: 0 | E15: - | F15: 10 | G15: 12 | H15: 6.8 | I15: OK7 | K15: =Table1417192021[[#This Row],[Slagg mängd]]&Table1417192021[[#This Row],[Gjuttemperatur]]&Table1417192021[[#This Row],[Temperatur motgjutningsyta]]&Table1417192021[[#This Row],[Väderskydd, uppvärmning (ingen vind)]]&Table1417192021[[#This Row],[Täckning '[mm']]]&Table1417192021[[#This Row],[OK<7 dagar]]&Table1417192021[[#This Row],[Kommentar]] -> Bas+0%15100-OK7
A16: Bas+0% | B16: =Förutsättningar!M$20 -> 15 | C16: =Förutsättningar!N$20 -> 10 | D16: 0 | E16: - | F16: 10 | G16: 20 | H16: 6.9 | I16: OK7 | K16: =Table1417192021[[#This Row],[Slagg mängd]]&Table1417192021[[#This Row],[Gjuttemperatur]]&Table1417192021[[#This Row],[Temperatur motgjutningsyta]]&Table1417192021[[#This Row],[Väderskydd, uppvärmning (ingen vind)]]&Table1417192021[[#This Row],[Täckning '[mm']]]&Table1417192021[[#This Row],[OK<7 dagar]]&Table1417192021[[#This Row],[Kommentar]] -> Bas+0%15100-OK7
A17: 0.4 | B17: =Förutsättningar!M$21 -> 20 | C17: =Förutsättningar!N$21 -> 5 | D17: 20 | E17: 20 | F17: 5 | G17: 0 | H17: 6.6 | I17: OK7 | K17: =Table1417192021[[#This Row],[Slagg mängd]]&Table1417192021[[#This Row],[Gjuttemperatur]]&Table1417192021[[#This Row],[Temperatur motgjutningsyta]]&Table1417192021[[#This Row],[Väderskydd, uppvärmning (ingen vind)]]&Table1417192021[[#This Row],[Täckning '[mm']]]&Table1417192021[[#This Row],[OK<7 dagar]]&Table1417192021[[#This Row],[Kommentar]] -> 0,42052020OK7
A18: 0.4 | B18: =Förutsättningar!M$21 -> 20 | C18: =Förutsättningar!N$21 -> 5 | D18: 20 | E18: 20 | F18: 5 | G18: 2 | H18: 7 | I18: OK7 | K18: =Table1417192021[[#This Row],[Slagg mängd]]&Table1417192021[[#This Row],[Gjuttemperatur]]&Table1417192021[[#This Row],[Temperatur motgjutningsyta]]&Table1417192021[[#This Row],[Väderskydd, uppvärmning (ingen vind)]]&Table1417192021[[#This Row],[Täckning '[mm']]]&Table1417192021[[#This Row],[OK<7 dagar]]&Table1417192021[[#This Row],[Kommentar]] -> 0,42052020OK7
A19: 0.4 | B19: =Förutsättningar!M$21 -> 20 | C19: =Förutsättningar!N$21 -> 5 | D19: 20 | E19: 30 | F19: 5 | G19: 7 | H19: 6.5 | I19: OK7 | K19: =Table1417192021[[#This Row],[Slagg mängd]]&Table1417192021[[#This Row],[Gjuttemperatur]]&Table1417192021[[#This Row],[Temperatur motgjutningsyta]]&Table1417192021[[#This Row],[Väderskydd, uppvärmning (ingen vind)]]&Table1417192021[[#This Row],[Täckning '[mm']]]&Table1417192021[[#This Row],[OK<7 dagar]]&Table1417192021[[#This Row],[Kommentar]] -> 0,42052030OK7
A20: 0.4 | B20: =Förutsättningar!M$21 -> 20 | C20: =Förutsättningar!N$21 -> 5 | D20: 20 | E20: 30 | F20: 5 | G20: 12 | H20: 6.5 | I20: OK7 | K20: =Table1417192021[[#This Row],[Slagg mängd]]&Table1417192021[[#This Row],[Gjuttemperatur]]&Table1417192021[[#This Row],[Temperatur motgjutningsyta]]&Table1417192021[[#This Row],[Väderskydd, uppvärmning (ingen vind)]]&Table1417192021[[#This Row],[Täckning '[mm']]]&Table1417192021[[#This Row],[OK<7 dagar]]&Table1417192021[[#This Row],[Kommentar]] -> 0,42052030OK7
A21: 0.4 | B21: =Förutsättningar!M$21 -> 20 | C21: =Förutsättningar!N$21 -> 5 | D21: 20 | E21: 30 | F21: 5 | G21: 20 | H21: 6.6 | I21: OK7 | K21: =Table1417192021[[#This Row],[Slagg mängd]]&Table1417192021[[#This Row],[Gjuttemperatur]]&Table1417192021[[#This Row],[Temperatur motgjutningsyta]]&Table1417192021[[#This Row],[Väderskydd, uppvärmning (ingen vind)]]&Table1417192021[[#This Row],[Täckning '[mm']]]&Table1417192021[[#This Row],[OK<7 dagar]]&Table1417192021[[#This Row],[Kommentar]] -> 0,42052030OK7
A22: 0.4 | B22: =Förutsättningar!M$22 -> 20 | C22: =Förutsättningar!N$22 -> 5 | D22: 20 | E22: 50 | F22: 0 | G22: 0 | H22: 7 | I22: OK7 | K22: =Table1417192021[[#This Row],[Slagg mängd]]&Table1417192021[[#This Row],[Gjuttemperatur]]&Table1417192021[[#This Row],[Temperatur motgjutningsyta]]&Table1417192021[[#This Row],[Väderskydd, uppvärmning (ingen vind)]]&Table1417192021[[#This Row],[Täckning '[mm']]]&Table1417192021[[#This Row],[OK<7 dagar]]&Table1417192021[[#This Row],[Kommentar]] -> 0,42052050OK7
A23: 0.3 | B23: =Förutsättningar!M$22 -> 20 | C23: =Förutsättningar!N$22 -> 5 | D23: 20 | E23: 30 | F23: 0 | G23: 2 | H23: 7 | I23: OK7 | K23: =Table1417192021[[#This Row],[Slagg mängd]]&Table1417192021[[#This Row],[Gjuttemperatur]]&Table1417192021[[#This Row],[Temperatur motgjutningsyta]]&Table1417192021[[#This Row],[Väderskydd, uppvärmning (ingen vind)]]&Table1417192021[[#This Row],[Täckning '[mm']]]&Table1417192021[[#This Row],[OK<7 dagar]]&Table1417192021[[#This Row],[Kommentar]] -> 0,32052030OK7
A24: 0.3 | B24: =Förutsättningar!M$22 -> 20 | C24: =Förutsättningar!N$22 -> 5 | D24: 20 | E24: 50 | F24: 0 | G24: 7 | H24: 6.2 | I24: OK7 | K24: =Table1417192021[[#This Row],[Slagg mängd]]&Table1417192021[[#This Row],[Gjuttemperatur]]&Table1417192021[[#This Row],[Temperatur motgjutningsyta]]&Table1417192021[[#This Row],[Väderskydd, uppvärmning (ingen vind)]]&Table1417192021[[#This Row],[Täckning '[mm']]]&Table1417192021[[#This Row],[OK<7 dagar]]&Table1417192021[[#This Row],[Kommentar]] -> 0,32052050OK7
A25: 0.3 | B25: =Förutsättningar!M$22 -> 20 | C25: =Förutsättningar!N$22 -> 5 | D25: 20 | E25: 50 | F25: 0 | G25: 12 | H25: 6.3 | I25: OK7 | K25: =Table1417192021[[#This Row],[Slagg mängd]]&Table1417192021[[#This Row],[Gjuttemperatur]]&Table1417192021[[#This Row],[Temperatur motgjutningsyta]]&Table1417192021[[#This Row],[Väderskydd, uppvärmning (ingen vind)]]&Table1417192021[[#This Row],[Täckning '[mm']]]&Table1417192021[[#This Row],[OK<7 dagar]]&Table1417192021[[#This Row],[Kommentar]] -> 0,32052050OK7
A26: 0.3 | B26: =Förutsättningar!M$22 -> 20 | C26: =Förutsättningar!N$22 -> 5 | D26: 20 | E26: 10 | F26: 0 | G26: 20 | H26: 6.3 | I26: OK7 | K26: =Table1417192021[[#This Row],[Slagg mängd]]&Table1417192021[[#This Row],[Gjuttemperatur]]&Table1417192021[[#This Row],[Temperatur motgjutningsyta]]&Table1417192021[[#This Row],[Väderskydd, uppvärmning (ingen vind)]]&Table1417192021[[#This Row],[Täckning '[mm']]]&Table1417192021[[#This Row],[OK<7 dagar]]&Table1417192021[[#This Row],[Kommentar]] -> 0,32052010OK7
A27: 0.2 | B27: =Förutsättningar!M$23 -> 20 | C27: =Förutsättningar!N$23 -> 5 | D27: 20 | E27: 50 | F27: -5 | G27: 0 | H27: 6.6 | I27: OK7 | K27: =Table1417192021[[#This Row],[Slagg mängd]]&Table1417192021[[#This Row],[Gjuttemperatur]]&Table1417192021[[#This Row],[Temperatur motgjutningsyta]]&Table1417192021[[#This Row],[Väderskydd, uppvärmning (ingen vind)]]&Table1417192021[[#This Row],[Täckning '[mm']]]&Table1417192021[[#This Row],[OK<7 dagar]]&Table1417192021[[#This Row],[Kommentar]] -> 0,22052050OK7
A28: 0.2 | B28: =Förutsättningar!M$23 -> 20 | C28: =Förutsättningar!N$23 -> 5 | D28: 20 | E28: 50 | F28: -5 | G28: 2 | H28: 6.8 | I28: OK7 | K28: =Table1417192021[[#This Row],[Slagg mängd]]&Table1417192021[[#This Row],[Gjuttemperatur]]&Table1417192021[[#This Row],[Temperatur motgjutningsyta]]&Table1417192021[[#This Row],[Väderskydd, uppvärmning (ingen vind)]]&Table1417192021[[#This Row],[Täckning '[mm']]]&Table1417192021[[#This Row],[OK<7 dagar]]&Table1417192021[[#This Row],[Kommentar]] -> 0,22052050OK7
A29: 0.1 | B29: =Förutsättningar!M$23 -> 20 | C29: =Förutsättningar!N$23 -> 5 | D29: 20 | E29: 30 | F29: -5 | G29: 7 | H29: 6.2 | I29: OK7 | K29: =Table1417192021[[#This Row],[Slagg mängd]]&Table1417192021[[#This Row],[Gjuttemperatur]]&Table1417192021[[#This Row],[Temperatur motgjutningsyta]]&Table1417192021[[#This Row],[Väderskydd, uppvärmning (ingen vind)]]&Table1417192021[[#This Row],[Täckning '[mm']]]&Table1417192021[[#This Row],[OK<7 dagar]]&Table1417192021[[#This Row],[Kommentar]] -> 0,12052030OK7
A30: 0.1 | B30: =Förutsättningar!M$23 -> 20 | C30: =Förutsättningar!N$23 -> 5 | D30: 20 | E30: 30 | F30: -5 | G30: 12 | H30: 6.4 | I30: OK7 | K30: =Table1417192021[[#This Row],[Slagg mängd]]&Table1417192021[[#This Row],[Gjuttemperatur]]&Table1417192021[[#This Row],[Temperatur motgjutningsyta]]&Table1417192021[[#This Row],[Väderskydd, uppvärmning (ingen vind)]]&Table1417192021[[#This Row],[Täckning '[mm']]]&Table1417192021[[#This Row],[OK<7 dagar]]&Table1417192021[[#This Row],[Kommentar]] -> 0,12052030OK7
A31: 0.1 | B31: =Förutsättningar!M$23 -> 20 | C31: =Förutsättningar!N$23 -> 5 | D31: 20 | E31: 30 | F31: -5 | G31: 20 | H31: 6.5 | I31: OK7 | K31: =Table1417192021[[#This Row],[Slagg mängd]]&Table1417192021[[#This Row],[Gjuttemperatur]]&Table1417192021[[#This Row],[Temperatur motgjutningsyta]]&Table1417192021[[#This Row],[Väderskydd, uppvärmning (ingen vind)]]&Table1417192021[[#This Row],[Täckning '[mm']]]&Table1417192021[[#This Row],[OK<7 dagar]]&Table1417192021[[#This Row],[Kommentar]] -> 0,12052030OK7
A32: 0.1 | B32: =Förutsättningar!M$24 -> 20 | C32: =Förutsättningar!N$24 -> 5 | D32: 20 | E32: 50 | F32: -10 | G32: 0 | H32: 6.5 | I32: OK7 | K32: =Table1417192021[[#This Row],[Slagg mängd]]&Table1417192021[[#This Row],[Gjuttemperatur]]&Table1417192021[[#This Row],[Temperatur motgjutningsyta]]&Table1417192021[[#This Row],[Väderskydd, uppvärmning (ingen vind)]]&Table1417192021[[#This Row],[Täckning '[mm']]]&Table1417192021[[#This Row],[OK<7 dagar]]&Table1417192021[[#This Row],[Kommentar]] -> 0,12052050OK7
A33: 0.1 | B33: =Förutsättningar!M$24 -> 20 | C33: =Förutsättningar!N$24 -> 5 | D33: 20 | E33: 50 | F33: -10 | G33: 2 | H33: 6.8 | I33: OK7 | K33: =Table1417192021[[#This Row],[Slagg mängd]]&Table1417192021[[#This Row],[Gjuttemperatur]]&Table1417192021[[#This Row],[Temperatur motgjutningsyta]]&Table1417192021[[#This Row],[Väderskydd, uppvärmning (ingen vind)]]&Table1417192021[[#This Row],[Täckning '[mm']]]&Table1417192021[[#This Row],[OK<7 dagar]]&Table1417192021[[#This Row],[Kommentar]] -> 0,12052050OK7
A34: Bas+0% | B34: =Förutsättningar!M$24 -> 20 | C34: =Förutsättningar!N$24 -> 5 | D34: 20 | E34: 30 | F34: -10 | G34: 7 | H34: 6 | I34: OK7 | K34: =Table1417192021[[#This Row],[Slagg mängd]]&Table1417192021[[#This Row],[Gjuttemperatur]]&Table1417192021[[#This Row],[Temperatur motgjutningsyta]]&Table1417192021[[#This Row],[Väderskydd, uppvärmning (ingen vind)]]&Table1417192021[[#This Row],[Täckning '[mm']]]&Table1417192021[[#This Row],[OK<7 dagar]]&Table1417192021[[#This Row],[Kommentar]] -> Bas+0%2052030OK7
A35: - | B35: - | C35: - | D35: - | E35: - | F35: -10 | G35: 12 | J35: Frys innan täck | K35: =Table1417192021[[#This Row],[Slagg mängd]]&Table1417192021[[#This Row],[Gjuttemperatur]]&Table1417192021[[#This Row],[Temperatur motgjutningsyta]]&Table1417192021[[#This Row],[Väderskydd, uppvärmning (ingen vind)]]&Table1417192021[[#This Row],[Täckning '[mm']]]&Table1417192021[[#This Row],[OK<7 dagar]]&Table1417192021[[#This Row],[Kommentar]] -> -----Frys innan täck
A36: - | B36: - | C36: - | D36: - | E36: - | F36: -10 | G36: 20 | J36: Frys innan täck | K36: =Table1417192021[[#This Row],[Slagg mängd]]&Table1417192021[[#This Row],[Gjuttemperatur]]&Table1417192021[[#This Row],[Temperatur motgjutningsyta]]&Table1417192021[[#This Row],[Väderskydd, uppvärmning (ingen vind)]]&Table1417192021[[#This Row],[Täckning '[mm']]]&Table1417192021[[#This Row],[OK<7 dagar]]&Table1417192021[[#This Row],[Kommentar]] -> -----Frys innan täck
A37: Bas+0% | B37: =Förutsättningar!M$25 -> 15 | C37: =Förutsättningar!N$25 -> 5 | D37: 20 | E37: 50 | F37: -15 | G37: 0 | H37: 7 | I37: OK7 | K37: =Table1417192021[[#This Row],[Slagg mängd]]&Table1417192021[[#This Row],[Gjuttemperatur]]&Table1417192021[[#This Row],[Temperatur motgjutningsyta]]&Table1417192021[[#This Row],[Väderskydd, uppvärmning (ingen vind)]]&Table1417192021[[#This Row],[Täckning '[mm']]]&Table1417192021[[#This Row],[OK<7 dagar]]&Table1417192021[[#This Row],[Kommentar]] -> Bas+0%1552050OK7
A38: - | B38: - | C38: - | D38: - | E38: - | F38: -15 | G38: 2 | J38: Når ej 70% | K38: =Table1417192021[[#This Row],[Slagg mängd]]&Table1417192021[[#This Row],[Gjuttemperatur]]&Table1417192021[[#This Row],[Temperatur motgjutningsyta]]&Table1417192021[[#This Row],[Väderskydd, uppvärmning (ingen vind)]]&Table1417192021[[#This Row],[Täckning '[mm']]]&Table1417192021[[#This Row],[OK<7 dagar]]&Table1417192021[[#This Row],[Kommentar]] -> -----Når ej 70%
A39: - | B39: - | C39: - | D39: - | E39: - | F39: -15 | G39: 7 | J39: Frys innan täck | K39: =Table1417192021[[#This Row],[Slagg mängd]]&Table1417192021[[#This Row],[Gjuttemperatur]]&Table1417192021[[#This Row],[Temperatur motgjutningsyta]]&Table1417192021[[#This Row],[Väderskydd, uppvärmning (ingen vind)]]&Table1417192021[[#This Row],[Täckning '[mm']]]&Table1417192021[[#This Row],[OK<7 dagar]]&Table1417192021[[#This Row],[Kommentar]] -> -----Frys innan täck
A40: - | B40: - | C40: - | D40: - | E40: - | F40: -15 | G40: 12 | J40: Frys innan täck | K40: =Table1417192021[[#This Row],[Slagg mängd]]&Table1417192021[[#This Row],[Gjuttemperatur]]&Table1417192021[[#This Row],[Temperatur motgjutningsyta]]&Table1417192021[[#This Row],[Väderskydd, uppvärmning (ingen vind)]]&Table1417192021[[#This Row],[Täckning '[mm']]]&Table1417192021[[#This Row],[OK<7 dagar]]&Table1417192021[[#This Row],[Kommentar]] -> -----Frys innan täck
...

Sheet Bjälklag (C28-35)
A1: Slagg mängd | B1: Gjuttemperatur | C1: Temperatur motgjutningsyta | D1: Väderskydd, uppvärmning (ingen vind) | E1: Täckning [mm] | F1: Temperatur | G1: Vind | H1: <7 d och >70% [Dagar] | I1: OK<7 dagar | J1: Kommentar | K1: Åtgärdskåd
A2: 0.4 | B2: =Förutsättningar!M$18 -> 15 | C2: =Förutsättningar!N$18 -> 20 | D2: - | E2: - | F2: 20 | G2: 0 | H2: 6.5 | I2: OK7 | K2: =Table14171920[[#This Row],[Slagg mängd]]&Table14171920[[#This Row],[Gjuttemperatur]]&Table14171920[[#This Row],[Temperatur motgjutningsyta]]&Table14171920[[#This Row],[Väderskydd, uppvärmning (ingen vind)]]&Table14171920[[#This Row],[Täckning '[mm']]]&Table14171920[[#This Row],[OK<7 dagar]]&Table14171920[[#This Row],[Kommentar]] -> 0,41520--OK7
A3: 0.4 | B3: =Förutsättningar!$M$18 -> 15 | C3: =Förutsättningar!N$18 -> 20 | D3: - | E3: - | F3: 20 | G3: 2 | H3: 7 | I3: OK7 | K3: =Table14171920[[#This Row],[Slagg mängd]]&Table14171920[[#This Row],[Gjuttemperatur]]&Table14171920[[#This Row],[Temperatur motgjutningsyta]]&Table14171920[[#This Row],[Väderskydd, uppvärmning (ingen vind)]]&Table14171920[[#This Row],[Täckning '[mm']]]&Table14171920[[#This Row],[OK<7 dagar]]&Table14171920[[#This Row],[Kommentar]] -> 0,41520--OK7
A4: 0.4 | B4: =Förutsättningar!$M$18 -> 15 | C4: =Förutsättningar!N$18 -> 20 | D4: 0 | E4: Presenning | F4: 20 | G4: 7 | H4: 6.9 | I4: OK7 | K4: =Table14171920[[#This Row],[Slagg mängd]]&Table14171920[[#This Row],[Gjuttemperatur]]&Table14171920[[#This Row],[Temperatur motgjutningsyta]]&Table14171920[[#This Row],[Väderskydd, uppvärmning (ingen vind)]]&Table14171920[[#This Row],[Täckning '[mm']]]&Table14171920[[#This Row],[OK<7 dagar]]&Table14171920[[#This Row],[Kommentar]] -> 0,415200PresenningOK7
A5: 0.4 | B5: =Förutsättningar!$M$18 -> 15 | C5: =Förutsättningar!N$18 -> 20 | D5: 0 | E5: Presenning | F5: 20 | G5: 12 | H5: 7 | I5: OK7 | K5: =Table14171920[[#This Row],[Slagg mängd]]&Table14171920[[#This Row],[Gjuttemperatur]]&Table14171920[[#This Row],[Temperatur motgjutningsyta]]&Table14171920[[#This Row],[Väderskydd, uppvärmning (ingen vind)]]&Table14171920[[#This Row],[Täckning '[mm']]]&Table14171920[[#This Row],[OK<7 dagar]]&Table14171920[[#This Row],[Kommentar]] -> 0,415200PresenningOK7
A6: 0.4 | B6: =Förutsättningar!$M$18 -> 15 | C6: =Förutsättningar!N$18 -> 20 | D6: 0 | E6: Presenning | F6: 20 | G6: 20 | H6: 7 | I6: OK7 | K6: =Table14171920[[#This Row],[Slagg mängd]]&Table14171920[[#This Row],[Gjuttemperatur]]&Table14171920[[#This Row],[Temperatur motgjutningsyta]]&Table14171920[[#This Row],[Väderskydd, uppvärmning (ingen vind)]]&Table14171920[[#This Row],[Täckning '[mm']]]&Table14171920[[#This Row],[OK<7 dagar]]&Table14171920[[#This Row],[Kommentar]] -> 0,415200PresenningOK7
A7: 0.2 | B7: =Förutsättningar!M$19 -> 15 | C7: =Förutsättningar!N$19 -> 15 | D7: - | E7: - | F7: 15 | G7: 0 | H7: 6.4 | I7: OK7 | K7: =Table14171920[[#This Row],[Slagg mängd]]&Table14171920[[#This Row],[Gjuttemperatur]]&Table14171920[[#This Row],[Temperatur motgjutningsyta]]&Table14171920[[#This Row],[Väderskydd, uppvärmning (ingen vind)]]&Table14171920[[#This Row],[Täckning '[mm']]]&Table14171920[[#This Row],[OK<7 dagar]]&Table14171920[[#This Row],[Kommentar]] -> 0,21515--OK7
A8: 0.2 | B8: =Förutsättningar!M$19 -> 15 | C8: =Förutsättningar!N$19 -> 15 | D8: 0 | E8: - | F8: 15 | G8: 2 | H8: 7 | I8: OK7 | K8: =Table14171920[[#This Row],[Slagg mängd]]&Table14171920[[#This Row],[Gjuttemperatur]]&Table14171920[[#This Row],[Temperatur motgjutningsyta]]&Table14171920[[#This Row],[Väderskydd, uppvärmning (ingen vind)]]&Table14171920[[#This Row],[Täckning '[mm']]]&Table14171920[[#This Row],[OK<7 dagar]]&Table14171920[[#This Row],[Kommentar]] -> 0,215150-OK7
A9: 0.1 | B9: =Förutsättningar!M$19 -> 15 | C9: =Förutsättningar!N$19 -> 15 | D9: - | E9: - | F9: 15 | G9: 7 | H9: 6 | I9: OK7 | K9: =Table14171920[[#This Row],[Slagg mängd]]&Table14171920[[#This Row],[Gjuttemperatur]]&Table14171920[[#This Row],[Temperatur motgjutningsyta]]&Table14171920[[#This Row],[Väderskydd, uppvärmning (ingen vind)]]&Table14171920[[#This Row],[Täckning '[mm']]]&Table14171920[[#This Row],[OK<7 dagar]]&Table14171920[[#This Row],[Kommentar]] -> 0,11515--OK7
A10: 0.1 | B10: =Förutsättningar!M$19 -> 15 | C10: =Förutsättningar!N$19 -> 15 | D10: - | E10: - | F10: 15 | G10: 12 | H10: 6 | I10: OK7 | K10: =Table14171920[[#This Row],[Slagg mängd]]&Table14171920[[#This Row],[Gjuttemperatur]]&Table14171920[[#This Row],[Temperatur motgjutningsyta]]&Table14171920[[#This Row],[Väderskydd, uppvärmning (ingen vind)]]&Table14171920[[#This Row],[Täckning '[mm']]]&Table14171920[[#This Row],[OK<7 dagar]]&Table14171920[[#This Row],[Kommentar]] -> 0,11515--OK7
A11: 0.1 | B11: =Förutsättningar!M$19 -> 15 | C11: =Förutsättningar!N$19 -> 15 | D11: - | E11: - | F11: 15 | G11: 20 | H11: 6.1 | I11: OK7 | K11: =Table14171920[[#This Row],[Slagg mängd]]&Table14171920[[#This Row],[Gjuttemperatur]]&Table14171920[[#This Row],[Temperatur motgjutningsyta]]&Table14171920[[#This Row],[Väderskydd, uppvärmning (ingen vind)]]&Table14171920[[#This Row],[Täckning '[mm']]]&Table14171920[[#This Row],[OK<7 dagar]]&Table14171920[[#This Row],[Kommentar]] -> 0,11515--OK7
A12: 0.1 | B12: =Förutsättningar!M$20 -> 15 | C12: =Förutsättningar!N$20 -> 10 | D12: - | E12: - | F12: 10 | G12: 0 | H12: 6.7 | I12: OK7 | K12: =Table14171920[[#This Row],[Slagg mängd]]&Table14171920[[#This Row],[Gjuttemperatur]]&Table14171920[[#This Row],[Temperatur motgjutningsyta]]&Table14171920[[#This Row],[Väderskydd, uppvärmning (ingen vind)]]&Table14171920[[#This Row],[Täckning '[mm']]]&Table14171920[[#This Row],[OK<7 dagar]]&Table14171920[[#This Row],[Kommentar]] -> 0,11510--OK7
A13: Bas+0% | B13: =Förutsättningar!M$20 -> 15 | C13: =Förutsättningar!N$20 -> 10 | D13: - | E13: - | F13: 10 | G13: 2 | H13: 5.8 | I13: OK7 | K13: =Table14171920[[#This Row],[Slagg mängd]]&Table14171920[[#This Row],[Gjuttemperatur]]&Table14171920[[#This Row],[Temperatur motgjutningsyta]]&Table14171920[[#This Row],[Väderskydd, uppvärmning (ingen vind)]]&Table14171920[[#This Row],[Täckning '[mm']]]&Table14171920[[#This Row],[OK<7 dagar]]&Table14171920[[#This Row],[Kommentar]] -> Bas+0%1510--OK7
A14: Bas+0% | B14: =Förutsättningar!M$20 -> 15 | C14: =Förutsättningar!N$20 -> 10 | D14: - | E14: - | F14: 10 | G14: 7 | H14: 6.3 | I14: OK7 | K14: =Table14171920[[#This Row],[Slagg mängd]]&Table14171920[[#This Row],[Gjuttemperatur]]&Table14171920[[#This Row],[Temperatur motgjutningsyta]]&Table14171920[[#This Row],[Väderskydd, uppvärmning (ingen vind)]]&Table14171920[[#This Row],[Täckning '[mm']]]&Table14171920[[#This Row],[OK<7 dagar]]&Table14171920[[#This Row],[Kommentar]] -> Bas+0%1510--OK7
A15: Bas+0% | B15: =Förutsättningar!M$20 -> 15 | C15: =Förutsättningar!N$20 -> 10 | D15: - | E15: - | F15: 10 | G15: 12 | H15: 6.4 | I15: OK7 | K15: =Table14171920[[#This Row],[Slagg mängd]]&Table14171920[[#This Row],[Gjuttemperatur]]&Table14171920[[#This Row],[Temperatur motgjutningsyta]]&Table14171920[[#This Row],[Väderskydd, uppvärmning (ingen vind)]]&Table14171920[[#This Row],[Täckning '[mm']]]&Table14171920[[#This Row],[OK<7 dagar]]&Table14171920[[#This Row],[Kommentar]] -> Bas+0%1510--OK7
A16: Bas+0% | B16: =Förutsättningar!M$20 -> 15 | C16: =Förutsättningar!N$20 -> 10 | D16: - | E16: - | F16: 10 | G16: 20 | H16: 6.4 | I16: OK7 | K16: =Table14171920[[#This Row],[Slagg mängd]]&Table14171920[[#This Row],[Gjuttemperatur]]&Table14171920[[#This Row],[Temperatur motgjutningsyta]]&Table14171920[[#This Row],[Väderskydd, uppvärmning (ingen vind)]]&Table14171920[[#This Row],[Täckning '[mm']]]&Table14171920[[#This Row],[OK<7 dagar]]&Table14171920[[#This Row],[Kommentar]] -> Bas+0%1510--OK7
A17: 0.4 | B17: =Förutsättningar!M$21 -> 20 | C17: =Förutsättningar!N$21 -> 5 | D17: 20 | E17: 10 | F17: 5 | G17: 0 | H17: 6.7 | I17: OK7 | K17: =Table14171920[[#This Row],[Slagg mängd]]&Table14171920[[#This Row],[Gjuttemperatur]]&Table14171920[[#This Row],[Temperatur motgjutningsyta]]&Table14171920[[#This Row],[Väderskydd, uppvärmning (ingen vind)]]&Table14171920[[#This Row],[Täckning '[mm']]]&Table14171920[[#This Row],[OK<7 dagar]]&Table14171920[[#This Row],[Kommentar]] -> 0,42052010OK7
A18: 0.4 | B18: =Förutsättningar!M$21 -> 20 | C18: =Förutsättningar!N$21 -> 5 | D18: 20 | E18: 20 | F18: 5 | G18: 2 | H18: 6.2 | I18: OK7 | K18: =Table14171920[[#This Row],[Slagg mängd]]&Table14171920[[#This Row],[Gjuttemperatur]]&Table14171920[[#This Row],[Temperatur motgjutningsyta]]&Table14171920[[#This Row],[Väderskydd, uppvärmning (ingen vind)]]&Table14171920[[#This Row],[Täckning '[mm']]]&Table14171920[[#This Row],[OK<7 dagar]]&Table14171920[[#This Row],[Kommentar]] -> 0,42052020OK7
A19: 0.4 | B19: =Förutsättningar!M$21 -> 20 | C19: =Förutsättningar!N$21 -> 5 | D19: 20 | E19: 20 | F19: 5 | G19: 7 | H19: 6.4 | I19: OK7 | K19: =Table14171920[[#This Row],[Slagg mängd]]&Table14171920[[#This Row],[Gjuttemperatur]]&Table14171920[[#This Row],[Temperatur motgjutningsyta]]&Table14171920[[#This Row],[Väderskydd, uppvärmning (ingen vind)]]&Table14171920[[#This Row],[Täckning '[mm']]]&Table14171920[[#This Row],[OK<7 dagar]]&Table14171920[[#This Row],[Kommentar]] -> 0,42052020OK7
A20: 0.4 | B20: =Förutsättningar!M$21 -> 20 | C20: =Förutsättningar!N$21 -> 5 | D20: 20 | E20: 20 | F20: 5 | G20: 12 | H20: 6.5 | I20: OK7 | K20: =Table14171920[[#This Row],[Slagg mängd]]&Table14171920[[#This Row],[Gjuttemperatur]]&Table14171920[[#This Row],[Temperatur motgjutningsyta]]&Table14171920[[#This Row],[Väderskydd, uppvärmning (ingen vind)]]&Table14171920[[#This Row],[Täckning '[mm']]]&Table14171920[[#This Row],[OK<7 dagar]]&Table14171920[[#This Row],[Kommentar]] -> 0,42052020OK7
A21: 0.4 | B21: =Förutsättningar!M$21 -> 20 | C21: =Förutsättningar!N$21 -> 5 | D21: 20 | E21: 20 | F21: 5 | G21: 20 | H21: 6.5 | I21: OK7 | K21: =Table14171920[[#This Row],[Slagg mängd]]&Table14171920[[#This Row],[Gjuttemperatur]]&Table14171920[[#This Row],[Temperatur motgjutningsyta]]&Table14171920[[#This Row],[Väderskydd, uppvärmning (ingen vind)]]&Table14171920[[#This Row],[Täckning '[mm']]]&Table14171920[[#This Row],[OK<7 dagar]]&Table14171920[[#This Row],[Kommentar]] -> 0,42052020OK7
A22: 0.4 | B22: =Förutsättningar!M$22 -> 20 | C22: =Förutsättningar!N$22 -> 5 | D22: 20 | E22: 20 | F22: 0 | G22: 0 | H22: 7 | I22: OK7 | K22: =Table14171920[[#This Row],[Slagg mängd]]&Table14171920[[#This Row],[Gjuttemperatur]]&Table14171920[[#This Row],[Temperatur motgjutningsyta]]&Table14171920[[#This Row],[Väderskydd, uppvärmning (ingen vind)]]&Table14171920[[#This Row],[Täckning '[mm']]]&Table14171920[[#This Row],[OK<7 dagar]]&Table14171920[[#This Row],[Kommentar]] -> 0,42052020OK7
A23: 0.4 | B23: =Förutsättningar!M$22 -> 20 | C23: =Förutsättningar!N$22 -> 5 | D23: 20 | E23: 50 | F23: 0 | G23: 2 | H23: 6.3 | I23: OK7 | K23: =Table14171920[[#This Row],[Slagg mängd]]&Table14171920[[#This Row],[Gjuttemperatur]]&Table14171920[[#This Row],[Temperatur motgjutningsyta]]&Table14171920[[#This Row],[Väderskydd, uppvärmning (ingen vind)]]&Table14171920[[#This Row],[Täckning '[mm']]]&Table14171920[[#This Row],[OK<7 dagar]]&Table14171920[[#This Row],[Kommentar]] -> 0,42052050OK7
A24: 0.4 | B24: =Förutsättningar!M$22 -> 20 | C24: =Förutsättningar!N$22 -> 5 | D24: 20 | E24: 50 | F24: 0 | G24: 7 | H24: 6.5 | I24: OK7 | K24: =Table14171920[[#This Row],[Slagg mängd]]&Table14171920[[#This Row],[Gjuttemperatur]]&Table14171920[[#This Row],[Temperatur motgjutningsyta]]&Table14171920[[#This Row],[Väderskydd, uppvärmning (ingen vind)]]&Table14171920[[#This Row],[Täckning '[mm']]]&Table14171920[[#This Row],[OK<7 dagar]]&Table14171920[[#This Row],[Kommentar]] -> 0,42052050OK7
A25: 0.4 | B25: =Förutsättningar!M$22 -> 20 | C25: =Förutsättningar!N$22 -> 5 | D25: 20 | E25: 50 | F25: 0 | G25: 12 | H25: 6.5 | I25: OK7 | K25: =Table14171920[[#This Row],[Slagg mängd]]&Table14171920[[#This Row],[Gjuttemperatur]]&Table14171920[[#This Row],[Temperatur motgjutningsyta]]&Table14171920[[#This Row],[Väderskydd, uppvärmning (ingen vind)]]&Table14171920[[#This Row],[Täckning '[mm']]]&Table14171920[[#This Row],[OK<7 dagar]]&Table14171920[[#This Row],[Kommentar]] -> 0,42052050OK7
A26: 0.4 | B26: =Förutsättningar!M$22 -> 20 | C26: =Förutsättningar!N$22 -> 5 | D26: 20 | E26: 50 | F26: 0 | G26: 20 | H26: 6.6 | I26: OK7 | K26: =Table14171920[[#This Row],[Slagg mängd]]&Table14171920[[#This Row],[Gjuttemperatur]]&Table14171920[[#This Row],[Temperatur motgjutningsyta]]&Table14171920[[#This Row],[Väderskydd, uppvärmning (ingen vind)]]&Table14171920[[#This Row],[Täckning '[mm']]]&Table14171920[[#This Row],[OK<7 dagar]]&Table14171920[[#This Row],[Kommentar]] -> 0,42052050OK7
A27: 0.3 | B27: =Förutsättningar!M$23 -> 20 | C27: =Förutsättningar!N$23 -> 5 | D27: 20 | E27: 50 | F27: -5 | G27: 0 | H27: 6.8 | I27: OK7 | K27: =Table14171920[[#This Row],[Slagg mängd]]&Table14171920[[#This Row],[Gjuttemperatur]]&Table14171920[[#This Row],[Temperatur motgjutningsyta]]&Table14171920[[#This Row],[Väderskydd, uppvärmning (ingen vind)]]&Table14171920[[#This Row],[Täckning '[mm']]]&Table14171920[[#This Row],[OK<7 dagar]]&Table14171920[[#This Row],[Kommentar]] -> 0,32052050OK7
A28: 0.3 | B28: =Förutsättningar!M$23 -> 20 | C28: =Förutsättningar!N$23 -> 5 | D28: 20 | E28: 50 | F28: -5 | G28: 2 | H28: 7 | I28: OK7 | K28: =Table14171920[[#This Row],[Slagg mängd]]&Table14171920[[#This Row],[Gjuttemperatur]]&Table14171920[[#This Row],[Temperatur motgjutningsyta]]&Table14171920[[#This Row],[Väderskydd, uppvärmning (ingen vind)]]&Table14171920[[#This Row],[Täckning '[mm']]]&Table14171920[[#This Row],[OK<7 dagar]]&Table14171920[[#This Row],[Kommentar]] -> 0,32052050OK7
A29: 0.2 | B29: =Förutsättningar!M$23 -> 20 | C29: =Förutsättningar!N$23 -> 5 | D29: 20 | E29: 50 | F29: -5 | G29: 7 | H29: 5.8 | I29: OK7 | K29: =Table14171920[[#This Row],[Slagg mängd]]&Table14171920[[#This Row],[Gjuttemperatur]]&Table14171920[[#This Row],[Temperatur motgjutningsyta]]&Table14171920[[#This Row],[Väderskydd, uppvärmning (ingen vind)]]&Table14171920[[#This Row],[Täckning '[mm']]]&Table14171920[[#This Row],[OK<7 dagar]]&Table14171920[[#This Row],[Kommentar]] -> 0,22052050OK7
A30: 0.2 | B30: =Förutsättningar!M$23 -> 20 | C30: =Förutsättningar!N$23 -> 5 | D30: 20 | E30: 50 | F30: -5 | G30: 12 | H30: 6 | I30: OK7 | K30: =Table14171920[[#This Row],[Slagg mängd]]&Table14171920[[#This Row],[Gjuttemperatur]]&Table14171920[[#This Row],[Temperatur motgjutningsyta]]&Table14171920[[#This Row],[Väderskydd, uppvärmning (ingen vind)]]&Table14171920[[#This Row],[Täckning '[mm']]]&Table14171920[[#This Row],[OK<7 dagar]]&Table14171920[[#This Row],[Kommentar]] -> 0,22052050OK7
A31: 0.2 | B31: =Förutsättningar!M$23 -> 20 | C31: =Förutsättningar!N$23 -> 5 | D31: 20 | E31: 50 | F31: -5 | G31: 20 | H31: 6.1 | I31: OK7 | K31: =Table14171920[[#This Row],[Slagg mängd]]&Table14171920[[#This Row],[Gjuttemperatur]]&Table14171920[[#This Row],[Temperatur motgjutningsyta]]&Table14171920[[#This Row],[Väderskydd, uppvärmning (ingen vind)]]&Table14171920[[#This Row],[Täckning '[mm']]]&Table14171920[[#This Row],[OK<7 dagar]]&Table14171920[[#This Row],[Kommentar]] -> 0,22052050OK7
A32: 0.1 | B32: =Förutsättningar!M$24 -> 20 | C32: =Förutsättningar!N$24 -> 5 | D32: 20 | E32: 30 | F32: -10 | G32: 0 | H32: 6.4 | I32: OK7 | K32: =Table14171920[[#This Row],[Slagg mängd]]&Table14171920[[#This Row],[Gjuttemperatur]]&Table14171920[[#This Row],[Temperatur motgjutningsyta]]&Table14171920[[#This Row],[Väderskydd, uppvärmning (ingen vind)]]&Table14171920[[#This Row],[Täckning '[mm']]]&Table14171920[[#This Row],[OK<7 dagar]]&Table14171920[[#This Row],[Kommentar]] -> 0,12052030OK7
A33: 0.1 | B33: =Förutsättningar!M$24 -> 20 | C33: =Förutsättningar!N$24 -> 5 | D33: 20 | E33: 30 | F33: -10 | G33: 2 | H33: 7 | I33: OK7 | K33: =Table14171920[[#This Row],[Slagg mängd]]&Table14171920[[#This Row],[Gjuttemperatur]]&Table14171920[[#This Row],[Temperatur motgjutningsyta]]&Table14171920[[#This Row],[Väderskydd, uppvärmning (ingen vind)]]&Table14171920[[#This Row],[Täckning '[mm']]]&Table14171920[[#This Row],[OK<7 dagar]]&Table14171920[[#This Row],[Kommentar]] -> 0,12052030OK7
A34: 0.1 | B34: =Förutsättningar!M$24 -> 20 | C34: =Förutsättningar!N$24 -> 5 | D34: 20 | E34: 50 | F34: -10 | G34: 7 | H34: 5.7 | I34: OK7 | K34: =Table14171920[[#This Row],[Slagg mängd]]&Table14171920[[#This Row],[Gjuttemperatur]]&Table14171920[[#This Row],[Temperatur motgjutningsyta]]&Table14171920[[#This Row],[Väderskydd, uppvärmning (ingen vind)]]&Table14171920[[#This Row],[Täckning '[mm']]]&Table14171920[[#This Row],[OK<7 dagar]]&Table14171920[[#This Row],[Kommentar]] -> 0,12052050OK7
A35: - | B35: - | C35: - | D35: - | E35: - | F35: -10 | G35: 12 | J35: Frys innan täck | K35: =Table14171920[[#This Row],[Slagg mängd]]&Table14171920[[#This Row],[Gjuttemperatur]]&Table14171920[[#This Row],[Temperatur motgjutningsyta]]&Table14171920[[#This Row],[Väderskydd, uppvärmning (ingen vind)]]&Table14171920[[#This Row],[Täckning '[mm']]]&Table14171920[[#This Row],[OK<7 dagar]]&Table14171920[[#This Row],[Kommentar]] -> -----Frys innan täck
A36: - | B36: - | C36: - | D36: - | E36: - | F36: -10 | G36: 20 | J36: Frys innan täck | K36: =Table14171920[[#This Row],[Slagg mängd]]&Table14171920[[#This Row],[Gjuttemperatur]]&Table14171920[[#This Row],[Temperatur motgjutningsyta]]&Table14171920[[#This Row],[Väderskydd, uppvärmning (ingen vind)]]&Table14171920[[#This Row],[Täckning '[mm']]]&Table14171920[[#This Row],[OK<7 dagar]]&Table14171920[[#This Row],[Kommentar]] -> -----Frys innan täck
A37: Bas+0% | B37: =Förutsättningar!M$25 -> 15 | C37: =Förutsättningar!N$25 -> 5 | D37: 20 | E37: 50 | F37: -15 | G37: 0 | H37: 5.2 | I37: OK7 | K37: =Table14171920[[#This Row],[Slagg mängd]]&Table14171920[[#This Row],[Gjuttemperatur]]&Table14171920[[#This Row],[Temperatur motgjutningsyta]]&Table14171920[[#This Row],[Väderskydd, uppvärmning (ingen vind)]]&Table14171920[[#This Row],[Täckning '[mm']]]&Table14171920[[#This Row],[OK<7 dagar]]&Table14171920[[#This Row],[Kommentar]] -> Bas+0%1552050OK7
A38: Bas+0% | B38: =Förutsättningar!M$25 -> 15 | C38: =Förutsättningar!N$25 -> 5 | D38: 20 | E38: 50 | F38: -15 | G38: 2 | H38: 5.5 | I38: OK7 | K38: =Table14171920[[#This Row],[Slagg mängd]]&Table14171920[[#This Row],[Gjuttemperatur]]&Table14171920[[#This Row],[Temperatur motgjutningsyta]]&Table14171920[[#This Row],[Väderskydd, uppvärmning (ingen vind)]]&Table14171920[[#This Row],[Täckning '[mm']]]&Table14171920[[#This Row],[OK<7 dagar]]&Table14171920[[#This Row],[Kommentar]] -> Bas+0%1552050OK7
A39: - | B39: - | C39: - | D39: - | E39: - | F39: -15 | G39: 7 | J39: Frys innan täck | K39: =Table14171920[[#This Row],[Slagg mängd]]&Table14171920[[#This Row],[Gjuttemperatur]]&Table14171920[[#This Row],[Temperatur motgjutningsyta]]&Table14171920[[#This Row],[Väderskydd, uppvärmning (ingen vind)]]&Table14171920[[#This Row],[Täckning '[mm']]]&Table14171920[[#This Row],[OK<7 dagar]]&Table14171920[[#This Row],[Kommentar]] -> -----Frys innan täck
