Workbook

Sheet Bjälklag (Bas+0% slagg)
A1: Kvalitet | B1: Gjuttemperatur | C1: Temperatur motgjutningsyta | D1: Värmekabel | E1: Antal värmekablar | F1: Täckning [mm] | G1: Formisolering [mm] | H1: Temperatur | I1: Vind | J1: <17 Timmar och >6 Mpa | K1: OK<17 Timamr | L1: Kommentar | M1: Åtgärdskåd
A2: C25/30 | B2: 15 | C2: 20 | D2: - | E2: - | F2: - | G2: Plywood 15, oisolerat | H2: 20 | I2: 0 | J2: 15.3 | M2: =Table155[[#This Row],[Kvalitet]]&Table155[[#This Row],[Gjuttemperatur]]&Table155[[#This Row],[Temperatur motgjutningsyta]]&Table155[[#This Row],[Värmekabel]]&Table155[[#This Row],[Täckning '[mm']]]&Table155[[#This Row],[OK<17 Timamr]]&Table155[[#This Row],[Kommentar]] -> C25/301520--
A3: C25/30 | B3: 15 | C3: 20 | D3: - | E3: - | F3: - | G3: Plywood 15, oisolerat | H3: 20 | I3: 2 | J3: 15.3 | M3: =Table155[[#This Row],[Kvalitet]]&Table155[[#This Row],[Gjuttemperatur]]&Table155[[#This Row],[Temperatur motgjutningsyta]]&Table155[[#This Row],[Värmekabel]]&Table155[[#This Row],[Täckning '[mm']]]&Table155[[#This Row],[OK<17 Timamr]]&Table155[[#This Row],[Kommentar]] -> C25/301520--
A4: C25/30 | B4: 15 | C4: 20 | D4: - | E4: - | F4: - | G4: Plywood 15, oisolerat | H4: 20 | I4: 7 | J4: 15.3 | M4: =Table155[[#This Row],[Kvalitet]]&Table155[[#This Row],[Gjuttemperatur]]&Table155[[#This Row],[Temperatur motgjutningsyta]]&Table155[[#This Row],[Värmekabel]]&Table155[[#This Row],[Täckning '[mm']]]&Table155[[#This Row],[OK<17 Timamr]]&Table155[[#This Row],[Kommentar]] -> C25/301520--
A5: C25/30 | B5: 15 | C5: 20 | D5: - | E5: - | F5: - | G5: Plywood 15, oisolerat | H5: 20 | I5: 12 | J5: 15.3 | M5: =Table155[[#This Row],[Kvalitet]]&Table155[[#This Row],[Gjuttemperatur]]&Table155[[#This Row],[Temperatur motgjutningsyta]]&Table155[[#This Row],[Värmekabel]]&Table155[[#This Row],[Täckning '[mm']]]&Table155[[#This Row],[OK<17 Timamr]]&Table155[[#This Row],[Kommentar]] -> C25/301520--
A6: C25/30 | B6: 15 | C6: 20 | D6: - | E6: - | F6: - | G6: Plywood 15, oisolerat | H6: 20 | I6: 20 | J6: 15.3 | M6: =Table155[[#This Row],[Kvalitet]]&Table155[[#This Row],[Gjuttemperatur]]&Table155[[#This Row],[Temperatur motgjutningsyta]]&Table155[[#This Row],[Värmekabel]]&Table155[[#This Row],[Täckning '[mm']]]&Table155[[#This Row],[OK<17 Timamr]]&Table155[[#This Row],[Kommentar]] -> C25/301520--
A7: C28/35 | B7: 15 | C7: 15 | D7: - | E7: - | F7: - | G7: Plywood 15, oisolerat | H7: 15 | I7: 0 | J7: 15.7 | M7: =Table155[[#This Row],[Kvalitet]]&Table155[[#This Row],[Gjuttemperatur]]&Table155[[#This Row],[Temperatur motgjutningsyta]]&Table155[[#This Row],[Värmekabel]]&Table155[[#This Row],[Täckning '[mm']]]&Table155[[#This Row],[OK<17 Timamr]]&Table155[[#This Row],[Kommentar]] -> C28/351515--
A8: C28/35 | B8: 15 | C8: 15 | D8: - | E8: - | F8: - | G8: Plywood 15, oisolerat | H8: 15 | I8: 2 | J8: 15.9 | M8: =Table155[[#This Row],[Kvalitet]]&Table155[[#This Row],[Gjuttemperatur]]&Table155[[#This Row],[Temperatur motgjutningsyta]]&Table155[[#This Row],[Värmekabel]]&Table155[[#This Row],[Täckning '[mm']]]&Table155[[#This Row],[OK<17 Timamr]]&Table155[[#This Row],[Kommentar]] -> C28/351515--
A9: C28/35 | B9: 15 | C9: 15 | D9: - | E9: - | F9: - | G9: Plywood 15, oisolerat | H9: 15 | I9: 7 | J9: 16 | M9: =Table155[[#This Row],[Kvalitet]]&Table155[[#This Row],[Gjuttemperatur]]&Table155[[#This Row],[Temperatur motgjutningsyta]]&Table155[[#This Row],[Värmekabel]]&Table155[[#This Row],[Täckning '[mm']]]&Table155[[#This Row],[OK<17 Timamr]]&Table155[[#This Row],[Kommentar]] -> C28/351515--
A10: C28/35 | B10: 15 | C10: 15 | D10: - | E10: - | F10: - | G10: Plywood 15, oisolerat | H10: 15 | I10: 12 | J10: 16.1 | M10: =Table155[[#This Row],[Kvalitet]]&Table155[[#This Row],[Gjuttemperatur]]&Table155[[#This Row],[Temperatur motgjutningsyta]]&Table155[[#This Row],[Värmekabel]]&Table155[[#This Row],[Täckning '[mm']]]&Table155[[#This Row],[OK<17 Timamr]]&Table155[[#This Row],[Kommentar]] -> C28/351515--
A11: C28/35 | B11: 15 | C11: 15 | D11: - | E11: - | F11: - | G11: Plywood 15, oisolerat | H11: 15 | I11: 20 | J11: 16.1 | M11: =Table155[[#This Row],[Kvalitet]]&Table155[[#This Row],[Gjuttemperatur]]&Table155[[#This Row],[Temperatur motgjutningsyta]]&Table155[[#This Row],[Värmekabel]]&Table155[[#This Row],[Täckning '[mm']]]&Table155[[#This Row],[OK<17 Timamr]]&Table155[[#This Row],[Kommentar]] -> C28/351515--
A12: C32/40 | B12: 15 | C12: 10 | D12: - | E12: - | F12: - | G12: Plywood 15, oisolerat | H12: 10 | I12: 0 | J12: 16.7 | M12: =Table155[[#This Row],[Kvalitet]]&Table155[[#This Row],[Gjuttemperatur]]&Table155[[#This Row],[Temperatur motgjutningsyta]]&Table155[[#This Row],[Värmekabel]]&Table155[[#This Row],[Täckning '[mm']]]&Table155[[#This Row],[OK<17 Timamr]]&Table155[[#This Row],[Kommentar]] -> C32/401510--
A13: C35/45 | B13: 15 | C13: 10 | D13: - | E13: - | F13: - | G13: Plywood 15, oisolerat | H13: 10 | I13: 2 | J13: 16.1 | M13: =Table155[[#This Row],[Kvalitet]]&Table155[[#This Row],[Gjuttemperatur]]&Table155[[#This Row],[Temperatur motgjutningsyta]]&Table155[[#This Row],[Värmekabel]]&Table155[[#This Row],[Täckning '[mm']]]&Table155[[#This Row],[OK<17 Timamr]]&Table155[[#This Row],[Kommentar]] -> C35/451510--
... A16: C35/45 | B16: 15 | C16: 10 | D16: - | E16: - | F16: Presenning | G16: Plywood 15, oisolerat | H16: 10 | I16: 20 | J16: 16.5 | M16: =Table155[[#This Row],[Kvalitet]]&Table155[[#This Row],[Gjuttemperatur]]&Table155[[#This Row],[Temperatur motgjutningsyta]]&Table155[[#This Row],[Värmekabel]]&Table155[[#This Row],[Täckning '[mm']]]&Table155[[#This Row],[OK<17 Timamr]]&Table155[[#This Row],[Kommentar]] -> C35/451510-Presenning
A17: C20/25 | B17: 20 | C17: 5 | D17: 40 | E17: 2 | F17: - | G17: Plywood 12-19 cellplast 50 | H17: 5 | I17: 0 | J17: 17 | M17: =Table155[[#This Row],[Kvalitet]]&Table155[[#This Row],[Gjuttemperatur]]&Table155[[#This Row],[Temperatur motgjutningsyta]]&Table155[[#This Row],[Värmekabel]]&Table155[[#This Row],[Täckning '[mm']]]&Table155[[#This Row],[OK<17 Timamr]]&Table155[[#This Row],[Kommentar]] -> C20/2520540-
A18: C20/25 | B18: 20 | C18: 5 | D18: 40 | E18: 2 | F18: 10 | G18: Plywood 12-19 cellplast 120 | H18: 5 | I18: 2 | J18: 17 | M18: =Table155[[#This Row],[Kvalitet]]&Table155[[#This Row],[Gjuttemperatur]]&Table155[[#This Row],[Temperatur motgjutningsyta]]&Table155[[#This Row],[Värmekabel]]&Table155[[#This Row],[Täckning '[mm']]]&Table155[[#This Row],[OK<17 Timamr]]&Table155[[#This Row],[Kommentar]] -> C20/252054010
A19: C25/30 | B19: 20 | C19: 5 | D19: 40 | E19: 1 | F19: 10 | G19: Plywood 12-19 cellplast 50 | H19: 5 | I19: 7 | J19: 16.9 | M19: =Table155[[#This Row],[Kvalitet]]&Table155[[#This Row],[Gjuttemperatur]]&Table155[[#This Row],[Temperatur motgjutningsyta]]&Table155[[#This Row],[Värmekabel]]&Table155[[#This Row],[Täckning '[mm']]]&Table155[[#This Row],[OK<17 Timamr]]&Table155[[#This Row],[Kommentar]] -> C25/302054010
A20: C25/30 | B20: 20 | C20: 5 | D20: 40 | E20: 1 | F20: 10 | G20: Plywood 12-19 cellplast 70 | H20: 5 | I20: 12 | J20: 16.9 | M20: =Table155[[#This Row],[Kvalitet]]&Table155[[#This Row],[Gjuttemperatur]]&Table155[[#This Row],[Temperatur motgjutningsyta]]&Table155[[#This Row],[Värmekabel]]&Table155[[#This Row],[Täckning '[mm']]]&Table155[[#This Row],[OK<17 Timamr]]&Table155[[#This Row],[Kommentar]] -> C25/302054010
A21: C25/30 | B21: 20 | C21: 5 | D21: 40 | E21: 1 | F21: 10 | G21: Plywood 12-19 cellplast 100 | H21: 5 | I21: 20 | J21: 17 | M21: =Table155[[#This Row],[Kvalitet]]&Table155[[#This Row],[Gjuttemperatur]]&Table155[[#This Row],[Temperatur motgjutningsyta]]&Table155[[#This Row],[Värmekabel]]&Table155[[#This Row],[Täckning '[mm']]]&Table155[[#This Row],[OK<17 Timamr]]&Table155[[#This Row],[Kommentar]] -> C25/302054010
A22: C20/25 | B22: 20 | C22: 5 | D22: 40 | E22: 3 | F22: 10 | G22: Plywood 12-19 cellplast 70 | H22: 0 | I22: 0 | J22: 16.9 | M22: =Table155[[#This Row],[Kvalitet]]&Table155[[#This Row],[Gjuttemperatur]]&Table155[[#This Row],[Temperatur motgjutningsyta]]&Table155[[#This Row],[Värmekabel]]&Table155[[#This Row],[Täckning '[mm']]]&Table155[[#This Row],[OK<17 Timamr]]&Table155[[#This Row],[Kommentar]] -> C20/252054010
A23: C25/30 | B23: 20 | C23: 5 | D23: 40 | E23: 1 | F23: 10 | G23: Plywood 12-19 cellplast 120 | H23: 0 | I23: 2 | J23: 17 | M23: =Table155[[#This Row],[Kvalitet]]&Table155[[#This Row],[Gjuttemperatur]]&Table155[[#This Row],[Temperatur motgjutningsyta]]&Table155[[#This Row],[Värmekabel]]&Table155[[#This Row],[Täckning '[mm']]]&Table155[[#This Row],[OK<17 Timamr]]&Table155[[#This Row],[Kommentar]] -> C25/302054010
A24: C25/30 | B24: 20 | C24: 5 | D24: 40 | E24: 2 | F24: 10 | G24: Plywood 12-19 cellplast 70 | H24: 0 | I24: 7 | J24: 16.8 | M24: =Table155[[#This Row],[Kvalitet]]&Table155[[#This Row],[Gjuttemperatur]]&Table155[[#This Row],[Temperatur motgjutningsyta]]&Table155[[#This Row],[Värmekabel]]&Table155[[#This Row],[Täckning '[mm']]]&Table155[[#This Row],[OK<17 Timamr]]&Table155[[#This Row],[Kommentar]] -> C25/302054010
A25: C25/30 | B25: 20 | C25: 5 | D25: 40 | E25: 2 | F25: 10 | G25: Plywood 12-19 cellplast 120 | H25: 0 | I25: 12 | J25: 17 | M25: =Table155[[#This Row],[Kvalitet]]&Table155[[#This Row],[Gjuttemperatur]]&Table155[[#This Row],[Temperatur motgjutningsyta]]&Table155[[#This Row],[Värmekabel]]&Table155[[#This Row],[Täckning '[mm']]]&Table155[[#This Row],[OK<17 Timamr]]&Table155[[#This Row],[Kommentar]] -> C25/302054010
A26: C25/30 | B26: 20 | C26: 5 | D26: 40 | E26: 3 | F26: 10 | G26: Plywood 12-19 cellplast 100 | H26: 0 | I26: 20 | J26: 17 | M26: =Table155[[#This Row],[Kvalitet]]&Table155[[#This Row],[Gjuttemperatur]]&Table155[[#This Row],[Temperatur motgjutningsyta]]&Table155[[#This Row],[Värmekabel]]&Table155[[#This Row],[Täckning '[mm']]]&Table155[[#This Row],[OK<17 Timamr]]&Table155[[#This Row],[Kommentar]] -> C25/302054010
A27: C25/30 | B27: 20 | C27: 5 | D27: 40 | E27: 1 | F27: 10 | G27: Plywood 12-19 cellplast 100 | H27: -5 | I27: 0 | J27: 17 | M27: =Table155[[#This Row],[Kvalitet]]&Table155[[#This Row],[Gjuttemperatur]]&Table155[[#This Row],[Temperatur motgjutningsyta]]&Table155[[#This Row],[Värmekabel]]&Table155[[#This Row],[Täckning '[mm']]]&Table155[[#This Row],[OK<17 Timamr]]&Table155[[#This Row],[Kommentar]] -> C25/302054010
A28: C25/30 | B28: 20 | C28: 5 | D28: 40 | E28: 2 | F28: 10 | G28: Plywood 12-19 cellplast 70 | H28: -5 | I28: 2 | J28: 16.8 | M28: =Table155[[#This Row],[Kvalitet]]&Table155[[#This Row],[Gjuttemperatur]]&Table155[[#This Row],[Temperatur motgjutningsyta]]&Table155[[#This Row],[Värmekabel]]&Table155[[#This Row],[Täckning '[mm']]]&Table155[[#This Row],[OK<17 Timamr]]&Table155[[#This Row],[Kommentar]] -> C25/302054010
A29: C28/35 | B29: 20 | C29: 5 | D29: 40 | E29: 1 | F29: 10 | G29: Plywood 12-19 cellplast 100 | H29: -5 | I29: 7 | J29: 16.7 | M29: =Table155[[#This Row],[Kvalitet]]&Table155[[#This Row],[Gjuttemperatur]]&Table155[[#This Row],[Temperatur motgjutningsyta]]&Table155[[#This Row],[Värmekabel]]&Table155[[#This Row],[Täckning '[mm']]]&Table155[[#This Row],[OK<17 Timamr]]&Table155[[#This Row],[Kommentar]] -> C28/352054010
A30: C28/35 | B30: 20 | C30: 5 | D30: 40 | E30: 2 | F30: 10 | G30: Plywood 12-19 cellplast 50 | H30: -5 | I30: 12 | J30: 16.8 | M30: =Table155[[#This Row],[Kvalitet]]&Table155[[#This Row],[Gjuttemperatur]]&Table155[[#This Row],[Temperatur motgjutningsyta]]&Table155[[#This Row],[Värmekabel]]&Table155[[#This Row],[Täckning '[mm']]]&Table155[[#This Row],[OK<17 Timamr]]&Table155[[#This Row],[Kommentar]] -> C28/352054010
A31: - | B31: - | C31: - | D31: - | E31: - | F31: - | G31: - | H31: -5 | I31: 20 | L31: Fryser innan täck | M31: =Table155[[#This Row],[Kvalitet]]&Table155[[#This Row],[Gjuttemperatur]]&Table155[[#This Row],[Temperatur motgjutningsyta]]&Table155[[#This Row],[Värmekabel]]&Table155[[#This Row],[Täckning '[mm']]]&Table155[[#This Row],[OK<17 Timamr]]&Table155[[#This Row],[Kommentar]] -> -----Fryser innan täck
A32: C25/30 | B32: 20 | C32: 5 | D32: 40 | E32: 2 | F32: 10 | G32: Plywood 12-19 cellplast 50 | H32: -10 | I32: 0 | J32: 16.7 | M32: =Table155[[#This Row],[Kvalitet]]&Table155[[#This Row],[Gjuttemperatur]]&Table155[[#This Row],[Temperatur motgjutningsyta]]&Table155[[#This Row],[Värmekabel]]&Table155[[#This Row],[Täckning '[mm']]]&Table155[[#This Row],[OK<17 Timamr]]&Table155[[#This Row],[Kommentar]] -> C25/302054010
A33: C25/30 | B33: 20 | C33: 5 | D33: 40 | E33: 3 | F33: 10 | G33: Plywood 12-19 cellplast 120 | H33: -10 | I33: 2 | J33: 16.9 | M33: =Table155[[#This Row],[Kvalitet]]&Table155[[#This Row],[Gjuttemperatur]]&Table155[[#This Row],[Temperatur motgjutningsyta]]&Table155[[#This Row],[Värmekabel]]&Table155[[#This Row],[Täckning '[mm']]]&Table155[[#This Row],[OK<17 Timamr]]&Table155[[#This Row],[Kommentar]] -> C25/302054010
A34: C28/35 | B34: 20 | C34: 5 | D34: 40 | E34: 2 | F34: 10 | G34: Plywood 12-19 cellplast 70 | H34: -10 | I34: 7 | J34: 17 | M34: =Table155[[#This Row],[Kvalitet]]&Table155[[#This Row],[Gjuttemperatur]]&Table155[[#This Row],[Temperatur motgjutningsyta]]&Table155[[#This Row],[Värmekabel]]&Table155[[#This Row],[Täckning '[mm']]]&Table155[[#This Row],[OK<17 Timamr]]&Table155[[#This Row],[Kommentar]] -> C28/352054010
A35: - | B35: - | C35: - | D35: - | E35: - | F35: - | G35: - | H35: -10 | I35: 12 | L35: Fryser innan täck | M35: =Table155[[#This Row],[Kvalitet]]&Table155[[#This Row],[Gjuttemperatur]]&Table155[[#This Row],[Temperatur motgjutningsyta]]&Table155[[#This Row],[Värmekabel]]&Table155[[#This Row],[Täckning '[mm']]]&Table155[[#This Row],[OK<17 Timamr]]&Table155[[#This Row],[Kommentar]] -> -----Fryser innan täck
A36: - | B36: - | C36: - | D36: - | E36: - | F36: - | G36: - | H36: -10 | I36: 20 | L36: Fryser innan täck | M36: =Table155[[#This Row],[Kvalitet]]&Table155[[#This Row],[Gjuttemperatur]]&Table155[[#This Row],[Temperatur motgjutningsyta]]&Table155[[#This Row],[Värmekabel]]&Table155[[#This Row],[Täckning '[mm']]]&Table155[[#This Row],[OK<17 Timamr]]&Table155[[#This Row],[Kommentar]] -> -----Fryser innan täck
A37: C28/35 | B37: 15 | C37: 5 | D37: 40 | E37: 3 | F37: 50 | G37: Plywood 12-19 cellplast 70 | H37: -15 | I37: 0 | J37: 17 | M37: =Table155[[#This Row],[Kvalitet]]&Table155[[#This Row],[Gjuttemperatur]]&Table155[[#This Row],[Temperatur motgjutningsyta]]&Table155[[#This Row],[Värmekabel]]&Table155[[#This Row],[Täckning '[mm']]]&Table155[[#This Row],[OK<17 Timamr]]&Table155[[#This Row],[Kommentar]] -> C28/351554050
A38: C32/40 | B38: 15 | C38: 5 | D38: 40 | E38: 3 | F38: 20 | G38: Plywood 12-19 cellplast 120 | H38: -15 | I38: 2 | J38: 17 | M38: =Table155[[#This Row],[Kvalitet]]&Table155[[#This Row],[Gjuttemperatur]]&Table155[[#This Row],[Temperatur motgjutningsyta]]&Table155[[#This Row],[Värmekabel]]&Table155[[#This Row],[Täckning '[mm']]]&Table155[[#This Row],[OK<17 Timamr]]&Table155[[#This Row],[Kommentar]] -> C32/401554020
A39: - | B39: - | C39: - | D39: - | E39: - | F39: - | G39: - | H39: -15 | I39: 7 | L39: Fryser innan täck | M39: =Table155[[#This Row],[Kvalitet]]&Table155[[#This Row],[Gjuttemperatur]]&Table155[[#This Row],[Temperatur motgjutningsyta]]&Table155[[#This Row],[Värmekabel]]&Table155[[#This Row],[Täckning '[mm']]]&Table155[[#This Row],[OK<17 Timamr]]&Table155[[#This Row],[Kommentar]] -> -----Fryser innan täck
A40: - | B40: - | C40: - | D40: - | E40: - | F40: - | G40: - | H40: -15 | I40: 12 | L40: Fryser innan täck | M40: =Table155[[#This Row],[Kvalitet]]&Table155[[#This Row],[Gjuttemperatur]]&Table155[[#This Row],[Temperatur motgjutningsyta]]&Table155[[#This Row],[Värmekabel]]&Table155[[#This Row],[Täckning '[mm']]]&Table155[[#This Row],[OK<17 Timamr]]&Table155[[#This Row],[Kommentar]] -> -----Fryser innan täck
A41: - | B41: - | C41: - | D41: - | E41: - | F41: - | G41: - | H41: -15 | I41: 20 | L41: Fryser innan täck | M41: =Table155[[#This Row],[Kvalitet]]&Table155[[#This Row],[Gjuttemperatur]]&Table155[[#This Row],[Temperatur motgjutningsyta]]&Table155[[#This Row],[Värmekabel]]&Table155[[#This Row],[Täckning '[mm']]]&Table155[[#This Row],[OK<17 Timamr]]&Table155[[#This Row],[Kommentar]] -> -----Fryser innan täck
A42: - | B42: - | C42: - | D42: - | E42: - | F42: - | G42: - | H42: -20 | I42: 0 | L42: Når ej 6 MPa | M42: =Table155[[#This Row],[Kvalitet]]&Table155[[#This Row],[Gjuttemperatur]]&Table155[[#This Row],[Temperatur motgjutningsyta]]&Table155[[#This Row],[Värmekabel]]&Table155[[#This Row],[Täckning '[mm']]]&Table155[[#This Row],[OK<17 Timamr]]&Table155[[#This Row],[Kommentar]] -> -----Når ej 6 MPa
...

Sheet Bjälklag (10% slagg)
A1: Kvalitet | B1: Gjuttemperatur | C1: Temperatur motgjutningsyta | D1: Värmekabel | E1: Antal värmekablar | F1: Täckning [mm] | G1: Formisolering [mm] | H1: Temperatur | I1: Vind | J1: <17 Timmar och >6 Mpa | K1: OK<17 Timamr | L1: Kommentar | M1: Åtgärdskåd
A2: C28/35 | B2: 15 | C2: 20 | D2: - | E2: - | F2: - | G2: Plywood 15, oisolerat | H2: 20 | I2: 0 | J2: 15.3 | M2: =Table1[[#This Row],[Kvalitet]]&Table1[[#This Row],[Gjuttemperatur]]&Table1[[#This Row],[Temperatur motgjutningsyta]]&Table1[[#This Row],[Värmekabel]]&Table1[[#This Row],[Täckning '[mm']]]&Table1[[#This Row],[OK<17 Timamr]]&Table1[[#This Row],[Kommentar]] -> C28/351520--
A3: C28/35 | B3: 15 | C3: 20 | D3: - | E3: - | F3: - | G3: Plywood 15, oisolerat | H3: 20 | I3: 2 | J3: 15.3 | M3: =Table1[[#This Row],[Kvalitet]]&Table1[[#This Row],[Gjuttemperatur]]&Table1[[#This Row],[Temperatur motgjutningsyta]]&Table1[[#This Row],[Värmekabel]]&Table1[[#This Row],[Täckning '[mm']]]&Table1[[#This Row],[OK<17 Timamr]]&Table1[[#This Row],[Kommentar]] -> C28/351520--
A4: C28/35 | B4: 15 | C4: 20 | D4: - | E4: - | F4: - | G4: Plywood 15, oisolerat | H4: 20 | I4: 7 | J4: 15.3 | M4: =Table1[[#This Row],[Kvalitet]]&Table1[[#This Row],[Gjuttemperatur]]&Table1[[#This Row],[Temperatur motgjutningsyta]]&Table1[[#This Row],[Värmekabel]]&Table1[[#This Row],[Täckning '[mm']]]&Table1[[#This Row],[OK<17 Timamr]]&Table1[[#This Row],[Kommentar]] -> C28/351520--
A5: C28/35 | B5: 15 | C5: 20 | D5: - | E5: - | F5: - | G5: Plywood 15, oisolerat | H5: 20 | I5: 12 | J5: 15.3 | M5: =Table1[[#This Row],[Kvalitet]]&Table1[[#This Row],[Gjuttemperatur]]&Table1[[#This Row],[Temperatur motgjutningsyta]]&Table1[[#This Row],[Värmekabel]]&Table1[[#This Row],[Täckning '[mm']]]&Table1[[#This Row],[OK<17 Timamr]]&Table1[[#This Row],[Kommentar]] -> C28/351520--
A6: C28/35 | B6: 15 | C6: 20 | D6: - | E6: - | F6: - | G6: Plywood 15, oisolerat | H6: 20 | I6: 20 | J6: 15.3 | M6: =Table1[[#This Row],[Kvalitet]]&Table1[[#This Row],[Gjuttemperatur]]&Table1[[#This Row],[Temperatur motgjutningsyta]]&Table1[[#This Row],[Värmekabel]]&Table1[[#This Row],[Täckning '[mm']]]&Table1[[#This Row],[OK<17 Timamr]]&Table1[[#This Row],[Kommentar]] -> C28/351520--
A7: C30/37 | B7: 15 | C7: 15 | D7: - | E7: - | F7: - | G7: Plywood 15, oisolerat | H7: 15 | I7: 0 | J7: 16.4 | M7: =Table1[[#This Row],[Kvalitet]]&Table1[[#This Row],[Gjuttemperatur]]&Table1[[#This Row],[Temperatur motgjutningsyta]]&Table1[[#This Row],[Värmekabel]]&Table1[[#This Row],[Täckning '[mm']]]&Table1[[#This Row],[OK<17 Timamr]]&Table1[[#This Row],[Kommentar]] -> C30/371515--
A8: C30/37 | B8: 15 | C8: 15 | D8: - | E8: - | F8: - | G8: Plywood 15, oisolerat | H8: 15 | I8: 2 | J8: 16.6 | M8: =Table1[[#This Row],[Kvalitet]]&Table1[[#This Row],[Gjuttemperatur]]&Table1[[#This Row],[Temperatur motgjutningsyta]]&Table1[[#This Row],[Värmekabel]]&Table1[[#This Row],[Täckning '[mm']]]&Table1[[#This Row],[OK<17 Timamr]]&Table1[[#This Row],[Kommentar]] -> C30/371515--
A9: C30/37 | B9: 15 | C9: 15 | D9: - | E9: - | F9: - | G9: Plywood 15, oisolerat | H9: 15 | I9: 7 | J9: 16.8 | M9: =Table1[[#This Row],[Kvalitet]]&Table1[[#This Row],[Gjuttemperatur]]&Table1[[#This Row],[Temperatur motgjutningsyta]]&Table1[[#This Row],[Värmekabel]]&Table1[[#This Row],[Täckning '[mm']]]&Table1[[#This Row],[OK<17 Timamr]]&Table1[[#This Row],[Kommentar]] -> C30/371515--
A10: C30/37 | B10: 15 | C10: 15 | D10: - | E10: - | F10: Presenning | G10: Plywood 15, oisolerat | H10: 15 | I10: 12 | J10: 16.9 | M10: =Table1[[#This Row],[Kvalitet]]&Table1[[#This Row],[Gjuttemperatur]]&Table1[[#This Row],[Temperatur motgjutningsyta]]&Table1[[#This Row],[Värmekabel]]&Table1[[#This Row],[Täckning '[mm']]]&Table1[[#This Row],[OK<17 Timamr]]&Table1[[#This Row],[Kommentar]] -> C30/371515-Presenning
A11: C30/37 | B11: 15 | C11: 15 | D11: - | E11: - | F11: Presenning | G11: Plywood 15, oisolerat | H11: 15 | I11: 20 | J11: 17 | M11: =Table1[[#This Row],[Kvalitet]]&Table1[[#This Row],[Gjuttemperatur]]&Table1[[#This Row],[Temperatur motgjutningsyta]]&Table1[[#This Row],[Värmekabel]]&Table1[[#This Row],[Täckning '[mm']]]&Table1[[#This Row],[OK<17 Timamr]]&Table1[[#This Row],[Kommentar]] -> C30/371515-Presenning
A12: C35/45 | B12: 15 | C12: 10 | D12: - | E12: - | F12: - | G12: Plywood 15, oisolerat | H12: 10 | I12: 0 | J12: 16.7 | M12: =Table1[[#This Row],[Kvalitet]]&Table1[[#This Row],[Gjuttemperatur]]&Table1[[#This Row],[Temperatur motgjutningsyta]]&Table1[[#This Row],[Värmekabel]]&Table1[[#This Row],[Täckning '[mm']]]&Table1[[#This Row],[OK<17 Timamr]]&Table1[[#This Row],[Kommentar]] -> C35/451510--
A13: C40/50 | B13: 15 | C13: 10 | D13: - | E13: - | F13: - | G13: Plywood 15, oisolerat | H13: 10 | I13: 2 | J13: 16.2 | M13: =Table1[[#This Row],[Kvalitet]]&Table1[[#This Row],[Gjuttemperatur]]&Table1[[#This Row],[Temperatur motgjutningsyta]]&Table1[[#This Row],[Värmekabel]]&Table1[[#This Row],[Täckning '[mm']]]&Table1[[#This Row],[OK<17 Timamr]]&Table1[[#This Row],[Kommentar]] -> C40/501510--
... A16: C40/50 | B16: 15 | C16: 10 | D16: - | E16: - | F16: Presenning | G16: Plywood 15, oisolerat | H16: 10 | I16: 20 | J16: 16.7 | M16: =Table1[[#This Row],[Kvalitet]]&Table1[[#This Row],[Gjuttemperatur]]&Table1[[#This Row],[Temperatur motgjutningsyta]]&Table1[[#This Row],[Värmekabel]]&Table1[[#This Row],[Täckning '[mm']]]&Table1[[#This Row],[OK<17 Timamr]]&Table1[[#This Row],[Kommentar]] -> C40/501510-Presenning
A17: C25/30 | B17: 20 | C17: 5 | D17: 40 | E17: 3 | F17: 10 | G17: Plywood 12-19 cellplast 50 | H17: 5 | I17: 0 | J17: 17 | M17: =Table1[[#This Row],[Kvalitet]]&Table1[[#This Row],[Gjuttemperatur]]&Table1[[#This Row],[Temperatur motgjutningsyta]]&Table1[[#This Row],[Värmekabel]]&Table1[[#This Row],[Täckning '[mm']]]&Table1[[#This Row],[OK<17 Timamr]]&Table1[[#This Row],[Kommentar]] -> C25/302054010
A18: C20/25 | B18: 20 | C18: 5 | D18: 40 | E18: 3 | F18: 10 | G18: Plywood 12-19 cellplast 70 | H18: 5 | I18: 2 | J18: 17 | M18: =Table1[[#This Row],[Kvalitet]]&Table1[[#This Row],[Gjuttemperatur]]&Table1[[#This Row],[Temperatur motgjutningsyta]]&Table1[[#This Row],[Värmekabel]]&Table1[[#This Row],[Täckning '[mm']]]&Table1[[#This Row],[OK<17 Timamr]]&Table1[[#This Row],[Kommentar]] -> C20/252054010
A19: C28/35 | B19: 20 | C19: 5 | D19: 40 | E19: 1 | F19: 10 | G19: Plywood 12-19 cellplast 50 | H19: 5 | I19: 7 | J19: 16.9 | M19: =Table1[[#This Row],[Kvalitet]]&Table1[[#This Row],[Gjuttemperatur]]&Table1[[#This Row],[Temperatur motgjutningsyta]]&Table1[[#This Row],[Värmekabel]]&Table1[[#This Row],[Täckning '[mm']]]&Table1[[#This Row],[OK<17 Timamr]]&Table1[[#This Row],[Kommentar]] -> C28/352054010
A20: C28/35 | B20: 20 | C20: 5 | D20: 40 | E20: 1 | F20: 10 | G20: Plywood 12-19 cellplast 70 | H20: 5 | I20: 12 | J20: 16.9 | M20: =Table1[[#This Row],[Kvalitet]]&Table1[[#This Row],[Gjuttemperatur]]&Table1[[#This Row],[Temperatur motgjutningsyta]]&Table1[[#This Row],[Värmekabel]]&Table1[[#This Row],[Täckning '[mm']]]&Table1[[#This Row],[OK<17 Timamr]]&Table1[[#This Row],[Kommentar]] -> C28/352054010
A21: C28/35 | B21: 20 | C21: 5 | D21: 40 | E21: 1 | F21: 10 | G21: Plywood 12-19 cellplast 100 | H21: 5 | I21: 20 | J21: 17 | M21: =Table1[[#This Row],[Kvalitet]]&Table1[[#This Row],[Gjuttemperatur]]&Table1[[#This Row],[Temperatur motgjutningsyta]]&Table1[[#This Row],[Värmekabel]]&Table1[[#This Row],[Täckning '[mm']]]&Table1[[#This Row],[OK<17 Timamr]]&Table1[[#This Row],[Kommentar]] -> C28/352054010
A22: C25/30 | B22: 20 | C22: 5 | D22: 40 | E22: 3 | F22: 10 | G22: Plywood 12-19 cellplast 70 | H22: 0 | I22: 0 | J22: 17 | M22: =Table1[[#This Row],[Kvalitet]]&Table1[[#This Row],[Gjuttemperatur]]&Table1[[#This Row],[Temperatur motgjutningsyta]]&Table1[[#This Row],[Värmekabel]]&Table1[[#This Row],[Täckning '[mm']]]&Table1[[#This Row],[OK<17 Timamr]]&Table1[[#This Row],[Kommentar]] -> C25/302054010
A23: C28/35 | B23: 20 | C23: 5 | D23: 40 | E23: 1 | F23: 10 | G23: Plywood 12-19 cellplast 100 | H23: 0 | I23: 2 | J23: 16.8 | M23: =Table1[[#This Row],[Kvalitet]]&Table1[[#This Row],[Gjuttemperatur]]&Table1[[#This Row],[Temperatur motgjutningsyta]]&Table1[[#This Row],[Värmekabel]]&Table1[[#This Row],[Täckning '[mm']]]&Table1[[#This Row],[OK<17 Timamr]]&Table1[[#This Row],[Kommentar]] -> C28/352054010
A24: C28/35 | B24: 20 | C24: 5 | D24: 40 | E24: 2 | F24: 10 | G24: Plywood 12-19 cellplast 50 | H24: 0 | I24: 7 | J24: 16.8 | M24: =Table1[[#This Row],[Kvalitet]]&Table1[[#This Row],[Gjuttemperatur]]&Table1[[#This Row],[Temperatur motgjutningsyta]]&Table1[[#This Row],[Värmekabel]]&Table1[[#This Row],[Täckning '[mm']]]&Table1[[#This Row],[OK<17 Timamr]]&Table1[[#This Row],[Kommentar]] -> C28/352054010
A25: C28/35 | B25: 20 | C25: 5 | D25: 40 | E25: 2 | F25: 10 | G25: Plywood 12-19 cellplast 100 | H25: 0 | I25: 12 | J25: 16.6 | M25: =Table1[[#This Row],[Kvalitet]]&Table1[[#This Row],[Gjuttemperatur]]&Table1[[#This Row],[Temperatur motgjutningsyta]]&Table1[[#This Row],[Värmekabel]]&Table1[[#This Row],[Täckning '[mm']]]&Table1[[#This Row],[OK<17 Timamr]]&Table1[[#This Row],[Kommentar]] -> C28/352054010
A26: C28/35 | B26: 20 | C26: 5 | D26: 40 | E26: 2 | F26: 10 | G26: Plywood 12-19 cellplast 120 | H26: 0 | I26: 20 | J26: 17 | M26: =Table1[[#This Row],[Kvalitet]]&Table1[[#This Row],[Gjuttemperatur]]&Table1[[#This Row],[Temperatur motgjutningsyta]]&Table1[[#This Row],[Värmekabel]]&Table1[[#This Row],[Täckning '[mm']]]&Table1[[#This Row],[OK<17 Timamr]]&Table1[[#This Row],[Kommentar]] -> C28/352054010
A27: C28/35 | B27: 20 | C27: 5 | D27: 40 | E27: 1 | F27: 10 | G27: Plywood 12-19 cellplast 100 | H27: -5 | I27: 0 | J27: 16.7 | M27: =Table1[[#This Row],[Kvalitet]]&Table1[[#This Row],[Gjuttemperatur]]&Table1[[#This Row],[Temperatur motgjutningsyta]]&Table1[[#This Row],[Värmekabel]]&Table1[[#This Row],[Täckning '[mm']]]&Table1[[#This Row],[OK<17 Timamr]]&Table1[[#This Row],[Kommentar]] -> C28/352054010
A28: C28/35 | B28: 20 | C28: 5 | D28: 40 | E28: 2 | F28: 10 | G28: Plywood 12-19 cellplast 50 | H28: -5 | I28: 2 | J28: 16.8 | M28: =Table1[[#This Row],[Kvalitet]]&Table1[[#This Row],[Gjuttemperatur]]&Table1[[#This Row],[Temperatur motgjutningsyta]]&Table1[[#This Row],[Värmekabel]]&Table1[[#This Row],[Täckning '[mm']]]&Table1[[#This Row],[OK<17 Timamr]]&Table1[[#This Row],[Kommentar]] -> C28/352054010
... A30: C30/37 | B30: 20 | C30: 5 | D30: 40 | E30: 2 | F30: 10 | G30: Plywood 12-19 cellplast 120 | H30: -5 | I30: 12 | J30: 17 | M30: =Table1[[#This Row],[Kvalitet]]&Table1[[#This Row],[Gjuttemperatur]]&Table1[[#This Row],[Temperatur motgjutningsyta]]&Table1[[#This Row],[Värmekabel]]&Table1[[#This Row],[Täckning '[mm']]]&Table1[[#This Row],[OK<17 Timamr]]&Table1[[#This Row],[Kommentar]] -> C30/372054010
A31: - | B31: - | C31: - | D31: - | E31: - | F31: - | G31: - | H31: -5 | I31: 20 | L31: Fryser innan täck | M31: =Table1[[#This Row],[Kvalitet]]&Table1[[#This Row],[Gjuttemperatur]]&Table1[[#This Row],[Temperatur motgjutningsyta]]&Table1[[#This Row],[Värmekabel]]&Table1[[#This Row],[Täckning '[mm']]]&Table1[[#This Row],[OK<17 Timamr]]&Table1[[#This Row],[Kommentar]] -> -----Fryser innan täck
A32: C28/35 | B32: 20 | C32: 5 | D32: 40 | E32: 2 | F32: 10 | G32: Plywood 12-19 cellplast 50 | H32: -10 | I32: 0 | J32: 16.4 | M32: =Table1[[#This Row],[Kvalitet]]&Table1[[#This Row],[Gjuttemperatur]]&Table1[[#This Row],[Temperatur motgjutningsyta]]&Table1[[#This Row],[Värmekabel]]&Table1[[#This Row],[Täckning '[mm']]]&Table1[[#This Row],[OK<17 Timamr]]&Table1[[#This Row],[Kommentar]] -> C28/352054010
A33: C28/35 | B33: 20 | C33: 5 | D33: 40 | E33: 3 | F33: 10 | G33: Plywood 12-19 cellplast 100 | H33: -10 | I33: 2 | J33: 16.8 | M33: =Table1[[#This Row],[Kvalitet]]&Table1[[#This Row],[Gjuttemperatur]]&Table1[[#This Row],[Temperatur motgjutningsyta]]&Table1[[#This Row],[Värmekabel]]&Table1[[#This Row],[Täckning '[mm']]]&Table1[[#This Row],[OK<17 Timamr]]&Table1[[#This Row],[Kommentar]] -> C28/352054010
A34: C32/40 | B34: 20 | C34: 5 | D34: 40 | E34: 2 | F34: 10 | G34: Plywood 12-19 cellplast 100 | H34: -10 | I34: 7 | J34: 16.7 | M34: =Table1[[#This Row],[Kvalitet]]&Table1[[#This Row],[Gjuttemperatur]]&Table1[[#This Row],[Temperatur motgjutningsyta]]&Table1[[#This Row],[Värmekabel]]&Table1[[#This Row],[Täckning '[mm']]]&Table1[[#This Row],[OK<17 Timamr]]&Table1[[#This Row],[Kommentar]] -> C32/402054010
A35: - | B35: - | C35: - | D35: - | E35: - | F35: - | G35: - | H35: -10 | I35: 12 | L35: Fryser innan täck | M35: =Table1[[#This Row],[Kvalitet]]&Table1[[#This Row],[Gjuttemperatur]]&Table1[[#This Row],[Temperatur motgjutningsyta]]&Table1[[#This Row],[Värmekabel]]&Table1[[#This Row],[Täckning '[mm']]]&Table1[[#This Row],[OK<17 Timamr]]&Table1[[#This Row],[Kommentar]] -> -----Fryser innan täck
A36: - | B36: - | C36: - | D36: - | E36: - | F36: - | G36: - | H36: -10 | I36: 20 | L36: Fryser innan täck | M36: =Table1[[#This Row],[Kvalitet]]&Table1[[#This Row],[Gjuttemperatur]]&Table1[[#This Row],[Temperatur motgjutningsyta]]&Table1[[#This Row],[Värmekabel]]&Table1[[#This Row],[Täckning '[mm']]]&Table1[[#This Row],[OK<17 Timamr]]&Table1[[#This Row],[Kommentar]] -> -----Fryser innan täck
A37: C32/40 | B37: 15 | C37: 5 | D37: 40 | E37: 2 | F37: 20 | G37: Plywood 12-19 cellplast 120 | H37: -15 | I37: 0 | J37: 16.9 | M37: =Table1[[#This Row],[Kvalitet]]&Table1[[#This Row],[Gjuttemperatur]]&Table1[[#This Row],[Temperatur motgjutningsyta]]&Table1[[#This Row],[Värmekabel]]&Table1[[#This Row],[Täckning '[mm']]]&Table1[[#This Row],[OK<17 Timamr]]&Table1[[#This Row],[Kommentar]] -> C32/401554020
A38: C40/50 | B38: 15 | C38: 5 | D38: 40 | E38: 2 | F38: 20 | G38: Plywood 12-19 cellplast 100 | H38: -15 | I38: 2 | J38: 16.8 | M38: =Table1[[#This Row],[Kvalitet]]&Table1[[#This Row],[Gjuttemperatur]]&Table1[[#This Row],[Temperatur motgjutningsyta]]&Table1[[#This Row],[Värmekabel]]&Table1[[#This Row],[Täckning '[mm']]]&Table1[[#This Row],[OK<17 Timamr]]&Table1[[#This Row],[Kommentar]] -> C40/501554020
A39: - | B39: - | C39: - | D39: - | E39: - | F39: - | G39: - | H39: -15 | I39: 7 | L39: Fryser innan täck | M39: =Table1[[#This Row],[Kvalitet]]&Table1[[#This Row],[Gjuttemperatur]]&Table1[[#This Row],[Temperatur motgjutningsyta]]&Table1[[#This Row],[Värmekabel]]&Table1[[#This Row],[Täckning '[mm']]]&Table1[[#This Row],[OK<17 Timamr]]&Table1[[#This Row],[Kommentar]] -> -----Fryser innan täck
A40: - | B40: - | C40: - | D40: - | E40: - | F40: - | G40: - | H40: -15 | I40: 12 | L40: Fryser innan täck | M40: =Table1[[#This Row],[Kvalitet]]&Table1[[#This Row],[Gjuttemperatur]]&Table1[[#This Row],[Temperatur motgjutningsyta]]&Table1[[#This Row],[Värmekabel]]&Table1[[#This Row],[Täckning '[mm']]]&Table1[[#This Row],[OK<17 Timamr]]&Table1[[#This Row],[Kommentar]] -> -----Fryser innan täck
A41: - | B41: - | C41: - | D41: - | E41: - | F41: - | G41: - | H41: -15 | I41: 20 | L41: Fryser innan täck | M41: =Table1[[#This Row],[Kvalitet]]&Table1[[#This Row],[Gjuttemperatur]]&Table1[[#This Row],[Temperatur motgjutningsyta]]&Table1[[#This Row],[Värmekabel]]&Table1[[#This Row],[Täckning '[mm']]]&Table1[[#This Row],[OK<17 Timamr]]&Table1[[#This Row],[Kommentar]] -> -----Fryser innan täck
A42: - | B42: - | C42: - | D42: - | E42: - | F42: - | G42: - | H42: -20 | I42: 0 | L42: Når ej 6 MPa | M42: =Table1[[#This Row],[Kvalitet]]&Table1[[#This Row],[Gjuttemperatur]]&Table1[[#This Row],[Temperatur motgjutningsyta]]&Table1[[#This Row],[Värmekabel]]&Table1[[#This Row],[Täckning '[mm']]]&Table1[[#This Row],[OK<17 Timamr]]&Table1[[#This Row],[Kommentar]] -> -----Når ej 6 MPa
A43: - | B43: - | C43: - | D43: - | E43: - | F43: - | G43: - | H43: -20 | I43: 2 | L43: Fryser innan täck | M43: =Table1[[#This Row],[Kvalitet]]&Table1[[#This Row],[Gjuttemperatur]]&Table1[[#This Row],[Temperatur motgjutningsyta]]&Table1[[#This Row],[Värmekabel]]&Table1[[#This Row],[Täckning '[mm']]]&Table1[[#This Row],[OK<17 Timamr]]&Table1[[#This Row],[Kommentar]] -> -----Fryser innan täck
...

Sheet Bjälklag (20% slagg)
A1: Kvalitet | B1: Gjuttemperatur | C1: Temperatur motgjutningsyta | D1: Värmekabel | E1: Antal värmekablar | F1: Täckning [mm] | G1: Formisolering [mm] | H1: Temperatur | I1: Vind | J1: <17 Timmar och >6 Mpa | K1: OK<17 Timamr | L1: Kommentar | M1: Åtgärdskåd
A2: C30/37 | B2: 15 | C2: 20 | D2: - | E2: - | F2: - | G2: Plywood 15, oisolerat | H2: 20 | I2: 0 | J2: 16.9 | M2: =Table123[[#This Row],[Kvalitet]]&Table123[[#This Row],[Gjuttemperatur]]&Table123[[#This Row],[Temperatur motgjutningsyta]]&Table123[[#This Row],[Värmekabel]]&Table123[[#This Row],[Täckning '[mm']]]&Table123[[#This Row],[OK<17 Timamr]]&Table123[[#This Row],[Kommentar]] -> C30/371520--
A3: C30/37 | B3: 15 | C3: 20 | D3: - | E3: - | F3: - | G3: Plywood 15, oisolerat | H3: 20 | I3: 2 | J3: 17 | M3: =Table123[[#This Row],[Kvalitet]]&Table123[[#This Row],[Gjuttemperatur]]&Table123[[#This Row],[Temperatur motgjutningsyta]]&Table123[[#This Row],[Värmekabel]]&Table123[[#This Row],[Täckning '[mm']]]&Table123[[#This Row],[OK<17 Timamr]]&Table123[[#This Row],[Kommentar]] -> C30/371520--
A4: C30/37 | B4: 15 | C4: 20 | D4: - | E4: - | F4: - | G4: Plywood 15, oisolerat | H4: 20 | I4: 7 | J4: 17 | M4: =Table123[[#This Row],[Kvalitet]]&Table123[[#This Row],[Gjuttemperatur]]&Table123[[#This Row],[Temperatur motgjutningsyta]]&Table123[[#This Row],[Värmekabel]]&Table123[[#This Row],[Täckning '[mm']]]&Table123[[#This Row],[OK<17 Timamr]]&Table123[[#This Row],[Kommentar]] -> C30/371520--
A5: C30/37 | B5: 15 | C5: 20 | D5: - | E5: - | F5: - | G5: Plywood 15, oisolerat | H5: 20 | I5: 12 | J5: 17 | M5: =Table123[[#This Row],[Kvalitet]]&Table123[[#This Row],[Gjuttemperatur]]&Table123[[#This Row],[Temperatur motgjutningsyta]]&Table123[[#This Row],[Värmekabel]]&Table123[[#This Row],[Täckning '[mm']]]&Table123[[#This Row],[OK<17 Timamr]]&Table123[[#This Row],[Kommentar]] -> C30/371520--
A6: C30/37 | B6: 15 | C6: 20 | D6: - | E6: - | F6: - | G6: Plywood 15, oisolerat | H6: 20 | I6: 20 | J6: 17 | M6: =Table123[[#This Row],[Kvalitet]]&Table123[[#This Row],[Gjuttemperatur]]&Table123[[#This Row],[Temperatur motgjutningsyta]]&Table123[[#This Row],[Värmekabel]]&Table123[[#This Row],[Täckning '[mm']]]&Table123[[#This Row],[OK<17 Timamr]]&Table123[[#This Row],[Kommentar]] -> C30/371520--
A7: C35/45 | B7: 15 | C7: 15 | D7: - | E7: - | F7: - | G7: Plywood 15, oisolerat | H7: 15 | I7: 0 | J7: 15.8 | M7: =Table123[[#This Row],[Kvalitet]]&Table123[[#This Row],[Gjuttemperatur]]&Table123[[#This Row],[Temperatur motgjutningsyta]]&Table123[[#This Row],[Värmekabel]]&Table123[[#This Row],[Täckning '[mm']]]&Table123[[#This Row],[OK<17 Timamr]]&Table123[[#This Row],[Kommentar]] -> C35/451515--
A8: C35/45 | B8: 15 | C8: 15 | D8: - | E8: - | F8: - | G8: Plywood 15, oisolerat | H8: 15 | I8: 2 | J8: 16 | M8: =Table123[[#This Row],[Kvalitet]]&Table123[[#This Row],[Gjuttemperatur]]&Table123[[#This Row],[Temperatur motgjutningsyta]]&Table123[[#This Row],[Värmekabel]]&Table123[[#This Row],[Täckning '[mm']]]&Table123[[#This Row],[OK<17 Timamr]]&Table123[[#This Row],[Kommentar]] -> C35/451515--
A9: C35/45 | B9: 15 | C9: 15 | D9: - | E9: - | F9: - | G9: Plywood 15, oisolerat | H9: 15 | I9: 7 | J9: 16.2 | M9: =Table123[[#This Row],[Kvalitet]]&Table123[[#This Row],[Gjuttemperatur]]&Table123[[#This Row],[Temperatur motgjutningsyta]]&Table123[[#This Row],[Värmekabel]]&Table123[[#This Row],[Täckning '[mm']]]&Table123[[#This Row],[OK<17 Timamr]]&Table123[[#This Row],[Kommentar]] -> C35/451515--
A10: C35/45 | B10: 15 | C10: 15 | D10: - | E10: - | F10: - | G10: Plywood 15, oisolerat | H10: 15 | I10: 12 | J10: 16.2 | M10: =Table123[[#This Row],[Kvalitet]]&Table123[[#This Row],[Gjuttemperatur]]&Table123[[#This Row],[Temperatur motgjutningsyta]]&Table123[[#This Row],[Värmekabel]]&Table123[[#This Row],[Täckning '[mm']]]&Table123[[#This Row],[OK<17 Timamr]]&Table123[[#This Row],[Kommentar]] -> C35/451515--
A11: C35/45 | B11: 15 | C11: 15 | D11: - | E11: - | F11: Presenning | G11: Plywood 15, oisolerat | H11: 15 | I11: 20 | J11: 16.3 | M11: =Table123[[#This Row],[Kvalitet]]&Table123[[#This Row],[Gjuttemperatur]]&Table123[[#This Row],[Temperatur motgjutningsyta]]&Table123[[#This Row],[Värmekabel]]&Table123[[#This Row],[Täckning '[mm']]]&Table123[[#This Row],[OK<17 Timamr]]&Table123[[#This Row],[Kommentar]] -> C35/451515-Presenning
B12: 15 | C12: 10 | H12: 10 | I12: 0 | M12: =Table123[[#This Row],[Kvalitet]]&Table123[[#This Row],[Gjuttemperatur]]&Table123[[#This Row],[Temperatur motgjutningsyta]]&Table123[[#This Row],[Värmekabel]]&Table123[[#This Row],[Täckning '[mm']]]&Table123[[#This Row],[OK<17 Timamr]]&Table123[[#This Row],[Kommentar]] -> 1510
B13: 15 | C13: 10 | H13: 10 | I13: 2 | M13: =Table123[[#This Row],[Kvalitet]]&Table123[[#This Row],[Gjuttemperatur]]&Table123[[#This Row],[Temperatur motgjutningsyta]]&Table123[[#This Row],[Värmekabel]]&Table123[[#This Row],[Täckning '[mm']]]&Table123[[#This Row],[OK<17 Timamr]]&Table123[[#This Row],[Kommentar]] -> 1510
B14: 15 | C14: 10 | H14: 10 | I14: 7 | M14: =Table123[[#This Row],[Kvalitet]]&Table123[[#This Row],[Gjuttemperatur]]&Table123[[#This Row],[Temperatur motgjutningsyta]]&Table123[[#This Row],[Värmekabel]]&Table123[[#This Row],[Täckning '[mm']]]&Table123[[#This Row],[OK<17 Timamr]]&Table123[[#This Row],[Kommentar]] -> 1510
B15: 15 | C15: 10 | H15: 10 | I15: 12 | M15: =Table123[[#This Row],[Kvalitet]]&Table123[[#This Row],[Gjuttemperatur]]&Table123[[#This Row],[Temperatur motgjutningsyta]]&Table123[[#This Row],[Värmekabel]]&Table123[[#This Row],[Täckning '[mm']]]&Table123[[#This Row],[OK<17 Timamr]]&Table123[[#This Row],[Kommentar]] -> 1510
B16: 15 | C16: 10 | H16: 10 | I16: 20 | M16: =Table123[[#This Row],[Kvalitet]]&Table123[[#This Row],[Gjuttemperatur]]&Table123[[#This Row],[Temperatur motgjutningsyta]]&Table123[[#This Row],[Värmekabel]]&Table123[[#This Row],[Täckning '[mm']]]&Table123[[#This Row],[OK<17 Timamr]]&Table123[[#This Row],[Kommentar]] -> 1510
A17: C28/35 | B17: 20 | C17: 5 | D17: 40 | E17: 2 | F17: - | G17: Plywood 12-19 cellplast 100 | H17: 5 | I17: 0 | J17: 17 | M17: =Table123[[#This Row],[Kvalitet]]&Table123[[#This Row],[Gjuttemperatur]]&Table123[[#This Row],[Temperatur motgjutningsyta]]&Table123[[#This Row],[Värmekabel]]&Table123[[#This Row],[Täckning '[mm']]]&Table123[[#This Row],[OK<17 Timamr]]&Table123[[#This Row],[Kommentar]] -> C28/3520540-
A18: C28/35 | B18: 20 | C18: 5 | D18: 40 | E18: 3 | F18: 10 | G18: Plywood 12-19 cellplast 120 | H18: 5 | I18: 2 | J18: 17 | M18: =Table123[[#This Row],[Kvalitet]]&Table123[[#This Row],[Gjuttemperatur]]&Table123[[#This Row],[Temperatur motgjutningsyta]]&Table123[[#This Row],[Värmekabel]]&Table123[[#This Row],[Täckning '[mm']]]&Table123[[#This Row],[OK<17 Timamr]]&Table123[[#This Row],[Kommentar]] -> C28/352054010
A19: C30/37 | B19: 20 | C19: 5 | D19: 40 | E19: 2 | F19: 10 | G19: Plywood 12-19 cellplast 100 | H19: 5 | I19: 7 | J19: 17 | M19: =Table123[[#This Row],[Kvalitet]]&Table123[[#This Row],[Gjuttemperatur]]&Table123[[#This Row],[Temperatur motgjutningsyta]]&Table123[[#This Row],[Värmekabel]]&Table123[[#This Row],[Täckning '[mm']]]&Table123[[#This Row],[OK<17 Timamr]]&Table123[[#This Row],[Kommentar]] -> C30/372054010
A20: C32/40 | B20: 20 | C20: 5 | D20: 40 | E20: 1 | F20: 10 | G20: Plywood 12-19 cellplast 100 | H20: 5 | I20: 12 | J20: 17 | M20: =Table123[[#This Row],[Kvalitet]]&Table123[[#This Row],[Gjuttemperatur]]&Table123[[#This Row],[Temperatur motgjutningsyta]]&Table123[[#This Row],[Värmekabel]]&Table123[[#This Row],[Täckning '[mm']]]&Table123[[#This Row],[OK<17 Timamr]]&Table123[[#This Row],[Kommentar]] -> C32/402054010
A21: C32/40 | B21: 20 | C21: 5 | D21: 40 | E21: 1 | F21: 10 | G21: Plywood 12-19 cellplast 100 | H21: 5 | I21: 20 | J21: 17 | M21: =Table123[[#This Row],[Kvalitet]]&Table123[[#This Row],[Gjuttemperatur]]&Table123[[#This Row],[Temperatur motgjutningsyta]]&Table123[[#This Row],[Värmekabel]]&Table123[[#This Row],[Täckning '[mm']]]&Table123[[#This Row],[OK<17 Timamr]]&Table123[[#This Row],[Kommentar]] -> C32/402054010
A22: C30/37 | B22: 20 | C22: 5 | D22: 40 | E22: 2 | F22: 10 | G22: Plywood 12-19 cellplast 70 | H22: 0 | I22: 0 | J22: 16.6 | M22: =Table123[[#This Row],[Kvalitet]]&Table123[[#This Row],[Gjuttemperatur]]&Table123[[#This Row],[Temperatur motgjutningsyta]]&Table123[[#This Row],[Värmekabel]]&Table123[[#This Row],[Täckning '[mm']]]&Table123[[#This Row],[OK<17 Timamr]]&Table123[[#This Row],[Kommentar]] -> C30/372054010
A23: C30/37 | B23: 20 | C23: 5 | D23: 40 | E23: 3 | F23: 10 | G23: Plywood 12-19 cellplast 70 | H23: 0 | I23: 2 | J23: 17 | M23: =Table123[[#This Row],[Kvalitet]]&Table123[[#This Row],[Gjuttemperatur]]&Table123[[#This Row],[Temperatur motgjutningsyta]]&Table123[[#This Row],[Värmekabel]]&Table123[[#This Row],[Täckning '[mm']]]&Table123[[#This Row],[OK<17 Timamr]]&Table123[[#This Row],[Kommentar]] -> C30/372054010
A24: C32/40 | B24: 20 | C24: 5 | D24: 40 | E24: 2 | F24: 10 | G24: Plywood 12-19 cellplast 70 | H24: 0 | I24: 7 | J24: 17 | M24: =Table123[[#This Row],[Kvalitet]]&Table123[[#This Row],[Gjuttemperatur]]&Table123[[#This Row],[Temperatur motgjutningsyta]]&Table123[[#This Row],[Värmekabel]]&Table123[[#This Row],[Täckning '[mm']]]&Table123[[#This Row],[OK<17 Timamr]]&Table123[[#This Row],[Kommentar]] -> C32/402054010
A25: C32/40 | B25: 20 | C25: 5 | D25: 40 | E25: 3 | F25: 10 | G25: Plywood 12-19 cellplast 100 | H25: 0 | I25: 12 | J25: 16.8 | M25: =Table123[[#This Row],[Kvalitet]]&Table123[[#This Row],[Gjuttemperatur]]&Table123[[#This Row],[Temperatur motgjutningsyta]]&Table123[[#This Row],[Värmekabel]]&Table123[[#This Row],[Täckning '[mm']]]&Table123[[#This Row],[OK<17 Timamr]]&Table123[[#This Row],[Kommentar]] -> C32/402054010
A26: C35/45 | B26: 20 | C26: 5 | D26: 40 | E26: 1 | F26: 10 | G26: Plywood 12-19 cellplast 50 | H26: 0 | I26: 20 | J26: 17 | M26: =Table123[[#This Row],[Kvalitet]]&Table123[[#This Row],[Gjuttemperatur]]&Table123[[#This Row],[Temperatur motgjutningsyta]]&Table123[[#This Row],[Värmekabel]]&Table123[[#This Row],[Täckning '[mm']]]&Table123[[#This Row],[OK<17 Timamr]]&Table123[[#This Row],[Kommentar]] -> C35/452054010
A27: C30/37 | B27: 20 | C27: 5 | D27: 40 | E27: 3 | F27: 10 | G27: Plywood 12-19 cellplast 70 | H27: -5 | I27: 0 | J27: 16.9 | M27: =Table123[[#This Row],[Kvalitet]]&Table123[[#This Row],[Gjuttemperatur]]&Table123[[#This Row],[Temperatur motgjutningsyta]]&Table123[[#This Row],[Värmekabel]]&Table123[[#This Row],[Täckning '[mm']]]&Table123[[#This Row],[OK<17 Timamr]]&Table123[[#This Row],[Kommentar]] -> C30/372054010
A28: C32/40 | B28: 20 | C28: 5 | D28: 40 | E28: 2 | F28: 10 | G28: Plywood 12-19 cellplast 70 | H28: -5 | I28: 2 | J28: 16.9 | M28: =Table123[[#This Row],[Kvalitet]]&Table123[[#This Row],[Gjuttemperatur]]&Table123[[#This Row],[Temperatur motgjutningsyta]]&Table123[[#This Row],[Värmekabel]]&Table123[[#This Row],[Täckning '[mm']]]&Table123[[#This Row],[OK<17 Timamr]]&Table123[[#This Row],[Kommentar]] -> C32/402054010
A29: C35/45 | B29: 20 | C29: 5 | D29: 40 | E29: 1 | F29: 10 | G29: Plywood 12-19 cellplast 120 | H29: -5 | I29: 7 | J29: 17 | M29: =Table123[[#This Row],[Kvalitet]]&Table123[[#This Row],[Gjuttemperatur]]&Table123[[#This Row],[Temperatur motgjutningsyta]]&Table123[[#This Row],[Värmekabel]]&Table123[[#This Row],[Täckning '[mm']]]&Table123[[#This Row],[OK<17 Timamr]]&Table123[[#This Row],[Kommentar]] -> C35/452054010
A30: C35/45 | B30: 20 | C30: 5 | D30: 40 | E30: 2 | F30: 10 | G30: Plywood 12-19 cellplast 70 | H30: -5 | I30: 12 | J30: 16.9 | M30: =Table123[[#This Row],[Kvalitet]]&Table123[[#This Row],[Gjuttemperatur]]&Table123[[#This Row],[Temperatur motgjutningsyta]]&Table123[[#This Row],[Värmekabel]]&Table123[[#This Row],[Täckning '[mm']]]&Table123[[#This Row],[OK<17 Timamr]]&Table123[[#This Row],[Kommentar]] -> C35/452054010
B31: 20 | C31: 5 | F31: 50 | H31: -5 | I31: 20 | L31: Fryser innan täck | M31: =Table123[[#This Row],[Kvalitet]]&Table123[[#This Row],[Gjuttemperatur]]&Table123[[#This Row],[Temperatur motgjutningsyta]]&Table123[[#This Row],[Värmekabel]]&Table123[[#This Row],[Täckning '[mm']]]&Table123[[#This Row],[OK<17 Timamr]]&Table123[[#This Row],[Kommentar]] -> 20550Fryser innan täck
A32: C30/37 | B32: 20 | C32: 5 | D32: 40 | E32: 3 | F32: 10 | G32: Plywood 12-19 cellplast 100 | H32: -10 | I32: 0 | J32: 17 | M32: =Table123[[#This Row],[Kvalitet]]&Table123[[#This Row],[Gjuttemperatur]]&Table123[[#This Row],[Temperatur motgjutningsyta]]&Table123[[#This Row],[Värmekabel]]&Table123[[#This Row],[Täckning '[mm']]]&Table123[[#This Row],[OK<17 Timamr]]&Table123[[#This Row],[Kommentar]] -> C30/372054010
A33: C35/45 | B33: 20 | C33: 5 | D33: 40 | E33: 1 | F33: 10 | G33: Plywood 12-19 cellplast 120 | H33: -10 | I33: 2 | J33: 17 | M33: =Table123[[#This Row],[Kvalitet]]&Table123[[#This Row],[Gjuttemperatur]]&Table123[[#This Row],[Temperatur motgjutningsyta]]&Table123[[#This Row],[Värmekabel]]&Table123[[#This Row],[Täckning '[mm']]]&Table123[[#This Row],[OK<17 Timamr]]&Table123[[#This Row],[Kommentar]] -> C35/452054010
A34: C35/45 | B34: 20 | C34: 5 | D34: 40 | E34: 3 | F34: 10 | G34: Plywood 12-19 cellplast 120 | H34: -10 | I34: 7 | J34: 16.9 | M34: =Table123[[#This Row],[Kvalitet]]&Table123[[#This Row],[Gjuttemperatur]]&Table123[[#This Row],[Temperatur motgjutningsyta]]&Table123[[#This Row],[Värmekabel]]&Table123[[#This Row],[Täckning '[mm']]]&Table123[[#This Row],[OK<17 Timamr]]&Table123[[#This Row],[Kommentar]] -> C35/452054010
B35: - | C35: - | F35: - | H35: -10 | I35: 12 | L35: Fryser innan täck | M35: =Table123[[#This Row],[Kvalitet]]&Table123[[#This Row],[Gjuttemperatur]]&Table123[[#This Row],[Temperatur motgjutningsyta]]&Table123[[#This Row],[Värmekabel]]&Table123[[#This Row],[Täckning '[mm']]]&Table123[[#This Row],[OK<17 Timamr]]&Table123[[#This Row],[Kommentar]] -> ---Fryser innan täck
B36: - | C36: - | F36: - | H36: -10 | I36: 20 | L36: Fryser innan täck | M36: =Table123[[#This Row],[Kvalitet]]&Table123[[#This Row],[Gjuttemperatur]]&Table123[[#This Row],[Temperatur motgjutningsyta]]&Table123[[#This Row],[Värmekabel]]&Table123[[#This Row],[Täckning '[mm']]]&Table123[[#This Row],[OK<17 Timamr]]&Table123[[#This Row],[Kommentar]] -> ---Fryser innan täck
A37: C35/45 | B37: 15 | C37: 5 | D37: 40 | E37: 3 | F37: 30 | G37: Plywood 12-19 cellplast 100 | H37: -15 | I37: 0 | J37: 17 | M37: =Table123[[#This Row],[Kvalitet]]&Table123[[#This Row],[Gjuttemperatur]]&Table123[[#This Row],[Temperatur motgjutningsyta]]&Table123[[#This Row],[Värmekabel]]&Table123[[#This Row],[Täckning '[mm']]]&Table123[[#This Row],[OK<17 Timamr]]&Table123[[#This Row],[Kommentar]] -> C35/451554030
A38: - | B38: - | C38: - | D38: - | E38: - | F38: - | G38: - | H38: -15 | I38: 2 | L38: Når ej 6 MPa | M38: =Table123[[#This Row],[Kvalitet]]&Table123[[#This Row],[Gjuttemperatur]]&Table123[[#This Row],[Temperatur motgjutningsyta]]&Table123[[#This Row],[Värmekabel]]&Table123[[#This Row],[Täckning '[mm']]]&Table123[[#This Row],[OK<17 Timamr]]&Table123[[#This Row],[Kommentar]] -> -----Når ej 6 MPa
A39: - | B39: - | C39: - | D39: - | E39: - | F39: - | G39: - | H39: -15 | I39: 7 | L39: Fryser innan täck | M39: =Table123[[#This Row],[Kvalitet]]&Table123[[#This Row],[Gjuttemperatur]]&Table123[[#This Row],[Temperatur motgjutningsyta]]&Table123[[#This Row],[Värmekabel]]&Table123[[#This Row],[Täckning '[mm']]]&Table123[[#This Row],[OK<17 Timamr]]&Table123[[#This Row],[Kommentar]] -> -----Fryser innan täck
A40: - | B40: - | C40: - | D40: - | E40: - | F40: - | G40: - | H40: -15 | I40: 12 | L40: Fryser innan täck | M40: =Table123[[#This Row],[Kvalitet]]&Table123[[#This Row],[Gjuttemperatur]]&Table123[[#This Row],[Temperatur motgjutningsyta]]&Table123[[#This Row],[Värmekabel]]&Table123[[#This Row],[Täckning '[mm']]]&Table123[[#This Row],[OK<17 Timamr]]&Table123[[#This Row],[Kommentar]] -> -----Fryser innan täck
...

Sheet Bjälklag (30% slagg)
A1: Kvalitet | B1: Gjuttemperatur | C1: Temperatur motgjutningsyta | D1: Värmekabel | E1: Antal värmekablar | F1: Täckning [mm] | G1: Formisolering [mm] | H1: Temperatur | I1: Vind | J1: <17 Timmar och >6 Mpa | K1: OK<17 Timamr | L1: Kommentar | M1: Åtgärdskåd
A2: C35/45 | B2: 15 | C2: 20 | D2: - | E2: - | F2: - | G2: Plywood 15, oisolerat | H2: 20 | I2: 0 | J2: 16.9 | M2: =Table1[[#This Row],[Kvalitet]]&Table1[[#This Row],[Gjuttemperatur]]&Table1[[#This Row],[Temperatur motgjutningsyta]]&Table1[[#This Row],[Värmekabel]]&Table1[[#This Row],[Täckning '[mm']]]&Table1[[#This Row],[OK<17 Timamr]]&Table1[[#This Row],[Kommentar]] -> C28/351520--
A3: C35/45 | B3: 15 | C3: 20 | D3: - | E3: - | F3: - | G3: Plywood 15, oisolerat | H3: 20 | I3: 2 | J3: 16.8 | M3: =Table1[[#This Row],[Kvalitet]]&Table1[[#This Row],[Gjuttemperatur]]&Table1[[#This Row],[Temperatur motgjutningsyta]]&Table1[[#This Row],[Värmekabel]]&Table1[[#This Row],[Täckning '[mm']]]&Table1[[#This Row],[OK<17 Timamr]]&Table1[[#This Row],[Kommentar]] -> C28/351520--
A4: C35/45 | B4: 15 | C4: 20 | D4: - | E4: - | F4: - | G4: Plywood 15, oisolerat | H4: 20 | I4: 7 | J4: 16.8 | M4: =Table1[[#This Row],[Kvalitet]]&Table1[[#This Row],[Gjuttemperatur]]&Table1[[#This Row],[Temperatur motgjutningsyta]]&Table1[[#This Row],[Värmekabel]]&Table1[[#This Row],[Täckning '[mm']]]&Table1[[#This Row],[OK<17 Timamr]]&Table1[[#This Row],[Kommentar]] -> C28/351520--
A5: C35/45 | B5: 15 | C5: 20 | D5: - | E5: - | F5: - | G5: Plywood 15, oisolerat | H5: 20 | I5: 12 | J5: 16.8 | M5: =Table1[[#This Row],[Kvalitet]]&Table1[[#This Row],[Gjuttemperatur]]&Table1[[#This Row],[Temperatur motgjutningsyta]]&Table1[[#This Row],[Värmekabel]]&Table1[[#This Row],[Täckning '[mm']]]&Table1[[#This Row],[OK<17 Timamr]]&Table1[[#This Row],[Kommentar]] -> C28/351520--
A6: C35/45 | B6: 15 | C6: 20 | D6: - | E6: - | F6: - | G6: Plywood 15, oisolerat | H6: 20 | I6: 20 | J6: 16.8 | M6: =Table1[[#This Row],[Kvalitet]]&Table1[[#This Row],[Gjuttemperatur]]&Table1[[#This Row],[Temperatur motgjutningsyta]]&Table1[[#This Row],[Värmekabel]]&Table1[[#This Row],[Täckning '[mm']]]&Table1[[#This Row],[OK<17 Timamr]]&Table1[[#This Row],[Kommentar]] -> C28/351520--
B7: 15 | C7: 15 | F7: - | H7: 15 | I7: 0 | M7: =Table1[[#This Row],[Kvalitet]]&Table1[[#This Row],[Gjuttemperatur]]&Table1[[#This Row],[Temperatur motgjutningsyta]]&Table1[[#This Row],[Värmekabel]]&Table1[[#This Row],[Täckning '[mm']]]&Table1[[#This Row],[OK<17 Timamr]]&Table1[[#This Row],[Kommentar]] -> C30/371515--
B8: 15 | C8: 15 | F8: - | H8: 15 | I8: 2 | M8: =Table1[[#This Row],[Kvalitet]]&Table1[[#This Row],[Gjuttemperatur]]&Table1[[#This Row],[Temperatur motgjutningsyta]]&Table1[[#This Row],[Värmekabel]]&Table1[[#This Row],[Täckning '[mm']]]&Table1[[#This Row],[OK<17 Timamr]]&Table1[[#This Row],[Kommentar]] -> C30/371515--
B9: 15 | C9: 15 | F9: - | H9: 15 | I9: 7 | M9: =Table1[[#This Row],[Kvalitet]]&Table1[[#This Row],[Gjuttemperatur]]&Table1[[#This Row],[Temperatur motgjutningsyta]]&Table1[[#This Row],[Värmekabel]]&Table1[[#This Row],[Täckning '[mm']]]&Table1[[#This Row],[OK<17 Timamr]]&Table1[[#This Row],[Kommentar]] -> C30/371515--
B10: 15 | C10: 15 | F10: Presenning | H10: 15 | I10: 12 | M10: =Table1[[#This Row],[Kvalitet]]&Table1[[#This Row],[Gjuttemperatur]]&Table1[[#This Row],[Temperatur motgjutningsyta]]&Table1[[#This Row],[Värmekabel]]&Table1[[#This Row],[Täckning '[mm']]]&Table1[[#This Row],[OK<17 Timamr]]&Table1[[#This Row],[Kommentar]] -> C30/371515-Presenning
B11: 15 | C11: 15 | F11: Presenning | H11: 15 | I11: 20 | M11: =Table1[[#This Row],[Kvalitet]]&Table1[[#This Row],[Gjuttemperatur]]&Table1[[#This Row],[Temperatur motgjutningsyta]]&Table1[[#This Row],[Värmekabel]]&Table1[[#This Row],[Täckning '[mm']]]&Table1[[#This Row],[OK<17 Timamr]]&Table1[[#This Row],[Kommentar]] -> C30/371515-Presenning
B12: 15 | C12: 10 | F12: - | H12: 10 | I12: 0 | M12: =Table1[[#This Row],[Kvalitet]]&Table1[[#This Row],[Gjuttemperatur]]&Table1[[#This Row],[Temperatur motgjutningsyta]]&Table1[[#This Row],[Värmekabel]]&Table1[[#This Row],[Täckning '[mm']]]&Table1[[#This Row],[OK<17 Timamr]]&Table1[[#This Row],[Kommentar]] -> C35/451510--
B13: 15 | C13: 10 | F13: Presenning | H13: 10 | I13: 2 | M13: =Table1[[#This Row],[Kvalitet]]&Table1[[#This Row],[Gjuttemperatur]]&Table1[[#This Row],[Temperatur motgjutningsyta]]&Table1[[#This Row],[Värmekabel]]&Table1[[#This Row],[Täckning '[mm']]]&Table1[[#This Row],[OK<17 Timamr]]&Table1[[#This Row],[Kommentar]] -> C40/501510--
B14: 15 | C14: 10 | F14: Presenning | H14: 10 | I14: 7 | M14: =Table1[[#This Row],[Kvalitet]]&Table1[[#This Row],[Gjuttemperatur]]&Table1[[#This Row],[Temperatur motgjutningsyta]]&Table1[[#This Row],[Värmekabel]]&Table1[[#This Row],[Täckning '[mm']]]&Table1[[#This Row],[OK<17 Timamr]]&Table1[[#This Row],[Kommentar]] -> C40/501510-Presenning
B15: 15 | C15: 10 | F15: Presenning | H15: 10 | I15: 12 | M15: =Table1[[#This Row],[Kvalitet]]&Table1[[#This Row],[Gjuttemperatur]]&Table1[[#This Row],[Temperatur motgjutningsyta]]&Table1[[#This Row],[Värmekabel]]&Table1[[#This Row],[Täckning '[mm']]]&Table1[[#This Row],[OK<17 Timamr]]&Table1[[#This Row],[Kommentar]] -> C40/501510-Presenning
B16: 15 | C16: 10 | F16: Presenning | H16: 10 | I16: 20 | M16: =Table1[[#This Row],[Kvalitet]]&Table1[[#This Row],[Gjuttemperatur]]&Table1[[#This Row],[Temperatur motgjutningsyta]]&Table1[[#This Row],[Värmekabel]]&Table1[[#This Row],[Täckning '[mm']]]&Table1[[#This Row],[OK<17 Timamr]]&Table1[[#This Row],[Kommentar]] -> C40/501510-Presenning
A17: C35/45 | B17: 20 | C17: 5 | D17: 40 | E17: 2 | F17: Presenning | G17: Plywood 15 cellplast 30 | H17: 5 | I17: 0 | J17: 16.6 | M17: =Table1[[#This Row],[Kvalitet]]&Table1[[#This Row],[Gjuttemperatur]]&Table1[[#This Row],[Temperatur motgjutningsyta]]&Table1[[#This Row],[Värmekabel]]&Table1[[#This Row],[Täckning '[mm']]]&Table1[[#This Row],[OK<17 Timamr]]&Table1[[#This Row],[Kommentar]] -> C25/302054010
A18: C35/45 | B18: 20 | C18: 5 | D18: 40 | E18: 2 | F18: 10 | G18: Plywood 12-19 cellplast 50 | H18: 5 | I18: 2 | J18: 16.7 | M18: =Table1[[#This Row],[Kvalitet]]&Table1[[#This Row],[Gjuttemperatur]]&Table1[[#This Row],[Temperatur motgjutningsyta]]&Table1[[#This Row],[Värmekabel]]&Table1[[#This Row],[Täckning '[mm']]]&Table1[[#This Row],[OK<17 Timamr]]&Table1[[#This Row],[Kommentar]] -> C20/252054010
A19: C35/45 | B19: 20 | C19: 5 | D19: 40 | E19: 2 | F19: 10 | G19: Plywood 12-19 cellplast 100 | H19: 5 | I19: 7 | J19: 17 | M19: =Table1[[#This Row],[Kvalitet]]&Table1[[#This Row],[Gjuttemperatur]]&Table1[[#This Row],[Temperatur motgjutningsyta]]&Table1[[#This Row],[Värmekabel]]&Table1[[#This Row],[Täckning '[mm']]]&Table1[[#This Row],[OK<17 Timamr]]&Table1[[#This Row],[Kommentar]] -> C28/352054010
A20: C40/50 | B20: 20 | C20: 5 | D20: 40 | E20: 2 | F20: 10 | G20: Plywood 15 cellplast 30 | H20: 5 | I20: 12 | J20: 16.9 | M20: =Table1[[#This Row],[Kvalitet]]&Table1[[#This Row],[Gjuttemperatur]]&Table1[[#This Row],[Temperatur motgjutningsyta]]&Table1[[#This Row],[Värmekabel]]&Table1[[#This Row],[Täckning '[mm']]]&Table1[[#This Row],[OK<17 Timamr]]&Table1[[#This Row],[Kommentar]] -> C28/352054010
A21: C40/50 | B21: 20 | C21: 5 | D21: 40 | E21: 2 | F21: 10 | G21: Plywood 12-19 cellplast 50 | H21: 5 | I21: 20 | J21: 16.8 | M21: =Table1[[#This Row],[Kvalitet]]&Table1[[#This Row],[Gjuttemperatur]]&Table1[[#This Row],[Temperatur motgjutningsyta]]&Table1[[#This Row],[Värmekabel]]&Table1[[#This Row],[Täckning '[mm']]]&Table1[[#This Row],[OK<17 Timamr]]&Table1[[#This Row],[Kommentar]] -> C28/352054010
A22: C40/50 | B22: 20 | C22: 5 | D22: 40 | E22: 2 | F22: 10 | G22: Plywood 15 cellplast 30 | H22: 0 | I22: 0 | J22: 16.2 | M22: =Table1[[#This Row],[Kvalitet]]&Table1[[#This Row],[Gjuttemperatur]]&Table1[[#This Row],[Temperatur motgjutningsyta]]&Table1[[#This Row],[Värmekabel]]&Table1[[#This Row],[Täckning '[mm']]]&Table1[[#This Row],[OK<17 Timamr]]&Table1[[#This Row],[Kommentar]] -> C25/302054010
A23: C40/50 | B23: 20 | C23: 5 | D23: 40 | E23: 2 | F23: 10 | G23: Plywood 12-19 cellplast 50 | H23: 0 | I23: 2 | J23: 16.6 | M23: =Table1[[#This Row],[Kvalitet]]&Table1[[#This Row],[Gjuttemperatur]]&Table1[[#This Row],[Temperatur motgjutningsyta]]&Table1[[#This Row],[Värmekabel]]&Table1[[#This Row],[Täckning '[mm']]]&Table1[[#This Row],[OK<17 Timamr]]&Table1[[#This Row],[Kommentar]] -> C28/352054010
A24: C40/50 | B24: 20 | C24: 5 | D24: 40 | E24: 3 | F24: 10 | G24: Plywood 12-19 cellplast 120 | H24: 0 | I24: 7 | J24: 16.8 | M24: =Table1[[#This Row],[Kvalitet]]&Table1[[#This Row],[Gjuttemperatur]]&Table1[[#This Row],[Temperatur motgjutningsyta]]&Table1[[#This Row],[Värmekabel]]&Table1[[#This Row],[Täckning '[mm']]]&Table1[[#This Row],[OK<17 Timamr]]&Table1[[#This Row],[Kommentar]] -> C28/352054010
B25: 20 | C25: 5 | F25: 20 | H25: 0 | I25: 12 | M25: =Table1[[#This Row],[Kvalitet]]&Table1[[#This Row],[Gjuttemperatur]]&Table1[[#This Row],[Temperatur motgjutningsyta]]&Table1[[#This Row],[Värmekabel]]&Table1[[#This Row],[Täckning '[mm']]]&Table1[[#This Row],[OK<17 Timamr]]&Table1[[#This Row],[Kommentar]] -> C28/352054010
B26: 20 | C26: 5 | F26: 20 | H26: 0 | I26: 20 | M26: =Table1[[#This Row],[Kvalitet]]&Table1[[#This Row],[Gjuttemperatur]]&Table1[[#This Row],[Temperatur motgjutningsyta]]&Table1[[#This Row],[Värmekabel]]&Table1[[#This Row],[Täckning '[mm']]]&Table1[[#This Row],[OK<17 Timamr]]&Table1[[#This Row],[Kommentar]] -> C28/352054010
B27: 20 | C27: 5 | F27: 30 | H27: -5 | I27: 0 | M27: =Table1[[#This Row],[Kvalitet]]&Table1[[#This Row],[Gjuttemperatur]]&Table1[[#This Row],[Temperatur motgjutningsyta]]&Table1[[#This Row],[Värmekabel]]&Table1[[#This Row],[Täckning '[mm']]]&Table1[[#This Row],[OK<17 Timamr]]&Table1[[#This Row],[Kommentar]] -> C28/352054010
B28: 20 | C28: 5 | F28: 30 | H28: -5 | I28: 2 | M28: =Table1[[#This Row],[Kvalitet]]&Table1[[#This Row],[Gjuttemperatur]]&Table1[[#This Row],[Temperatur motgjutningsyta]]&Table1[[#This Row],[Värmekabel]]&Table1[[#This Row],[Täckning '[mm']]]&Table1[[#This Row],[OK<17 Timamr]]&Table1[[#This Row],[Kommentar]] -> C28/352054010
B29: 20 | C29: 5 | F29: 50 | H29: -5 | I29: 7 | M29: =Table1[[#This Row],[Kvalitet]]&Table1[[#This Row],[Gjuttemperatur]]&Table1[[#This Row],[Temperatur motgjutningsyta]]&Table1[[#This Row],[Värmekabel]]&Table1[[#This Row],[Täckning '[mm']]]&Table1[[#This Row],[OK<17 Timamr]]&Table1[[#This Row],[Kommentar]] -> C30/372054010
B30: 20 | C30: 5 | F30: 50 | H30: -5 | I30: 12 | M30: =Table1[[#This Row],[Kvalitet]]&Table1[[#This Row],[Gjuttemperatur]]&Table1[[#This Row],[Temperatur motgjutningsyta]]&Table1[[#This Row],[Värmekabel]]&Table1[[#This Row],[Täckning '[mm']]]&Table1[[#This Row],[OK<17 Timamr]]&Table1[[#This Row],[Kommentar]] -> C30/372054010
B31: 20 | C31: 5 | F31: 50 | H31: -5 | I31: 20 | L31: Fryser innan täck | M31: =Table1[[#This Row],[Kvalitet]]&Table1[[#This Row],[Gjuttemperatur]]&Table1[[#This Row],[Temperatur motgjutningsyta]]&Table1[[#This Row],[Värmekabel]]&Table1[[#This Row],[Täckning '[mm']]]&Table1[[#This Row],[OK<17 Timamr]]&Table1[[#This Row],[Kommentar]] -> -----Fryser innan täck
B32: 20 | C32: 5 | F32: 50 | H32: -10 | I32: 0 | L32: Når ej 6 MPa | M32: =Table1[[#This Row],[Kvalitet]]&Table1[[#This Row],[Gjuttemperatur]]&Table1[[#This Row],[Temperatur motgjutningsyta]]&Table1[[#This Row],[Värmekabel]]&Table1[[#This Row],[Täckning '[mm']]]&Table1[[#This Row],[OK<17 Timamr]]&Table1[[#This Row],[Kommentar]] -> C28/352054010 | N32: 70% hållfasthet
B33: 20 | C33: 5 | F33: 50 | H33: -10 | I33: 2 | L33: Når ej 6 MPa | M33: =Table1[[#This Row],[Kvalitet]]&Table1[[#This Row],[Gjuttemperatur]]&Table1[[#This Row],[Temperatur motgjutningsyta]]&Table1[[#This Row],[Värmekabel]]&Table1[[#This Row],[Täckning '[mm']]]&Table1[[#This Row],[OK<17 Timamr]]&Table1[[#This Row],[Kommentar]] -> C28/352054010 | N33: 17.5
