Workbook

Sheet Bjälklag (C20-25)
A1: Slaggmängd | B1: Gjuttemperatur | C1: Temperatur motgjutningsyta | D1: Värmekabel | E1: Antal värmekablar | F1: Täckning [mm] | G1: Formisolering [mm] | H1: Temperatur | I1: Vind | J1: <17 Timmar och >6 Mpa | K1: OK<17 Timamr | L1: Kommentar | M1: Åtgärdskåd
A2: -- | B2: - | C2: - | D2: - | E2: - | F2: - | G2: - | H2: 20 | I2: 0 | L2: Når ej 6 MPa | M2: =Table1[[#This Row],[Slaggmängd]]&Table1[[#This Row],[Gjuttemperatur]]&Table1[[#This Row],[Temperatur motgjutningsyta]]&Table1[[#This Row],[Värmekabel]]&Table1[[#This Row],[Antal värmekablar]]&Table1[[#This Row],[Täckning '[mm']]]&Table1[[#This Row],[Formisolering '[mm']]]&Table1[[#This Row],[OK<17 Timamr]]&Table1[[#This Row],[Kommentar]] -> --------Når ej 6 MPa
A3: - | B3: - | C3: - | D3: - | E3: - | F3: - | G3: - | H3: 20 | I3: 2 | L3: Når ej 6 MPa | M3: =Table1[[#This Row],[Slaggmängd]]&Table1[[#This Row],[Gjuttemperatur]]&Table1[[#This Row],[Temperatur motgjutningsyta]]&Table1[[#This Row],[Värmekabel]]&Table1[[#This Row],[Antal värmekablar]]&Table1[[#This Row],[Täckning '[mm']]]&Table1[[#This Row],[Formisolering '[mm']]]&Table1[[#This Row],[OK<17 Timamr]]&Table1[[#This Row],[Kommentar]] -> -------Når ej 6 MPa
A4: - | B4: - | C4: - | D4: - | E4: - | F4: - | G4: - | H4: 20 | I4: 7 | L4: Når ej 6 MPa | M4: =Table1[[#This Row],[Slaggmängd]]&Table1[[#This Row],[Gjuttemperatur]]&Table1[[#This Row],[Temperatur motgjutningsyta]]&Table1[[#This Row],[Värmekabel]]&Table1[[#This Row],[Antal värmekablar]]&Table1[[#This Row],[Täckning '[mm']]]&Table1[[#This Row],[Formisolering '[mm']]]&Table1[[#This Row],[OK<17 Timamr]]&Table1[[#This Row],[Kommentar]] -> -------Når ej 6 MPa
A5: - | B5: - | C5: - | D5: - | E5: - | F5: - | G5: - | H5: 20 | I5: 12 | L5: Når ej 6 MPa | M5: =Table1[[#This Row],[Slaggmängd]]&Table1[[#This Row],[Gjuttemperatur]]&Table1[[#This Row],[Temperatur motgjutningsyta]]&Table1[[#This Row],[Värmekabel]]&Table1[[#This Row],[Antal värmekablar]]&Table1[[#This Row],[Täckning '[mm']]]&Table1[[#This Row],[Formisolering '[mm']]]&Table1[[#This Row],[OK<17 Timamr]]&Table1[[#This Row],[Kommentar]] -> -------Når ej 6 MPa
A6: - | B6: - | C6: - | D6: - | E6: - | F6: - | G6: - | H6: 20 | I6: 20 | L6: Når ej 6 MPa | M6: =Table1[[#This Row],[Slaggmängd]]&Table1[[#This Row],[Gjuttemperatur]]&Table1[[#This Row],[Temperatur motgjutningsyta]]&Table1[[#This Row],[Värmekabel]]&Table1[[#This Row],[Antal värmekablar]]&Table1[[#This Row],[Täckning '[mm']]]&Table1[[#This Row],[Formisolering '[mm']]]&Table1[[#This Row],[OK<17 Timamr]]&Table1[[#This Row],[Kommentar]] -> -------Når ej 6 MPa
A7: - | B7: - | C7: - | D7: - | E7: - | F7: - | G7: - | H7: 15 | I7: 0 | L7: Når ej 6 MPa | M7: =Table1[[#This Row],[Slaggmängd]]&Table1[[#This Row],[Gjuttemperatur]]&Table1[[#This Row],[Temperatur motgjutningsyta]]&Table1[[#This Row],[Värmekabel]]&Table1[[#This Row],[Antal värmekablar]]&Table1[[#This Row],[Täckning '[mm']]]&Table1[[#This Row],[Formisolering '[mm']]]&Table1[[#This Row],[OK<17 Timamr]]&Table1[[#This Row],[Kommentar]] -> -------Når ej 6 MPa
A8: - | B8: - | C8: - | D8: - | E8: - | F8: - | G8: - | H8: 15 | I8: 2 | L8: Når ej 6 MPa | M8: =Table1[[#This Row],[Slaggmängd]]&Table1[[#This Row],[Gjuttemperatur]]&Table1[[#This Row],[Temperatur motgjutningsyta]]&Table1[[#This Row],[Värmekabel]]&Table1[[#This Row],[Antal värmekablar]]&Table1[[#This Row],[Täckning '[mm']]]&Table1[[#This Row],[Formisolering '[mm']]]&Table1[[#This Row],[OK<17 Timamr]]&Table1[[#This Row],[Kommentar]] -> -------Når ej 6 MPa
A9: - | B9: - | C9: - | D9: - | E9: - | F9: - | G9: - | H9: 15 | I9: 7 | L9: Når ej 6 MPa | M9: =Table1[[#This Row],[Slaggmängd]]&Table1[[#This Row],[Gjuttemperatur]]&Table1[[#This Row],[Temperatur motgjutningsyta]]&Table1[[#This Row],[Värmekabel]]&Table1[[#This Row],[Antal värmekablar]]&Table1[[#This Row],[Täckning '[mm']]]&Table1[[#This Row],[Formisolering '[mm']]]&Table1[[#This Row],[OK<17 Timamr]]&Table1[[#This Row],[Kommentar]] -> -------Når ej 6 MPa
A10: - | B10: - | C10: - | D10: - | E10: - | F10: - | G10: - | H10: 15 | I10: 12 | L10: Når ej 6 MPa | M10: =Table1[[#This Row],[Slaggmängd]]&Table1[[#This Row],[Gjuttemperatur]]&Table1[[#This Row],[Temperatur motgjutningsyta]]&Table1[[#This Row],[Värmekabel]]&Table1[[#This Row],[Antal värmekablar]]&Table1[[#This Row],[Täckning '[mm']]]&Table1[[#This Row],[Formisolering '[mm']]]&Table1[[#This Row],[OK<17 Timamr]]&Table1[[#This Row],[Kommentar]] -> -------Når ej 6 MPa
A11: - | B11: - | C11: - | D11: - | E11: - | F11: - | G11: - | H11: 15 | I11: 20 | L11: Når ej 6 MPa | M11: =Table1[[#This Row],[Slaggmängd]]&Table1[[#This Row],[Gjuttemperatur]]&Table1[[#This Row],[Temperatur motgjutningsyta]]&Table1[[#This Row],[Värmekabel]]&Table1[[#This Row],[Antal värmekablar]]&Table1[[#This Row],[Täckning '[mm']]]&Table1[[#This Row],[Formisolering '[mm']]]&Table1[[#This Row],[OK<17 Timamr]]&Table1[[#This Row],[Kommentar]] -> -------Når ej 6 MPa
A12: - | B12: - | C12: - | D12: - | E12: - | F12: - | G12: - | H12: 10 | I12: 0 | L12: Når ej 6 MPa | M12: =Table1[[#This Row],[Slaggmängd]]&Table1[[#This Row],[Gjuttemperatur]]&Table1[[#This Row],[Temperatur motgjutningsyta]]&Table1[[#This Row],[Värmekabel]]&Table1[[#This Row],[Antal värmekablar]]&Table1[[#This Row],[Täckning '[mm']]]&Table1[[#This Row],[Formisolering '[mm']]]&Table1[[#This Row],[OK<17 Timamr]]&Table1[[#This Row],[Kommentar]] -> -------Når ej 6 MPa
A13: - | B13: - | C13: - | D13: - | E13: - | F13: - | G13: - | H13: 10 | I13: 2 | L13: Når ej 6 MPa | M13: =Table1[[#This Row],[Slaggmängd]]&Table1[[#This Row],[Gjuttemperatur]]&Table1[[#This Row],[Temperatur motgjutningsyta]]&Table1[[#This Row],[Värmekabel]]&Table1[[#This Row],[Antal värmekablar]]&Table1[[#This Row],[Täckning '[mm']]]&Table1[[#This Row],[Formisolering '[mm']]]&Table1[[#This Row],[OK<17 Timamr]]&Table1[[#This Row],[Kommentar]] -> -------Når ej 6 MPa
... A16: - | B16: - | C16: - | D16: - | E16: - | F16: - | G16: - | H16: 10 | I16: 20 | L16: Når ej 6 MPa | M16: =Table1[[#This Row],[Slaggmängd]]&Table1[[#This Row],[Gjuttemperatur]]&Table1[[#This Row],[Temperatur motgjutningsyta]]&Table1[[#This Row],[Värmekabel]]&Table1[[#This Row],[Antal värmekablar]]&Table1[[#This Row],[Täckning '[mm']]]&Table1[[#This Row],[Formisolering '[mm']]]&Table1[[#This Row],[OK<17 Timamr]]&Table1[[#This Row],[Kommentar]] -> -------Når ej 6 MPa
A17: Bas+0% | B17: 20 | C17: 5 | D17: 40 | E17: 2 | F17: - | G17: Plywood 12-19 cellplast 50 | H17: 5 | I17: 0 | J17: 17 | K17: OK17 | M17: =Table1[[#This Row],[Slaggmängd]]&Table1[[#This Row],[Gjuttemperatur]]&Table1[[#This Row],[Temperatur motgjutningsyta]]&Table1[[#This Row],[Värmekabel]]&Table1[[#This Row],[Antal värmekablar]]&Table1[[#This Row],[Täckning '[mm']]]&Table1[[#This Row],[Formisolering '[mm']]]&Table1[[#This Row],[OK<17 Timamr]]&Table1[[#This Row],[Kommentar]] -> Bas+0%205402-Plywood 12-19 cellplast 50OK17
A18: Bas+0% | B18: 20 | C18: 5 | D18: 40 | E18: 2 | F18: 10 | G18: Plywood 12-19 cellplast 120 | H18: 5 | I18: 2 | J18: 17 | K18: OK17 | M18: =Table1[[#This Row],[Slaggmängd]]&Table1[[#This Row],[Gjuttemperatur]]&Table1[[#This Row],[Temperatur motgjutningsyta]]&Table1[[#This Row],[Värmekabel]]&Table1[[#This Row],[Antal värmekablar]]&Table1[[#This Row],[Täckning '[mm']]]&Table1[[#This Row],[Formisolering '[mm']]]&Table1[[#This Row],[OK<17 Timamr]]&Table1[[#This Row],[Kommentar]] -> Bas+0%20540210Plywood 12-19 cellplast 120OK17
A19: - | B19: - | C19: - | D19: - | E19: - | F19: - | G19: - | H19: 5 | I19: 7 | L19: Når ej 6 MPa | M19: =Table1[[#This Row],[Slaggmängd]]&Table1[[#This Row],[Gjuttemperatur]]&Table1[[#This Row],[Temperatur motgjutningsyta]]&Table1[[#This Row],[Värmekabel]]&Table1[[#This Row],[Antal värmekablar]]&Table1[[#This Row],[Täckning '[mm']]]&Table1[[#This Row],[Formisolering '[mm']]]&Table1[[#This Row],[OK<17 Timamr]]&Table1[[#This Row],[Kommentar]] -> -------Når ej 6 MPa
A20: - | B20: - | C20: - | D20: - | E20: - | F20: - | G20: - | H20: 5 | I20: 12 | L20: Når ej 6 MPa | M20: =Table1[[#This Row],[Slaggmängd]]&Table1[[#This Row],[Gjuttemperatur]]&Table1[[#This Row],[Temperatur motgjutningsyta]]&Table1[[#This Row],[Värmekabel]]&Table1[[#This Row],[Antal värmekablar]]&Table1[[#This Row],[Täckning '[mm']]]&Table1[[#This Row],[Formisolering '[mm']]]&Table1[[#This Row],[OK<17 Timamr]]&Table1[[#This Row],[Kommentar]] -> -------Når ej 6 MPa
A21: - | B21: - | C21: - | D21: - | E21: - | F21: - | G21: - | H21: 5 | I21: 20 | L21: Når ej 6 MPa | M21: =Table1[[#This Row],[Slaggmängd]]&Table1[[#This Row],[Gjuttemperatur]]&Table1[[#This Row],[Temperatur motgjutningsyta]]&Table1[[#This Row],[Värmekabel]]&Table1[[#This Row],[Antal värmekablar]]&Table1[[#This Row],[Täckning '[mm']]]&Table1[[#This Row],[Formisolering '[mm']]]&Table1[[#This Row],[OK<17 Timamr]]&Table1[[#This Row],[Kommentar]] -> -------Når ej 6 MPa
A22: Bas+0% | B22: 20 | C22: 5 | D22: 40 | E22: 3 | F22: 10 | G22: Plywood 12-19 cellplast 70 | H22: 0 | I22: 0 | J22: 16.9 | K22: OK17 | M22: =Table1[[#This Row],[Slaggmängd]]&Table1[[#This Row],[Gjuttemperatur]]&Table1[[#This Row],[Temperatur motgjutningsyta]]&Table1[[#This Row],[Värmekabel]]&Table1[[#This Row],[Antal värmekablar]]&Table1[[#This Row],[Täckning '[mm']]]&Table1[[#This Row],[Formisolering '[mm']]]&Table1[[#This Row],[OK<17 Timamr]]&Table1[[#This Row],[Kommentar]] -> Bas+0%20540310Plywood 12-19 cellplast 70OK17
A23: - | B23: - | C23: - | D23: - | E23: - | F23: - | G23: - | H23: 0 | I23: 2 | L23: Når ej 6 MPa | M23: =Table1[[#This Row],[Slaggmängd]]&Table1[[#This Row],[Gjuttemperatur]]&Table1[[#This Row],[Temperatur motgjutningsyta]]&Table1[[#This Row],[Värmekabel]]&Table1[[#This Row],[Antal värmekablar]]&Table1[[#This Row],[Täckning '[mm']]]&Table1[[#This Row],[Formisolering '[mm']]]&Table1[[#This Row],[OK<17 Timamr]]&Table1[[#This Row],[Kommentar]] -> -------Når ej 6 MPa
A24: - | B24: - | C24: - | D24: - | E24: - | F24: - | G24: - | H24: 0 | I24: 7 | L24: Når ej 6 MPa | M24: =Table1[[#This Row],[Slaggmängd]]&Table1[[#This Row],[Gjuttemperatur]]&Table1[[#This Row],[Temperatur motgjutningsyta]]&Table1[[#This Row],[Värmekabel]]&Table1[[#This Row],[Antal värmekablar]]&Table1[[#This Row],[Täckning '[mm']]]&Table1[[#This Row],[Formisolering '[mm']]]&Table1[[#This Row],[OK<17 Timamr]]&Table1[[#This Row],[Kommentar]] -> -------Når ej 6 MPa
A25: - | B25: - | C25: - | D25: - | E25: - | F25: - | G25: - | H25: 0 | I25: 12 | L25: Når ej 6 MPa | M25: =Table1[[#This Row],[Slaggmängd]]&Table1[[#This Row],[Gjuttemperatur]]&Table1[[#This Row],[Temperatur motgjutningsyta]]&Table1[[#This Row],[Värmekabel]]&Table1[[#This Row],[Antal värmekablar]]&Table1[[#This Row],[Täckning '[mm']]]&Table1[[#This Row],[Formisolering '[mm']]]&Table1[[#This Row],[OK<17 Timamr]]&Table1[[#This Row],[Kommentar]] -> -------Når ej 6 MPa
A26: - | B26: - | C26: - | D26: - | E26: - | F26: - | G26: - | H26: 0 | I26: 20 | L26: Når ej 6 MPa | M26: =Table1[[#This Row],[Slaggmängd]]&Table1[[#This Row],[Gjuttemperatur]]&Table1[[#This Row],[Temperatur motgjutningsyta]]&Table1[[#This Row],[Värmekabel]]&Table1[[#This Row],[Antal värmekablar]]&Table1[[#This Row],[Täckning '[mm']]]&Table1[[#This Row],[Formisolering '[mm']]]&Table1[[#This Row],[OK<17 Timamr]]&Table1[[#This Row],[Kommentar]] -> -------Når ej 6 MPa
A27: - | B27: - | C27: - | D27: - | E27: - | F27: - | G27: - | H27: -5 | I27: 0 | L27: Når ej 6 MPa | M27: =Table1[[#This Row],[Slaggmängd]]&Table1[[#This Row],[Gjuttemperatur]]&Table1[[#This Row],[Temperatur motgjutningsyta]]&Table1[[#This Row],[Värmekabel]]&Table1[[#This Row],[Antal värmekablar]]&Table1[[#This Row],[Täckning '[mm']]]&Table1[[#This Row],[Formisolering '[mm']]]&Table1[[#This Row],[OK<17 Timamr]]&Table1[[#This Row],[Kommentar]] -> -------Når ej 6 MPa
A28: - | B28: - | C28: - | D28: - | E28: - | F28: - | G28: - | H28: -5 | I28: 2 | L28: Når ej 6 MPa | M28: =Table1[[#This Row],[Slaggmängd]]&Table1[[#This Row],[Gjuttemperatur]]&Table1[[#This Row],[Temperatur motgjutningsyta]]&Table1[[#This Row],[Värmekabel]]&Table1[[#This Row],[Antal värmekablar]]&Table1[[#This Row],[Täckning '[mm']]]&Table1[[#This Row],[Formisolering '[mm']]]&Table1[[#This Row],[OK<17 Timamr]]&Table1[[#This Row],[Kommentar]] -> -------Når ej 6 MPa
A29: - | B29: - | C29: - | D29: - | E29: - | F29: - | G29: - | H29: -5 | I29: 7 | L29: Når ej 6 MPa | M29: =Table1[[#This Row],[Slaggmängd]]&Table1[[#This Row],[Gjuttemperatur]]&Table1[[#This Row],[Temperatur motgjutningsyta]]&Table1[[#This Row],[Värmekabel]]&Table1[[#This Row],[Antal värmekablar]]&Table1[[#This Row],[Täckning '[mm']]]&Table1[[#This Row],[Formisolering '[mm']]]&Table1[[#This Row],[OK<17 Timamr]]&Table1[[#This Row],[Kommentar]] -> -------Når ej 6 MPa
A30: - | B30: - | C30: - | D30: - | E30: - | F30: - | G30: - | H30: -5 | I30: 12 | L30: Når ej 6 MPa | M30: =Table1[[#This Row],[Slaggmängd]]&Table1[[#This Row],[Gjuttemperatur]]&Table1[[#This Row],[Temperatur motgjutningsyta]]&Table1[[#This Row],[Värmekabel]]&Table1[[#This Row],[Antal värmekablar]]&Table1[[#This Row],[Täckning '[mm']]]&Table1[[#This Row],[Formisolering '[mm']]]&Table1[[#This Row],[OK<17 Timamr]]&Table1[[#This Row],[Kommentar]] -> -------Når ej 6 MPa
A31: - | B31: - | C31: - | D31: - | E31: - | F31: - | G31: - | H31: -5 | I31: 20 | L31: Fryser innan täck | M31: =Table1[[#This Row],[Slaggmängd]]&Table1[[#This Row],[Gjuttemperatur]]&Table1[[#This Row],[Temperatur motgjutningsyta]]&Table1[[#This Row],[Värmekabel]]&Table1[[#This Row],[Antal värmekablar]]&Table1[[#This Row],[Täckning '[mm']]]&Table1[[#This Row],[Formisolering '[mm']]]&Table1[[#This Row],[OK<17 Timamr]]&Table1[[#This Row],[Kommentar]] -> -------Fryser innan täck
A32: - | B32: - | C32: - | D32: - | E32: - | F32: - | G32: - | H32: -10 | I32: 0 | L32: Når ej 6 MPa | M32: =Table1[[#This Row],[Slaggmängd]]&Table1[[#This Row],[Gjuttemperatur]]&Table1[[#This Row],[Temperatur motgjutningsyta]]&Table1[[#This Row],[Värmekabel]]&Table1[[#This Row],[Antal värmekablar]]&Table1[[#This Row],[Täckning '[mm']]]&Table1[[#This Row],[Formisolering '[mm']]]&Table1[[#This Row],[OK<17 Timamr]]&Table1[[#This Row],[Kommentar]] -> -------Når ej 6 MPa
A33: - | B33: - | C33: - | D33: - | E33: - | F33: - | G33: - | H33: -10 | I33: 2 | L33: Når ej 6 MPa | M33: =Table1[[#This Row],[Slaggmängd]]&Table1[[#This Row],[Gjuttemperatur]]&Table1[[#This Row],[Temperatur motgjutningsyta]]&Table1[[#This Row],[Värmekabel]]&Table1[[#This Row],[Antal värmekablar]]&Table1[[#This Row],[Täckning '[mm']]]&Table1[[#This Row],[Formisolering '[mm']]]&Table1[[#This Row],[OK<17 Timamr]]&Table1[[#This Row],[Kommentar]] -> -------Når ej 6 MPa
A34: - | B34: - | C34: - | D34: - | E34: - | F34: - | G34: - | H34: -10 | I34: 7 | L34: Når ej 6 MPa | M34: =Table1[[#This Row],[Slaggmängd]]&Table1[[#This Row],[Gjuttemperatur]]&Table1[[#This Row],[Temperatur motgjutningsyta]]&Table1[[#This Row],[Värmekabel]]&Table1[[#This Row],[Antal värmekablar]]&Table1[[#This Row],[Täckning '[mm']]]&Table1[[#This Row],[Formisolering '[mm']]]&Table1[[#This Row],[OK<17 Timamr]]&Table1[[#This Row],[Kommentar]] -> -------Når ej 6 MPa
... A46: - | B46: - | C46: - | D46: - | E46: - | F46: - | G46: - | H46: -20 | I46: 20 | L46: Fryser innan täck | M46: =Table1[[#This Row],[Slaggmängd]]&Table1[[#This Row],[Gjuttemperatur]]&Table1[[#This Row],[Temperatur motgjutningsyta]]&Table1[[#This Row],[Värmekabel]]&Table1[[#This Row],[Antal värmekablar]]&Table1[[#This Row],[Täckning '[mm']]]&Table1[[#This Row],[Formisolering '[mm']]]&Table1[[#This Row],[OK<17 Timamr]]&Table1[[#This Row],[Kommentar]] -> -------Fryser innan täck

Sheet Bjälklag (C25-30)
A1: Slaggmängd | B1: Gjuttemperatur | C1: Temperatur motgjutningsyta | D1: Värmekabel | E1: Antal värmekablar | F1: Täckning [mm] | G1: Formisolering [mm] | H1: Temperatur | I1: Vind | J1: <17 Timmar och >6 Mpa | K1: OK<17 Timamr | L1: Kommentar | M1: Åtgärdskåd
A2: Bas+0% | B2: 15 | C2: 20 | D2: - | E2: - | F2: - | G2: Plywood 15, oisolerat | H2: 20 | I2: 0 | J2: 15.3 | K2: OK17 | M2: =Table127[[#This Row],[Slaggmängd]]&Table127[[#This Row],[Gjuttemperatur]]&Table127[[#This Row],[Temperatur motgjutningsyta]]&Table127[[#This Row],[Värmekabel]]&Table127[[#This Row],[Antal värmekablar]]&Table127[[#This Row],[Täckning '[mm']]]&Table127[[#This Row],[Formisolering '[mm']]]&Table127[[#This Row],[OK<17 Timamr]]&Table127[[#This Row],[Kommentar]] -> Bas+0%1520---Plywood 15, oisoleratOK17
A3: Bas+0% | B3: 15 | C3: 20 | D3: - | E3: - | F3: - | G3: Plywood 15, oisolerat | H3: 20 | I3: 2 | J3: 15.3 | K3: OK17 | M3: =Table127[[#This Row],[Slaggmängd]]&Table127[[#This Row],[Gjuttemperatur]]&Table127[[#This Row],[Temperatur motgjutningsyta]]&Table127[[#This Row],[Värmekabel]]&Table127[[#This Row],[Antal värmekablar]]&Table127[[#This Row],[Täckning '[mm']]]&Table127[[#This Row],[Formisolering '[mm']]]&Table127[[#This Row],[OK<17 Timamr]]&Table127[[#This Row],[Kommentar]] -> Bas+0%1520---Plywood 15, oisoleratOK17
A4: Bas+0% | B4: 15 | C4: 20 | D4: - | E4: - | F4: - | G4: Plywood 15, oisolerat | H4: 20 | I4: 7 | J4: 15.3 | K4: OK17 | M4: =Table127[[#This Row],[Slaggmängd]]&Table127[[#This Row],[Gjuttemperatur]]&Table127[[#This Row],[Temperatur motgjutningsyta]]&Table127[[#This Row],[Värmekabel]]&Table127[[#This Row],[Antal värmekablar]]&Table127[[#This Row],[Täckning '[mm']]]&Table127[[#This Row],[Formisolering '[mm']]]&Table127[[#This Row],[OK<17 Timamr]]&Table127[[#This Row],[Kommentar]] -> Bas+0%1520---Plywood 15, oisoleratOK17
A5: Bas+0% | B5: 15 | C5: 20 | D5: - | E5: - | F5: - | G5: Plywood 15, oisolerat | H5: 20 | I5: 12 | J5: 15.3 | K5: OK17 | M5: =Table127[[#This Row],[Slaggmängd]]&Table127[[#This Row],[Gjuttemperatur]]&Table127[[#This Row],[Temperatur motgjutningsyta]]&Table127[[#This Row],[Värmekabel]]&Table127[[#This Row],[Antal värmekablar]]&Table127[[#This Row],[Täckning '[mm']]]&Table127[[#This Row],[Formisolering '[mm']]]&Table127[[#This Row],[OK<17 Timamr]]&Table127[[#This Row],[Kommentar]] -> Bas+0%1520---Plywood 15, oisoleratOK17
A6: Bas+0% | B6: 15 | C6: 20 | D6: - | E6: - | F6: - | G6: Plywood 15, oisolerat | H6: 20 | I6: 20 | J6: 15.3 | K6: OK17 | M6: =Table127[[#This Row],[Slaggmängd]]&Table127[[#This Row],[Gjuttemperatur]]&Table127[[#This Row],[Temperatur motgjutningsyta]]&Table127[[#This Row],[Värmekabel]]&Table127[[#This Row],[Antal värmekablar]]&Table127[[#This Row],[Täckning '[mm']]]&Table127[[#This Row],[Formisolering '[mm']]]&Table127[[#This Row],[OK<17 Timamr]]&Table127[[#This Row],[Kommentar]] -> Bas+0%1520---Plywood 15, oisoleratOK17
A7: - | B7: - | C7: - | D7: - | E7: - | F7: - | G7: - | H7: 15 | I7: 0 | L7: Når ej 6 MPa | M7: =Table127[[#This Row],[Slaggmängd]]&Table127[[#This Row],[Gjuttemperatur]]&Table127[[#This Row],[Temperatur motgjutningsyta]]&Table127[[#This Row],[Värmekabel]]&Table127[[#This Row],[Antal värmekablar]]&Table127[[#This Row],[Täckning '[mm']]]&Table127[[#This Row],[Formisolering '[mm']]]&Table127[[#This Row],[OK<17 Timamr]]&Table127[[#This Row],[Kommentar]] -> -------Når ej 6 MPa
A8: - | B8: - | C8: - | D8: - | E8: - | F8: - | G8: - | H8: 15 | I8: 2 | L8: Når ej 6 MPa | M8: =Table127[[#This Row],[Slaggmängd]]&Table127[[#This Row],[Gjuttemperatur]]&Table127[[#This Row],[Temperatur motgjutningsyta]]&Table127[[#This Row],[Värmekabel]]&Table127[[#This Row],[Antal värmekablar]]&Table127[[#This Row],[Täckning '[mm']]]&Table127[[#This Row],[Formisolering '[mm']]]&Table127[[#This Row],[OK<17 Timamr]]&Table127[[#This Row],[Kommentar]] -> -------Når ej 6 MPa
A9: - | B9: - | C9: - | D9: - | E9: - | F9: - | G9: - | H9: 15 | I9: 7 | L9: Når ej 6 MPa | M9: =Table127[[#This Row],[Slaggmängd]]&Table127[[#This Row],[Gjuttemperatur]]&Table127[[#This Row],[Temperatur motgjutningsyta]]&Table127[[#This Row],[Värmekabel]]&Table127[[#This Row],[Antal värmekablar]]&Table127[[#This Row],[Täckning '[mm']]]&Table127[[#This Row],[Formisolering '[mm']]]&Table127[[#This Row],[OK<17 Timamr]]&Table127[[#This Row],[Kommentar]] -> -------Når ej 6 MPa
A10: - | B10: - | C10: - | D10: - | E10: - | F10: - | G10: - | H10: 15 | I10: 12 | L10: Når ej 6 MPa | M10: =Table127[[#This Row],[Slaggmängd]]&Table127[[#This Row],[Gjuttemperatur]]&Table127[[#This Row],[Temperatur motgjutningsyta]]&Table127[[#This Row],[Värmekabel]]&Table127[[#This Row],[Antal värmekablar]]&Table127[[#This Row],[Täckning '[mm']]]&Table127[[#This Row],[Formisolering '[mm']]]&Table127[[#This Row],[OK<17 Timamr]]&Table127[[#This Row],[Kommentar]] -> -------Når ej 6 MPa
A11: - | B11: - | C11: - | D11: - | E11: - | F11: - | G11: - | H11: 15 | I11: 20 | L11: Når ej 6 MPa | M11: =Table127[[#This Row],[Slaggmängd]]&Table127[[#This Row],[Gjuttemperatur]]&Table127[[#This Row],[Temperatur motgjutningsyta]]&Table127[[#This Row],[Värmekabel]]&Table127[[#This Row],[Antal värmekablar]]&Table127[[#This Row],[Täckning '[mm']]]&Table127[[#This Row],[Formisolering '[mm']]]&Table127[[#This Row],[OK<17 Timamr]]&Table127[[#This Row],[Kommentar]] -> -------Når ej 6 MPa
A12: - | B12: - | C12: - | D12: - | E12: - | F12: - | G12: - | H12: 10 | I12: 0 | L12: Når ej 6 MPa | M12: =Table127[[#This Row],[Slaggmängd]]&Table127[[#This Row],[Gjuttemperatur]]&Table127[[#This Row],[Temperatur motgjutningsyta]]&Table127[[#This Row],[Värmekabel]]&Table127[[#This Row],[Antal värmekablar]]&Table127[[#This Row],[Täckning '[mm']]]&Table127[[#This Row],[Formisolering '[mm']]]&Table127[[#This Row],[OK<17 Timamr]]&Table127[[#This Row],[Kommentar]] -> -------Når ej 6 MPa
A13: - | B13: - | C13: - | D13: - | E13: - | F13: - | G13: - | H13: 10 | I13: 2 | L13: Når ej 6 MPa | M13: =Table127[[#This Row],[Slaggmängd]]&Table127[[#This Row],[Gjuttemperatur]]&Table127[[#This Row],[Temperatur motgjutningsyta]]&Table127[[#This Row],[Värmekabel]]&Table127[[#This Row],[Antal värmekablar]]&Table127[[#This Row],[Täckning '[mm']]]&Table127[[#This Row],[Formisolering '[mm']]]&Table127[[#This Row],[OK<17 Timamr]]&Table127[[#This Row],[Kommentar]] -> -------Når ej 6 MPa
A14: - | B14: - | C14: - | D14: - | E14: - | F14: - | G14: - | H14: 10 | I14: 7 | L14: Når ej 6 MPa | M14: =Table127[[#This Row],[Slaggmängd]]&Table127[[#This Row],[Gjuttemperatur]]&Table127[[#This Row],[Temperatur motgjutningsyta]]&Table127[[#This Row],[Värmekabel]]&Table127[[#This Row],[Antal värmekablar]]&Table127[[#This Row],[Täckning '[mm']]]&Table127[[#This Row],[Formisolering '[mm']]]&Table127[[#This Row],[OK<17 Timamr]]&Table127[[#This Row],[Kommentar]] -> -------Når ej 6 MPa
A15: - | B15: - | C15: - | D15: - | E15: - | F15: - | G15: - | H15: 10 | I15: 12 | L15: Når ej 6 MPa | M15: =Table127[[#This Row],[Slaggmängd]]&Table127[[#This Row],[Gjuttemperatur]]&Table127[[#This Row],[Temperatur motgjutningsyta]]&Table127[[#This Row],[Värmekabel]]&Table127[[#This Row],[Antal värmekablar]]&Table127[[#This Row],[Täckning '[mm']]]&Table127[[#This Row],[Formisolering '[mm']]]&Table127[[#This Row],[OK<17 Timamr]]&Table127[[#This Row],[Kommentar]] -> -------Når ej 6 MPa
A16: - | B16: - | C16: - | D16: - | E16: - | F16: - | G16: - | H16: 10 | I16: 20 | L16: Når ej 6 MPa | M16: =Table127[[#This Row],[Slaggmängd]]&Table127[[#This Row],[Gjuttemperatur]]&Table127[[#This Row],[Temperatur motgjutningsyta]]&Table127[[#This Row],[Värmekabel]]&Table127[[#This Row],[Antal värmekablar]]&Table127[[#This Row],[Täckning '[mm']]]&Table127[[#This Row],[Formisolering '[mm']]]&Table127[[#This Row],[OK<17 Timamr]]&Table127[[#This Row],[Kommentar]] -> -------Når ej 6 MPa
A17: 0.1 | B17: 20 | C17: 5 | D17: 40 | E17: 3 | F17: 10 | G17: Plywood 12-19 cellplast 50 | H17: 5 | I17: 0 | J17: 17 | K17: OK17 | M17: =Table127[[#This Row],[Slaggmängd]]&Table127[[#This Row],[Gjuttemperatur]]&Table127[[#This Row],[Temperatur motgjutningsyta]]&Table127[[#This Row],[Värmekabel]]&Table127[[#This Row],[Antal värmekablar]]&Table127[[#This Row],[Täckning '[mm']]]&Table127[[#This Row],[Formisolering '[mm']]]&Table127[[#This Row],[OK<17 Timamr]]&Table127[[#This Row],[Kommentar]] -> 0,120540310Plywood 12-19 cellplast 50OK17
A18: 0.1 | B18: 20 | C18: 5 | D18: 40 | E18: 3 | F18: 10 | G18: Plywood 12-19 cellplast 70 | H18: 5 | I18: 2 | J18: 17 | K18: OK17 | M18: =Table127[[#This Row],[Slaggmängd]]&Table127[[#This Row],[Gjuttemperatur]]&Table127[[#This Row],[Temperatur motgjutningsyta]]&Table127[[#This Row],[Värmekabel]]&Table127[[#This Row],[Antal värmekablar]]&Table127[[#This Row],[Täckning '[mm']]]&Table127[[#This Row],[Formisolering '[mm']]]&Table127[[#This Row],[OK<17 Timamr]]&Table127[[#This Row],[Kommentar]] -> 0,120540310Plywood 12-19 cellplast 70OK17
A19: Bas+0% | B19: 20 | C19: 5 | D19: 40 | E19: 1 | F19: 10 | G19: Plywood 12-19 cellplast 50 | H19: 5 | I19: 7 | J19: 16.9 | K19: OK17 | M19: =Table127[[#This Row],[Slaggmängd]]&Table127[[#This Row],[Gjuttemperatur]]&Table127[[#This Row],[Temperatur motgjutningsyta]]&Table127[[#This Row],[Värmekabel]]&Table127[[#This Row],[Antal värmekablar]]&Table127[[#This Row],[Täckning '[mm']]]&Table127[[#This Row],[Formisolering '[mm']]]&Table127[[#This Row],[OK<17 Timamr]]&Table127[[#This Row],[Kommentar]] -> Bas+0%20540110Plywood 12-19 cellplast 50OK17
A20: Bas+0% | B20: 20 | C20: 5 | D20: 40 | E20: 1 | F20: 10 | G20: Plywood 12-19 cellplast 70 | H20: 5 | I20: 12 | J20: 16.9 | K20: OK17 | M20: =Table127[[#This Row],[Slaggmängd]]&Table127[[#This Row],[Gjuttemperatur]]&Table127[[#This Row],[Temperatur motgjutningsyta]]&Table127[[#This Row],[Värmekabel]]&Table127[[#This Row],[Antal värmekablar]]&Table127[[#This Row],[Täckning '[mm']]]&Table127[[#This Row],[Formisolering '[mm']]]&Table127[[#This Row],[OK<17 Timamr]]&Table127[[#This Row],[Kommentar]] -> Bas+0%20540110Plywood 12-19 cellplast 70OK17
A21: Bas+0% | B21: 20 | C21: 5 | D21: 40 | E21: 1 | F21: 10 | G21: Plywood 12-19 cellplast 100 | H21: 5 | I21: 20 | J21: 17 | K21: OK17 | M21: =Table127[[#This Row],[Slaggmängd]]&Table127[[#This Row],[Gjuttemperatur]]&Table127[[#This Row],[Temperatur motgjutningsyta]]&Table127[[#This Row],[Värmekabel]]&Table127[[#This Row],[Antal värmekablar]]&Table127[[#This Row],[Täckning '[mm']]]&Table127[[#This Row],[Formisolering '[mm']]]&Table127[[#This Row],[OK<17 Timamr]]&Table127[[#This Row],[Kommentar]] -> Bas+0%20540110Plywood 12-19 cellplast 100OK17
A22: 0.1 | B22: 20 | C22: 5 | D22: 40 | E22: 3 | F22: 10 | G22: Plywood 12-19 cellplast 70 | H22: 0 | I22: 0 | J22: 17 | K22: OK17 | M22: =Table127[[#This Row],[Slaggmängd]]&Table127[[#This Row],[Gjuttemperatur]]&Table127[[#This Row],[Temperatur motgjutningsyta]]&Table127[[#This Row],[Värmekabel]]&Table127[[#This Row],[Antal värmekablar]]&Table127[[#This Row],[Täckning '[mm']]]&Table127[[#This Row],[Formisolering '[mm']]]&Table127[[#This Row],[OK<17 Timamr]]&Table127[[#This Row],[Kommentar]] -> 0,120540310Plywood 12-19 cellplast 70OK17
A23: Bas+0% | B23: 20 | C23: 5 | D23: 40 | E23: 1 | F23: 10 | G23: Plywood 12-19 cellplast 120 | H23: 0 | I23: 2 | J23: 17 | K23: OK17 | M23: =Table127[[#This Row],[Slaggmängd]]&Table127[[#This Row],[Gjuttemperatur]]&Table127[[#This Row],[Temperatur motgjutningsyta]]&Table127[[#This Row],[Värmekabel]]&Table127[[#This Row],[Antal värmekablar]]&Table127[[#This Row],[Täckning '[mm']]]&Table127[[#This Row],[Formisolering '[mm']]]&Table127[[#This Row],[OK<17 Timamr]]&Table127[[#This Row],[Kommentar]] -> Bas+0%20540110Plywood 12-19 cellplast 120OK17
A24: Bas+0% | B24: 20 | C24: 5 | D24: 40 | E24: 2 | F24: 10 | G24: Plywood 12-19 cellplast 70 | H24: 0 | I24: 7 | J24: 16.8 | K24: OK17 | M24: =Table127[[#This Row],[Slaggmängd]]&Table127[[#This Row],[Gjuttemperatur]]&Table127[[#This Row],[Temperatur motgjutningsyta]]&Table127[[#This Row],[Värmekabel]]&Table127[[#This Row],[Antal värmekablar]]&Table127[[#This Row],[Täckning '[mm']]]&Table127[[#This Row],[Formisolering '[mm']]]&Table127[[#This Row],[OK<17 Timamr]]&Table127[[#This Row],[Kommentar]] -> Bas+0%20540210Plywood 12-19 cellplast 70OK17
A25: Bas+0% | B25: 20 | C25: 5 | D25: 40 | E25: 2 | F25: 10 | G25: Plywood 12-19 cellplast 120 | H25: 0 | I25: 12 | J25: 17 | K25: OK17 | M25: =Table127[[#This Row],[Slaggmängd]]&Table127[[#This Row],[Gjuttemperatur]]&Table127[[#This Row],[Temperatur motgjutningsyta]]&Table127[[#This Row],[Värmekabel]]&Table127[[#This Row],[Antal värmekablar]]&Table127[[#This Row],[Täckning '[mm']]]&Table127[[#This Row],[Formisolering '[mm']]]&Table127[[#This Row],[OK<17 Timamr]]&Table127[[#This Row],[Kommentar]] -> Bas+0%20540210Plywood 12-19 cellplast 120OK17
A26: - | B26: - | C26: - | D26: - | E26: - | F26: - | G26: - | H26: 0 | I26: 20 | L26: Når ej 6 MPa | M26: =Table127[[#This Row],[Slaggmängd]]&Table127[[#This Row],[Gjuttemperatur]]&Table127[[#This Row],[Temperatur motgjutningsyta]]&Table127[[#This Row],[Värmekabel]]&Table127[[#This Row],[Antal värmekablar]]&Table127[[#This Row],[Täckning '[mm']]]&Table127[[#This Row],[Formisolering '[mm']]]&Table127[[#This Row],[OK<17 Timamr]]&Table127[[#This Row],[Kommentar]] -> -------Når ej 6 MPa
A27: Bas+0% | B27: 20 | C27: 5 | D27: 40 | E27: 1 | F27: 10 | G27: Plywood 12-19 cellplast 100 | H27: -5 | I27: 0 | J27: 17 | K27: OK17 | M27: =Table127[[#This Row],[Slaggmängd]]&Table127[[#This Row],[Gjuttemperatur]]&Table127[[#This Row],[Temperatur motgjutningsyta]]&Table127[[#This Row],[Värmekabel]]&Table127[[#This Row],[Antal värmekablar]]&Table127[[#This Row],[Täckning '[mm']]]&Table127[[#This Row],[Formisolering '[mm']]]&Table127[[#This Row],[OK<17 Timamr]]&Table127[[#This Row],[Kommentar]] -> Bas+0%20540110Plywood 12-19 cellplast 100OK17
A28: Bas+0% | B28: 20 | C28: 5 | D28: 40 | E28: 2 | F28: 10 | G28: Plywood 12-19 cellplast 70 | H28: -5 | I28: 2 | J28: 16.8 | K28: OK17 | M28: =Table127[[#This Row],[Slaggmängd]]&Table127[[#This Row],[Gjuttemperatur]]&Table127[[#This Row],[Temperatur motgjutningsyta]]&Table127[[#This Row],[Värmekabel]]&Table127[[#This Row],[Antal värmekablar]]&Table127[[#This Row],[Täckning '[mm']]]&Table127[[#This Row],[Formisolering '[mm']]]&Table127[[#This Row],[OK<17 Timamr]]&Table127[[#This Row],[Kommentar]] -> Bas+0%20540210Plywood 12-19 cellplast 70OK17
A29: - | B29: - | C29: - | D29: - | E29: - | F29: - | G29: - | H29: -5 | I29: 7 | L29: Når ej 6 MPa | M29: =Table127[[#This Row],[Slaggmängd]]&Table127[[#This Row],[Gjuttemperatur]]&Table127[[#This Row],[Temperatur motgjutningsyta]]&Table127[[#This Row],[Värmekabel]]&Table127[[#This Row],[Antal värmekablar]]&Table127[[#This Row],[Täckning '[mm']]]&Table127[[#This Row],[Formisolering '[mm']]]&Table127[[#This Row],[OK<17 Timamr]]&Table127[[#This Row],[Kommentar]] -> -------Når ej 6 MPa
A30: - | B30: - | C30: - | D30: - | E30: - | F30: - | G30: - | H30: -5 | I30: 12 | L30: Når ej 6 MPa | M30: =Table127[[#This Row],[Slaggmängd]]&Table127[[#This Row],[Gjuttemperatur]]&Table127[[#This Row],[Temperatur motgjutningsyta]]&Table127[[#This Row],[Värmekabel]]&Table127[[#This Row],[Antal värmekablar]]&Table127[[#This Row],[Täckning '[mm']]]&Table127[[#This Row],[Formisolering '[mm']]]&Table127[[#This Row],[OK<17 Timamr]]&Table127[[#This Row],[Kommentar]] -> -------Når ej 6 MPa
A31: - | B31: - | C31: - | D31: - | E31: - | F31: - | G31: - | H31: -5 | I31: 20 | L31: Fryser innan täck | M31: =Table127[[#This Row],[Slaggmängd]]&Table127[[#This Row],[Gjuttemperatur]]&Table127[[#This Row],[Temperatur motgjutningsyta]]&Table127[[#This Row],[Värmekabel]]&Table127[[#This Row],[Antal värmekablar]]&Table127[[#This Row],[Täckning '[mm']]]&Table127[[#This Row],[Formisolering '[mm']]]&Table127[[#This Row],[OK<17 Timamr]]&Table127[[#This Row],[Kommentar]] -> -------Fryser innan täck
A32: Bas+0% | B32: 20 | C32: 5 | D32: 40 | E32: 2 | F32: 10 | G32: Plywood 12-19 cellplast 50 | H32: -10 | I32: 0 | J32: 16.7 | K32: OK17 | M32: =Table127[[#This Row],[Slaggmängd]]&Table127[[#This Row],[Gjuttemperatur]]&Table127[[#This Row],[Temperatur motgjutningsyta]]&Table127[[#This Row],[Värmekabel]]&Table127[[#This Row],[Antal värmekablar]]&Table127[[#This Row],[Täckning '[mm']]]&Table127[[#This Row],[Formisolering '[mm']]]&Table127[[#This Row],[OK<17 Timamr]]&Table127[[#This Row],[Kommentar]] -> Bas+0%20540210Plywood 12-19 cellplast 50OK17
A33: Bas+0% | B33: 20 | C33: 5 | D33: 40 | E33: 3 | F33: 10 | G33: Plywood 12-19 cellplast 120 | H33: -10 | I33: 2 | J33: 16.9 | K33: OK17 | M33: =Table127[[#This Row],[Slaggmängd]]&Table127[[#This Row],[Gjuttemperatur]]&Table127[[#This Row],[Temperatur motgjutningsyta]]&Table127[[#This Row],[Värmekabel]]&Table127[[#This Row],[Antal värmekablar]]&Table127[[#This Row],[Täckning '[mm']]]&Table127[[#This Row],[Formisolering '[mm']]]&Table127[[#This Row],[OK<17 Timamr]]&Table127[[#This Row],[Kommentar]] -> Bas+0%20540310Plywood 12-19 cellplast 120OK17
A34: - | B34: - | C34: - | D34: - | E34: - | F34: - | G34: - | H34: -10 | I34: 7 | L34: Når ej 6 MPa | M34: =Table127[[#This Row],[Slaggmängd]]&Table127[[#This Row],[Gjuttemperatur]]&Table127[[#This Row],[Temperatur motgjutningsyta]]&Table127[[#This Row],[Värmekabel]]&Table127[[#This Row],[Antal värmekablar]]&Table127[[#This Row],[Täckning '[mm']]]&Table127[[#This Row],[Formisolering '[mm']]]&Table127[[#This Row],[OK<17 Timamr]]&Table127[[#This Row],[Kommentar]] -> -------Når ej 6 MPa
A35: - | B35: - | C35: - | D35: - | E35: - | F35: - | G35: - | H35: -10 | I35: 12 | L35: Fryser innan täck | M35: =Table127[[#This Row],[Slaggmängd]]&Table127[[#This Row],[Gjuttemperatur]]&Table127[[#This Row],[Temperatur motgjutningsyta]]&Table127[[#This Row],[Värmekabel]]&Table127[[#This Row],[Antal värmekablar]]&Table127[[#This Row],[Täckning '[mm']]]&Table127[[#This Row],[Formisolering '[mm']]]&Table127[[#This Row],[OK<17 Timamr]]&Table127[[#This Row],[Kommentar]] -> -------Fryser innan täck
A36: - | B36: - | C36: - | D36: - | E36: - | F36: - | G36: - | H36: -10 | I36: 20 | L36: Fryser innan täck | M36: =Table127[[#This Row],[Slaggmängd]]&Table127[[#This Row],[Gjuttemperatur]]&Table127[[#This Row],[Temperatur motgjutningsyta]]&Table127[[#This Row],[Värmekabel]]&Table127[[#This Row],[Antal värmekablar]]&Table127[[#This Row],[Täckning '[mm']]]&Table127[[#This Row],[Formisolering '[mm']]]&Table127[[#This Row],[OK<17 Timamr]]&Table127[[#This Row],[Kommentar]] -> -------Fryser innan täck
A37: - | B37: - | C37: - | D37: - | E37: - | F37: - | G37: - | H37: -15 | I37: 0 | L37: Når ej 6 MPa | M37: =Table127[[#This Row],[Slaggmängd]]&Table127[[#This Row],[Gjuttemperatur]]&Table127[[#This Row],[Temperatur motgjutningsyta]]&Table127[[#This Row],[Värmekabel]]&Table127[[#This Row],[Antal värmekablar]]&Table127[[#This Row],[Täckning '[mm']]]&Table127[[#This Row],[Formisolering '[mm']]]&Table127[[#This Row],[OK<17 Timamr]]&Table127[[#This Row],[Kommentar]] -> -------Når ej 6 MPa
A38: - | B38: - | C38: - | D38: - | E38: - | F38: - | G38: - | H38: -15 | I38: 2 | L38: Når ej 6 MPa | M38: =Table127[[#This Row],[Slaggmängd]]&Table127[[#This Row],[Gjuttemperatur]]&Table127[[#This Row],[Temperatur motgjutningsyta]]&Table127[[#This Row],[Värmekabel]]&Table127[[#This Row],[Antal värmekablar]]&Table127[[#This Row],[Täckning '[mm']]]&Table127[[#This Row],[Formisolering '[mm']]]&Table127[[#This Row],[OK<17 Timamr]]&Table127[[#This Row],[Kommentar]] -> -------Når ej 6 MPa
A39: - | B39: - | C39: - | D39: - | E39: - | F39: - | G39: - | H39: -15 | I39: 7 | L39: Fryser innan täck | M39: =Table127[[#This Row],[Slaggmängd]]&Table127[[#This Row],[Gjuttemperatur]]&Table127[[#This Row],[Temperatur motgjutningsyta]]&Table127[[#This Row],[Värmekabel]]&Table127[[#This Row],[Antal värmekablar]]&Table127[[#This Row],[Täckning '[mm']]]&Table127[[#This Row],[Formisolering '[mm']]]&Table127[[#This Row],[OK<17 Timamr]]&Table127[[#This Row],[Kommentar]] -> -------Fryser innan täck
A40: - | B40: - | C40: - | D40: - | E40: - | F40: - | G40: - | H40: -15 | I40: 12 | L40: Fryser innan täck | M40: =Table127[[#This Row],[Slaggmängd]]&Table127[[#This Row],[Gjuttemperatur]]&Table127[[#This Row],[Temperatur motgjutningsyta]]&Table127[[#This Row],[Värmekabel]]&Table127[[#This Row],[Antal värmekablar]]&Table127[[#This Row],[Täckning '[mm']]]&Table127[[#This Row],[Formisolering '[mm']]]&Table127[[#This Row],[OK<17 Timamr]]&Table127[[#This Row],[Kommentar]] -> -------Fryser innan täck
...

Sheet Bjälklag (C28-35)
A1: Slaggmängd | B1: Gjuttemperatur | C1: Temperatur motgjutningsyta | D1: Värmekabel | E1: Antal värmekablar | F1: Täckning [mm] | G1: Formisolering [mm] | H1: Temperatur | I1: Vind | J1: <17 Timmar och >6 Mpa | K1: OK<17 Timamr | L1: Kommentar | M1: Åtgärdskåd
A2: 0.1 | B2: 15 | C2: 20 | D2: - | E2: - | F2: - | G2: Plywood 15, oisolerat | H2: 20 | I2: 0 | J2: 15.3 | K2: OK17 | M2: =Table128[[#This Row],[Slaggmängd]]&Table128[[#This Row],[Gjuttemperatur]]&Table128[[#This Row],[Temperatur motgjutningsyta]]&Table128[[#This Row],[Värmekabel]]&Table128[[#This Row],[Antal värmekablar]]&Table128[[#This Row],[Täckning '[mm']]]&Table128[[#This Row],[Formisolering '[mm']]]&Table128[[#This Row],[OK<17 Timamr]]&Table128[[#This Row],[Kommentar]] -> 0,11520---Plywood 15, oisoleratOK17
A3: 0.1 | B3: 15 | C3: 20 | D3: - | E3: - | F3: - | G3: Plywood 15, oisolerat | H3: 20 | I3: 2 | J3: 15.3 | K3: OK17 | M3: =Table128[[#This Row],[Slaggmängd]]&Table128[[#This Row],[Gjuttemperatur]]&Table128[[#This Row],[Temperatur motgjutningsyta]]&Table128[[#This Row],[Värmekabel]]&Table128[[#This Row],[Antal värmekablar]]&Table128[[#This Row],[Täckning '[mm']]]&Table128[[#This Row],[Formisolering '[mm']]]&Table128[[#This Row],[OK<17 Timamr]]&Table128[[#This Row],[Kommentar]] -> 0,11520---Plywood 15, oisoleratOK17
A4: 0.1 | B4: 15 | C4: 20 | D4: - | E4: - | F4: - | G4: Plywood 15, oisolerat | H4: 20 | I4: 7 | J4: 15.3 | K4: OK17 | M4: =Table128[[#This Row],[Slaggmängd]]&Table128[[#This Row],[Gjuttemperatur]]&Table128[[#This Row],[Temperatur motgjutningsyta]]&Table128[[#This Row],[Värmekabel]]&Table128[[#This Row],[Antal värmekablar]]&Table128[[#This Row],[Täckning '[mm']]]&Table128[[#This Row],[Formisolering '[mm']]]&Table128[[#This Row],[OK<17 Timamr]]&Table128[[#This Row],[Kommentar]] -> 0,11520---Plywood 15, oisoleratOK17
A5: 0.1 | B5: 15 | C5: 20 | D5: - | E5: - | F5: - | G5: Plywood 15, oisolerat | H5: 20 | I5: 12 | J5: 15.3 | K5: OK17 | M5: =Table128[[#This Row],[Slaggmängd]]&Table128[[#This Row],[Gjuttemperatur]]&Table128[[#This Row],[Temperatur motgjutningsyta]]&Table128[[#This Row],[Värmekabel]]&Table128[[#This Row],[Antal värmekablar]]&Table128[[#This Row],[Täckning '[mm']]]&Table128[[#This Row],[Formisolering '[mm']]]&Table128[[#This Row],[OK<17 Timamr]]&Table128[[#This Row],[Kommentar]] -> 0,11520---Plywood 15, oisoleratOK17
A6: 0.1 | B6: 15 | C6: 20 | D6: - | E6: - | F6: - | G6: Plywood 15, oisolerat | H6: 20 | I6: 20 | J6: 15.3 | K6: OK17 | M6: =Table128[[#This Row],[Slaggmängd]]&Table128[[#This Row],[Gjuttemperatur]]&Table128[[#This Row],[Temperatur motgjutningsyta]]&Table128[[#This Row],[Värmekabel]]&Table128[[#This Row],[Antal värmekablar]]&Table128[[#This Row],[Täckning '[mm']]]&Table128[[#This Row],[Formisolering '[mm']]]&Table128[[#This Row],[OK<17 Timamr]]&Table128[[#This Row],[Kommentar]] -> 0,11520---Plywood 15, oisoleratOK17
A7: Bas+0% | B7: 15 | C7: 15 | D7: - | E7: - | F7: - | G7: Plywood 15, oisolerat | H7: 15 | I7: 0 | J7: 15.7 | K7: OK17 | M7: =Table128[[#This Row],[Slaggmängd]]&Table128[[#This Row],[Gjuttemperatur]]&Table128[[#This Row],[Temperatur motgjutningsyta]]&Table128[[#This Row],[Värmekabel]]&Table128[[#This Row],[Antal värmekablar]]&Table128[[#This Row],[Täckning '[mm']]]&Table128[[#This Row],[Formisolering '[mm']]]&Table128[[#This Row],[OK<17 Timamr]]&Table128[[#This Row],[Kommentar]] -> Bas+0%1515---Plywood 15, oisoleratOK17
A8: Bas+0% | B8: 15 | C8: 15 | D8: - | E8: - | F8: - | G8: Plywood 15, oisolerat | H8: 15 | I8: 2 | J8: 15.9 | K8: OK17 | M8: =Table128[[#This Row],[Slaggmängd]]&Table128[[#This Row],[Gjuttemperatur]]&Table128[[#This Row],[Temperatur motgjutningsyta]]&Table128[[#This Row],[Värmekabel]]&Table128[[#This Row],[Antal värmekablar]]&Table128[[#This Row],[Täckning '[mm']]]&Table128[[#This Row],[Formisolering '[mm']]]&Table128[[#This Row],[OK<17 Timamr]]&Table128[[#This Row],[Kommentar]] -> Bas+0%1515---Plywood 15, oisoleratOK17
A9: Bas+0% | B9: 15 | C9: 15 | D9: - | E9: - | F9: - | G9: Plywood 15, oisolerat | H9: 15 | I9: 7 | J9: 16 | K9: OK17 | M9: =Table128[[#This Row],[Slaggmängd]]&Table128[[#This Row],[Gjuttemperatur]]&Table128[[#This Row],[Temperatur motgjutningsyta]]&Table128[[#This Row],[Värmekabel]]&Table128[[#This Row],[Antal värmekablar]]&Table128[[#This Row],[Täckning '[mm']]]&Table128[[#This Row],[Formisolering '[mm']]]&Table128[[#This Row],[OK<17 Timamr]]&Table128[[#This Row],[Kommentar]] -> Bas+0%1515---Plywood 15, oisoleratOK17
A10: Bas+0% | B10: 15 | C10: 15 | D10: - | E10: - | F10: - | G10: Plywood 15, oisolerat | H10: 15 | I10: 12 | J10: 16.1 | K10: OK17 | M10: =Table128[[#This Row],[Slaggmängd]]&Table128[[#This Row],[Gjuttemperatur]]&Table128[[#This Row],[Temperatur motgjutningsyta]]&Table128[[#This Row],[Värmekabel]]&Table128[[#This Row],[Antal värmekablar]]&Table128[[#This Row],[Täckning '[mm']]]&Table128[[#This Row],[Formisolering '[mm']]]&Table128[[#This Row],[OK<17 Timamr]]&Table128[[#This Row],[Kommentar]] -> Bas+0%1515---Plywood 15, oisoleratOK17
A11: Bas+0% | B11: 15 | C11: 15 | D11: - | E11: - | F11: - | G11: Plywood 15, oisolerat | H11: 15 | I11: 20 | J11: 16.1 | K11: OK17 | M11: =Table128[[#This Row],[Slaggmängd]]&Table128[[#This Row],[Gjuttemperatur]]&Table128[[#This Row],[Temperatur motgjutningsyta]]&Table128[[#This Row],[Värmekabel]]&Table128[[#This Row],[Antal värmekablar]]&Table128[[#This Row],[Täckning '[mm']]]&Table128[[#This Row],[Formisolering '[mm']]]&Table128[[#This Row],[OK<17 Timamr]]&Table128[[#This Row],[Kommentar]] -> Bas+0%1515---Plywood 15, oisoleratOK17
A12: - | B12: - | C12: - | D12: - | E12: - | F12: - | G12: - | H12: 10 | I12: 0 | L12: Når ej 6 MPa | M12: =Table128[[#This Row],[Slaggmängd]]&Table128[[#This Row],[Gjuttemperatur]]&Table128[[#This Row],[Temperatur motgjutningsyta]]&Table128[[#This Row],[Värmekabel]]&Table128[[#This Row],[Antal värmekablar]]&Table128[[#This Row],[Täckning '[mm']]]&Table128[[#This Row],[Formisolering '[mm']]]&Table128[[#This Row],[OK<17 Timamr]]&Table128[[#This Row],[Kommentar]] -> -------Når ej 6 MPa
A13: - | B13: - | C13: - | D13: - | E13: - | F13: - | G13: - | H13: 10 | I13: 2 | L13: Når ej 6 MPa | M13: =Table128[[#This Row],[Slaggmängd]]&Table128[[#This Row],[Gjuttemperatur]]&Table128[[#This Row],[Temperatur motgjutningsyta]]&Table128[[#This Row],[Värmekabel]]&Table128[[#This Row],[Antal värmekablar]]&Table128[[#This Row],[Täckning '[mm']]]&Table128[[#This Row],[Formisolering '[mm']]]&Table128[[#This Row],[OK<17 Timamr]]&Table128[[#This Row],[Kommentar]] -> -------Når ej 6 MPa
A14: - | B14: - | C14: - | D14: - | E14: - | F14: - | G14: - | H14: 10 | I14: 7 | L14: Når ej 6 MPa | M14: =Table128[[#This Row],[Slaggmängd]]&Table128[[#This Row],[Gjuttemperatur]]&Table128[[#This Row],[Temperatur motgjutningsyta]]&Table128[[#This Row],[Värmekabel]]&Table128[[#This Row],[Antal värmekablar]]&Table128[[#This Row],[Täckning '[mm']]]&Table128[[#This Row],[Formisolering '[mm']]]&Table128[[#This Row],[OK<17 Timamr]]&Table128[[#This Row],[Kommentar]] -> -------Når ej 6 MPa
A15: - | B15: - | C15: - | D15: - | E15: - | F15: - | G15: - | H15: 10 | I15: 12 | L15: Når ej 6 MPa | M15: =Table128[[#This Row],[Slaggmängd]]&Table128[[#This Row],[Gjuttemperatur]]&Table128[[#This Row],[Temperatur motgjutningsyta]]&Table128[[#This Row],[Värmekabel]]&Table128[[#This Row],[Antal värmekablar]]&Table128[[#This Row],[Täckning '[mm']]]&Table128[[#This Row],[Formisolering '[mm']]]&Table128[[#This Row],[OK<17 Timamr]]&Table128[[#This Row],[Kommentar]] -> -------Når ej 6 MPa
A16: - | B16: - | C16: - | D16: - | E16: - | F16: - | G16: - | H16: 10 | I16: 20 | L16: Når ej 6 MPa | M16: =Table128[[#This Row],[Slaggmängd]]&Table128[[#This Row],[Gjuttemperatur]]&Table128[[#This Row],[Temperatur motgjutningsyta]]&Table128[[#This Row],[Värmekabel]]&Table128[[#This Row],[Antal värmekablar]]&Table128[[#This Row],[Täckning '[mm']]]&Table128[[#This Row],[Formisolering '[mm']]]&Table128[[#This Row],[OK<17 Timamr]]&Table128[[#This Row],[Kommentar]] -> -------Når ej 6 MPa
A17: 0.2 | B17: 20 | C17: 5 | D17: 40 | E17: 2 | F17: - | G17: Plywood 12-19 cellplast 100 | H17: 5 | I17: 0 | J17: 17 | K17: OK17 | M17: =Table128[[#This Row],[Slaggmängd]]&Table128[[#This Row],[Gjuttemperatur]]&Table128[[#This Row],[Temperatur motgjutningsyta]]&Table128[[#This Row],[Värmekabel]]&Table128[[#This Row],[Antal värmekablar]]&Table128[[#This Row],[Täckning '[mm']]]&Table128[[#This Row],[Formisolering '[mm']]]&Table128[[#This Row],[OK<17 Timamr]]&Table128[[#This Row],[Kommentar]] -> 0,2205402-Plywood 12-19 cellplast 100OK17
A18: 0.2 | B18: 20 | C18: 5 | D18: 40 | E18: 3 | F18: 10 | G18: Plywood 12-19 cellplast 120 | H18: 5 | I18: 2 | J18: 17 | K18: OK17 | M18: =Table128[[#This Row],[Slaggmängd]]&Table128[[#This Row],[Gjuttemperatur]]&Table128[[#This Row],[Temperatur motgjutningsyta]]&Table128[[#This Row],[Värmekabel]]&Table128[[#This Row],[Antal värmekablar]]&Table128[[#This Row],[Täckning '[mm']]]&Table128[[#This Row],[Formisolering '[mm']]]&Table128[[#This Row],[OK<17 Timamr]]&Table128[[#This Row],[Kommentar]] -> 0,220540310Plywood 12-19 cellplast 120OK17
A19: 0.1 | B19: 20 | C19: 5 | D19: 40 | E19: 1 | F19: 10 | G19: Plywood 12-19 cellplast 50 | H19: 5 | I19: 7 | J19: 16.9 | K19: OK17 | M19: =Table128[[#This Row],[Slaggmängd]]&Table128[[#This Row],[Gjuttemperatur]]&Table128[[#This Row],[Temperatur motgjutningsyta]]&Table128[[#This Row],[Värmekabel]]&Table128[[#This Row],[Antal värmekablar]]&Table128[[#This Row],[Täckning '[mm']]]&Table128[[#This Row],[Formisolering '[mm']]]&Table128[[#This Row],[OK<17 Timamr]]&Table128[[#This Row],[Kommentar]] -> 0,120540110Plywood 12-19 cellplast 50OK17
A20: 0.1 | B20: 20 | C20: 5 | D20: 40 | E20: 1 | F20: 10 | G20: Plywood 12-19 cellplast 70 | H20: 5 | I20: 12 | J20: 16.9 | K20: OK17 | M20: =Table128[[#This Row],[Slaggmängd]]&Table128[[#This Row],[Gjuttemperatur]]&Table128[[#This Row],[Temperatur motgjutningsyta]]&Table128[[#This Row],[Värmekabel]]&Table128[[#This Row],[Antal värmekablar]]&Table128[[#This Row],[Täckning '[mm']]]&Table128[[#This Row],[Formisolering '[mm']]]&Table128[[#This Row],[OK<17 Timamr]]&Table128[[#This Row],[Kommentar]] -> 0,120540110Plywood 12-19 cellplast 70OK17
A21: 0.1 | B21: 20 | C21: 5 | D21: 40 | E21: 1 | F21: 10 | G21: Plywood 12-19 cellplast 100 | H21: 5 | I21: 20 | J21: 17 | K21: OK17 | M21: =Table128[[#This Row],[Slaggmängd]]&Table128[[#This Row],[Gjuttemperatur]]&Table128[[#This Row],[Temperatur motgjutningsyta]]&Table128[[#This Row],[Värmekabel]]&Table128[[#This Row],[Antal värmekablar]]&Table128[[#This Row],[Täckning '[mm']]]&Table128[[#This Row],[Formisolering '[mm']]]&Table128[[#This Row],[OK<17 Timamr]]&Table128[[#This Row],[Kommentar]] -> 0,120540110Plywood 12-19 cellplast 100OK17
A22: 0.2 | B22: 20 | C22: 5 | D22: 40 | E22: 3 | F22: 10 | G22: Plywood 12-19 cellplast 100 | H22: 0 | I22: 0 | J22: 16.9 | K22: OK17 | M22: =Table128[[#This Row],[Slaggmängd]]&Table128[[#This Row],[Gjuttemperatur]]&Table128[[#This Row],[Temperatur motgjutningsyta]]&Table128[[#This Row],[Värmekabel]]&Table128[[#This Row],[Antal värmekablar]]&Table128[[#This Row],[Täckning '[mm']]]&Table128[[#This Row],[Formisolering '[mm']]]&Table128[[#This Row],[OK<17 Timamr]]&Table128[[#This Row],[Kommentar]] -> 0,220540310Plywood 12-19 cellplast 100OK17
A23: 0.1 | B23: 20 | C23: 5 | D23: 40 | E23: 1 | F23: 10 | G23: Plywood 12-19 cellplast 100 | H23: 0 | I23: 2 | J23: 16.8 | K23: OK17 | M23: =Table128[[#This Row],[Slaggmängd]]&Table128[[#This Row],[Gjuttemperatur]]&Table128[[#This Row],[Temperatur motgjutningsyta]]&Table128[[#This Row],[Värmekabel]]&Table128[[#This Row],[Antal värmekablar]]&Table128[[#This Row],[Täckning '[mm']]]&Table128[[#This Row],[Formisolering '[mm']]]&Table128[[#This Row],[OK<17 Timamr]]&Table128[[#This Row],[Kommentar]] -> 0,120540110Plywood 12-19 cellplast 100OK17
A24: 0.1 | B24: 20 | C24: 5 | D24: 40 | E24: 2 | F24: 10 | G24: Plywood 12-19 cellplast 50 | H24: 0 | I24: 7 | J24: 16.8 | K24: OK17 | M24: =Table128[[#This Row],[Slaggmängd]]&Table128[[#This Row],[Gjuttemperatur]]&Table128[[#This Row],[Temperatur motgjutningsyta]]&Table128[[#This Row],[Värmekabel]]&Table128[[#This Row],[Antal värmekablar]]&Table128[[#This Row],[Täckning '[mm']]]&Table128[[#This Row],[Formisolering '[mm']]]&Table128[[#This Row],[OK<17 Timamr]]&Table128[[#This Row],[Kommentar]] -> 0,120540210Plywood 12-19 cellplast 50OK17
A25: 0.1 | B25: 20 | C25: 5 | D25: 40 | E25: 2 | F25: 10 | G25: Plywood 12-19 cellplast 100 | H25: 0 | I25: 12 | J25: 16.6 | K25: OK17 | M25: =Table128[[#This Row],[Slaggmängd]]&Table128[[#This Row],[Gjuttemperatur]]&Table128[[#This Row],[Temperatur motgjutningsyta]]&Table128[[#This Row],[Värmekabel]]&Table128[[#This Row],[Antal värmekablar]]&Table128[[#This Row],[Täckning '[mm']]]&Table128[[#This Row],[Formisolering '[mm']]]&Table128[[#This Row],[OK<17 Timamr]]&Table128[[#This Row],[Kommentar]] -> 0,120540210Plywood 12-19 cellplast 100OK17
A26: 0.1 | B26: 20 | C26: 5 | D26: 40 | E26: 2 | F26: 10 | G26: Plywood 12-19 cellplast 120 | H26: 0 | I26: 20 | J26: 17 | K26: OK17 | M26: =Table128[[#This Row],[Slaggmängd]]&Table128[[#This Row],[Gjuttemperatur]]&Table128[[#This Row],[Temperatur motgjutningsyta]]&Table128[[#This Row],[Värmekabel]]&Table128[[#This Row],[Antal värmekablar]]&Table128[[#This Row],[Täckning '[mm']]]&Table128[[#This Row],[Formisolering '[mm']]]&Table128[[#This Row],[OK<17 Timamr]]&Table128[[#This Row],[Kommentar]] -> 0,120540210Plywood 12-19 cellplast 120OK17
A27: 0.1 | B27: 20 | C27: 5 | D27: 40 | E27: 1 | F27: 10 | G27: Plywood 12-19 cellplast 100 | H27: -5 | I27: 0 | J27: 16.7 | K27: OK17 | M27: =Table128[[#This Row],[Slaggmängd]]&Table128[[#This Row],[Gjuttemperatur]]&Table128[[#This Row],[Temperatur motgjutningsyta]]&Table128[[#This Row],[Värmekabel]]&Table128[[#This Row],[Antal värmekablar]]&Table128[[#This Row],[Täckning '[mm']]]&Table128[[#This Row],[Formisolering '[mm']]]&Table128[[#This Row],[OK<17 Timamr]]&Table128[[#This Row],[Kommentar]] -> 0,120540110Plywood 12-19 cellplast 100OK17
A28: 0.1 | B28: 20 | C28: 5 | D28: 40 | E28: 2 | F28: 10 | G28: Plywood 12-19 cellplast 50 | H28: -5 | I28: 2 | J28: 16.8 | K28: OK17 | M28: =Table128[[#This Row],[Slaggmängd]]&Table128[[#This Row],[Gjuttemperatur]]&Table128[[#This Row],[Temperatur motgjutningsyta]]&Table128[[#This Row],[Värmekabel]]&Table128[[#This Row],[Antal värmekablar]]&Table128[[#This Row],[Täckning '[mm']]]&Table128[[#This Row],[Formisolering '[mm']]]&Table128[[#This Row],[OK<17 Timamr]]&Table128[[#This Row],[Kommentar]] -> 0,120540210Plywood 12-19 cellplast 50OK17
A29: Bas+0% | B29: 20 | C29: 5 | D29: 40 | E29: 1 | F29: 10 | G29: Plywood 12-19 cellplast 100 | H29: -5 | I29: 7 | J29: 16.7 | K29: OK17 | M29: =Table128[[#This Row],[Slaggmängd]]&Table128[[#This Row],[Gjuttemperatur]]&Table128[[#This Row],[Temperatur motgjutningsyta]]&Table128[[#This Row],[Värmekabel]]&Table128[[#This Row],[Antal värmekablar]]&Table128[[#This Row],[Täckning '[mm']]]&Table128[[#This Row],[Formisolering '[mm']]]&Table128[[#This Row],[OK<17 Timamr]]&Table128[[#This Row],[Kommentar]] -> Bas+0%20540110Plywood 12-19 cellplast 100OK17
A30: Bas+0% | B30: 20 | C30: 5 | D30: 40 | E30: 2 | F30: 10 | G30: Plywood 12-19 cellplast 50 | H30: -5 | I30: 12 | J30: 16.8 | K30: OK17 | M30: =Table128[[#This Row],[Slaggmängd]]&Table128[[#This Row],[Gjuttemperatur]]&Table128[[#This Row],[Temperatur motgjutningsyta]]&Table128[[#This Row],[Värmekabel]]&Table128[[#This Row],[Antal värmekablar]]&Table128[[#This Row],[Täckning '[mm']]]&Table128[[#This Row],[Formisolering '[mm']]]&Table128[[#This Row],[OK<17 Timamr]]&Table128[[#This Row],[Kommentar]] -> Bas+0%20540210Plywood 12-19 cellplast 50OK17
A31: - | B31: - | C31: - | D31: - | E31: - | F31: - | G31: - | H31: -5 | I31: 20 | L31: Fryser innan täck | M31: =Table128[[#This Row],[Slaggmängd]]&Table128[[#This Row],[Gjuttemperatur]]&Table128[[#This Row],[Temperatur motgjutningsyta]]&Table128[[#This Row],[Värmekabel]]&Table128[[#This Row],[Antal värmekablar]]&Table128[[#This Row],[Täckning '[mm']]]&Table128[[#This Row],[Formisolering '[mm']]]&Table128[[#This Row],[OK<17 Timamr]]&Table128[[#This Row],[Kommentar]] -> -------Fryser innan täck
A32: 0.1 | B32: 20 | C32: 5 | D32: 40 | E32: 2 | F32: 10 | G32: Plywood 12-19 cellplast 50 | H32: -10 | I32: 0 | J32: 16.4 | K32: OK17 | M32: =Table128[[#This Row],[Slaggmängd]]&Table128[[#This Row],[Gjuttemperatur]]&Table128[[#This Row],[Temperatur motgjutningsyta]]&Table128[[#This Row],[Värmekabel]]&Table128[[#This Row],[Antal värmekablar]]&Table128[[#This Row],[Täckning '[mm']]]&Table128[[#This Row],[Formisolering '[mm']]]&Table128[[#This Row],[OK<17 Timamr]]&Table128[[#This Row],[Kommentar]] -> 0,120540210Plywood 12-19 cellplast 50OK17
A33: 0.1 | B33: 20 | C33: 5 | D33: 40 | E33: 3 | F33: 10 | G33: Plywood 12-19 cellplast 100 | H33: -10 | I33: 2 | J33: 16.8 | K33: OK17 | M33: =Table128[[#This Row],[Slaggmängd]]&Table128[[#This Row],[Gjuttemperatur]]&Table128[[#This Row],[Temperatur motgjutningsyta]]&Table128[[#This Row],[Värmekabel]]&Table128[[#This Row],[Antal värmekablar]]&Table128[[#This Row],[Täckning '[mm']]]&Table128[[#This Row],[Formisolering '[mm']]]&Table128[[#This Row],[OK<17 Timamr]]&Table128[[#This Row],[Kommentar]] -> 0,120540310Plywood 12-19 cellplast 100OK17
A34: Bas+0% | B34: 20 | C34: 5 | D34: 40 | E34: 2 | F34: 10 | G34: Plywood 12-19 cellplast 70 | H34: -10 | I34: 7 | J34: 17 | K34: OK17 | M34: =Table128[[#This Row],[Slaggmängd]]&Table128[[#This Row],[Gjuttemperatur]]&Table128[[#This Row],[Temperatur motgjutningsyta]]&Table128[[#This Row],[Värmekabel]]&Table128[[#This Row],[Antal värmekablar]]&Table128[[#This Row],[Täckning '[mm']]]&Table128[[#This Row],[Formisolering '[mm']]]&Table128[[#This Row],[OK<17 Timamr]]&Table128[[#This Row],[Kommentar]] -> Bas+0%20540210Plywood 12-19 cellplast 70OK17
A35: - | B35: - | C35: - | D35: - | E35: - | F35: - | G35: - | H35: -10 | I35: 12 | L35: Fryser innan täck | M35: =Table128[[#This Row],[Slaggmängd]]&Table128[[#This Row],[Gjuttemperatur]]&Table128[[#This Row],[Temperatur motgjutningsyta]]&Table128[[#This Row],[Värmekabel]]&Table128[[#This Row],[Antal värmekablar]]&Table128[[#This Row],[Täckning '[mm']]]&Table128[[#This Row],[Formisolering '[mm']]]&Table128[[#This Row],[OK<17 Timamr]]&Table128[[#This Row],[Kommentar]] -> -------Fryser innan täck
A36: - | B36: - | C36: - | D36: - | E36: - | F36: - | G36: - | H36: -10 | I36: 20 | L36: Fryser innan täck | M36: =Table128[[#This Row],[Slaggmängd]]&Table128[[#This Row],[Gjuttemperatur]]&Table128[[#This Row],[Temperatur motgjutningsyta]]&Table128[[#This Row],[Värmekabel]]&Table128[[#This Row],[Antal värmekablar]]&Table128[[#This Row],[Täckning '[mm']]]&Table128[[#This Row],[Formisolering '[mm']]]&Table128[[#This Row],[OK<17 Timamr]]&Table128[[#This Row],[Kommentar]] -> -------Fryser innan täck
A37: Bas+0% | B37: 15 | C37: 5 | D37: 40 | E37: 3 | F37: 50 | G37: Plywood 12-19 cellplast 70 | H37: -15 | I37: 0 | J37: 17 | K37: OK17 | M37: =Table128[[#This Row],[Slaggmängd]]&Table128[[#This Row],[Gjuttemperatur]]&Table128[[#This Row],[Temperatur motgjutningsyta]]&Table128[[#This Row],[Värmekabel]]&Table128[[#This Row],[Antal värmekablar]]&Table128[[#This Row],[Täckning '[mm']]]&Table128[[#This Row],[Formisolering '[mm']]]&Table128[[#This Row],[OK<17 Timamr]]&Table128[[#This Row],[Kommentar]] -> Bas+0%15540350Plywood 12-19 cellplast 70OK17
A38: - | B38: - | C38: - | D38: - | E38: - | F38: - | G38: - | H38: -15 | I38: 2 | L38: Når ej 6 MPa | M38: =Table128[[#This Row],[Slaggmängd]]&Table128[[#This Row],[Gjuttemperatur]]&Table128[[#This Row],[Temperatur motgjutningsyta]]&Table128[[#This Row],[Värmekabel]]&Table128[[#This Row],[Antal värmekablar]]&Table128[[#This Row],[Täckning '[mm']]]&Table128[[#This Row],[Formisolering '[mm']]]&Table128[[#This Row],[OK<17 Timamr]]&Table128[[#This Row],[Kommentar]] -> -------Når ej 6 MPa
A39: - | B39: - | C39: - | D39: - | E39: - | F39: - | G39: - | H39: -15 | I39: 7 | L39: Fryser innan täck | M39: =Table128[[#This Row],[Slaggmängd]]&Table128[[#This Row],[Gjuttemperatur]]&Table128[[#This Row],[Temperatur motgjutningsyta]]&Table128[[#This Row],[Värmekabel]]&Table128[[#This Row],[Antal värmekablar]]&Table128[[#This Row],[Täckning '[mm']]]&Table128[[#This Row],[Formisolering '[mm']]]&Table128[[#This Row],[OK<17 Timamr]]&Table128[[#This Row],[Kommentar]] -> -------Fryser innan täck
A40: - | B40: - | C40: - | D40: - | E40: - | F40: - | G40: - | H40: -15 | I40: 12 | L40: Fryser innan täck | M40: =Table128[[#This Row],[Slaggmängd]]&Table128[[#This Row],[Gjuttemperatur]]&Table128[[#This Row],[Temperatur motgjutningsyta]]&Table128[[#This Row],[Värmekabel]]&Table128[[#This Row],[Antal värmekablar]]&Table128[[#This Row],[Täckning '[mm']]]&Table128[[#This Row],[Formisolering '[mm']]]&Table128[[#This Row],[OK<17 Timamr]]&Table128[[#This Row],[Kommentar]] -> -------Fryser innan täck
...

Sheet Bjälklag (C30-37)
A1: Slaggmängd | B1: Gjuttemperatur | C1: Temperatur motgjutningsyta | D1: Värmekabel | E1: Antal värmekablar | F1: Täckning [mm] | G1: Formisolering [mm] | H1: Temperatur | I1: Vind | J1: <17 Timmar och >6 Mpa | K1: OK<17 Timamr | L1: Kommentar | M1: Åtgärdskåd
A2: 0.2 | B2: 15 | C2: 20 | D2: - | E2: - | F2: - | G2: Plywood 15, oisolerat | H2: 20 | I2: 0 | J2: 16.9 | K2: OK17 | M2: =Table132[[#This Row],[Slaggmängd]]&Table132[[#This Row],[Gjuttemperatur]]&Table132[[#This Row],[Temperatur motgjutningsyta]]&Table132[[#This Row],[Värmekabel]]&Table132[[#This Row],[Antal värmekablar]]&Table132[[#This Row],[Täckning '[mm']]]&Table132[[#This Row],[Formisolering '[mm']]]&Table132[[#This Row],[OK<17 Timamr]]&Table132[[#This Row],[Kommentar]] -> 0,21520---Plywood 15, oisoleratOK17
A3: 0.2 | B3: 15 | C3: 20 | D3: - | E3: - | F3: - | G3: Plywood 15, oisolerat | H3: 20 | I3: 2 | J3: 17 | K3: OK17 | M3: =Table132[[#This Row],[Slaggmängd]]&Table132[[#This Row],[Gjuttemperatur]]&Table132[[#This Row],[Temperatur motgjutningsyta]]&Table132[[#This Row],[Värmekabel]]&Table132[[#This Row],[Antal värmekablar]]&Table132[[#This Row],[Täckning '[mm']]]&Table132[[#This Row],[Formisolering '[mm']]]&Table132[[#This Row],[OK<17 Timamr]]&Table132[[#This Row],[Kommentar]] -> 0,21520---Plywood 15, oisoleratOK17
A4: 0.2 | B4: 15 | C4: 20 | D4: - | E4: - | F4: - | G4: Plywood 15, oisolerat | H4: 20 | I4: 7 | J4: 17 | K4: OK17 | M4: =Table132[[#This Row],[Slaggmängd]]&Table132[[#This Row],[Gjuttemperatur]]&Table132[[#This Row],[Temperatur motgjutningsyta]]&Table132[[#This Row],[Värmekabel]]&Table132[[#This Row],[Antal värmekablar]]&Table132[[#This Row],[Täckning '[mm']]]&Table132[[#This Row],[Formisolering '[mm']]]&Table132[[#This Row],[OK<17 Timamr]]&Table132[[#This Row],[Kommentar]] -> 0,21520---Plywood 15, oisoleratOK17
A5: 0.2 | B5: 15 | C5: 20 | D5: - | E5: - | F5: - | G5: Plywood 15, oisolerat | H5: 20 | I5: 12 | J5: 17 | K5: OK17 | M5: =Table132[[#This Row],[Slaggmängd]]&Table132[[#This Row],[Gjuttemperatur]]&Table132[[#This Row],[Temperatur motgjutningsyta]]&Table132[[#This Row],[Värmekabel]]&Table132[[#This Row],[Antal värmekablar]]&Table132[[#This Row],[Täckning '[mm']]]&Table132[[#This Row],[Formisolering '[mm']]]&Table132[[#This Row],[OK<17 Timamr]]&Table132[[#This Row],[Kommentar]] -> 0,21520---Plywood 15, oisoleratOK17
A6: 0.2 | B6: 15 | C6: 20 | D6: - | E6: - | F6: - | G6: Plywood 15, oisolerat | H6: 20 | I6: 20 | J6: 17 | K6: OK17 | M6: =Table132[[#This Row],[Slaggmängd]]&Table132[[#This Row],[Gjuttemperatur]]&Table132[[#This Row],[Temperatur motgjutningsyta]]&Table132[[#This Row],[Värmekabel]]&Table132[[#This Row],[Antal värmekablar]]&Table132[[#This Row],[Täckning '[mm']]]&Table132[[#This Row],[Formisolering '[mm']]]&Table132[[#This Row],[OK<17 Timamr]]&Table132[[#This Row],[Kommentar]] -> 0,21520---Plywood 15, oisoleratOK17
